Workbook

Sheet Rekap
B2: REKAP DATA PENDUDUK
B3: LINGKUNGAN BAWAK GUNUNG
B4: RT | C4: Jumlah Penduduk | E4: Total | F4: Jumlah KK | H4: Total | I4: Jumlah Duda / Janda | K4: Total | L4: Jumlah Lansia ( =>60 ) | N4: Total
C5: L | D5: P | F5: L | G5: P | I5: L | J5: P | L5: L | M5: P
B6: RT 1 | C6: =COUNTIF('RT 01'!$H$8:$H$394,"L") -> 187 | D6: =COUNTIF('RT 01'!$H$8:$H$394,"P") -> 200 | E6: =SUM(C6:D6) -> 387 | F6: =COUNTIFS('RT 01'!$F$8:$F$394,"KK",'RT 01'!$H$8:$H$394,"L") -> 104 | G6: =COUNTIFS('RT 01'!$F$8:$F$394,"KK",'RT 01'!$H$8:$H$394,"P") -> 20 | H6: =SUM(F6:G6) -> 124 | I6: =COUNTIFS('RT 01'!$I$8:$I$394,"Cerai Mati",'RT 01'!$H$8:$H$394,"L")+COUNTIFS('RT 01'!$I$8:$I$394,"Cerai Hidup",'RT 01'!$H$8:$H$394,"L")+COUNTIFS('RT 01'!$I$8:$I$394,"Duda",'RT 01'!$H$8:$H$394,"L") -> 3 | J6: =COUNTIFS('RT 01'!$I$8:$I$394,"Cerai Mati",'RT 01'!$H$8:$H$394,"P")+COUNTIFS('RT 01'!$I$8:$I$394,"Cerai Hidup",'RT 01'!$H$8:$H$394,"P")+COUNTIFS('RT 01'!$I$8:$I$394,"Janda",'RT 01'!$H$8:$H$394,"P") -> 21 | K6: =SUM(I6:J6) -> 24 | L6: 16 | M6: 15 | N6: =SUM(L6:M6) -> 31
B7: RT 2 | C7: =COUNTIF('RT 02'!$H$8:$H$204,"L") -> 94 | D7: =COUNTIF('RT 02'!$H$8:$H$204,"P") -> 103 | E7: =SUM(C7:D7) -> 197 | F7: =COUNTIFS('RT 02'!$F$8:$F$204,"KK",'RT 02'!$H$8:$H$204,"L") -> 53 | G7: =COUNTIFS('RT 02'!$F$8:$F$204,"KK",'RT 02'!$H$8:$H$204,"P") -> 13 | H7: =SUM(F7:G7) -> 66 | I7: =COUNTIFS('RT 02'!$I$8:$I$204,"Cerai Mati",'RT 02'!$H$8:$H$204,"L")+COUNTIFS('RT 02'!$I$8:$I$204,"Cerai Hidup",'RT 02'!$H$8:$H$204,"L")+COUNTIFS('RT 02'!$I$8:$I$204,"Duda",'RT 02'!$H$8:$H$204,"L") -> 4 | J7: =COUNTIFS('RT 02'!$I$8:$I$204,"Cerai Mati",'RT 02'!$H$8:$H$204,"P")+COUNTIFS('RT 02'!$I$8:$I$204,"Cerai Hidup",'RT 02'!$H$8:$H$204,"P")+COUNTIFS('RT 02'!$I$8:$I$204,"Janda",'RT 02'!$H$8:$H$204,"P") -> 15 | K7: =SUM(I7:J7) -> 19 | L7: 10 | M7: 11 | N7: =SUM(L7:M7) -> 21
B8: RT 3 | C8: =COUNTIF('RT 03'!$H$8:$H$291,"L") -> 123 | D8: =COUNTIF('RT 03'!$H$8:$H$291,"P") -> 161 | E8: =SUM(C8:D8) -> 284 | F8: =COUNTIFS('RT 03'!$F$8:$F$291,"KK",'RT 03'!$H$8:$H$291,"L") -> 76 | G8: =COUNTIFS('RT 03'!$F$8:$F$291,"KK",'RT 03'!$H$8:$H$291,"P") -> 29 | H8: =SUM(F8:G8) -> 105 | I8: =COUNTIFS('RT 03'!$I$8:$I$291,"Cerai Mati",'RT 03'!$H$8:$H$291,"L")+COUNTIFS('RT 03'!$I$8:$I$291,"Cerai Hidup",'RT 03'!$H$8:$H$291,"L")+COUNTIFS('RT 03'!$I$8:$I$291,"Duda",'RT 03'!$H$8:$H$291,"L") -> 6 | J8: =COUNTIFS('RT 03'!$I$8:$I$291,"Cerai Mati",'RT 03'!$H$8:$H$291,"P")+COUNTIFS('RT 03'!$I$8:$I$291,"Cerai Hidup",'RT 03'!$H$8:$H$291,"P")+COUNTIFS('RT 03'!$I$8:$I$291,"Janda",'RT 03'!$H$8:$H$291,"P") -> 34 | K8: =SUM(I8:J8) -> 40 | L8: 18 | M8: 29 | N8: =SUM(L8:M8) -> 47
B9: RT 4 | C9: =COUNTIF('RT 04'!$H$8:$H$167,"L") -> 76 | D9: =COUNTIF('RT 04'!$H$8:$H$167,"P") -> 84 | E9: =SUM(C9:D9) -> 160 | F9: =COUNTIFS('RT 04'!$F$8:$F$167,"KK",'RT 04'!$H$8:$H$167,"L") -> 41 | G9: =COUNTIFS('RT 04'!$F$8:$F$167,"KK",'RT 04'!$H$8:$H$167,"P") -> 13 | H9: =SUM(F9:G9) -> 54 | I9: =COUNTIFS('RT 04'!$I$8:$I$167,"Cerai Mati",'RT 04'!$H$8:$H$167,"L")+COUNTIFS('RT 04'!$I$8:$I$167,"Cerai Hidup",'RT 04'!$H$8:$H$167,"L")+COUNTIFS('RT 04'!$I$8:$I$167,"Duda",'RT 04'!$H$8:$H$167,"L") -> 4 | J9: =COUNTIFS('RT 04'!$I$8:$I$167,"Cerai Mati",'RT 04'!$H$8:$H$167,"P")+COUNTIFS('RT 04'!$I$8:$I$167,"Cerai Hidup",'RT 04'!$H$8:$H$167,"P")+COUNTIFS('RT 04'!$I$8:$I$167,"Janda",'RT 04'!$H$8:$H$167,"P") -> 21 | K9: =SUM(I9:J9) -> 25 | L9: 13 | M9: 17 | N9: =SUM(L9:M9) -> 30
B10: JUMLAH TOTAL | C10: =SUM(C6:C9) -> 480 | D10: =SUM(D6:D9) -> 548 | E10: =SUM(E6:E9) -> 1028 | F10: =SUM(F6:F9) -> 274 | G10: =SUM(G6:G9) -> 75 | H10: =SUM(H6:H9) -> 349 | I10: =SUM(I6:I9) -> 17 | J10: =SUM(J6:J9) -> 91 | ... N10: =SUM(N6:N9) -> 129
C14: Mengetahui
C15: Lurah Dasan Geres | K15: Kepala Lingkungan
C19: Hulaifi, S.H. | K19: Sahidir
C20: NIP. 19841231 201101 1 023

Sheet RT 01
B1: DATA INDUK PENDUDUK KELURAHAN DASAN GERES
B2: TAHUN 2019
B3: LINGKUNGAN BAWAK GUNUNG
B4: RT 01
B5: No. | C5: Nomor KK | D5: Jumlah Jiwa | E5: Nama Lengkap / Panggilan | F5: Kedudukan dalam Keluarga | G5: NIK | H5: Jenis Kelamin (L/P) | I5: Status Perkawinan | J5: Lahir | M5: Usia | N5: Agama | O5: Etnis | P5: Pendidikan Terakhir | Q5: Jurusan | R5: Pekerjaan
J6: Tempat | K6: Tanggal | L6: Tahun
B8: 1 | D8: 1 | E8: Haji Mukhtar | F8: KK | G8: 520101 3112720143 | H8: L | I8: Kawin | K8: 26664 | L8: =YEAR(K8) -> 1972 | M8: =2019-L8 -> 47 | N8: Islam | P8: SLTA/MA | R8: Pegawai swasta
D9: 2 | E9: Rosipah | F9: Istri | G9: 520101 7112750199 | H9: P | I9: Kawin | K9: 27759 | L9: =YEAR(K9) -> 1975 | M9: =2019-L9 -> 44 | N9: Islam | P9: - | R9: Pedagang
D10: 3 | E10: Sihabudin | F10: Anak | G10: 520101 1901950001 | H10: L | I10: Belum kawin | K10: 34718 | L10: =YEAR(K10) -> 1995 | M10: =2019-L10 -> 24 | N10: Islam | P10: SLTA/MA | R10: Pekerja lepas
D11: 4 | E11: Khairul Anan | F11: Anak | G11: 520101 0811040002 | H11: L | I11: Belum kawin | K11: 38210 | L11: =YEAR(K11) -> 2004 | M11: =2019-L11 -> 15 | N11: Islam | P11: SD/MI | R11: -
D12: 5 | E12: Suhra Wardi | F12: Anak | G12: 520101 2803120002 | H12: L | I12: Belum kawin | K12: 40996 | L12: =YEAR(K12) -> 2012 | M12: =2019-L12 -> 7 | N12: Islam | P12: - | R12: -
B13: 2 | C13: 520101 1109120008 | D13: 6 | E13: Arta Winata | F13: KK | G13: 520101 1210810003 | H13: L | I13: Kawin | J13: Lembar | K13: 29871 | L13: 1981 | M13: =2019-L13 -> 38 | N13: Islam | O13: Sasak | P13: SLTA/SEDERAJAT | R13: Karyawan Swasta
D14: 7 | E14: Surianti | F14: Istri | G14: 520101 7112870166 | H14: P | I14: Kawin | J14: Aik Ampat | K14: 32142 | L14: 1987 | M14: =2019-L14 -> 32 | N14: Islam | O14: Sasak | P14: DIPLOMA IV/STRATA 1 | R14: Guru
D15: 8 | E15: Cahaya Artanti | F15: Anak | G15: 520101 4409090003 | H15: P | I15: Belum kawin | J15: Gerung | K15: 40060 | L15: 2009 | M15: =2019-L15 -> 10 | N15: Islam | O15: Sasak | P15: TIDAK/BELUM SEKOLAH | R15: Belum/Tidak Bekerja
B16: 3 | C16: 520101 2210120017 | D16: 9 | E16: Ariawan | F16: KK | G16: 520101 3112880035 | H16: L | I16: Kawin | J16: Aik Ampat | K16: 32345 | L16: 1988 | M16: =2019-L16 -> 31 | N16: Islam | O16: Sasak | P16: TIDAK/BELUM SEKOLAH | R16: buruh harian lepas
D17: 10 | E17: Murjiah | F17: Istri | G17: 520101 4606910001 | H17: P | I17: Kawin | J17: Cemare | K17: 33395 | L17: 1991 | M17: =2019-L17 -> 28 | N17: Islam | O17: Sasak | P17: SD/MI | R17: Belum/Tidak Bekerja
D18: 11 | E18: Muhamad Haekam | F18: Anak | G18: 520101 0307150002 | H18: L | I18: Belum kawin | J18: Aik Ampat | K18: 42188 | L18: 2015 | M18: =2019-L18 -> 4 | N18: Islam | O18: Sasak | P18: TIDAK/BELUM SEKOLAH | R18: Belum/Tidak Bekerja
B19: 4 | C19: 520101 0503089050 | D19: 12 | E19: Basri | F19: KK | G19: 520101 1312701001 | H19: L | I19: Kawin | J19: Bawak Gunung | K19: 25915 | L19: 1970 | M19: =2019-L19 -> 49 | N19: Islam | O19: Sasak | P19: TIDAK/BELUM SEKOLAH | R19: Buruh Harian Lepas
D20: 13 | E20: Ma’ah | F20: Istri | G20: 520101 7112701007 | H20: P | I20: Kawin | J20: Bawak Gunung | K20: 25933 | L20: 1970 | M20: =2019-L20 -> 49 | N20: Islam | O20: Sasak | P20: TAMAT SD/SEDERAJAT | R20: Buruh Harian Lepas
D21: 14 | E21: Muhamad Samsul Hadi | F21: Anak | G21: 520101 0107051001 | H21: L | I21: Belum kawin | J21: Bawak Gunung | K21: 38534 | L21: 2005 | M21: =2019-L21 -> 14 | N21: Islam | O21: Sasak | P21: BELUM TAMAT SD/SEDERAJAT | R21: Pelajar/Mahasiswa
B22: 5 | C22: 520101 0503088784 | D22: 15 | E22: Nurhadi | F22: KK | G22: 520101 0107850383 | H22: L | I22: Kawin | J22: Bawak Gunung | K22: 31229 | L22: 1985 | M22: =2019-L22 -> 34 | N22: Islam | O22: Sasak | P22: SD/MI | R22: Wiraswasta
D23: 16 | E23: Helmianti | F23: Istri | G23: 520101 4107870449 | H23: P | I23: Kawin | J23: Batu Mulik | K23: 32965 | L23: 1990 | M23: =2019-L23 -> 29 | N23: Islam | O23: Sasak | P23: SD/MI | R23: Mengurus Rumah Tangga
D24: 17 | E24: Ayudia Asanti | F24: Anak | G24: 520101 5104110006 | H24: P | I24: Belum kawin | J24: Bawak Gunung | K24: 11 April 20011 | L24: 2011 | M24: =2019-L24 -> 8 | N24: Islam | O24: Sasak | P24: TIDAK/BELUM SEKOLAH | R24: Belum/Tidak Bekerja
B25: 6 | C25: 520101 0104150004 | D25: 18 | E25: Iwan Saputra | F25: KK | G25: 520101 0505830002 | H25: L | I25: Kawin | J25: Bawak Gunung | K25: 30441 | L25: 1983 | M25: =2019-L25 -> 36 | N25: Islam | O25: Sasak | P25: SD/MI | R25: Wiraswasta
D26: 19 | E26: Miskah | F26: Istri | G26: 520101 7112870228 | H26: P | I26: Kawin | J26: Bawak Gunung | K26: 32142 | L26: 1987 | M26: =2019-L26 -> 32 | N26: Islam | O26: Sasak | P26: SD/MI | R26: Mengurus Rumah Tangga
D27: 20 | E27: Haziaratul Nasuha | F27: Anak | G27: 520101 4710110003 | H27: P | I27: Belum kawin | J27: Aik Ampat | K27: 40823 | L27: 2011 | M27: =2019-L27 -> 8 | N27: Islam | O27: Sasak | P27: TIDAK/BELUM SEKOLAH | R27: Belum/Tidak Bekerja
B28: 7 | D28: 21 | E28: Hajjah Saibah Ilhami | F28: KK | G28: 520101 1712850282 | H28: P | I28: Kawin | K28: 31412 | L28: =YEAR(K28) -> 1985 | M28: =2019-L28 -> 34 | N28: Islam | P28: SLTP/MTSN | R28: Petani
D29: 22 | E29: Katrun Nada | F29: Anak | G29: 520101 8907080002 | H29: P | I29: Belum kawin | K29: 39654 | L29: =YEAR(K29) -> 2008 | M29: =2019-L29 -> 11 | N29: Islam | P29: - | R29: -
B30: 8 | D30: 23 | E30: Mahsun | F30: KK | G30: 520101 1312850003 | H30: L | I30: Kawin | K30: 30594 | L30: =YEAR(K30) -> 1983 | M30: =2019-L30 -> 36 | N30: Islam | P30: SD/MI | R30: Pekerja lepas
D31: 24 | E31: Sahini | F31: Istri | G31: 520101 7112860162 | H31: P | I31: Kawin | K31: 32508 | L31: =YEAR(K31) -> 1988 | M31: =2019-L31 -> 31 | N31: Islam | P31: SD/MI | R31: Pekerja lepas
B32: 9 | D32: 25 | E32: Mariah | F32: KK | G32: 0 | H32: P | I32: Janda | K32: 24022 | L32: =YEAR(K32) -> 1965 | M32: =2019-L32 -> 54 | N32: Islam | P32: - | R32: Pekerja lepas
D33: 26 | E33: Tohri | F33: Anak | G33: 0 | H33: L | I33: Belum kawin | K33: 33610 | L33: =YEAR(K33) -> 1992 | M33: =2019-L33 -> 27 | N33: Islam | P33: SLTP/MTSN | R33: Pekerja lepas
B34: 10 | D34: 27 | E34: Naswin | F34: KK | G34: 520101 0107821020 | H34: L | I34: Kawin | K34: 12054 | L34: =YEAR(K34) -> 1932 | M34: =2019-L34 -> 87 | N34: Islam | P34: SLTP/MTSN | R34: Wiraswasta
D35: 28 | E35: Juliantin | F35: Istri | G35: 520101 5708850002 | H35: P | I35: Kawin | K35: 31215 | L35: =YEAR(K35) -> 1985 | M35: =2019-L35 -> 34 | N35: Islam | P35: SLTA/MA | R35: -
D36: 29 | E36: Nela Deswita Putri | F36: Anak | G36: 520101 6812040001 | H36: P | I36: Belum kawin | K36: 38349 | L36: =YEAR(K36) -> 2004 | M36: =2019-L36 -> 15 | N36: Islam | P36: - | R36: -
B37: 11 | C37: 520101 2611090009 | D37: 30 | E37: Rosihin | F37: KK | G37: 520101 1002820001 | H37: L | I37: Kawin | J37: Aik Ampat | K37: 30316 | L37: 1982 | M37: =2019-L37 -> 37 | N37: Islam | O37: Sasak | P37: TAMAT SD/SEDERAJAT | R37: Wiraswasta
D38: 31 | E38: Munirah | F38: Istri | G38: 520101 4017860063 | H38: P | I38: Kawin | J38: Bawak Gunung | K38: 31594 | L38: 1986 | M38: =2019-L38 -> 33 | N38: Islam | O38: Sasak | P38: SLTP/SEDERAJAT | R38: Mengurus Rumah Tangga
D39: 32 | E39: M. Havizan | F39: Anak | G39: 520101 412070002 | H39: L | I39: Belum kawin | J39: Bawak Gunung | K39: 39420 | L39: 2007 | M39: =2019-L39 -> 12 | N39: Islam | O39: Sasak | P39: BELUM TAMAT SD/SEDERAJAT | R39: Pelajar/Mahasiswa
B40: 12 | D40: 33 | E40: Jumisah | F40: KK | G40: 520101 1302740005 | H40: L | I40: Kawin | K40: 27073 | L40: =YEAR(K40) -> 1974 | M40: =2019-L40 -> 45 | N40: Islam | P40: SD/MI | R40: Pekerja lepas
D41: 34 | E41: Hamnah | F41: Istri | G41: 520101 530270008 | H41: P | I41: Kawin | K41: 26708 | L41: =YEAR(K41) -> 1973 | M41: =2019-L41 -> 46 | N41: Islam | P41: SD/MI | R41: Pedagang
...

Sheet RT 02
B1: DATA INDUK PENDUDUK KELURAHAN DASAN GERES
B2: TAHUN 2019
B3: LINGKUNGAN BAWAK GUNUNG
B4: RT 02
B5: No | C5: Nomor KK | D5: Jumlah Jiwa | E5: Nama Lengkap/ Panggilan | F5: Kedudukan dalam Keluarga | G5: NIK | H5: Jenis Kelamin (L/P) | I5: Status Perkawinan | J5: Lahir | M5: Usia | N5: Agama | O5: Etnis | P5: Pendidikan Terakhir | Q5: Jurusan | R5: Pekerjaan
J6: Tempat | K6: Tanggal | L6: Tahun
B8: 1 | C8: 520101 0503088216 | D8: 1 | E8: Husne | F8: KK | G8: 520101 4107700243 | H8: P | I8: Kawin | J8: Bawak Gunung | K8: 25750 | L8: 1970 | M8: =2019-L8 -> 49 | N8: Islam | O8: Sasak | P8: TAMAT SD/SEDERAJAT | R8: Mengurus Rumah Tangga
B9: 2 | C9: 520101 2502141010 | D9: 2 | E9: Gusni | F9: KK | G9: 520101 0107830116 | H9: L | I9: Kawin | J9: Aik Ampat | K9: 29545 | L9: 1980 | M9: =2019-L9 -> 39 | N9: Islam | O9: Sasak | P9: SLTP/MTSN | R9: Buruh Harian Lepas
D10: 3 | E10: Mukinah | F10: Istri | G10: 520101 6510830003 | H10: P | I10: Kawin | J10: Dasan Geres | K10: 30614 | L10: 1983 | M10: =2019-L10 -> 36 | N10: Islam | O10: Sasak | P10: SLTA/SEDERAJAT | R10: Buruh Harian Lepas
D11: 4 | E11: Zurriyatun Toyyibah | F11: Anak | G11: 520101 5002090004 | H11: P | I11: Belum kawin | J11: Cemare | K11: 39854 | L11: 2009 | M11: =2019-L11 -> 10 | N11: Islam | O11: Sasak | P11: TIDAK/BLM SEKOLAH | R11: Belum / Tidak Bekerja
B12: 3 | C12: 520101 0503088551 | D12: 5 | E12: Ilham | F12: KK | G12: 520101 0111800001 | H12: L | I12: Kawin | J12: Bawak Gunung | K12: 29526 | L12: 1980 | M12: =2019-L12 -> 39 | N12: Islam | O12: Sasak | P12: SD/MI | R12: Buruh Harian Lepas
D13: 6 | E13: Nurhidayah | F13: Istri | G13: 520101 4706860004 | H13: P | I13: Kawin | J13: Aik Ampat | K13: 31539 | L13: 1986 | M13: =2019-L13 -> 33 | N13: Islam | O13: Sasak | P13: SLTP/MTSN | R13: Mengurus Rumah Tangga
D14: 7 | E14: Maria Ulfa | F14: Anak | G14: 520101 5311050001 | H14: P | I14: Belum kawin | J14: Bawak Gunung | K14: 38669 | L14: 2005 | M14: =2019-L14 -> 14 | N14: Islam | O14: Sasak | P14: SD/MI | R14: Pelajar / Mahasiswa
D15: 8 | E15: Ainul Arifah | F15: Anak | G15: 520101 4209120002 | H15: P | I15: Belum kawin | J15: Dasan Geres | K15: 41123 | L15: 2012 | M15: =2019-L15 -> 7 | N15: Islam | O15: Sasak | P15: TIDAK/BLM SEKOLAH | R15: Belum / Tidak Bekerja
B16: 4 | C16: 520101 0503088630 | D16: 9 | E16: Ahmad Zaenudin | F16: KK | G16: 520101 0107770244 | H16: L | I16: Kawin | J16: Bawak Gunung | K16: 27759 | L16: 1975 | M16: =2019-L16 -> 44 | N16: Islam | O16: Sasak | P16: TIDAK/BLM SEKOLAH | R16: Buruh Harian Lepas
D17: 10 | E17: Uswatun Hasanah | F17: Istri | G17: 520101 4107800361 | H17: P | I17: Kawin | J17: Aik Ampat | K17: 30334 | L17: 1983 | M17: =2019-L17 -> 36 | N17: Islam | O17: Sasak | P17: SLTP/SEDERAJAT | R17: Mengurus Rumah Tangga
D18: 11 | E18: Nahjul Istiqomah | F18: Anak | G18: 520101 4107030061 | H18: P | I18: Belum kawin | J18: Aik Ampat | K18: 37388 | L18: 2002 | M18: =2019-L18 -> 17 | N18: Islam | O18: Sasak | P18: SLTP/SEDERAJAT | R18: Pelajar / Mahasiswa
D19: 12 | E19: M. Urwatil Wutsqo | F19: anak | G19: 520101 1020170003 | H19: L | I19: Belum kawin | J19: Aik Ampat | K19: 43010 | L19: 2017 | M19: =2019-L19 -> 2 | N19: Islam | O19: Sasak | P19: TIDAK/BLM SEKOLAH | R19: Belum / Tidak Bekerja
B20: 5 | C20: 520101 3103120008 | D20: 13 | E20: Rahman | F20: KK | G20: 520101 3112600210 | H20: L | I20: Kawin | J20: Aik Ampat | K20: 22263 | L20: 1960 | M20: =2019-L20 -> 59 | N20: Islam | O20: Sasak | P20: TIDAK/BLM SEKOLAH | R20: Buruh Harian Lepas
D21: 14 | E21: Almah | F21: Istri | G21: 520101 7112700186 | H21: P | I21: Kawin | J21: Aik Ampat | K21: 25933 | L21: 1970 | M21: =2019-L21 -> 49 | N21: Islam | O21: Sasak | P21: TIDAK/BLM SEKOLAH | R21: Buruh Harian Lepas
D22: 15 | E22: Ahyar Rosidi | F22: Anak | G22: 520101 0108860003 | H22: L | I22: Belum kawin | J22: Aik Ampat | K22: 31656 | L22: 1986 | M22: =2019-L22 -> 33 | N22: Islam | O22: Sasak | P22: SLTP/SEDERAJAT | R22: Buruh Harian Lepas
D23: 16 | E23: Musabbi Baskiar Hollid | F23: Cucu | G23: 520101 1206090002 | H23: L | I23: Belum kawin | J23: Menang | K23: 39976 | L23: 2009 | M23: =2019-L23 -> 10 | N23: Islam | O23: Sasak | P23: TIDAK/BLM SEKOLAH | R23: Belum / Tidak Bekerja
B24: 6 | C24: 520101 2405130008 | D24: 17 | E24: H. Alimudin | F24: KK | G24: 520101 0107840438 | H24: L | I24: Kawin | J24: Aik Ampat | K24: 30864 | L24: 1984 | M24: =2019-L24 -> 35 | N24: Islam | P24: SD/MI | R24: Buruh Harian Lepas
D25: 18 | E25: Yulianti | F25: Istri | G25: 520101 5707870004 | H25: P | I25: Kawin | J25: Sumbawa | K25: 31975 | L25: 1987 | M25: =2019-L25 -> 32 | N25: Islam | P25: SLTP/MTSN | R25: Buruh Harian Lepas
D26: 19 | E26: M. Arjan Risqi | F26: Anak | G26: 520101 2702130002 | H26: L | I26: Belum kawin | J26: Aik Ampat | K26: 41332 | L26: 2013 | M26: =2019-L26 -> 6 | N26: Islam | P26: TIDAK/BLM SEKOLAH | R26: Belum / Tidak Bekerja
D27: 20 | E27: M. Ahlal | F27: Anak | G27: 520101 2311140001 | H27: L | I27: Belum kawin | J27: Aik Ampat | K27: 41966 | L27: 2014 | M27: =2019-L27 -> 5 | N27: Islam | P27: TIDAK/BLM SEKOLAH | R27: Belum / Tidak Bekerja
B28: 7 | D28: 21 | E28: Kecah | F28: KK | G28: 0 | H28: P | I28: Janda | K28: 11140 | L28: =YEAR(K28) -> 1930 | M28: =2019-L28 -> 89 | N28: Islam | P28: - | R28: -
B29: 8 | C29: 520101 1403120017 | D29: 22 | E29: Inaq Bah | F29: KK | G29: 520101 4107400027 | H29: P | I29: Cerai Mati | J29: Bawak Gunung | K29: 14793 | L29: 1940 | M29: =2019-L29 -> 79 | N29: Islam | O29: Sasak | P29: TAMAT SD/SEDERAJAT | R29: Buruh Harian Lepas
D30: 23 | E30: Lia Izmi | F30: Anak | G30: 520101 5803991001 | H30: P | I30: Belum kawin | J30: Aik Ampat | K30: 36237 | L30: 1999 | M30: =2019-L30 -> 20 | N30: Islam | O30: Sasak | P30: SLTP/MTSN | R30: Pelajar / Mahasiswa
D31: 24 | E31: Siti Habibah | F31: Anak | G31: 520101 6908071001 | H31: P | I31: Belum kawin | J31: Aik Ampat | K31: 39322 | L31: 2007 | M31: =2019-L31 -> 12 | N31: Islam | O31: Sasak | P31: TIDAK/BLM SEKOLAH | R31: Belum / Tidak Bekerja
B32: 9 | D32: 25 | E32: Husni | F32: KK | G32: 520101 0107610155 | H32: L | I32: Duda | K32: 22463 | L32: =YEAR(K32) -> 1961 | M32: =2019-L32 -> 58 | N32: Islam | P32: - | R32: Pekerja lepas
B33: 10 | C33: 520101 0503088154 | D33: 26 | E33: Saibi | F33: KK | G33: 520101 2007840002 | H33: L | I33: Kawin | J33: Bawak Gunung | K33: 30883 | L33: 1984 | M33: =2019-L33 -> 35 | N33: Islam | O33: Sasak | P33: TAMAT SD/SEDERAJAT | R33: Buruh Harian Lepas
D34: 27 | E34: Rina | F34: Istri | G34: 520112 4107800386 | H34: P | I34: Kawin | J34: Karang Bayan | K34: 29403 | L34: 1980 | M34: =2019-L34 -> 39 | N34: Islam | O34: Sasak | P34: TAMAT SD/SEDERAJAT | R34: Buruh Harian Lepas
B35: 11 | C35: 520101 3103120010 | D35: 28 | E35: Mar’i | F35: KK | G35: 520101 3112740142 | H35: L | I35: Kawin | J35: Lombok Barat | K35: 27394 | L35: 1974 | M35: =2019-L35 -> 45 | N35: Islam | O35: Sasak | P35: SLTA/MA | R35: Buruh Harian Lepas
D36: 29 | E36: Maswah | F36: Istri | G36: 520101 7112740138 | H36: P | I36: Kawin | J36: Aik Ampat | K36: 27759 | L36: 1975 | M36: =2019-L36 -> 44 | N36: Islam | O36: Sasak | P36: SLTP/MTSN | R36: Mengurus Rumah Tangga
D37: 30 | E37: Zulmarwatika | F37: Anak | G37: 520101 5504970001 | H37: P | I37: Belum kawin | J37: Bawak Gunung | K37: 35535 | L37: 1997 | M37: =2019-L37 -> 22 | N37: Islam | O37: Sasak | P37: SLTP/MTSN | R37: Pelajar / Mahasiswa
D38: 31 | E38: Azzahra Wani | F38: Anak | G38: 520101 5411110001 | H38: P | I38: Belum kawin | J38: Bawak Gunung | K38: 40861 | L38: 2011 | M38: =2019-L38 -> 8 | N38: Islam | O38: Sasak | P38: TIDAK/BLM SEKOLAH | R38: Belum / Tidak Bekerja
D39: 32 | E39: Muhammad Hifdzi | F39: Anak | G39: 520101 2004150001 | H39: L | I39: Belum kawin | J39: Gerung | K39: 42114 | L39: 2015 | M39: =2019-L39 -> 4 | N39: Islam | O39: Sasak | P39: TIDAK/BLM SEKOLAH | R39: Belum / Tidak Bekerja
B40: 12 | C40: 520101 0612090048 | D40: 33 | E40: Bahmin | F40: KK | G40: 520101 3112620014 | H40: L | I40: Kawin | J40: Aik Ampat | K40: 23011 | L40: 1962 | M40: =2019-L40 -> 57 | N40: Islam | O40: Sasak | P40: BELUM TAMAT SD/SEDERAJAT | R40: Petani/Pekebun
D41: 34 | E41: Khadijah | F41: Istri | G41: 520101 7112640024 | H41: P | I41: Kawin | J41: Aik Ampat | K41: 23742 | L41: 1964 | M41: =2019-L41 -> 55 | N41: Islam | O41: Sasak | P41: BELUM TAMAT SD/SEDERAJAT | R41: Petani/Pekebun
...

Sheet RT 03
B1: DATA INDUK PENDUDUK KELURAHAN DASAN GERES
B2: TAHUN 2019
B3: LINGKUNGAN BAWAK GUNUNG
B4: RT 03
B5: No | C5: Nomor KK | D5: Jumlah Jiwa | E5: Nama Lengkap/ Panggilan | F5: Kedudukan dalam Keluarga | G5: NIK | H5: Jenis Kelamin (L/P) | I5: Status Perkawinan | J5: Lahir | M5: Usia | N5: Agama | O5: Etnis | P5: Pendidikan Terakhir | Q5: Jurusan | R5: Pekerjaan
J6: Tempat | K6: Tanggal | L6: Tahun
B8: 1 | D8: 1 | E8: Haji Fahrul | F8: KK | G8: 520101 0308680001 | H8: L | I8: Belum kawin | K8: 25053 | L8: =YEAR(K8) -> 1968 | M8: =2019-L8 -> 51 | N8: Islam | P8: SLTP/MTSN | R8: Petani
B9: 2 | D9: 2 | E9: Sahidin | F9: KK | G9: 520101 1003790002 | H9: L | I9: Kawin | K9: 28924 | L9: =YEAR(K9) -> 1979 | M9: =2019-L9 -> 40 | N9: Islam | P9: SLTA/MA | R9: Pegawai swasta
D10: 3 | E10: Haerani | F10: Istri | G10: 520101 7112800173 | H10: P | I10: Kawin | K10: 32508 | L10: =YEAR(K10) -> 1988 | M10: =2019-L10 -> 31 | N10: Islam | P10: SLTA/MA | R10: Pedagang
D11: 4 | E11: Qanita Majwa Khalisah | F11: Anak | G11: 520101 5412110002 | H11: P | I11: Belum kawin | K11: 40891 | L11: =YEAR(K11) -> 2011 | M11: =2019-L11 -> 8 | N11: Islam | P11: - | R11: -
B12: 3 | C12: 520101 2709120087 | D12: 5 | E12: Aminah | F12: KK | G12: 520101 3112670155 | H12: P | I12: Cerai Mati | J12: Bawak Gunung | K12: 23011 | L12: 1962 | M12: =2019-L12 -> 57 | N12: Islam | P12: TIDAK/BLM SEKOLAH | R12: Buruh Harian Lepas
B13: 4 | D13: 6 | E13: Amenah | F13: KK | G13: 0 | H13: P | I13: Janda | K13: 18445 | L13: =YEAR(K13) -> 1950 | M13: =2019-L13 -> 69 | N13: Islam | P13: - | R13: Pekerja lepas
B14: 5 | D14: 7 | E14: Haji Nasir | F14: KK | G14: 520101 1607720001 | H14: L | I14: Kawin | K14: 27014 | L14: =YEAR(K14) -> 1973 | M14: =2019-L14 -> 46 | N14: Islam | P14: SD/MI | R14: Petani
D15: 8 | E15: Mukyah | F15: Istri | G15: 520101 3012760001 | H15: P | I15: Kawin | K15: 28125 | L15: =YEAR(K15) -> 1976 | M15: =2019-L15 -> 43 | N15: Islam | P15: SLTA/MA | R15: Pekerja lepas
D16: 9 | E16: Ismie Aton Hasanah | F16: Anak | G16: 520101 5007990001 | H16: P | I16: Belum kawin | K16: 36321 | L16: =YEAR(K16) -> 1999 | M16: =2019-L16 -> 20 | N16: Islam | P16: SLTP/MTSN | R16: -
D17: 10 | E17: Sulis No vita Dewi | F17: Anak | G17: 520101 5811080001 | H17: P | I17: Belum kawin | K17: 39039 | L17: =YEAR(K17) -> 2006 | M17: =2019-L17 -> 13 | N17: Islam | P17: - | R17: -
B18: 6 | C18: 520101 2505130010 | D18: 11 | E18: Junaidi | F18: KK | G18: 520101 3112760073 | H18: L | I18: Kawin | J18: Bawak Gunung | K18: 30881 | L18: 1984 | M18: =2019-L18 -> 35 | N18: Islam | O18: Sasak | P18: SLTP/MTSN | R18: Buruh Harian Lepas
D19: 12 | E19: Aeniah | F19: Istri | G19: 520101 6403941001 | H19: P | I19: Kawin | J19: Aik Ampat | K19: 34417 | L19: 1994 | M19: =2019-L19 -> 25 | N19: Islam | O19: Sasak | P19: SLTP/MTSN | R19: Mengurus Rumah Tangga
D20: 13 | E20: Zahratun Laila | F20: Anak | G20: 520101 4309131002 | H20: P | I20: Belum kawin | J20: Bawak Gunung | K20: 41520 | L20: 2013 | M20: =2019-L20 -> 6 | N20: Islam | O20: Sasak | P20: TIDAK/BLM SEKOLAH | R20: Belum /Tidak Bekerja
B21: 7 | D21: 14 | E21: Hajjah Maemunah | F21: KK | G21: 520101 7112510010 | H21: P | I21: Janda | K21: 18993 | L21: =YEAR(K21) -> 1951 | M21: =2019-L21 -> 68 | N21: Islam | P21: - | R21: Swasta
D22: 15 | E22: Zulkipli | F22: Anak | G22: 520101 3112850081 | H22: L | I22: Belum kawin | K22: 32873 | L22: =YEAR(K22) -> 1989 | M22: =2019-L22 -> 30 | N22: Islam | P22: SD/MI | R22: Pekerja lepas
D23: 16 | E23: Sudirman | F23: Anak | G23: 520101 0808900001 | H23: L | I23: Belum kawin | K23: 33032 | L23: =YEAR(K23) -> 1990 | M23: =2019-L23 -> 29 | N23: Islam | P23: SD/MI | R23: Pekerja lepas
B24: 8 | D24: 17 | E24: Mugni | F24: KK | G24: 0 | H24: L | I24: Kawin | K24: 27942 | L24: =YEAR(K24) -> 1976 | M24: =2019-L24 -> 43 | N24: Islam | P24: SLTP/MTSN | R24: Pekerja lepas
D25: 18 | E25: Marwatika | F25: Istri | G25: 520101 4111780003 | H25: P | I25: Kawin | K25: 28795 | L25: =YEAR(K25) -> 1978 | M25: =2019-L25 -> 41 | N25: Islam | P25: SLTP/MTSN | R25: -
B26: 9 | D26: 19 | E26: Haji ANo ar Hadi | F26: KK | G26: 520101 0107570345 | H26: L | I26: Kawin | K26: 21002 | L26: =YEAR(K26) -> 1957 | M26: =2019-L26 -> 62 | N26: Islam | P26: - | R26: Petani
D27: 20 | E27: Miskah | F27: Istri | G27: 520101 4107620384 | H27: P | I27: Kawin | K27: 21367 | L27: =YEAR(K27) -> 1958 | M27: =2019-L27 -> 61 | N27: Islam | P27: - | R27: Petani
D28: 21 | E28: Haji Budiman | F28: Anak | G28: 520101 3112850031 | H28: L | I28: Belum kawin | K28: 31412 | L28: =YEAR(K28) -> 1985 | M28: =2019-L28 -> 34 | N28: Islam | P28: SLTA/MA | R28: Pekerja lepas
B29: 10 | D29: 22 | E29: Hajjah Raodah | F29: KK | G29: 520101 4107570569 | H29: P | I29: Janda | K29: 18628 | L29: =YEAR(K29) -> 1950 | M29: =2019-L29 -> 69 | N29: Islam | P29: - | R29: -
B30: 11 | D30: 23 | E30: Yusup | F30: KK | G30: 520101 0412810091 | H30: L | I30: Kawin | K30: 29924 | L30: =YEAR(K30) -> 1981 | M30: =2019-L30 -> 38 | N30: Islam | P30: SLTP/MTSN | R30: Pekerja lepas
D31: 24 | E31: Ansori | F31: Istri | G31: 520101 5307880001 | H31: P | I31: Kawin | K31: 30510 | L31: =YEAR(K31) -> 1983 | M31: =2019-L31 -> 36 | N31: Islam | P31: SD/MI | R31: Pekerja lepas
D32: 25 | E32: Siti Auriya | F32: Anak | G32: 520101 4504090001 | H32: P | I32: Belum kawin | K32: 39912 | L32: =YEAR(K32) -> 2009 | M32: =2019-L32 -> 10 | N32: Islam | P32: - | R32: -
B33: 12 | D33: 26 | E33: Haji Suhaemi | F33: KK | G33: 520101 0110730001 | H33: L | I33: Kawin | K33: 26938 | L33: =YEAR(K33) -> 1973 | M33: =2019-L33 -> 46 | N33: Islam | P33: - | R33: Pekerja lepas
D34: 27 | E34: Hajjah Nuraini | F34: Istri | G34: 520101 5203821001 | H34: P | I34: Kawin | K34: 30022 | L34: =YEAR(K34) -> 1982 | M34: =2019-L34 -> 37 | N34: Islam | P34: SD/MI | R34: -
D35: 28 | E35: Wahyu Saputra | F35: Anak | G35: 520101 0707020002 | H35: L | I35: Belum kawin | K35: 37444 | L35: =YEAR(K35) -> 2002 | M35: =2019-L35 -> 17 | N35: Islam | P35: - | R35: -
D36: 29 | E36: Raditia Adaha | F36: Anak | G36: 520101 1510131002 | H36: L | I36: Belum kawin | K36: 41562 | L36: =YEAR(K36) -> 2013 | M36: =2019-L36 -> 6 | N36: Islam | P36: - | R36: -
B37: 13 | D37: 30 | E37: Hajjah Huriyah | F37: KK | G37: 520101 4107520251 | H37: P | I37: Janda | K37: 22828 | L37: =YEAR(K37) -> 1962 | M37: =2019-L37 -> 57 | N37: Islam | P37: - | R37: -
B38: 14 | D38: 31 | E38: Hajjah Nurasiah | F38: KK | G38: 520101 7112650113 | H38: P | I38: Janda | K38: 24107 | L38: =YEAR(K38) -> 1965 | M38: =2019-L38 -> 54 | N38: Islam | P38: - | R38: Pedagang
B39: 15 | D39: 32 | E39: Ahmad Musihir | F39: KK | G39: 0 | H39: L | I39: Kawin | K39: 32329 | L39: =YEAR(K39) -> 1988 | M39: =2019-L39 -> 31 | N39: Islam | P39: SLTA/MA | R39: Pekerja lepas
D40: 33 | E40: Titik Dewi Jayanti | F40: Istri | G40: 520101 5505940002 | H40: P | I40: Kawin | K40: 34469 | L40: =YEAR(K40) -> 1994 | M40: =2019-L40 -> 25 | N40: Islam | P40: SLTA/MA | R40: -
B41: 16 | C41: 520101 1105120034 | D41: 34 | E41: Marsuni | F41: KK | G41: 520101 3112670106 | H41: L | I41: Kawin | J41: Aik Ampat | K41: 24837 | L41: 1967 | M41: =2019-L41 -> 52 | N41: Islam | O41: Sasak | P41: SD/MI | R41: Wiraswasta
...

Sheet RT 04
B1: DATA INDUK PENDUDUK KELURAHAN DASAN GERES
B2: TAHUN 2019
B3: LINGKUNGAN BAWAK GUNUNG
B4: RT 04
B5: No | C5: Nomor KK | D5: Jumlah Jiwa | E5: Nama Lengkap/ Panggilan | F5: Kedudukan dalam Keluarga | G5: NIK | H5: Jenis Kelamin (L/P) | I5: Status Perkawinan | J5: Lahir | M5: Usia | N5: Agama | O5: Etnis | P5: Pendidikan Terakhir | Q5: Jurusan | R5: Pekerjaan
J6: Tempat | K6: Tanggal | L6: Tahun
B8: 1 | C8: 520101 0503089339 | D8: 1 | E8: Cinok | F8: KK | G8: 520101 0107520259 | H8: P | I8: Cerai Mati | J8: Bawak Gunung | K8: 14062 | L8: 1938 | M8: =2019-L8 -> 81 | N8: Islam | O8: Sasak | P8: SD/MI | R8: Buruh Harian Lepas
D9: 2 | E9: Menah | F9: Anak | G9: 520101 4107670168 | H9: P | I9: Cerai Hidup | J9: Bawak Gunung | K9: 24654 | L9: 1967 | M9: =2019-L9 -> 52 | N9: Islam | O9: Sasak | P9: TIDAK/BELUM SKOLAH | R9: Buruh Harian Lepas
D10: 3 | E10: Muhsinin | F10: cucu | G10: 520101 1204970001 | H10: L | I10: Belum kawin | J10: Bawak Gunung | K10: 35532 | L10: 1997 | M10: =2019-L10 -> 22 | N10: Islam | O10: Sasak | P10: SD/MI | R10: Pelajar/Mahasiswa
D11: 4 | E11: Hunaen | F11: Lain-lain | G11: 0 | H11: L | I11: Belum kawin | J11: Bawak Gunung | K11: 37803 | L11: 2003 | M11: =2019-L11 -> 16 | N11: Islam | O11: Sasak | P11: - | R11: -
B12: 2 | C12: 520101 1508120013 | D12: 5 | E12: Mahsin | F12: KK | G12: 520101 1104771001 | H12: L | I12: Kawin | J12: Aik Ampat | K12: 28226 | L12: 1977 | M12: =2019-L12 -> 42 | N12: Islam | O12: Sasak | P12: SD/MI | R12: Buruh Harian Lepas
D13: 6 | E13: Muliaten | F13: Istri | G13: 520101 6004871001 | H13: P | I13: Kawin | J13: Aik Ampat | K13: 31887 | L13: 1987 | M13: =2019-L13 -> 32 | N13: Islam | O13: Sasak | P13: TIDAK/BELUM SKOLAH | R13: Buruh Harian Lepas
D14: 7 | E14: Mayanita | F14: Anak | G14: 520101 4303101001 | H14: L | I14: Belum kawin | J14: Aik Ampat | K14: 40240 | L14: 2010 | M14: =2019-L14 -> 9 | N14: Islam | O14: Sasak | P14: TIDAK/BELUM SKOLAH | R14: Belum/Tidak Bekerja
D15: 8 | E15: M. Hanafi | F15: Anak | G15: 520101 0805111001 | H15: L | I15: Belum kawin | J15: Aik Ampat | K15: 40671 | L15: 2011 | M15: =2019-L15 -> 8 | N15: Islam | O15: Sasak | P15: TIDAK/BELUM SKOLAH | R15: Belum/Tidak Bekerja
B16: 3 | C16: 520101 0503089097 | D16: 9 | E16: Sahidin | F16: KK | G16: 520101 3112741002 | H16: L | I16: Kawin | J16: Bawak Gunung | K16: 27394 | L16: 1974 | M16: =2019-L16 -> 45 | N16: Islam | O16: Sasak | P16: SD/MI | R16: Petani/Pekebun
D17: 10 | E17: Saba'ah | F17: Istri | G17: 520101 4904790003 | H17: P | I17: Kawin | J17: Aik Ampat | K17: 28589 | L17: 1978 | M17: =2019-L17 -> 41 | N17: Islam | O17: Sasak | P17: SD/MI | R17: Mengurus Rumah Tangga
D18: 11 | E18: Saparudin | F18: Anak | G18: 520101 1002930004 | H18: L | I18: Belum kawin | J18: Aik Ampat | K18: 34010 | L18: 1993 | M18: =2019-L18 -> 26 | N18: Islam | O18: Sasak | P18: SD/MI | R18: Buruh Harian Lepas
D19: 12 | E19: Muat Jalil | F19: Anak | G19: 520101 0101081001 | H19: L | I19: Belum kawin | J19: Aik Ampat | K19: 39448 | L19: 2008 | M19: =2019-L19 -> 11 | N19: Islam | O19: Sasak | P19: BELUM TAMAT SD/SEDERAJAT | R19: Pelajar/Mahasiswa
D20: 13 | E20: Rasidah | F20: Lain-lain | G20: 520101 107570365 | H20: P | I20: Janda | J20: Aik Ampat | K20: 22098 | L20: 1960 | M20: =2019-L20 -> 59 | N20: Islam | O20: Sasak | P20: TIDAK/BELUM SKOLAH | R20: Buruh Harian Lepas
B21: 4 | D21: 14 | E21: Saparudin | F21: KK | G21: 0 | H21: L | I21: Duda | K21: 20820 | L21: =YEAR(K21) -> 1956 | M21: =2019-L21 -> 63 | N21: Islam | P21: - | R21: Pekerja lepas
D22: 15 | E22: Minerah | F22: Anak | G22: 0 | H22: P | I22: Janda | K22: 31959 | L22: =YEAR(K22) -> 1987 | M22: =2019-L22 -> 32 | N22: Islam | P22: SD/MI | R22: Pekerja lepas
B23: 5 | D23: 16 | E23: Fadhil | F23: KK | G23: 520101 3112861025 | H23: L | I23: Kawin | K23: 31777 | L23: =YEAR(K23) -> 1986 | M23: =2019-L23 -> 33 | N23: Islam | P23: SLTP/MTSN | R23: Pekerja lepas
D24: 17 | E24: Sumiati | F24: Istri | G24: 520101 7112921007 | H24: P | I24: Kawin | K24: 33969 | L24: =YEAR(K24) -> 1992 | M24: =2019-L24 -> 27 | N24: Islam | P24: SLTP/MTSN | R24: Pekerja lepas
D25: 18 | E25: Naufal Arrasid | F25: Anak | G25: 0 | H25: L | I25: Belum kawin | K25: 42096 | L25: =YEAR(K25) -> 2015 | M25: =2019-L25 -> 4 | N25: Islam | P25: - | R25: -
B26: 6 | D26: 19 | E26: Ayub | F26: KK | G26: 520101 3112650125 | H26: L | I26: Duda | K26: 24107 | L26: =YEAR(K26) -> 1965 | M26: =2019-L26 -> 54 | N26: Islam | P26: - | R26: -
D27: 20 | E27: Murni | F27: Anak | G27: 0 | H27: P | I27: Belum kawin | K27: 26846 | L27: =YEAR(K27) -> 1973 | M27: =2019-L27 -> 46 | N27: Islam | P27: SLTA/MA | R27: Pekerja lepas
D28: 21 | E28: Joni Iskandar | F28: Anak | G28: 520101 0210850002 | H28: L | I28: Belum kawin | K28: 31327 | L28: =YEAR(K28) -> 1985 | M28: =2019-L28 -> 34 | N28: Islam | P28: - | R28: Pekerja lepas
B29: 7 | C29: 520101 2502150042 | D29: 22 | E29: Muhamad Syukur | F29: KK | G29: 520101 2112820001 | H29: L | I29: Kawin | J29: Bawak Gunung | K29: 28855 | L29: 1978 | M29: =2019-L29 -> 41 | N29: Islam | O29: Sasak | P29: SD/MI | R29: Buruh Harian Lepas
D30: 23 | E30: Majenan | F30: Istri | G30: 520101 4107870454 | H30: P | I30: Kawin | J30: Bawak Gunung | K30: 31959 | L30: 1987 | M30: =2019-L30 -> 32 | N30: Islam | O30: Sasak | P30: SD/MI | R30: Buruh Harian Lepas
D31: 24 | E31: Siti Urfina | F31: Anak | G31: 520101 6305120001 | H31: P | I31: Belum kawin | J31: Gerung | K31: 41052 | L31: 2012 | M31: =2019-L31 -> 7 | N31: Islam | O31: Sasak | P31: TIDAK/BELUM SKOLAH | R31: Belum/Tidak Bekerja
B32: 8 | C32: 520101 0503088433 | D32: 25 | E32: Amat | F32: KK | G32: 520101 0107720188 | H32: L | I32: Kawin | J32: Bawak Gunung | K32: 26481 | L32: 1972 | M32: =2019-L32 -> 47 | N32: Islam | O32: Sasak | P32: TIDAK/BELUM SKOLAH | R32: Buruh Harian Lepas
D33: 26 | E33: Caah | F33: Istri | G33: 520101 4107770526 | H33: P | I33: Kawin | J33: Bawak Gunung | K33: 28307 | L33: 1977 | M33: =2019-L33 -> 42 | N33: Islam | O33: Sasak | P33: TIDAK/BELUM SKOLAH | R33: Buruh Harian Lepas
D34: 27 | E34: Jamiah | F34: Orang Tua | G34: 520101 7112400045 | H34: P | I34: Cerai Mati | J34: Bawak Gunung | K34: 14976 | L34: 1940 | M34: =2019-L34 -> 79 | N34: Islam | O34: Sasak | P34: TIDAK/BELUM SKOLAH | R34: Belum/Tidak Bekerja
B35: 9 | C35: 520101 2810120007 | D35: 28 | E35: Mansur | F35: KK | G35: 520101 3112670107 | H35: L | I35: Kawin | J35: Aik Ampat | K35: 25568 | L35: 1969 | M35: =2019-L35 -> 50 | N35: Islam | O35: Sasak | P35: SD/MI | R35: Buruh Tani/Perkebunan
D36: 29 | E36: Murini | F36: Istri | G36: 520101 7112760124 | H36: P | I36: Kawin | J36: Aik Ampat | K36: 28125 | L36: 1976 | M36: =2019-L36 -> 43 | N36: Islam | O36: Sasak | P36: SD/MI | R36: Buruh Tani/Perkebunan
B37: 10 | C37: 520101 0904150005 | D37: 30 | E37: Cenim | F37: KK | G37: 520101 4107570389 | H37: P | I37: Cerai Mati | J37: Bawak Gunung | K37: 21185 | L37: 1957 | M37: =2019-L37 -> 62 | N37: Islam | O37: Sasak | P37: TAMAT SD/SEDERAJAT | R37: Mengurus Rumah Tangga
D38: 31 | E38: Sokni | F38: Anak | G38: 520101 6209880001 | H38: P | I38: Belum kawin | J38: Bawak Gunung | K38: 32408 | L38: 1988 | M38: =2019-L38 -> 31 | N38: Islam | O38: Sasak | P38: TAMAT SD/SEDERAJAT | R38: Buruh Harian Lepas
D39: 32 | E39: Hikmah | F39: Anak | G39: 520101 5303890001 | H39: P | I39: Belum kawin | J39: Bawak Gunung | K39: 32525 | L39: 1989 | M39: =2019-L39 -> 30 | N39: Islam | O39: Sasak | P39: TAMAT SD/SEDERAJAT | R39: Wiraswasta
B40: 11 | C40: 520101 1611090027 | D40: 33 | E40: H. Haerudin | F40: KK | G40: 520101 1107840002 | H40: L | I40: Kawin | J40: Bawak Gunung | K40: 30874 | L40: 1984 | M40: =2019-L40 -> 35 | N40: Islam | O40: Sasak | P40: SD/MI | R40: Wiraswasta
D41: 34 | E41: Mahnam | F41: Istri | G41: 520101 5109860003 | H41: P | I41: Kawin | J41: Bawak Gunung | K41: 31666 | L41: 1986 | M41: =2019-L41 -> 33 | N41: Islam | O41: Sasak | P41: SD/MI | R41: Wiraswasta
...

Sheet Jumlah Semua
A1: 116 | C1: 360
A2: 63 | C2: 187
A3: 108 | C3: 288
A4: 48 | C4: 150
A5: =SUM(A1:A4) -> 335 | C5: =SUM(C1:C4) -> 985

Sheet Pindah Keluar
A4: No. | B4: Nomor KK | C4: Jumlah Jiwa | D4: Nama Lengkap / Panggilan | E4: Kedudukan dalam Keluarga | F4: NIK | G4: Jenis Kelamin (L/P) | H4: Status Perkawinan | I4: Lahir | L4: Usia | M4: Agama | N4: Etnis | O4: Pendidikan Terakhir | P4: Jurusan | Q4: Pekerjaan | R4: Cacat | T4: Ada / Tidak
I5: Tempat | J5: Tanggal | K5: Tahun | R5: Mental | S5: Fisik | T5: KK | U5: KTP/KIA | V5: Buku Nikah | W5: Akte Kelahiran
C7: 263 | D7: Mukinah | E7: Lain-lain | F7: 0 | G7: P | H7: Janda | J7: 31-21-1956 | L7: =2019-K7 -> 2019 | M7: Islam | O7: - | Q7: -
C8: 151 | D8: Kameran | E8: Anak | F8: 520101 4107470061 | G8: P | H8: Janda | J8: 17349 | L8: =2019-K8 -> 2019 | M8: Islam | O8: - | Q8: -
C9: 205 | D9: Muhsinin Haji | E9: Anak | F9: 0 | G9: L | H9: Belum kawin | J9: 32880 | L9: =2019-K9 -> 2019 | M9: Islam | O9: SLTA/MA | Q9: Pekerja lepas
C10: 249 | D10: Mislah | E10: Lain-Lain | F10: 520101 4405750002 | G10: P | H10: Janda | J10: 20917 | L10: =2019-K10 -> 2019 | M10: Islam | O10: - | Q10: -
C11: 13 | D11: Vera Pasira | E11: Anak | F11: 520101 4206971001 | G11: P | H11: Belum kawin | J11: 35467 | L11: =2019-K11 -> 2019 | M11: Islam | O11: SD/MI | Q11: -
C12: 134 | D12: Paidawati | E12: Anak | F12: 520101 8004990001 | G12: P | H12: Kawin | J12: 36437 | L12: =2019-K12 -> 2019 | M12: Islam | O12: SLTA/MA | Q12: -
C13: 81 | D13: Yusup S.Pd | E13: Anak | F13: 520101 3112841012 | G13: L | H13: Belum kawin | J13: 31047 | L13: =2019-K13 -> 2019 | M13: Islam | O13: PT/Akademi | Q13: Pegawai swasta
C14: 173 | D14: Haji Haris | E14: Lain-lain | F14: 520101 3112280175 | G14: L | H14: Belum kawin | J14: 32873 | L14: =2019-K14 -> 2019 | M14: Islam | O14: SLTA/MA | Q14: Pekerja lepas
C15: 189 | D15: Hikmah | E15: Anak | F15: 520101 4505930003 | G15: P | H15: Belum kawin | I15: Aik Ampat | J15: 34094 | K15: 1993 | L15: =2019-K15 -> 26 | M15: Islam | N15: Sasak | O15: TAMAT SD/SEDERAJAT | Q15: Wiraswasta
C16: 94 | D16: Aini | E16: Anak | F16: 520101 6505980001 | G16: P | H16: Belum kawin | I16: Aik Ampat | J16: 35940 | L16: =2019-K16 -> 2019 | M16: Islam | O16: SLTA/MA | Q16: -
C17: 283 | D17: Nurfatilawati | E17: Anak | F17: 520101 4208050001 | G17: P | H17: Belum kawin | J17: 33486 | K17: 1991 | L17: =2019-K17 -> 28 | M17: Islam | N17: Sasak | O17: PT/Akademi | Q17: Pegawai swasta
C18: 147 | D18: Jamilah | E18: Anak | F18: 520101 4404940001 | G18: P | H18: Belum kawin | I18: Bawak Gunung | J18: 34598 | K18: 1994 | L18: =2019-K18 -> 25 | M18: Islam | N18: Sasak | O18: SLTA/MA | Q18: -
C19: 133 | D19: Misaah | E19: Lain-lain | F19: 520101 6110940002 | G19: P | H19: Belum kawin | I19: Bawak Gunung | J19: 34488 | K19: 1994 | L19: =2019-K19 -> 25 | M19: Islam | N19: Sasak | O19: SLTP/MTSN | Q19: Belum/Tidak Bekerja
C20: 75 | D20: Suriatiniya | E20: Anak | F20: 520101 7112840104 | G20: P | H20: Belum kawin | I20: Bawak Gunung | J20: 31047 | K20: 1984 | L20: =2019-K20 -> 35 | M20: Islam | N20: Sasak | O20: PT/Akademi

Sheet Meninggal
A4: No. | B4: Nomor KK | C4: Jumlah Jiwa | D4: Nama Lengkap / Panggilan | E4: Kedudukan dalam Keluarga | F4: NIK | G4: Jenis Kelamin (L/P) | H4: Status Perkawinan | I4: Lahir | L4: Usia | M4: Agama | N4: Etnis | O4: Pendidikan Terakhir | P4: Jurusan | Q4: Pekerjaan | R4: Cacat | T4: Ada / Tidak
I5: Tempat | J5: Tanggal | K5: Tahun | R5: Mental | S5: Fisik | T5: KK | U5: KTP/KIA | V5: Buku Nikah | W5: Akte Kelahiran
C7: 254 | D7: Rosaal Jannah | E7: Anak | F7: 0 | G7: P | H7: Belum kawin | J7: 42126 | L7: =2019-K7 -> 2019 | M7: Islam | O7: - | Q7: -
C8: 309 | D8: Meluk | E8: Lain-Lain | F8: 520101 4107620247 | G8: P | H8: Janda | J8: 31-12-1942 | L8: =2019-K8 -> 2019 | M8: Islam | O8: - | Q8: Pekerja lepas
C9: 151 | D9: Sinarah | E9: Lainnya | F9: 0 | G9: P | H9: Janda | J9: 21557 | L9: =2019-K9 -> 2019 | M9: Islam | O9: - | Q9: Pekerja lepas
C10: 103 | D10: Sakyah | E10: KK | F10: 520101 0104470218 | G10: P | H10: Janda | I10: Bawak Gunung | J10: 13697 | K10: 1937 | L10: =2019-K10 -> 82 | M10: Islam | N10: Sasak | O10: TIDAK/BLM SEKOLAH | Q10: Buruh Harian Lepas
C11: 188 | D11: Munzir | E11: Anak | F11: 520101 1011900002 | G11: L | H11: Belum kawin | I11: Aik Ampat | J11: 33187 | K11: 1990 | L11: =2019-K11 -> 29 | M11: Islam | N11: Sasak | O11: TAMAT SD/SEDERAJAT | Q11: Wiraswasta
C12: 367 | D12: Sahabudin | E12: KK | F12: 520101 0107670673 | G12: L | H12: Kawin | I12: Bawak Gunung | J12: 24654 | K12: 1967 | L12: =2019-K12 -> 52 | M12: Islam | N12: Sasak | O12: - | Q12: Buruh Harian Lepas
D13: 263 | E13: Satman | F13: KK | G13: 520101 3112851009 | H13: L | I13: Kawin | J13: Aik Ampat | K13: 31412 | M13: =2019-L13 -> 2019 | N13: Islam | O13: Sasak | P13: - | R13: Pekerja lepas
