Workbook
Name _GoBack: 'RT 01'!$J$167

Sheet Rekap
C3: Jumlah Penduduk | E3: Total | F3: Jumlah KK | H3: Total | I3: Jumlah Duda / Janda | K3: Total | L3: Jumlah Lansia ( =>60 ) | N3: Total
C4: L | D4: P | F4: L | G4: P | I4: L | J4: P | L4: L | M4: P
B5: RT 1 | C5: =COUNTIF('RT 01'!$E$6:$E$209,"L") -> 108 | D5: =COUNTIF('RT 01'!$E$6:$E$209,"P") -> 96 | E5: =SUM(C5:D5) -> 204 | F5: =COUNTIFS('RT 01'!$M$6:$M$209,"KK",'RT 01'!$E$6:$E$209,"L") -> 50 | G5: =COUNTIFS('RT 01'!$M$6:$M$209,"KK",'RT 01'!$E$6:$E$209,"P") -> 0 | H5: =SUM(F5:G5) -> 50 | I5: =COUNTIFS('RT 01'!$F$6:$F$209,"Cerai Mati",'RT 01'!$E$6:$E$209,"L")+COUNTIFS('RT 01'!$F$6:$F$209,"Cerai Hidup",'RT 01'!$E$6:$E$209,"L") -> 0 | J5: =COUNTIFS('RT 01'!$F$6:$F$209,"Cerai Mati",'RT 01'!$E$6:$E$209,"P")+COUNTIFS('RT 01'!$F$6:$F$209,"Cerai Hidup",'RT 01'!$E$6:$E$209,"P") -> 0 | K5: =SUM(I5:J5) -> 0 | N5: =SUM(L5:M5) -> 0
B6: RT 2 | C6: =COUNTIF('RT 02'!$E$4:$E$252,"L") -> 135 | D6: =COUNTIF('RT 02'!$E$4:$E$252,"P") -> 113 | E6: =SUM(C6:D6) -> 248 | F6: =COUNTIFS('RT 02'!$M$4:$M$252,"KK",'RT 02'!$E$4:$E$252,"L") -> 59 | G6: =COUNTIFS('RT 02'!$M$4:$M$252,"KK",'RT 02'!$E$4:$E$252,"P") -> 3 | H6: =SUM(F6:G6) -> 62 | I6: =COUNTIFS('RT 02'!$F$4:$F$251,"Cerai Mati",'RT 02'!$E$4:$E$251,"L")+COUNTIFS('RT 02'!$F$4:$F$251,"Cerai Hidup",'RT 02'!$E$4:$E$251,"L") -> 0 | J6: =COUNTIFS('RT 02'!$F$4:$F$251,"Cerai Mati",'RT 02'!$E$4:$E$251,"P")+COUNTIFS('RT 02'!$F$4:$F$251,"Cerai Hidup",'RT 02'!$E$4:$E$251,"P") -> 0 | K6: =SUM(I6:J6) -> 0 | N6: =SUM(L6:M6) -> 0
B7: RT 3 | C7: =COUNTIF('RT 03'!$E$4:$E$275,"L") -> 141 | D7: =COUNTIF('RT 03'!$E$4:$E$275,"P") -> 131 | E7: =SUM(C7:D7) -> 272 | F7: =COUNTIFS('RT 03'!$M$4:$M$275,"KK",'RT 03'!$E$4:$E$275,"L") -> 70 | G7: =COUNTIFS('RT 03'!$M$4:$M$275,"KK",'RT 03'!$E$4:$E$275,"P") -> 2 | H7: =SUM(F7:G7) -> 72 | I7: =COUNTIFS('RT 03'!$F$4:$F$275,"Cerai Mati",'RT 03'!$E$4:$E$275,"L")+COUNTIFS('RT 03'!$F$4:$F$275,"Cerai Hidup",'RT 03'!$E$4:$E$275,"L") -> 0 | J7: =COUNTIFS('RT 03'!$F$4:$F$275,"Cerai Mati",'RT 03'!$E$4:$E$275,"P")+COUNTIFS('RT 03'!$F$4:$F$275,"Cerai Hidup",'RT 03'!$E$4:$E$275,"P") -> 0 | K7: =SUM(I7:J7) -> 0 | N7: =SUM(L7:M7) -> 0
B8: RT 4 | C8: =COUNTIF('RT 04'!$E$4:$E$328,"L") -> 169 | D8: =COUNTIF('RT 04'!$E$4:$E$328,"P") -> 154 | E8: =SUM(C8:D8) -> 323 | F8: =COUNTIFS('RT 04'!$M$4:$M$328,"KK",'RT 04'!$E$4:$E$328,"L") -> 89 | G8: =COUNTIFS('RT 04'!$M$4:$M$328,"KK",'RT 04'!$E$4:$E$328,"P") -> 4 | H8: =SUM(F8:G8) -> 93 | I8: =COUNTIFS('RT 04'!$F$4:$F$328,"Cerai Mati",'RT 04'!$E$4:$E$328,"L")+COUNTIFS('RT 04'!$F$4:$F$328,"Cerai Hidup",'RT 04'!$E$4:$E$328,"L") -> 0 | J8: =COUNTIFS('RT 04'!$F$4:$F$328,"Cerai Mati",'RT 04'!$E$4:$E$328,"P")+COUNTIFS('RT 04'!$F$4:$F$328,"Cerai Hidup",'RT 04'!$E$4:$E$328,"P") -> 0 | K8: =SUM(I8:J8) -> 0 | N8: =SUM(L8:M8) -> 0
B9: RT 5 | C9: =COUNTIF('RT 05'!$E$4:$E$261,"L") -> 128 | D9: =COUNTIF('RT 05'!$E$4:$E$261,"P") -> 127 | E9: =SUM(C9:D9) -> 255 | F9: =COUNTIFS('RT 05'!$M$4:$M$261,"KK",'RT 05'!$E$4:$E$261,"L") -> 64 | G9: =COUNTIFS('RT 05'!$M$4:$M$261,"KK",'RT 05'!$E$4:$E$261,"P") -> 3 | H9: =SUM(F9:G9) -> 67 | I9: =COUNTIFS('RT 05'!$F$4:$F$261,"Cerai Mati",'RT 05'!$E$4:$E$261,"L")+COUNTIFS('RT 05'!$F$4:$F$261,"Cerai Hidup",'RT 05'!$E$4:$E$261,"L") -> 0 | J9: =COUNTIFS('RT 05'!$F$4:$F$261,"Cerai Mati",'RT 05'!$E$4:$E$261,"P")+COUNTIFS('RT 05'!$F$4:$F$261,"Cerai Hidup",'RT 05'!$E$4:$E$261,"P") -> 0 | K9: =SUM(I9:J9) -> 0 | N9: =SUM(L9:M9) -> 0
B10: JUMLAH TOTAL | C10: =SUM(C5:C9) -> 681 | D10: =SUM(D5:D9) -> 621 | E10: =SUM(E5:E9) -> 1302 | F10: =SUM(F5:F9) -> 332 | G10: =SUM(G5:G9) -> 12 | H10: =SUM(H5:H9) -> 344 | I10: =SUM(I5:I9) -> 0 | J10: =SUM(J5:J9) -> 0 | ... N10: =SUM(N5:N9) -> 0

Sheet RT 01
B1: DATA INDUK PENDUDUK KELURAHAN DASAN GERES TAHUN 2015
D2: RT 01
B4: No | D4: Nama Lengkap/ | E4: Jenis Kelamin (L/P) | F4: Status Perkawinan | G4: Tanggal Lahir | H4: Agama | I4: Pendidikan Terakhir | J4: Pekerjaan | K4: Kewarganegaraan | L4: Alamat Lengkap | M4: Kedudukan dalam Keluarga | N4: NIK
D5: Panggilan
B6: 1 | C6: 1 | D6: Amran | E6: L | F6: Kawin | G6: 28713 | H6: Islam | I6: SLTA/MA | J6: PNS/TNI/ POLRI | K6: WNI | L6: Lingkungan Perumda Selatan No 01 RT 01 RW 09 | M6: KK | N6: 520101 1108780002
C7: 2 | D7: Sri Nurani | E7: P | F7: Kawin | G7: 28633 | H7: Islam | I7: SLTA/MA | J7: PNS/TNI/ POLRI | K7: WNI | L7: Lingkungan Perumda Selatan No 01 RT 01 RW 09 | M7: Istri | N7: 520101 6305780001
B8: 2 | C8: 3 | D8: Agus Harianto | E8: L | F8: Kawin | G8: 20927 | H8: Islam | I8: SLTA/MA | J8: Wiraswasta | K8: WNI | L8: Lingkungan Perumda Selatan No 02 RT 01 RW 09 | M8: KK | N8: 520101 1704570001
C9: 4 | D9: Sumi Ati | E9: P | F9: Kawin | G9: 29591 | H9: Islam | I9: SD/MI | J9: - | K9: WNI | L9: Lingkungan Perumda Selatan No 02 RT 01 RW 09 | M9: Istri | N9: 520101 4501010003
C10: 5 | D10: Wendy Damayanti | E10: L | F10: Belum kawin | G10: 31131 | H10: Islam | I10: SLTA/MA | J10: - | K10: WNI | L10: Lingkungan Perumda Selatan No 02 RT 01 RW 09 | M10: Anak | N10: 520101 0503960002
C11: 6 | D11: Aditya Arya Pangestu | E11: P | F11: Belum kawin | G11: 36119 | H11: Islam | I11: SLTP/MTSN | J11: - | K11: WNI | L11: Lingkungan Perumda Selatan No 02 RT 01 RW 09 | M11: Anak | N11: 520101 6512889994
C12: 7 | D12: Giska Arya aryanto | E12: L | F12: Belum kawin | G12: 38474 | H12: Islam | I12: - | J12: - | K12: WNI | L12: Lingkungan Perumda Selatan No 02 RT 01 RW 09 | M12: Anak | N12: 520101 6512880004
C13: 8 | D13: Dwi Putri | E13: P | F13: Belum kawin | G13: 32502 | H13: Islam | I13: SLTA/MA | J13: - | K13: WNI | L13: Lingkungan Perumda Selatan No 02 RT 01 RW 09 | M13: Lain-lain | N13: 520101 6512880004
B14: 3 | C14: 9 | D14: Sabdi | E14: L | F14: Kawin | G14: 29214 | H14: Islam | I14: SD/MI | J14: Wiraswasta | K14: WNI | L14: Lingkungan Perumda Selatan No 03 RT 01 RW 09 | M14: KK | N14: 520101 2512799001
C15: 10 | D15: Sahni | E15: P | F15: Kawin | G15: 31397 | H15: Islam | I15: SLTA/MA | J15: - | K15: WNI | L15: Lingkungan Perumda Selatan No 03 RT 01 RW 09 | M15: Istri | N15: 520101 2612850001
C16: 11 | D16: M. Sopyan Assaufi | E16: L | F16: Belum kawin | G16: 38575 | H16: Islam | I16: - | J16: - | K16: WNI | L16: Lingkungan Perumda Selatan No 03 RT 01 RW 09 | M16: Anak | N16: 520101 1109050001
C17: 12 | D17: Dini Aulia Putri | E17: P | F17: Belum kawin | G17: 39812 | H17: Islam | I17: - | J17: - | K17: WNI | L17: Lingkungan Perumda Selatan No 03 RT 01 RW 09 | M17: Anak | N17: 520101 7012080001
B18: 4 | C18: 13 | D18: Ramli S.Sos | E18: L | F18: Kawin | G18: 26313 | H18: Islam | I18: PT/Akademi | J18: Wiraswasta | K18: WNI | L18: Lingkungan Perumda Selatan No 04 RT 01 RW 09 | M18: KK | N18: 520101 1601720002
C19: 14 | D19: Jumrah S.Pd | E19: P | F19: Kawin | G19: 27759 | H19: Islam | I19: PT/Akademi | J19: Pegawai swasta | K19: WNI | L19: Lingkungan Perumda Selatan No 04 RT 01 RW 09 | M19: Istri | N19: 520101 7112750144
C20: 15 | D20: Raran Paturrahman Ustara | E20: L | F20: Belum kawin | G20: 33446 | H20: Islam | I20: SLTA/MA | J20: - | K20: WNI | L20: Lingkungan Perumda Selatan No 04 RT 01 RW 09 | M20: Anak | N20: 520101 2707940001
C21: 16 | D21: M. Charil Syazwan | E21: L | F21: Belum kawin | G21: 39634 | H21: Islam | I21: - | J21: - | K21: WNI | L21: Lingkungan Perumda Selatan No 04 RT 01 RW 09 | M21: Anak | N21: 520101 1506070001
C22: 17 | D22: M. Bima Azharul Gifari | E22: L | F22: Belum kawin | G22: 40508 | H22: Islam | I22: - | J22: - | K22: WNI | L22: Lingkungan Perumda Selatan No 04 RT 01 RW 09 | M22: Anak | N22: 520101 2611100001
B23: 5 | C23: 18 | D23: Wahid S.Ag | E23: L | F23: Kawin | G23: 26664 | H23: Islam | I23: PT/Akademi | J23: PNS/TNI/ POLRI | K23: WNI | L23: Lingkungan Perumda Selatan No 05 RT 01 RW 09 | M23: KK | N23: 520101 3112700032
C24: 19 | D24: Sazmini S.E | E24: P | F24: Kawin | G24: 27029 | H24: Islam | I24: PT/Akademi | J24: PNS/TNI/ POLRI | K24: WNI | L24: Lingkungan Perumda Selatan No 05 RT 01 RW 09 | M24: Istri | N24: 520101 3112730022
C25: 20 | D25: Azfiah B. Hasani | E25: L | F25: Belum kawin | G25: 37651 | H25: Islam | I25: - | J25: - | K25: WNI | L25: Lingkungan Perumda Selatan No 05 RT 01 RW 09 | M25: Anak | N25: 520101 3001030001
C26: 21 | D26: Sholehatun Auliya | E26: P | F26: Belum kawin | G26: 38539 | H26: Islam | I26: -- | J26: - | K26: WNI | L26: Lingkungan Perumda Selatan No 05 RT 01 RW 09 | M26: Anak | N26: 520101 4607050001
B27: 6 | C27: 22 | D27: Erlan Zamroni | E27: L | F27: Kawin | G27: 25765 | H27: Islam | I27: PT/Akademi | J27: Wiraswasta | K27: WNI | L27: Lingkungan Perumda Selatan No 06 RT 01 RW 09 | M27: KK | N27: 520491 1007702002
C28: 23 | D28: Sri Sudariani | E28: P | F28: Kawin | G28: 26868 | H28: Islam | I28: PT/Akademi | J28: PNS/TNI/ POLRI | K28: WNI | L28: Lingkungan Perumda Selatan No 06 RT 01 RW 09 | M28: Istri | N28: 52018 14301730001
C29: 24 | D29: Irzam Haikal Qilbari | E29: L | F29: Belum kawin | G29: 36177 | H29: Islam | I29: SLTP/MTSN | J29: - | K29: WNI | L29: Lingkungan Perumda Selatan No 06 RT 01 RW 09 | M29: Anak | N29: 520101 1701950001
C30: 25 | D30: Irzam Ghivar Kawarizmi | E30: P | F30: Belum kawin | G30: 37642 | H30: Islam | I30: - | J30: - | K30: WNI | L30: Lingkungan Perumda Selatan No 06 RT 01 RW 09 | M30: Anak | N30: 520101 2701020002
B31: 7 | C31: 26 | D31: M. Irham Haji S.Pi | E31: L | F31: Kawin | G31: 25674 | H31: Islam | I31: PT/Akademi | J31: PNS/TNI/ POLRI | K31: WNI | L31: Lingkungan Perumda Selatan No 07 RT 01 RW 09 | M31: KK | N31: 520112 1604700002
C32: 27 | D32: Sahidawan Hajah S.Pi | E32: P | F32: Kawin | G32: 25203 | H32: Islam | I32: PT/Akademi | J32: PNS/TNI/ POLRI | K32: WNI | L32: Lingkungan Perumda Selatan No 07 RT 01 RW 09 | M32: Istri | N32: 520112 7112680067
C33: 28 | D33: Ahmad Mujahidin Irham | E33: L | F33: Belum kawin | G33: 36540 | H33: Islam | I33: SD/MI | J33: - | K33: WNI | L33: Lingkungan Perumda Selatan No 07 RT 01 RW 09 | M33: Anak | N33: 520112 1501000003
C34: 29 | D34: Aditya Dawanta Irham | E34: L | F34: Belum kawin | G34: 37108 | H34: Islam | I34: SD/MI | J34: - | K34: WNI | L34: Lingkungan Perumda Selatan No 07 RT 01 RW 09 | M34: Anak | N34: 520112 0608010002
C35: 30 | D35: Bayu Muliana Dewi | E35: L | F35: Belum kawin | G35: 33154 | H35: Islam | I35: - | J35: - | K35: WNI | L35: Lingkungan Perumda Selatan No 07 RT 01 RW 09 | M35: Anak | N35: 520112 4610900003
C36: 31 | D36: Trio Oktaviani | E36: P | F36: Belum kawin | G36: 34610 | H36: Islam | I36: - | J36: - | K36: WNI | L36: Lingkungan Perumda Selatan No 07 RT 01 RW 09 | M36: Anak | N36: 520112 4310940001
B37: 8 | C37: 32 | D37: Yasir Arhofat | E37: L | F37: Kawin | G37: 29891 | H37: Islam | I37: SLTA/MA | J37: Wiraswasta | K37: WNI | L37: Lingkungan Perumda Selatan No 08 RT 01 RW 09 | M37: KK | N37: 520101 0211811001
C38: 33 | D38: Eva Afriani | E38: P | F38: Kawin | G38: 29335 | H38: Islam | I38: SLTA/MA | J38: Wiraswasta | K38: WNI | L38: Lingkungan Perumda Selatan No 08 RT 01 RW 09 | M38: Istri | N38: 520101 6404801001
C39: 34 | D39: Latisya Aqweena Arhofat | E39: P | F39: Belum kawin | G39: 41426 | H39: Islam | I39: - | J39: - | K39: WNI | L39: Lingkungan Perumda Selatan No 08 RT 01 RW 09 | M39: Anak | N39: 520101 4208131001
B40: 9 | C40: 35 | D40: Aganmadai S.Pd SD | E40: L | F40: Kawin | G40: 23867 | H40: Islam | I40: PT/ Akademi | J40: PNS/TNI/ POLRI | K40: WNI | L40: Lingkungan Perumda Selatan No 09 RT 01 RW 09 | M40: KK | N40: 520101 0509650001
C41: 36 | D41: Mariyanah | E41: P | F41: Kawin | G41: 31-02-1966 | H41: Islam | I41: SLTA/MA | J41: - | K41: WNI | L41: Lingkungan Perumda Selatan No 09 RT 01 RW 09 | M41: Istri | N41: 520101 4102960002
...

Sheet RT 02
B1: DATA INDUK PENDUDUK KELURAHAN DASAN GERES PERUMDA SELATAN RT 02 TAHUN 2015
B2: No | D2: Nama Lengkap/ | E2: Jenis Kelamin (L/P) | F2: Status Perkawinan | G2: Tanggal Lahir | H2: Agama | I2: Pendidikan Terakhir | J2: Pekerjaan | K2: Kewarganegaraan | L2: Alamat Lengkap | M2: Kedudukan dalam Keluarga | N2: NIK
D3: Panggilan
B4: 1 | C4: 1 | D4: Haji Soedirman | E4: L | F4: Kawin | G4: 19507 | H4: Islam | I4: SLTA/MA | J4: Pedagang | K4: WNI | L4: Lingkungan Perumda Selatan No 01 RT 02 RW 02 | M4: KK | N4: 520108 201000853
C5: 2 | D5: Hajjah Salmiah | E5: P | F5: Belum kawin | G5: 21185 | H5: Islam | I5: SD/MI | J5: - | K5: WNI | L5: Lingkungan Perumda Selatan No 03 RT 02 RW 02 | M5: Istri | N5: 520108 201000854
B6: 2 | C6: 3 | D6: Marif Murzaki | E6: L | F6: Kawin | G6: 17167 | H6: Islam | I6: SLTA/MA | J6: Pekerja lepas | K6: WNI | L6: Lingkungan Perumda Selatan No 02 RT 02 RW 02 | M6: KK | N6: 520101 3112460014
C7: 4 | D7: Marhana | E7: P | F7: Kawin | G7: 26664 | H7: Islam | I7: SD/MI | J7: Pedagang | K7: WNI | L7: Lingkungan Perumda Selatan No 03 RT 02 RW 02 | M7: Istri | N7: 520101 7112002001
C8: 5 | D8: Slamet Riadi | E8: L | F8: Belum kawin | G8: 29984 | H8: Islam | I8: SLTA/MA | J8: - | K8: WNI | L8: Lingkungan Perumda Selatan No 03 RT 02 RW 02 | M8: Anak | N8: 520101 0202820002
C9: 6 | D9: Nurlaela Zakira | E9: P | F9: Belum kawin | G9: 40810 | H9: Islam | I9: - | J9: - | K9: WNI | L9: Lingkungan Perumda Selatan No 03 RT 02 RW 02 | M9: Anak | N9: 520101 6409110002
B10: 3 | C10: 7 | D10: Edi Kurniawan | E10: L | F10: Kawin | G10: 26464 | H10: Islam | I10: SLTA/MA | J10: Pekerja lepas | K10: WNI | L10: Lingkungan Perumda Selatan No 03 RT 02 RW 02 | M10: KK | N10: 520101 1406720001
C11: 8 | D11: Ni Kadek Ayudani | E11: P | F11: Kawin | G11: 30644 | H11: Islam | I11: SLTA/MA | J11: Lainnya | K11: WNI | L11: Lingkungan Perumda Selatan No 03 RT 02 RW 02 | M11: Istri | N11: 520101 6411830001
C12: 9 | D12: Gede Mohamat Wiratama | E12: L | F12: Belum kawin | G12: 38656 | H12: Islam | I12: - | J12: - | K12: WNI | L12: Lingkungan Perumda Selatan No 03 RT 02 RW 02 | M12: Anak | N12: 520101 3110050001
C13: 10 | D13: Gede Prayoga Cakra Negara K | E13: L | F13: Belum kawin | G13: 41709 | H13: Islam | I13: - | J13: - | K13: WNI | L13: Lingkungan Perumda Selatan No 03 RT 02 RW 02 | M13: Anak | N13: 520101 1103140001
C14: 11 | D14: Waasesa Atmajaya | E14: L | F14: Belum kawin | G14: 35974 | H14: Islam | I14: SD/MI | J14: - | K14: WNI | L14: Lingkungan Perumda Selatan No 03 RT 02 RW 02 | M14: Lainnya | N14: 520101 2806480001
B15: 4 | C15: 12 | D15: I Made Dartana | E15: L | F15: Kawin | G15: 29559 | H15: Hindu | I15: SD/MI | J15: Wiraswasta | K15: WNI | L15: Lingkungan Perumda Selatan No 04 RT 02 RW 02 | M15: KK | N15: 520101 0412800001
C16: 13 | D16: Ni Ketut Dresty | E16: P | F16: Belum kawin | G16: 01-11-1071 | H16: Hindu | I16: SD/MI | J16: Pekerja lepas | K16: WNI | L16: Lingkungan Perumda Selatan No 04 RT 02 RW 02 | M16: Istri | N16: 520101 4111710001
B17: 5 | C17: 14 | D17: M Ali Sadikin | E17: L | F17: Kawin | G17: 30315 | H17: Islam | I17: SLTA/MA | K17: WNI | L17: Lingkungan Perumda Selatan No 05 RT 02 RW 02 | M17: KK | N17: 520101 3012820001
C18: 15 | D18: Sumiati | E18: P | F18: Kawin | G18: 12-12-198 | H18: Islam | I18: SLTA/MA | J18: Wiraswasta | K18: WNI | L18: Lingkungan Perumda Selatan No 05 RT 02 RW 02 | M18: Istri | N18: 000000 00000000000
B19: 6 | C19: 16 | D19: Faisal S.pd | E19: L | F19: Kawin | G19: 10-10-1068 | H19: Islam | I19: PT/Akademi | J19: - | K19: WNI | L19: Lingkungan Perumda Selatan No 06 RT 02 RW 02 | M19: KK | N19: 520101 1010680001
C20: 17 | D20: Eny Rohaida | E20: P | F20: Kawin | G20: 28595 | H20: Islam | I20: PT/Akademi | J20: PNS/TNI/ POLRI | K20: WNI | L20: Lingkungan Perumda Selatan No 06 RT 02 RW 02 | M20: Istri | N20: 520101 5509780001
C21: 18 | D21: Firman Harifanda Hartadi | E21: L | F21: Belum kawin | G21: 35526 | H21: Islam | I21: SLTP/MTSN | J21: - | K21: WNI | L21: Lingkungan Perumda Selatan No 06 RT 02 RW 02 | M21: Anak | N21: 520101 0604970002
C22: 19 | D22: M Taufik Febriansah H | E22: L | F22: Belum kawin | G22: 38022 | H22: Islam | I22: - | J22: - | K22: WNI | L22: Lingkungan Perumda Selatan No 06 RT 02 RW 02 | M22: Anak | N22: 520101 0502040001
C23: 20 | D23: Rizkian Alfaro Mauladi | E23: L | F23: Belum kawin | G23: 42005 | H23: Islam | I23: - | J23: - | K23: WNI | L23: Lingkungan Perumda Selatan No 06 RT 02 RW 02 | M23: Anak | N23: 520101 0101150001
B24: 7 | C24: 21 | D24: Ahmad Sukriman Lalu | E24: L | F24: Kawin | G24: 27164 | H24: Islam | I24: PT/Akademi | J24: PNS/TNI/ POLRI | K24: WNI | L24: Lingkungan Perumda Selatan No 07 RT 02 RW 02 | M24: KK | N24: 520101 1505740003
C25: 22 | D25: Desty Natalia Her Noza S.Adm | E25: P | F25: Kawin | G25: 30309 | H25: Islam | I25: PT/Akademi | J25: PNS/TNI/ POLRI | K25: WNI | L25: Lingkungan Perumda Selatan No 07 RT 02 RW 02 | M25: Istri | N25: 520101 6412820003
C26: 23 | D26: Lalu Alidhio Suryawan A | E26: L | F26: Belum kawin | G26: 38401 | H26: Islam | I26: - | J26: - | K26: WNI | L26: Lingkungan Perumda Selatan No 07 RT 02 RW 02 | M26: Anak | N26: 520101 1802050003
B27: 8 | C27: 24 | D27: Waginan Agi Firmansyah | E27: L | F27: Kawin | G27: 30234 | H27: Islam | I27: SLTP/MTSN | J27: Pekerja Lepas | K27: WNI | L27: Lingkungan Perumda Selatan No 08 RT 02 RW 02 | M27: KK | N27: 520101 211102003
C28: 25 | D28: Munirah Sygun Basri | E28: P | F28: Kawin | G28: 29479 | H28: Islam | I28: SD/MI | J28: - | K28: WNI | L28: Lingkungan Perumda Selatan No 08 RT 02 RW 02 | M28: Istri | N28: 520101 0204500002
C29: 26 | D29: Nuri Wulandari | E29: P | F29: Belum kawin | G29: 06-04-007 | H29: Islam | I29: - | J29: - | K29: WNI | L29: Lingkungan Perumda Selatan No 08 RT 02 RW 02 | M29: Anak | N29: 520101 0204070004
C30: 27 | D30: Nasyatul Laily | E30: P | F30: Belum kawin | G30: 40579 | H30: Islam | I30: - | J30: - | K30: WNI | L30: Lingkungan Perumda Selatan No 08 RT 02 RW 02 | M30: Anak | N30: 520101 8603110002
B31: 9 | C31: 28 | D31: Batiah | E31: P | F31: Kawin | G31: 26298 | H31: Islam | I31: SD/MI | J31: Pegawas swasta | K31: WNI | L31: Lingkungan Perumda Selatan No 09 RT 02 RW 02 | M31: KK | N31: 520101 7112710074
C32: 29 | D32: Zaenudin | E32: L | F32: Kawin | G32: 34012 | H32: Islam | I32: SLTP/MTSN | J32: - | K32: WNI | L32: Lingkungan Perumda Selatan No 09 RT 02 RW 02 | M32: Istri | N32: 520101 1202930004
C33: 30 | D33: Pauzul Hakim | E33: L | F33: Kawin | G33: 35787 | H33: Islam | I33: SD/MI | J33: - | K33: WNI | L33: Lingkungan Perumda Selatan No 09 RT 02 RW 02 | M33: Anak | N33: 520101 2312970001
B34: 10 | C34: 31 | D34: Dian Putra | E34: L | F34: Kawin | G34: 30587 | H34: Islam | I34: SLTA/MA | J34: Pekerja lepas | K34: WNI | L34: Lingkungan Perumda Selatan No 10 RT 02 RW 02 | M34: KK | N34: 520101 2809831011
C35: 32 | D35: Idawati | E35: P | F35: Kawin | G35: 33670 | H35: Islam | I35: SLTA/MA | J35: - | K35: WNI | L35: Lingkungan Perumda Selatan No 10 RT 02 RW 02 | M35: Istri | N35: 520101 4703921001
C36: 33 | D36: Gilang Pratama Saputra | E36: L | F36: Belum kawin | G36: 41453 | H36: Islam | I36: - | J36: - | K36: WNI | L36: Lingkungan Perumda Selatan No 12 RT 02 RW 02 | M36: Anak | N36: 520101 2806131001
B37: 11 | C37: 34 | D37: Ahmad Tamli | E37: L | F37: Kawin | G37: 27023 | H37: Islam | I37: PT/Akademi | J37: Pegawai swasta | K37: WNI | L37: Lingkungan Perumda Selatan No 11 RT 02 RW 02 | M37: KK | N37: 520101 2512730001
C38: 35 | D38: Sri Ariyani | E38: P | F38: Kawin | G38: 28980 | H38: Islam | I38: PT/Akademi | J38: PNS/TNI/ POLRI | K38: WNI | L38: Lingkungan Perumda Selatan No 11 RT 02 RW 02 | M38: Istri | N38: 520101 4505750001
C39: 36 | D39: Aril Ramdan A L Farisi | E39: L | F39: Bwlum kawin | G39: 38630 | H39: Islam | I39: - | J39: - | K39: WNI | L39: Lingkungan Perumda Selatan No 11 RT 02 RW 02 | M39: Anak | N39: 520101 0310050001
C40: 37 | D40: Aulia Suci Arini | E40: P | F40: Belum kawin | G40: 38630 | H40: Islam | I40: - | J40: - | K40: WNI | L40: Lingkungan Perumda Selatan No 11 RT 02 RW 02 | M40: Anak | N40: 520101 4319950001
...

Sheet RT 03
B1: DATA INDUK PENDUDUK PERUMDA SELATAN RT 03 KELURAHAN DASAN GERES TAHUN 2015
B2: No | D2: Nama Lengkap/ | E2: Jenis Kelamin (L/P) | F2: Status Perkawinan | G2: Tanggal Lahir | H2: Agama | I2: Pendidikan Terakhir | J2: Pekerjaan | K2: Kewarganegaraan | L2: Alamat Lengkap | M2: Kedudukan dalam Keluarga | N2: NIK
D3: Panggilan
B4: 1 | C4: 1 | D4: Sahnan S.H | E4: L | F4: Kawin | G4: 21550 | H4: Islam | I4: PT/Akademi | J4: Pedagang | K4: WNI | L4: Lingkungan Perumda Selatan No 01 RT 03 RW 09 | M4: KK | N4: 520101 3112580002
C5: 2 | D5: Suhairani | E5: P | F5: Kawin | G5: 28029 | H5: Islam | I5: SLTA/MA | J5: - | K5: WNI | L5: Lingkungan Perumda Selatan No 01 RT 03 RW 09 | M5: Istri | N5: 520101 6609760001
C6: 3 | D6: Rizal M Yasin | E6: L | F6: Belum kawin | G6: 32510 | H6: Islam | I6: SLTA/MA | J6: Wiraswasta | K6: WNI | L6: Lingkungan Perumda Selatan No 01 RT 03 RW 09 | M6: Anak | N6: 520101 0201890001
C7: 4 | D7: Abdul Rizki Nurmansyah | E7: L | F7: Belum kawin | G7: 35151 | H7: Islam | I7: SLTA/MA | J7: Wiraswasta | K7: WNI | L7: Lingkungan Perumda Selatan No 01 RT 03 RW 09 | M7: Anak | N7: 520101 2703960001
C8: 5 | D8: Muhammad Zulhan Syahroni | E8: L | F8: Belum kawin | G8: 858 | H8: Islam | I8: - | J8: - | K8: WNI | L8: Lingkungan Perumda Selatan No 01 RT 03 RW 09 | M8: Anak | N8: 520101 0705020001
C9: 6 | D9: Muhammad Izzudddin Harari | E9: L | F9: Belum kawin | G9: 38041 | H9: Islam | I9: - | J9: - | K9: WNI | L9: Lingkungan Perumda Selatan No 01 RT 03 RW 09 | M9: Anak | N9: 520101 2402040001
C10: 7 | D10: Muhammad Alkausar Amhayasin | E10: L | F10: Belum kawin | G10: 39993 | H10: Islam | I10: - | J10: - | K10: WNI | L10: Lingkungan Perumda Selatan No 01 RT 03 RW 09 | M10: Anak | N10: 000000 0000000000
B11: 2 | C11: 8 | D11: Lalu Idham Chalid | E11: L | F11: Kawin | G11: 14-10-1880 | H11: Islam | I11: SLTA/MA | J11: - | K11: WNI | L11: Lingkungan Perumda Selatan No 02 RT 03 RW 09 | M11: KK | N11: 520101 1810800001
C12: 9 | D12: Suryaningsih | E12: P | F12: Kawin | G12: 30316 | H12: Islam | I12: SLTP/MTSN | J12: - | K12: WNI | L12: Lingkungan Perumda Selatan No 02 RT 03 RW 09 | M12: Istri | N12: 520101 7112620009
C13: 10 | D13: Baiq Hilniatun Nisa | E13: P | F13: Belum kawin | G13: 36952 | H13: Islam | I13: SD/MI | J13: - | K13: WNI | L13: Lingkungan Perumda Selatan No 02 RT 03 RW 09 | M13: Anak | N13: 520101 4203010001
C14: 11 | D14: Lalu Raysarabrar | E14: L | F14: Belum kawin | G14: 39909 | H14: Islam | I14: - | J14: - | K14: WNI | L14: Lingkungan Perumda Selatan No 02 RT 03 RW 09 | M14: Anak | N14: 520101 0604090001
B15: 3 | C15: 12 | D15: Lalu Nursidi | E15: L | F15: Kawin | G15: 26115 | H15: Islam | I15: SLTA/MA | J15: PNS/TNI/ POLRI | K15: WNI | L15: Lingkungan Perumda Selatan No 03 RT 03 RW 09 | M15: KK | N15: 520101 0107710109
C16: 13 | D16: Rina Juhernawati | E16: P | F16: Kawin | G16: 28363 | H16: Islam | I16: SLTA/MA | J16: - | K16: WNI | L16: Lingkungan Perumda Selatan No 03 RT 03 RW 09 | M16: Istri | N16: 520101 6608770001
C17: 14 | D17: Lalu Muhammad Rafli Nurcholik | E17: L | F17: Belum kawin | G17: 37382 | H17: Islam | I17: - | J17: - | K17: WNI | L17: Lingkungan Perumda Selatan No 03 RT 03 RW 09 | M17: Anak | N17: 520101 0609020001
C18: 15 | D18: Lalu Muhammad Rizky Maulana | E18: L | F18: Belum kawin | G18: 38094 | H18: Islam | I18: - | J18: - | K18: WNI | L18: Lingkungan Perumda Selatan No 03 RT 03 RW 09 | M18: Anak | N18: 520101 1704044001
C19: 16 | D19: Baiq Bilqis Ayudia Humaira Humaira | E19: P | F19: Belum kawin | G19: 41982 | H19: Islam | I19: - | J19: - | K19: WNI | L19: Lingkungan Perumda Selatan No 03 RT 03 RW 09 | M19: Anak | N19: 520101 4912140001
B20: 4 | C20: 17 | D20: Juni Hardi Satriawan | E20: L | F20: Kawin | G20: 30106 | H20: Islam | I20: SLTA/MA | J20: Wiraswasta | K20: WNI | L20: Lingkungan Perumda Selatan No 04 RT 03 RW 09 | M20: KK | N20: 520101 0906820003
C21: 18 | D21: Maesha Susilawati | E21: P | F21: Kawin | G21: 33024 | H21: Islam | I21: SLTP/MTSN | J21: - | K21: WNI | L21: Lingkungan Perumda Selatan No 04 RT 03 RW 09 | M21: Istri | N21: 520101 7105900002
C22: 19 | D22: Muhammad Faesal Ghazali | E22: L | F22: Belum kawin | G22: 42103 | H22: Islam | I22: - | J22: - | K22: WNI | L22: Lingkungan Perumda Selatan No 04 RT 03 RW 09 | M22: Anak | N22: 000000 0000000000
B23: 5 | C23: 20 | D23: Mawardi | E23: L | F23: Kawin | G23: 21550 | H23: Islam | I23: SLTA/MA | J23: - | K23: WNI | L23: Lingkungan Perumda Selatan No 05 RT 03 RW 09 | M23: KK | N23: 520101 3112580069
C24: 21 | D24: Baiq Hapni | E24: P | F24: Kawin | G24: 20454 | H24: Islam | I24: SD/MI | J24: - | K24: WNI | L24: Lingkungan Perumda Selatan No 05 RT 03 RW 09 | M24: Istri | N24: 520101 7112560042
B25: 6 | C25: 22 | D25: Baiq Sahuri | E25: P | F25: Janda | G25: 20820 | H25: Islam | I25: SD/MI | J25: - | K25: WNI | L25: Lingkungan Perumda Selatan No 05 RT 03 RW 09 | M25: KK | N25: 520101 7112560053
C26: 23 | D26: Baiq Umi Kalsum | E26: P | F26: Belum kawin | G26: 28991 | H26: Islam | I26: PT/Akademi | J26: Wiraswasta | K26: WNI | L26: Lingkungan Perumda Selatan No 05 RT 03 RW 09 | M26: Anak | N26: 520101 5605790001
C27: 24 | D27: Baiq Rospita | E27: P | F27: Belum kawin | G27: 32549 | H27: Islam | I27: PT/Akademi | J27: Pegawai swasta | K27: WNI | L27: Lingkungan Perumda Selatan No 05 RT 03 RW 09 | M27: Anak | N27: 520101 5002890009
B28: 7 | C28: 25 | D28: Johsan S.E | E28: L | F28: Kawin | G28: 23625 | H28: Islam | I28: PT/Akademi | J28: PNS/TNI/ POLRI | K28: WNI | L28: Lingkungan Perumda Selatan No 06 RT 03 RW 09 | M28: KK | N28: 520101 0509640001
C29: 26 | D29: Syafiatun | E29: P | F29: Kawin | G29: 25195 | H29: Islam | I29: SLTA/MA | J29: Wiraswasta | K29: WNI | L29: Lingkungan Perumda Selatan No 06 RT 03 RW 09 | M29: Istri | N29: 520101 6312680001
C30: 27 | D30: Alfian Chandra | E30: L | F30: Belum kawin | G30: 33053 | H30: Islam | I30: SLTA/MA | J30: - | K30: WNI | L30: Lingkungan Perumda Selatan No 06 RT 03 RW 09 | M30: Anak | N30: 520101 2906900001
C31: 28 | D31: Buchari Irsan | E31: L | F31: Belum kawin | G31: 33910 | H31: Islam | I31: SLTA/MA | J31: PNS/TNI/ POLRI | K31: WNI | L31: Lingkungan Perumda Selatan No 06 RT 03 RW 09 | M31: Anak | N31: 520101 2811921001
C32: 29 | D32: Riskiyadi Khaerul Abdi | E32: L | F32: Belum kawin | G32: 36365 | H32: Islam | I32: SLTP/MTSN | J32: - | K32: WNI | L32: Lingkungan Perumda Selatan No 06 RT 03 RW 09 | M32: Anak | N32: 520101 2407920001
B33: 8 | C33: 30 | D33: I Ketut Wirya | E33: L | F33: Kawin | G33: 24043 | H33: Hindu | I33: PT/Akademi | J33: PNS/TNI/ POLRI | K33: WNI | L33: Lingkungan Perumda Selatan No 07 RT 03 RW 09 | M33: KK | N33: 520101 2810650001
C34: 31 | D34: Ni Made Suparsini | E34: P | F34: Kawin | G34: 25049 | H34: Hindu | I34: PT/Akademi | J34: PNS/TNI/ POLRI | K34: WNI | L34: Lingkungan Perumda Selatan No 07 RT 03 RW 09 | M34: Istri | N34: 5.2017007e+15
C35: 32 | D35: Ni Made Pradnya Wiriani | E35: P | F35: Belum kawin | G35: 34010 | H35: Hindu | I35: SLTA/MA | J35: - | K35: WNI | L35: Lingkungan Perumda Selatan No 07 RT 03 RW 09 | M35: Anak | N35: 520101 4107930163
C36: 33 | D36: Nyoman Genter Wiriana | E36: L | F36: Belum kawin | G36: 34842 | H36: Hindu | I36: SLTA/MA | J36: - | K36: WNI | L36: Lingkungan Perumda Selatan No 07 RT 03 RW 09 | M36: Anak | N36: 520101 2305950001
C37: 34 | D37: I Wayan Putra Panida | E37: L | F37: Kawin | G37: 25734 | H37: Hindu | I37: SLTA/MA | J37: Pegawai swasta | K37: WNI | L37: Lingkungan Perumda Selatan No 07 RT 03 RW 09 | M37: Anak | N37: 520101 1506701007
B38: 9 | C38: 35 | D38: Panut Eko Priyo No | E38: L | F38: Kawin | G38: 27378 | H38: Islam | I38: PT/Akademi | J38: PNS/TNI/ POLRI | K38: WNI | L38: Lingkungan Perumda Selatan No 08 RT 03 RW 09 | M38: Suami | N38: 520101 1160570001
C39: 36 | D39: Kamariah | E39: P | F39: Kawin | G39: 27394 | H39: Islam | J39: PNS/TNI/ POLRI | K39: WNI | L39: Lingkungan Perumda Selatan No 08 RT 03 RW 09 | M39: Istri | N39: 520101 7112740197
C40: 37 | D40: Alif Febrianto | E40: L | F40: Belum kawin | G40: 35850 | H40: Islam | I40: PT/Akademi | J40: - | K40: WNI | L40: Lingkungan Perumda Selatan No 08 RT 03 RW 09 | M40: Anak | N40: 520101 2402980003
...

Sheet RT 04
B1: DATA INDUK PENDUDUK PERUMDA SELATAN RT 04 KELURAHAN DASAN GERES TAHUN 2015
B2: No | D2: Nama Lengkap/ | E2: Jenis Kelamin (L/P) | F2: Status Perkawinan | G2: Tanggal Lahir | H2: Agama | I2: Pendidikan Terakhir | J2: Pekerjaan | K2: Kewarganegaraan | L2: Alamat Lengkap | M2: Kedudukan dalam Keluarga | N2: NIK
D3: Panggilan
B4: 1 | C4: 1 | D4: Ainul Yakin | E4: L | F4: Kawin | G4: 34334 | H4: Islam | I4: SLTA/MA | J4: Wiraswasta | K4: WNI | L4: Lingkungan Perumda SelatanNo 31 RT 04 RW 09 | M4: KK | N4: 520101 3112890011
C5: 2 | D5: Uswatun Hasanah | E5: P | F5: Kawin | G5: 32887 | H5: Islam | I5: SLTA/MA | J5: PNS/TNI/ POLRI | K5: WNI | L5: Lingkungan Perumda SelatanNo 31 RT 04 RW 09 | M5: Istri | N5: 520101 5401830001
C6: 3 | D6: Keisya Khusnul Syahida | E6: P | F6: Belum kawin | G6: 40866 | H6: Islam | I6: SLTA/MA | J6: - | K6: WNI | L6: Lingkungan Perumda SelatanNo 31 RT 04 RW 09 | M6: Anak | N6: 520101 6809150001
B7: 2 | C7: 4 | D7: Dani Faosan S.T | E7: L | F7: Kawin | G7: 35252 | H7: Islam | I7: PT/Akademi | J7: PNS/TNI/ POLRI | K7: WNI | L7: Lingkungan Perumda SelatanNo 27 RT 04 RW 09 | M7: KK | N7: 520101 0807780004
C8: 5 | D8: Murni Puspita Sari S.E | E8: P | F8: Kawin | G8: 28097 | H8: Islam | I8: PT/Akademi | J8: PNS/TNI/ POLRI | K8: WNI | L8: Lingkungan Perumda SelatanNo 27 RT 04 RW 09 | M8: Istri | N8: 520101 4312760003
C9: 6 | D9: Muhamad Farhan Farhan Zulfahmi | E9: L | F9: Belum kawin | G9: 37092 | H9: Islam | I9: SD/MI | J9: - | K9: WNI | L9: Lingkungan Perumda SelatanNo 27 RT 04 RW 09 | M9: Anak | N9: 520101 2007010005
C10: 7 | D10: Adelia Hayundari | E10: P | F10: Belum kawin | G10: 41398 | H10: Islam | I10: - | J10: - | K10: WNI | L10: Lingkungan Perumda SelatanNo 27 RT 04 RW 09 | M10: Anak | N10: 520101 5406960002
B11: 3 | C11: 8 | D11: Boiman S.Pd | E11: L | F11: Kawin | G11: 25517 | H11: Islam | I11: PT/Akademi | J11: PNS/TNI/ POLRI | K11: WNI | L11: Lingkungan Perumda SelatanNo 25 RT 04 RW 09 | M11: KK | N11: 520101 1011690001
C12: 9 | D12: Titi Srimulyanti Mulyandari | E12: P | F12: Kawin | G12: 29535 | H12: Islam | I12: PT/Akademi | J12: PNS/TNI/ POLRI | K12: WNI | L12: Lingkungan Perumda SelatanNo 25 RT 04 RW 09 | M12: Istri | N12: 520101 5011800001
C13: 10 | D13: Imanika Srimulyandari | E13: P | F13: Belum kawin | G13: 37088 | H13: islam | I13: SD/MI | J13: - | K13: WNI | L13: Lingkungan Perumda SelatanNo 25 RT 04 RW 09 | M13: Anak | N13: 520101 5607010001
C14: 11 | D14: Hanifa Dwi Yanti Imadini | E14: P | F14: Belum kawin | G14: 38890 | H14: Islam | I14: - | J14: - | K14: WNI | L14: Lingkungan Perumda SelatanNo 25 RT 04 RW 09 | M14: Anak | N14: 520101 6206060001
B15: 4 | C15: 12 | D15: Mawardi | E15: L | F15: Kawin | G15: 27760 | H15: Islam | I15: SLTP/MTSN | J15: Wiraswasta | K15: WNI | L15: Lingkungan Perumda SelatanNo 21 RT 04 RW 09 | M15: KK | N15: 520113 0101750002
C16: 13 | D16: Permayasari Gusti Ayu | E16: P | F16: Kawin | G16: 29642 | H16: Islam | I16: PT/Akademi | J16: PNS/TNI/ POLRI | K16: WNI | L16: Lingkungan Perumda SelatanNo 21 RT 04 RW 09 | M16: Istri | N16: 520113 6502810002
C17: 14 | D17: Jania Anantha Sahyra | E17: P | F17: Belum kawin | G17: 39475 | H17: Islam | I17: - | J17: - | K17: WNI | L17: Lingkungan Perumda SelatanNo 21 RT 04 RW 09 | M17: Anak | N17: 520113 6801080002
B18: 5 | C18: 15 | D18: Mujitahid | E18: L | F18: Kawin | G18: 33102 | H18: Islam | I18: SLTA/MA | J18: Wiraswasta | K18: WNI | L18: Lingkungan Perumda SelatanNo 20 RT 04 RW 09 | M18: KK | N18: 520101 1708900003
C19: 16 | D19: Mahnep | E19: P | F19: Kawin | G19: 33238 | H19: Islam | I19: SLTA/MA | J19: - | K19: WNI | L19: Lingkungan Perumda SelatanNo 20 RT 04 RW 09 | M19: Istri | N19: 520101 7112900080
C20: 17 | D20: Sabila Rasyad | E20: P | F20: Belum kawin | G20: 40953 | H20: Islam | I20: - | J20: - | K20: WNI | L20: Lingkungan Perumda SelatanNo 20 RT 04 RW 09 | M20: Anak | N20: 000000 0000000000
B21: 6 | C21: 18 | D21: Zulhakim | E21: L | F21: Kawin | G21: 29294 | H21: Islam | I21: SLTA/MA | J21: PNS/ TNI/ POLRI | K21: WNI | L21: Lingkungan Perumda SelatanNo 19 RT 04 RW 09 | M21: KK | N21: 520115 0107800214
C22: 19 | D22: Herawati S.Pd | E22: P | F22: Kawin | G22: 30051 | H22: Islam | I22: SLTA/MA | J22: Wiraswasta | K22: WNI | L22: Lingkungan Perumda Selatan No 19 RT 04 RW 09 | M22: Istri | N22: 520115 5004820001
C23: 20 | D23: Aira Putri Zulfa Hakim | E23: P | F23: Belum kawin | G23: 40073 | H23: Islam | I23: - | J23: - | K23: WNI | L23: Lingkungan Perumda Selatan No 19 RT 04 RW 09 | M23: Anak | N23: 520115 5709090002
B24: 7 | C24: 21 | D24: Joni Hariyanto | E24: L | F24: Kawin | G24: 26434 | H24: Islam | I24: PT/Akademi | J24: PNS/ TNI/ POLRI | K24: WNI | L24: Lingkungan Perumda SelatanNo 18 RT 04 RW 09 | M24: KK | N24: 520107 1606720002
C25: 22 | D25: Baiq Erniwati | E25: P | F25: Kawin | G25: 26626 | H25: Islam | I25: SLTP/MTSN | J25: Wiraswasta | K25: WNI | L25: Lingkungan Perumda SelatanNo 18 RT 04 RW 09 | M25: Istri | N25: 520107 6311720002
C26: 23 | D26: Aditya Yudi Permadi | E26: L | F26: Belum kawin | G26: 35045 | H26: Islam | I26: SLTA/MA | J26: - | K26: WNI | L26: Lingkungan Perumda SelatanNo 18 RT 04 RW 09 | M26: Anak | N26: 520107 1212950002
C27: 24 | D27: Wahyu Dwi Saputra | E27: L | F27: Belum kawin | G27: 37583 | H27: Islam | I27: - | J27: - | K27: WNI | L27: Lingkungan Perumda SelatanNo 18 RT 04 RW 09 | M27: Anak | N27: 520107 0311020002
C28: 25 | D28: M. Fahrrozi | E28: L | F28: Belum kawin | G28: 38993 | H28: Islam | I28: - | J28: - | K28: WNI | L28: Lingkungan Perumda SelatanNo 18 RT 04 RW 09 | M28: Anak | N28: 520107 0311080001
B29: 8 | C29: 26 | D29: Rival Hendriawan Lalu | E29: L | F29: Kawin | G29: 32173 | H29: Islam | I29: SD/MI | J29: Wiraswasta | K29: WNI | L29: Lingkungan Perumda SelatanNo 17 RT 04 RW 09 | M29: KK | N29: 520102 3103860001
C30: 27 | D30: Mustikah | E30: P | F30: Kawin | G30: 35958 | H30: Islam | I30: SD/MI | J30: Wiraswasta | K30: WNI | L30: Lingkungan Perumda SelatanNo 17 RT 04 RW 09 | M30: Istri | N30: 520101 5206880001
B31: 9 | C31: 28 | D31: Engkus Kusnendar S.E | E31: L | F31: Kawin | G31: 31483 | H31: Islam | I31: PT/Akademik | J31: Wiraswasta | K31: WNI | L31: Lingkungan Perumda SelatanNo 16 RT 04 RW 09 | M31: KK | N31: 527105 1203860005
C32: 29 | D32: Ety Sastriani S.E | E32: P | F32: Kawin | G32: 31672 | H32: Islam | I32: PT/Akademi | J32: - | K32: WNI | L32: Lingkungan Perumda SelatanNo 16 RT 04 RW 09 | M32: Istri | N32: 520208 5709860004
C33: 30 | D33: Fiola Anastasya Cantika | E33: P | F33: Belum kawin | G33: 41244 | H33: Islam | I33: - | K33: WNI | L33: Lingkungan Perumda SelatanNo 16 RT 04 RW 09 | M33: Anak | N33: 520208 4112120001
B34: 10 | C34: 31 | D34: Bidrah | E34: P | F34: Janda | G34: 29042 | H34: Islam | I34: SLTP/MTSNN | J34: Wiraswasta | K34: WNI | L34: Lingkungan Perumda SelatanNo 15 RT 04 RW 09 | M34: KK | N34: 520101 4607790001
B35: 11 | C35: 32 | D35: Lalu Sunarman | E35: L | F35: Kawin | G35: 23940 | H35: Islam | I35: SLTA/MA | J35: PNS/ TNI/ POLRI | K35: WNI | L35: Lingkungan Perumda SelatanNo 13 RT 04 RW 09 | M35: KK | N35: 520101 1707650001
C36: 33 | D36: Hilyatil Mardilah | E36: P | F36: Kawin | G36: 24712 | H36: Islam | I36: SLTA/MA | J36: PNS/ TNI/ POLRI | K36: WNI | L36: Lingkungan Perumda SelatanNo 13 RT 04 RW 09 | M36: Istri | N36: 520101 6808670001
C37: 34 | D37: Lalu Ilman Haris | E37: L | F37: Belum kawin | G37: 31958 | H37: Islam | I37: SLTA/MA | J37: Wiraswasta | K37: WNI | L37: Lingkungan Perumda SelatanNo 13 RT 04 RW 09 | M37: KK | N37: 520101 3012870006
C38: 35 | D38: Lalu Helmi Suleman Haris | E38: L | F38: Belum kawin | G38: 0709-1989 | H38: Islam | I38: SLTA/MA | J38: Wiraswasta | K38: WNI | L38: Lingkungan Perumda SelatanNo 13 RT 04 RW 09 | M38: KK | N38: 520101 0709890002
C39: 36 | D39: Lalu Zainul Rahman Haris | E39: L | F39: Belum kawin | G39: 35210 | H39: Islam | I39: SLTA/MA | J39: - | K39: WNI | L39: Lingkungan Perumda SelatanNo 13 RT 04 RW 09 | M39: KK | N39: 520101 2503960001
C40: 37 | D40: Baiq Isma Najwa Farhani H. | E40: P | F40: Belum kawin | G40: 39061 | H40: Islam | I40: - | J40: - | K40: WNI | L40: Lingkungan Perumda SelatanNo 13 RT 04 RW 09 | M40: KK | N40: 520101 5012960003
...

Sheet RT 05
B1: DATA INDUK PENDUDUK PERUMDA SELATAN RT 05 KELURAHAN DASAN GERES TAHUN 2015
B2: No | D2: Nama Lengkap/ | E2: Jenis Kelamin (L/P) | F2: Status Perkawinan | G2: Tanggal Lahir | H2: Agama | I2: Pendidikan Terakhir | J2: Pekerjaan | K2: Kewarganegaraan | L2: Alamat Lengkap | M2: Kedudukan dalam Keluarga | N2: NIK
D3: Panggilan
B4: 1 | C4: 1 | D4: Supardi R | E4: L | F4: Kawin | G4: 20520 | H4: Islam | I4: SLTA/MA | J4: Pensiunan | K4: WNI | L4: Lingkungan Perumda Selatan No 01 RT 05 RW 09 | M4: KK | N4: 527102 0603340001
C5: 2 | D5: Siti Kariaton | E5: P | F5: Belum kawin | G5: 21550 | H5: Islam | I5: - | J5: Pedagang | K5: WNI | L5: Lingkungan Perumda Selatan No 01 RT 05 RW 09 | M5: Istri | N5: 527102 7112580175
B6: 2 | C6: 3 | D6: Taufikurrahman | E6: L | F6: Kawin | G6: 27826 | H6: Islam | I6: SLTA/MA | J6: Lainnya | K6: WNI | L6: Lingkungan Perumda Selatan No 01 RT 05 RW 09 | M6: KK | N6: 520101 0703760001
C7: 4 | D7: Mardiah | E7: P | F7: Kawin | G7: 29343 | H7: Islam | I7: SLTA/MA | J7: - | K7: WNI | L7: Lingkungan Perumda Selatan No 01 RT 05 RW 09 | M7: Istri | N7: 520101 4205800004
C8: 5 | D8: Irsalaman | E8: L | F8: Belum kawin | G8: 39488 | H8: Islam | I8: - | J8: - | K8: WNI | L8: Lingkungan Perumda Selatan No 02 RT 05 RW 09 | M8: Anak | N8: 520101 1002080001
C9: 6 | D9: Mayesa Ayu Ramadani | E9: P | F9: Belum kawin | G9: 41818 | H9: Islam | I9: - | J9: - | K9: WNI | L9: Lingkungan Perumda Selatan No 01 RT 05 RW 09 | M9: Anak | N9: 520101 6800140002
B10: 3 | C10: 7 | D10: Topan Budiawan | E10: L | F10: Kawin | G10: 32512 | H10: Islam | I10: PT/Akademi | J10: Lainnya | K10: WNI | L10: Lingkungan Perumda Selatan No 02 RT 05 RW 09 | M10: KK | N10: 520101 0107880169
C11: 8 | D11: Dessy Cessara Rizqi | E11: P | F11: Kawin | G11: 32483 | H11: Islam | I11: PT/Akademi | J11: Wiraswasta | K11: WNI | L11: Lingkungan Perumda Selatan No 02 RT 05 RW 09 | M11: Istri | N11: 520101 4612880005
C12: 9 | D12: Adelia Deva Annida | E12: P | F12: Belum kawin | G12: 41596 | H12: Islam | I12: - | J12: - | K12: WNI | L12: Lingkungan Perumda Selatan No 02 RT 05 RW 09 | M12: Anak | N12: 520101 5811311001
B13: 4 | C13: 10 | D13: Muniah | E13: P | F13: Janda | G13: 16071 | H13: Islam | I13: - | J13: - | K13: WNI | L13: Lingkungan Perumda Selatan No 03 RT 05 RW 09 | M13: KK | N13: 520101 7112430014
C14: 11 | D14: Indah | E14: P | F14: Belum kawin | G14: 36711 | H14: Islam | I14: SLTP/MTSN | J14: - | K14: WNI | L14: Lingkungan Perumda Selatan No 03 RT 05 RW 09 | M14: Istri | N14: 520101 4492830002
C15: 12 | D15: Marnah Munir | E15: P | F15: Kawin | G15: 26370 | H15: Islam | I15: PT/Akademi | J15: PNS/TNI/ POLRI | K15: WNI | L15: Lingkungan Perumda Selatan No 03 RT 05 RW 09 | M15: Anak | N15: 520101 8203720002
B16: 5 | C16: 13 | D16: Drs Muhammad Nuh | E16: L | F16: Kawin | G16: 21406 | H16: Islam | I16: PT/Akademi | J16: PNS/TNI/ POLRI | K16: WNI | L16: Lingkungan Perumda Selatan No 04 RT 05 RW 09 | M16: KK | N16: 520108 0908580001
C17: 14 | D17: Baiq Huriah | E17: P | F17: Kawin | G17: 22991 | H17: Islam | I17: PT/Akademi | J17: - | K17: WNI | L17: Lingkungan Perumda Selatan No 04 RT 05 RW 09 | M17: Istri | N17: 520108 7112620078
C18: 15 | D18: Zahratul Fitriani | E18: P | F18: Belum kawin | G18: 33702 | H18: Islam | I18: SLTA/MA | J18: - | K18: WNI | L18: Lingkungan Perumda Selatan No 04 RT 05 RW 09 | M18: Anak | N18: 520108 4804920002
C19: 16 | D19: Fitriyan Hartika | E19: P | F19: Belum kawin | G19: 34476 | H19: Islam | I19: SLTA/MA | J19: - | K19: WNI | L19: Lingkungan Perumda Selatan No 04 RT 05 RW 09 | M19: Anak | N19: 520108 4205949997
B20: 6 | C20: 17 | D20: Kariadi | E20: L | F20: Kawin | G20: 28247 | H20: Islam | I20: SLTA/MA | J20: PNS/TNI/ POLRI | K20: WNI | L20: Lingkungan Perumda Selatan No 05 RT 05 RW 09 | M20: KK | N20: 520102 0205770001
C21: 18 | D21: Laily Sumiati | E21: P | F21: Kawin | G21: 30281 | H21: Islam | I21: PT/Akadmi | J21: Pekerja lepas | K21: WNI | L21: Lingkungan Perumda Selatan No 05 RT 05 RW 09 | M21: Istri | N21: 520102 6611020001
C22: 19 | D22: Adila Aura Kharisma | E22: P | F22: Belum kawin | G22: 41074 | H22: Islam | I22: - | J22: - | K22: WNI | L22: Lingkungan Perumda Selatan No 05 RT 05 RW 09 | M22: Anak | N22: 520102 3405120001
B23: 7 | C23: 20 | D23: Aditya Alfandi Saputra | E23: L | F23: Kawin | G23: 30823 | H23: Islam | I23: SLTA/MA | J23: Wiraswasta | K23: WNI | L23: Lingkungan Perumda Selatan No 06 RT 05 RW 09 | M23: KK | N23: 520101 2105840006
C24: 21 | D24: Lucky Febriana | E24: P | F24: Kawin | G24: 32911 | H24: Islam | I24: SLTA/MA | J24: - | K24: WNI | L24: Lingkungan Perumda Selatan No 06 RT 05 RW 09 | M24: Istri | N24: 520101 4702900001
C25: 22 | D25: Yandre Dwi Saputra | E25: P | F25: Belum kawin | G25: 34575 | H25: Islam | I25: SLTA/MA | J25: - | K25: WNI | L25: Lingkungan Perumda Selatan No 06 RT 05 RW 09 | M25: Anak | N25: 520101 2908940002
B26: 8 | C26: 23 | D26: Irfan Juhari S.T | E26: L | F26: Kawin | G26: 12068 | H26: Islam | I26: PT/Akademi | J26: PNS/TNI/ POLRI | K26: WNI | L26: Lingkungan Perumda Selatan No 07 RT 05 RW 09 | M26: KK | N26: 520101 1401820004
C27: 24 | D27: Aluh Ari Yuliarti S.Pd | E27: P | F27: Kawin | G27: 31959 | H27: Islam | I27: PT/Akademi | J27: Wiraswasta | K27: WNI | L27: Lingkungan Perumda Selatan No 07 RT 05 RW 09 | M27: Istri | N27: 520101 4107670127
C28: 25 | D28: Fathia Aljauza Irfani | E28: P | F28: Belum kawin | G28: 40635 | H28: Islam | I28: - | J28: - | K28: WNI | L28: Lingkungan Perumda Selatan No 07 RT 05 RW 09 | M28: Anak | N28: 520101 4204110005
B29: 9 | C29: 26 | D29: Musalihin | E29: L | F29: Kawin | G29: 24833 | H29: Islam | I29: SLTA/MA | J29: Pedagang | K29: WNI | L29: Lingkungan Perumda Selatan No 08 RT 05 RW 09 | M29: KK | N29: 527102 2712670001
C30: 27 | D30: Rohani | E30: P | F30: Kawin | G30: 22862 | H30: Islam | I30: - | J30: Pedagang | K30: WNI | L30: Lingkungan Perumda Selatan No 08 RT 05 RW 09 | M30: Istri | N30: 527102 4408620001
C31: 28 | D31: Nurulhida | E31: P | F31: Belum kawin | G31: 27394 | H31: Islam | I31: - | J31: Pedagang | K31: WNI | L31: Lingkungan Perumda Selatan No 08 RT 05 RW 09 | M31: Anak | N31: 527102 7112740115
C32: 29 | D32: Linda lestari | E32: P | F32: Belum kawin | G32: 34439 | H32: Islam | I32: SLTP/MTSN | J32: Pedagang | K32: WNI | L32: Lingkungan Perumda Selatan No 08 RT 05 RW 09 | M32: Anak | N32: 527102 5504940002
B33: 10 | C33: 30 | D33: Lalu Abdul Majid | E33: L | F33: Kawin | G33: 25933 | H33: Islam | I33: SLTA/MA | J33: PNS/TNI/ POLRI | K33: WNI | L33: Lingkungan Perumda Selatan No 09 RT 05 RW 09 | M33: KK | N33: 520101 3112100206
C34: 31 | D34: Mulianah | E34: P | F34: Kawin | G34: 26969 | H34: Islam | I34: PT/Akademi | J34: PNS/TNI/ POLRI | K34: WNI | L34: Lingkungan Perumda Selatan No 09 RT 05 RW 09 | M34: Istri | N34: 520101 4111730001
C35: 32 | D35: Lalu Fashabrun Jamil | E35: L | F35: Belum kawin | G35: 40452 | H35: Islam | I35: - | J35: - | K35: WNI | L35: Lingkungan Perumda Selatan No 09 RT 05 RW 09 | M35: Anak | N35: 520101 0111100006
C36: 33 | D36: Lalu Ihya Ulumuddin | E36: L | F36: Belum kawin | G36: 40910 | H36: Islam | I36: - | J36: - | K36: WNI | L36: Lingkungan Perumda Selatan No 09 RT 05 RW 09 | M36: Anak | N36: 520101 0101120002
B37: 11 | C37: 34 | D37: Ayi Sopandi | E37: L | F37: Kawin | G37: 24270 | H37: Islam | I37: PT/Akademi | J37: PNS/TNI/ POLRI | K37: WNI | L37: Lingkungan Perumda Selatan No 10 RT 05 RW 09 | M37: KK | N37: 520101 1209650001
C38: 35 | D38: Ratna Wahyuningsih | E38: P | F38: Kawin | G38: 27233 | H38: Islam | I38: PT/Akademi | J38: PNS/TNI/ POLRI | K38: WNI | L38: Lingkungan Perumda Selatan No 10 RT 05 RW 09 | M38: Istri | N38: 520101 8307740001
C39: 36 | D39: Agisna Maulana Noviandi | E39: P | F39: Belum kawin | G39: 34658 | H39: Islam | I39: SLTA/MA | J39: - | K39: WNI | L39: Lingkungan Perumda Selatan No 10 RT 05 RW 09 | M39: Anak | N39: 520101 2011840001
C40: 37 | D40: Arif Maulana Rahman | E40: L | F40: Belum kawin | G40: 36333 | H40: Islam | I40: SLTP/MTSN | J40: - | K40: WNI | L40: Lingkungan Perumda Selatan No 10 RT 05 RW 09 | M40: Anak | N40: 520101 3290890001
...

Sheet Sheet1
A1: 52 | C1: 204
A2: 62 | C2: 249
A3: 73 | C3: 273
A4: 84 | C4: 325
A5: 67 | C5: 258
A6: =SUM(A1:A5) -> 338 | C6: =SUM(C1:C5) -> 1309

Sheet Sheet2
A1: 324 | E1: 928
A2: 335 | E2: 985
A3: 341 | E3: 1032
A4: 279 | E4: 1023
A5: 213 | E5: 742
A6: 210 | E6: 763
A7: 199 | E7: 685
A8: 77 | E8: 213
A9: 338 | E9: 1309
A10: =SUM(A1:A9) -> 2316 | E10: =SUM(E1:E9) -> 7680
