Workbook

Sheet Rekap
B2: REKAP DATA PENDUDUK
B3: LINGKUNGAN CEMARA TIMUR
B4: RT | C4: Jumlah Penduduk | E4: Total | F4: Jumlah KK | H4: Total | I4: Jumlah Duda / Janda | K4: Total | L4: Jumlah Lansia ( =>60 ) | N4: Total
C5: L | D5: P | F5: L | G5: P | I5: L | J5: P | L5: L | M5: P
B6: RT 4 | C6: =COUNTIF('RT 04'!$H$8:$H$250,"L") -> 120 | D6: =COUNTIF('RT 04'!$H$8:$H$250,"P") -> 123 | E6: =SUM(C6:D6) -> 243 | F6: =COUNTIFS('RT 04'!$F$8:$F$250,"KK",'RT 04'!$H$8:$H$250,"L") -> 64 | G6: =COUNTIFS('RT 04'!$F$8:$F$250,"KK",'RT 04'!$H$8:$H$250,"P") -> 7 | H6: =SUM(F6:G6) -> 71 | I6: =COUNTIFS('RT 04'!$I$8:$I$250,"Cerai Mati",'RT 04'!$H$8:$H$250,"L")+COUNTIFS('RT 04'!$I$8:$I$250,"Cerai Hidup",'RT 04'!$H$8:$H$250,"L")+COUNTIFS('RT 04'!$I$8:$I$250,"Duda",'RT 04'!$H$8:$H$250,"L") -> 1 | J6: =COUNTIFS('RT 04'!$I$8:$I$250,"Cerai Mati",'RT 04'!$H$8:$H$250,"P")+COUNTIFS('RT 04'!$I$8:$I$250,"Cerai Hidup",'RT 04'!$H$8:$H$250,"P")+COUNTIFS('RT 04'!$I$8:$I$250,"Janda",'RT 04'!$H$8:$H$250,"P") -> 6 | K6: =SUM(I6:J6) -> 7 | L6: 9 | M6: 4 | N6: =SUM(L6:M6) -> 13
B7: RT 5 | C7: =COUNTIF('RT05'!$H$8:$H$190,"L") -> 96 | D7: =COUNTIF('RT05'!$H$8:$H$190,"P") -> 87 | E7: =SUM(C7:D7) -> 183 | F7: =COUNTIFS('RT05'!$F$8:$F$190,"KK",'RT05'!$H$8:$H$190,"L") -> 46 | G7: =COUNTIFS('RT05'!$F$8:$F$190,"KK",'RT05'!$H$8:$H$190,"P") -> 8 | H7: =SUM(F7:G7) -> 54 | I7: =COUNTIFS('RT05'!$I$8:$I$190,"Cerai Mati",'RT05'!$H$8:$H$190,"L")+COUNTIFS('RT05'!$I$8:$I$190,"Cerai Hidup",'RT05'!$H$8:$H$190,"L")+COUNTIFS('RT05'!$I$8:$I$190,"Duda",'RT05'!$H$8:$H$190,"L") -> 1 | J7: =COUNTIFS('RT05'!$I$8:$I$190,"Cerai Mati",'RT05'!$H$8:$H$190,"L")+COUNTIFS('RT05'!$I$8:$I$190,"Cerai Hidup",'RT05'!$H$8:$H$190,"P")+COUNTIFS('RT05'!$I$8:$I$190,"Janda",'RT05'!$H$8:$H$190,"P") -> 5 | K7: =SUM(I7:J7) -> 6 | L7: 6 | M7: 7 | N7: =SUM(L7:M7) -> 13
B8: JUMLAH TOTAL | C8: =SUM(C6:C7) -> 216 | D8: =SUM(D6:D7) -> 210 | E8: =SUM(E6:E7) -> 426 | F8: =SUM(F6:F7) -> 110 | G8: =SUM(G6:G7) -> 15 | H8: =SUM(H6:H7) -> 125 | I8: =SUM(I6:I7) -> 2 | J8: =SUM(J6:J7) -> 11 | ... N8: =SUM(N6:N7) -> 26
C12: Mengetahui
C13: Lurah Dasan Geres | K13: Kepala Lingkungan
C17: Hulaifi, S.H. | K17: Sulaifi
C18: NIP. 19841231 201101 1 023

Sheet RT 04
B1: DATA INDUK PENDUDUK KELURAHAN DASAN GERES
B2: TAHUN 2019
B3: LINGKUNGAN CEMARA TIMUR
B4: RT 04
B5: No | C5: Nomor KK | D5: Jumlah Jiwa | E5: Nama Lengkap/ Panggilan | F5: Kedudukan dalam Keluarga | G5: NIK | H5: Jenis Kelamin (L/P) | I5: Status Perkawinan | J5: Lahir | M5: Usia | N5: Agama | O5: Etnis | P5: Pendidikan Terakhir | Q5: Jurusan | R5: Pekerjaan
J6: Tempat | K6: Tanggal | L6: Tahun
B8: 1 | C8: 520101 0503085587 | D8: 1 | E8: Dalisah | F8: KK | G8: 520101 0107670698 | H8: L | I8: Kawin | J8: Cemare | K8: 24654 | L8: 1967 | M8: =2019-L8 -> 52 | N8: Islam | O8: Sasak | P8: TAMAT SD/SEDERAJAT | R8: Buruh Harian Lepas
D9: 2 | E9: Rusnah | F9: Istri | G9: 520101 4107700249 | H9: P | I9: Kawin | J9: Aik Ampat | K9: 25750 | L9: 1970 | M9: =2019-L9 -> 49 | N9: Islam | O9: Sasak | P9: TAMAT SD/SEDERAJAT | R9: Buruh Harian Lepas
D10: 3 | E10: Mujiah | F10: Anak | G10: 520101 4107980254 | H10: P | I10: Belum kawin | J10: Cemare | K10: 36044 | L10: 1998 | M10: =2019-L10 -> 21 | N10: Islam | O10: Sasak | P10: TAMAT SD/SEDERAJAT | R10: Buruh Harian Lepas
D11: 4 | E11: Priawan | F11: Anak | G11: 520101 0107050287 | H11: L | I11: Belum kawin | J11: Cemare | K11: 38096 | L11: 2004 | M11: =2019-L11 -> 15 | N11: Islam | O11: Sasak | P11: BELUM TAMAT SD/SEDERAJAT | R11: PELAJAR/MAHASISWA
D12: 5 | E12: Sahira | F12: Anak | G12: 520101 4508150001 | H12: P | I12: Belum kawin | J12: Cemare | K12: 42214 | L12: 2015 | M12: =2019-L12 -> 4 | N12: Islam | O12: Sasak | P12: TIDAK/BELUM SEKOLAH | R12: BELUM/TIDAK BEKERJA
B13: 2 | D13: 6 | E13: Asmat | F13: KK | G13: 520101 3112740019 | H13: L | I13: Kawin | K13: 27394 | L13: =YEAR(K13) -> 1974 | M13: =2019-L13 -> 45 | N13: Islam | P13: - | R13: Pekerja lepas
D14: 7 | E14: Nurhasanah | F14: Istri | G14: 520101 7112780009 | H14: P | I14: Kawin | K14: 28125 | L14: =YEAR(K14) -> 1976 | M14: =2019-L14 -> 43 | N14: Islam | P14: - | R14: Pekerja lepas
D15: 8 | E15: Nurul Hidayah | F15: Anak | G15: 520101 5011980001 | H15: P | I15: Kawin | K15: 36109 | L15: =YEAR(K15) -> 1998 | M15: =2019-L15 -> 21 | N15: Islam | P15: SLTP/MTSN | R15: Pekerja lepas
D16: 9 | E16: Ahmad Faozan | F16: Anak | G16: 520101 0503020001 | H16: L | I16: Belum kawin | K16: 37320 | L16: =YEAR(K16) -> 2002 | M16: =2019-L16 -> 17 | N16: Islam | P16: - | R16: -
B17: 3 | D17: 10 | E17: Sanusi | F17: KK | G17: 520101 2007810001 | H17: L | I17: Kawin | K17: 29787 | L17: =YEAR(K17) -> 1981 | M17: =2019-L17 -> 38 | N17: Islam | P17: SD/MI | R17: Pedagang
D18: 11 | E18: Hartini | F18: Istri | G18: 520101 5005830001 | H18: P | I18: Kawin | K18: 30446 | L18: =YEAR(K18) -> 1983 | M18: =2019-L18 -> 36 | N18: Islam | P18: SD/MI | R18: Pedagang
D19: 12 | E19: Najwa Falah Yuniawati | F19: Anak | G19: 520101 4105040005 | H19: P | I19: Belum kawin | K19: 38108 | L19: =YEAR(K19) -> 2004 | M19: =2019-L19 -> 15 | N19: Islam | P19: - | R19: -
D20: 13 | E20: Isna Malika Ardiana | F20: Anak | G20: 520101 8204090001 | H20: P | I20: Belum kawin | K20: 39925 | L20: =YEAR(K20) -> 2009 | M20: =2019-L20 -> 10 | N20: Islam | P20: - | R20: -
B21: 4 | D21: 14 | E21: Rusdin | F21: KK | G21: 520101 3112320083 | H21: L | I21: Kawin | K21: 30316 | L21: =YEAR(K21) -> 1982 | M21: =2019-L21 -> 37 | N21: Islam | P21: SD/MI | R21: Pekerja lepas
D22: 15 | E22: Yati Oktarita | F22: Istri | G22: 520101 7113900042 | H22: P | I22: Kawin | K22: 33238 | L22: =YEAR(K22) -> 1990 | M22: =2019-L22 -> 29 | N22: Islam | P22: SD/MI | R22: Pekerja lepas
D23: 16 | E23: Wipki Sofia Desita | F23: Anak | G23: 520101 6712070001 | H23: P | I23: Belum kawin | K23: 39443 | L23: =YEAR(K23) -> 2007 | M23: =2019-L23 -> 12 | N23: Islam | P23: - | R23: -
B24: 5 | C24: 520101 0909110026 | D24: 17 | E24: Sahrun | F24: KK | G24: 520101 1011670001 | H24: L | I24: Kawin | J24: Cemare | K24: 24786 | L24: 1967 | M24: =2019-L24 -> 52 | N24: Islam | O24: Sasak | P24: TAMAT SD/SEDERAJAT | R24: WIRASWATA
D25: 18 | E25: Minansah | F25: Istri | G25: 520101 5408680001 | H25: P | I25: Kawin | J25: Cemare | K25: 25003 | L25: 1968 | M25: =2019-L25 -> 51 | N25: Islam | O25: Sasak | P25: TAMAT SD/SEDERAJAT | R25: Buruh Harian Lepas
D26: 19 | E26: M.Aziz Faozan | F26: Anak | G26: 520101 1505990004 | H26: L | I26: Belum kawin | J26: Cemare | K26: 35930 | L26: 1998 | M26: =2019-L26 -> 21 | N26: Islam | O26: Sasak | P26: SLTP/SEDERAJAT | R26: BELUM/TIDAK BEKERJA
B27: 6 | C27: 520101 0503085393 | D27: 20 | E27: Sabarudin Abi | F27: KK | G27: 520101 1210790004 | H27: L | I27: Kawin | J27: Cemare | K27: 29140 | L27: 1979 | M27: =2019-L27 -> 40 | N27: Islam | O27: Sasak | P27: SLTP/SEDERAJAT | R27: WIRASWATA
D28: 21 | E28: Nurhikmah | F28: Istri | G28: 520101 4312800001 | H28: P | I28: Kawin | J28: Lintak Buwur | K28: 29558 | L28: 1980 | M28: =2019-L28 -> 39 | N28: Islam | O28: Sasak | P28: TAMAT SD/SEDERAJAT | R28: PETANI/PEKEBUN
D29: 22 | E29: Abi Masyaril Ulum | F29: Anak | G29: 520101 1102050002 | H29: L | I29: Belum kawin | J29: Cemare | K29: 38832 | L29: 2006 | M29: =2019-L29 -> 13 | N29: Islam | O29: Sasak | P29: BELUM TAMAT SD/SEDERAJAT | R29: PELAJAR/MAHASISWA
D30: 23 | E30: Putri Khayla Fathina | F30: Anak | G30: 520101 6210170001 | H30: P | I30: Belum kawin | J30: Dasan Geres | K30: 43061 | L30: 2017 | M30: =2019-L30 -> 2 | N30: Islam | O30: Sasak | P30: TIDAK/BELUM SEKOLAH | R30: BELUM/TIDAK BEKERJA
B31: 7 | C31: 520101 1509120013 | D31: 24 | E31: Abdullah | F31: KK | G31: 520101 1003751001 | H31: L | I31: Kawin | J31: Bermi | K31: 27463 | L31: 1975 | M31: =2019-L31 -> 44 | N31: Islam | O31: Sasak | P31: TAMAT SD/SEDERAJAT | R31: WIRASWATA
D32: 25 | E32: Rohana | F32: Istri | G32: 520101 6211770001 | H32: P | I32: Kawin | J32: Cemare | K32: 28451 | L32: 1977 | M32: =2019-L32 -> 42 | N32: Islam | O32: Sasak | P32: TAMAT SD/SEDERAJAT | R32: Pedagang
D33: 26 | E33: Maharani Juniati | F33: Anak | G33: 520101 5606031001 | H33: P | I33: Belum kawin | J33: Cemare | K33: 37788 | L33: 2003 | M33: =2019-L33 -> 16 | N33: Islam | O33: Sasak | P33: BELUM TAMAT SD/SEDERAJAT | R33: PELAJAR/MAHASISWA
D34: 27 | E34: Muhammad Nur Maulana | F34: Anak | G34: 520101 1612131001 | H34: L | I34: Belum kawin | J34: Cemare | K34: 41624 | L34: 2013 | M34: =2019-L34 -> 6 | N34: Islam | O34: Sasak | P34: TIDAK/BELUM SEKOLAH | R34: BELUM/TIDAK BEKERJA
B35: 8 | C35: 520101 1009140007 | D35: 28 | E35: Muhibin | F35: KK | G35: 520101 0103890001 | H35: L | I35: Kawin | J35: Cemare | K35: 32873 | L35: 1989 | M35: =2019-L35 -> 30 | N35: Islam | O35: Sasak | P35: SLTA/SEDERAJAT | R35: WIRASWATA
D36: 29 | E36: Muslimin | F36: Istri | G36: 520101 4107930147 | H36: P | I36: Kawin | J36: Aik Ampat | K36: 34151 | L36: 1993 | M36: =2019-L36 -> 26 | N36: Islam | O36: Sasak | P36: SLTA/SEDERAJAT | R36: Mengurus Rumah Tangga
D37: 30 | E37: Muhammad Ishak Alfatih | F37: Anak | G37: 520101 2509140002 | H37: L | I37: Belum kawin | J37: Dasan Geres | K37: 41907 | L37: 2014 | M37: =2019-L37 -> 5 | N37: Islam | O37: Sasak | P37: TIDAK/BELUM SEKOLAH | R37: BELUM/TIDAK BEKERJA
B38: 9 | D38: 31 | E38: Sanip | F38: KK | G38: 520101 7012600007 | H38: P | I38: Janda | K38: 22280 | L38: 1960 | M38: =2019-L38 -> 59 | N38: Islam | O38: Sasak | P38: -
B39: 10 | C39: 520101 0503086022 | D39: 32 | E39: Herman | F39: KK | G39: 520101 2101790001 | H39: L | I39: Kawin | J39: Cemare | K39: 28876 | L39: 1979 | M39: =2019-L39 -> 40 | N39: Islam | O39: Sasak | P39: SLTP/SEDERAJAT | R39: BURUH HARIAN LEPAS
D40: 33 | E40: Eka Rahmawati | F40: Istri | G40: 520101 7012840002 | H40: P | I40: Kawin | J40: Kadatuk | K40: 31046 | L40: 1984 | M40: =2019-L40 -> 35 | N40: Islam | O40: Sasak | P40: SLTP/SEDERAJAT | R40: BURUH HARIAN LEPAS
D41: 34 | E41: Alma Sabila | F41: Anak | G41: 520101 6601070003 | H41: P | I41: Belum kawin | J41: Cemare | K41: 39108 | L41: 2007 | M41: =2019-L41 -> 12 | N41: Islam | O41: Sasak | P41: BELUM TAMAT SD/SEDERAJAT | R41: PELAJAR/MAHASISWA
...

Sheet RT05
B1: DATA INDUK PENDUDUK KELURAHAN DASAN GERES
B2: TAHUN 2019
B3: LINGKUNGAN CEMARA TIMUR
B4: RT 05
B5: No | C5: Nomor KK | D5: Jumlah Jiwa | E5: Nama Lengkap/ Panggilan | F5: Kedudukan dalam Keluarga | G5: NIK | H5: Jenis Kelamin (L/P) | I5: Status Perkawinan | J5: Lahir | M5: Usia | N5: Agama | O5: Etnis | P5: Pendidikan Terakhir | Q5: Jurusan | R5: Pekerjaan
J6: Tempat | K6: Tanggal | L6: Tahun
B8: 1 | C8: 520101 1506120022 | D8: 1 | E8: Selamet | F8: KK | G8: 520101 3112820171 | H8: L | I8: Kawin | J8: Cemare | K8: 30316 | L8: 1982 | M8: =2019-L8 -> 37 | N8: Islam | O8: Sasak | P8: TAMAT SD/SEDERAJAT | R8: WIRASWASTA
D9: 2 | E9: Hikmah | F9: Istri | G9: 520101 7112830127 | H9: P | I9: Kawin | J9: Cemare | K9: 30681 | L9: 1983 | M9: =2019-L9 -> 36 | N9: Islam | O9: Sasak | P9: TAMAT SD/SEDERAJAT | R9: MENGURUS RUMAH TANGGA
D10: 3 | E10: Silfi Hidayat | F10: Anak | G10: 520101 4902010004 | H10: P | I10: Belum kawin | J10: Cemare | K10: 36931 | L10: 2001 | M10: =2019-L10 -> 18 | N10: Islam | O10: Sasak | P10: BELUM TAMAT SD/SEDERAJAT | R10: PELAJAR/MAHASISWA
D11: 4 | E11: Maya Ziyadah | F11: Anak | G11: 520101 6805080001 | H11: P | I11: Belum kawin | J11: Cemare | K11: 39596 | L11: 2008 | M11: =2019-L11 -> 11 | N11: Islam | O11: Sasak | P11: TIDAK/BELUM SEKOLAH | R11: BELUM/TIDAK BEKERJA
D12: 5 | E12: Andika Fratama | F12: Anak | G12: 520101 1602141002 | H12: L | I12: Belum kawin | J12: Cemare | K12: 41686 | L12: 2014 | M12: =2019-L12 -> 5 | N12: Islam | O12: Sasak | P12: TIDAK/BELUM SEKOLAH | R12: BELUM/TIDAK BEKERJA
B13: 2 | D13: 6 | E13: Mahusun | F13: KK | G13: 520101 3112730053 | H13: L | I13: Kawin | K13: 27029 | L13: =YEAR(K13) -> 1973 | M13: =2019-L13 -> 46 | N13: Islam | P13: - | R13: Pekerja lepas
D14: 7 | E14: Dedi Johari | F14: Anak | G14: 520101 1304030001 | H14: L | I14: Belum kawin | K14: 37724 | L14: =YEAR(K14) -> 2003 | M14: =2019-L14 -> 16 | N14: Islam | P14: - | R14: -
D15: 8 | E15: Muhadis Fahri | F15: Anak | G15: 520101 3011080001 | H15: L | I15: Belum kawin | K15: 39782 | L15: =YEAR(K15) -> 2008 | M15: =2019-L15 -> 11 | N15: Islam | P15: - | R15: -
B16: 3 | C16: 520101 2402150017 | D16: 9 | E16: Risah | F16: KK | G16: 520101 1211600001 | H16: L | I16: Kawin | J16: Cemare | K16: 22232 | L16: 1960 | M16: =2019-L16 -> 59 | N16: Islam | O16: Sasak | P16: TIDAK/BELUM SEKOLAH | R16: BURUH HARIAN LEPAS
D17: 10 | E17: Remah | F17: Istri | G17: 520101 4502980001 | H17: P | I17: Kawin | J17: Cemare | K17: 24107 | L17: 1965 | M17: =2019-L17 -> 54 | N17: Islam | O17: Sasak | P17: TIDAK/BELUM SEKOLAH | R17: BURUH HARIAN LEPAS
D18: 11 | E18: Ahmad Hidayat | F18: Anak | G18: 520101 0502980001 | H18: L | I18: Belum kawin | J18: Cemare | K18: 35831 | L18: 1998 | M18: =2019-L18 -> 21 | N18: Islam | O18: Sasak | P18: SLTP/SEDERAJAT | R18: PELAJAR/MAHASISWA
B19: 4 | D19: 12 | E19: Riduk | F19: KK | G19: 520101 3117500118 | H19: L | I19: Kawin | K19: 27759 | L19: =YEAR(K19) -> 1975 | M19: =2019-L19 -> 44 | N19: Islam | P19: SD/MI | R19: Pekerja lepas
D20: 13 | E20: Masiah | F20: Istri | G20: 520101 4612760002 | H20: P | I20: Kawin | K20: 35769 | L20: =YEAR(K20) -> 1997 | M20: =2019-L20 -> 22 | N20: Islam | P20: - | R20: Pekerja lepas
D21: 14 | E21: Mila Isnayani | F21: Anak | G21: 520101 6504080001 | H21: P | I21: Belum kawin | K21: 39563 | L21: =YEAR(K21) -> 2008 | M21: =2019-L21 -> 11 | N21: Islam | P21: - | R21: -
B22: 5 | C22: 520101 0503150007 | D22: 15 | E22: Marzuki | F22: KK | G22: 520101 0102800001 | H22: L | I22: Kawin | J22: Cemare | K22: 30681 | L22: 1983 | M22: =2019-L22 -> 36 | N22: Islam | O22: Sasak | P22: SLTP/SEDERAJAT | R22: WIRASWASTA
D23: 16 | E23: Mukminah | F23: Istri | G23: 520101 7112930038 | H23: P | I23: Kawin | J23: Cemare | K23: 34334 | L23: 1993 | M23: =2019-L23 -> 26 | N23: Islam | O23: Sasak | P23: TAMAT SD/SEDERAJAT | R23: MENGURUS RUMAH TANGGA
D24: 17 | E24: Danu Wartadi | F24: Anak | G24: 520101 2601130001 | H24: L | I24: Belum kawin | J24: Cemare | K24: 40105 | L24: 2009 | M24: =2019-L24 -> 10 | N24: Islam | O24: Sasak | P24: TIDAK/BELUM SEKOLAH | R24: BELUM/TIDAK BEKERJA
D25: 18 | E25: Bagas Pratama | F25: Anak | G25: 520101 1708150002 | H25: L | I25: Belum kawin | J25: Gerung | K25: 42233 | L25: 2015 | M25: =2019-L25 -> 4 | N25: Islam | O25: Sasak | P25: TIDAK/BELUM SEKOLAH | R25: BELUM/TIDAK BEKERJA
D26: 19 | E26: Bagus Prayuda | F26: Anak | G26: 520101 1708150001 | H26: L | I26: Belum kawin | J26: Gerung | K26: 42233 | L26: 2015 | M26: =2019-L26 -> 4 | N26: Islam | O26: Sasak | P26: TIDAK/BELUM SEKOLAH | R26: BELUM/TIDAK BEKERJA
B27: 6 | C27: 520101 10503085625 | D27: 20 | E27: Mahdi | F27: KK | G27: 520101 2001840001 | H27: L | I27: Kawin | J27: Cemare | K27: 30701 | L27: 1984 | M27: =2019-L27 -> 35 | N27: Islam | O27: Sasak | P27: TAMAT SD/SEDERAJAT | R27: Tukang Kayu
D28: 21 | E28: Sinerah | F28: Istri | G28: 520101 7112870003 | H28: P | I28: Kawin | J28: Bile Kedit | K28: 32142 | L28: 1987 | M28: =2019-L28 -> 32 | N28: Islam | O28: Sasak | P28: TAMAT SD/SEDERAJAT | R28: MENGURUS RUMAH TANGGA
D29: 22 | E29: Wahyudi Kurniawan | F29: Anak | G29: 520101 2908050001 | H29: L | I29: Belum kawin | J29: Cemare | K29: 38513 | L29: 2005 | M29: =2019-L29 -> 14 | N29: Islam | O29: Sasak | P29: BELUM TAMAT SD/SEDERAJAT | R29: PELAJAR/MAHASISWA
D30: 23 | E30: Rudi Gunawan | F30: Anak | G30: 520101 6006070001 | H30: L | I30: Belum kawin | J30: Cemare | K30: 40231 | L30: 2010 | M30: =2019-L30 -> 9 | N30: Islam | O30: Sasak | P30: BELUM TAMAT SD/SEDERAJAT | R30: PELAJAR/MAHASISWA
D31: 24 | E31: Mahendra Yudajulianto | F31: Anak | G31: 520101 2509180002 | H31: L | I31: Belum kawin | J31: Cemare | K31: 43368 | L31: 2018 | M31: =2019-L31 -> 1 | N31: Islam | O31: Sasak | P31: TIDAK/BELUM SEKOLAH | R31: BELUM/TIDAK BEKERJA
B32: 7 | C32: 520101 0403110038 | D32: 25 | E32: Safi'i | F32: KK | G32: 520101 3007800001 | H32: L | I32: Kawin | J32: Cemare | K32: 29432 | L32: 1980 | M32: =2019-L32 -> 39 | N32: Islam | O32: Sasak | P32: TAMAT SD/SEDERAJAT | R32: PETANI/PEKEBUN
D33: 26 | E33: Munisah | F33: Istri | G33: 520101 7112811010 | H33: P | I33: Kawin | J33: Cemare | K33: 29951 | L33: 1981 | M33: =2019-L33 -> 38 | N33: Islam | O33: Sasak | P33: TAMAT SD/SEDERAJAT | R33: MENGURUS RUMAH TANGGA
D34: 27 | E34: Agusni | F34: Anak | G34: 520101 1008991001 | H34: L | I34: Belum kawin | J34: Cemare | K34: 36382 | L34: 1999 | M34: =2019-L34 -> 20 | N34: Islam | O34: Sasak | P34: SLTA/SEDERAJAT | R34: PELAJAR/MAHASISWA
D35: 28 | E35: Saipul Muhamad Rizki | F35: Anak | G35: 520101 2002081001 | H35: L | I35: Belum kawin | J35: Cemare | K35: 39498 | L35: 2008 | M35: =2019-L35 -> 11 | N35: Islam | O35: Sasak | P35: BELUM TAMAT SD/SEDERAJAT | R35: PELAJAR/MAHASISWA
B36: 8 | C36: 520101 0503085409 | D36: 29 | E36: Rahmin | F36: KK | G36: 520101 0408700001 | H36: L | I36: Kawin | J36: Cemare | K36: 24107 | L36: 1965 | M36: =2019-L36 -> 54 | N36: Islam | O36: Sasak | P36: TIDAK/BELUM SEKOLAH | R36: PETANI/PEKEBUN
D37: 30 | E37: Haeriah | F37: Istri | G37: 520101 4804710001 | H37: P | I37: Kawin | J37: Cemare | K37: 26031 | L37: 1971 | M37: =2019-L37 -> 48 | N37: Islam | O37: Sasak | P37: TIDAK/BELUM SEKOLAH | R37: Pedagang
D38: 31 | E38: Jamaludin | F38: Anak | G38: 520101 1910890001 | H38: L | I38: Belum kawin | J38: Cemare | K38: 32794 | L38: 1989 | M38: =2019-L38 -> 30 | N38: Islam | O38: Sasak | P38: SLTP/SEDERAJAT | R38: WIRASWASTA
B39: 9 | D39: 32 | E39: Marzuki | F39: KK | G39: 520101 3112840082 | H39: L | I39: Kawin | K39: 31047 | L39: =YEAR(K39) -> 1984 | M39: =2019-L39 -> 35 | N39: Islam | P39: SD/MI | R39: Pekerja lepas
D40: 33 | E40: Siti Murni | F40: Istri | G40: 520101 5208850002 | H40: P | I40: Kawin | K40: 31272 | L40: =YEAR(K40) -> 1985 | M40: =2019-L40 -> 34 | N40: Islam | P40: SD/MI | R40: Pekerja lepas
D41: 34 | E41: Nayla Miftahussaadah | F41: Anak | G41: 520101 4107090002 | H41: p | I41: Belum kawin | K41: 39995 | L41: =YEAR(K41) -> 2009 | M41: =2019-L41 -> 10 | N41: Islam | P41: - | R41: -
...

Sheet Sheet2
A1: 97 | C1: 263
A2: 87 | C2: 274
A3: 70 | C3: 232
A4: 63 | C4: 193
A5: 24 | C5: 70
A6: =SUM(A1:A5) -> 341 | C6: =SUM(C1:C5) -> 1032

Sheet Meninggal
A3: No | B3: Nomor KK | C3: Jumlah | D3: Nama Lengkap/panggilan | E3: Kedudukan dalam Keluarga | F3: NIK | G3: Jenis Kelamin (L/P) | H3: Status Perkawinan | I3: Lahir | L3: Usia | M3: Agama | O3: Pendidikan Terakhir | Q3: Pekerjaan | R3: Cacat | T3: Ada / Tidak
C4: Jiwa | I4: Tempat | J4: Tanggal | K4: Tahun | R4: Mental | S4: Fisik | T4: KK | U4: KTP/KIA | V4: Buku Nikah | W4: Akte Kelahiran
B6: 520101 0503085998 | D6: Nurilah | E6: KK | F6: 520101 1004640001 | G6: L | H6: Kawin | I6: Cemare | J6: 23477 | K6: 1964 | L6: =2019-K6 -> 55 | M6: Islam | O6: BELUM TAMAT SD/ SEDERAJAT | Q6: BURUH TANI/PERKEBUNAN
B7: 520101 0503085543 | D7: Nafisah | E7: Istri | F7: 520101 7112700199 | G7: P | H7: Kawin | I7: Cemare | J7: 25933 | K7: 1970 | L7: =2019-K7 -> 49 | M7: Islam | O7: TAMAT SD/SEDERAJAT | Q7: BURUH HARIAN LEPAS
B8: 65 | C8: 520101 0503085341 | E8: Rifa'i | F8: KK | G8: 520101 0509620001 | H8: L | I8: Kawin | J8: Cemare | K8: 22894 | L8: 1962 | M8: =2019-L8 -> 57 | N8: Islam | O8: Sasak | P8: TIDAK/BELUM SEKOLAH | R8: Tukang Kayu
C9: 520101 0503085889 | E9: Drs. Ahmad | F9: KK | G9: 520101 1412620001 | H9: L | I9: Kawin | J9: Aik Ampat | K9: 18628 | L9: 1950 | M9: =2019-L9 -> 69 | N9: Islam | O9: Sasak | P9: DIPLOMA IV/STRATA I | R9: PENSIUNAN
A10: RT 4 | B10: 42 | D10: 149 | E10: Masitah | F10: KK | G10: 520101 4107630033 | H10: P | I10: Janda | K10: 23193 | M10: =2019-L10 -> 2019 | N10: Islam | P10: - | R10: Pekerja lepas
D11: 520101 11502120051 | E11: RAKYAH | F11: KK | G11: 520101 3112680141 | H11: L | I11: Kawin | J11: Cemare | K11: 21550 | L11: 1958 | M11: Islam | N11: Sasak | O11: TAMAT SD/SEDERAJAT | Q11: wiraswasta
D12: 72 | E12: Nafisah | F12: Istri | G12: 520101 7112700199 | H12: P | I12: Kawin | J12: Cemare | K12: 25933 | L12: 1970 | M12: =2019-L12 -> 49 | N12: Islam | O12: Sasak | P12: TAMAT SD/SEDERAJAT | R12: BURUH HARIAN LEPAS
B13: 33 | C13: 520101 0503085889 | D13: 113 | E13: Drs. Ahmad | F13: KK | G13: 520101 1412620001 | H13: L | I13: Kawin | J13: Aik Ampat | K13: 18628 | L13: 1950 | M13: =2019-L13 -> 69 | N13: Islam | O13: Sasak | P13: DIPLOMA IV/STRATA I | R13: PENSIUNAN

Sheet Pindah Keluar
A3: No | B3: Nomor KK | C3: Jumlah | D3: Nama Lengkap/panggilan | E3: Kedudukan dalam Keluarga | F3: NIK | G3: Jenis Kelamin (L/P) | H3: Status Perkawinan | I3: Lahir | L3: Usia | M3: Agama | O3: Pendidikan Terakhir | Q3: Pekerjaan | R3: Cacat | T3: Ada / Tidak
C4: Jiwa | I4: Tempat | J4: Tanggal | K4: Tahun | R4: Mental | S4: Fisik | T4: KK | U4: KTP/KIA | V4: Buku Nikah | W4: Akte Kelahiran
D6: Pahriah | E6: Anak | F6: 520101 7112920016 | G6: P | H6: Belum kawin | I6: AIK AMPAT | J6: 33969 | L6: =2019-K6 -> 2019 | M6: Islam | O6: SLTA/MA | Q6: Pekerja lepas
C7: 77 | D7: Irpan Jaelani | E7: Anak | F7: 520101 0802960002 | G7: L | H7: Belum kawin | J7: 35103 | L7: =2019-K7 -> 2019 | M7: Islam | O7: SLTA/MA | Q7: -
C8: 50 | D8: Fathul Azziz | E8: Anak | F8: 520101 0205920002 | G8: L | H8: Belum kawin | J8: 33726 | L8: =2019-K8 -> 2019 | M8: Islam | O8: SLTP/MTSN | Q8: Pekerja lepas
C9: 168 | D9: Fatimah | E9: Anak | F9: 520101 5011930001 | G9: P | H9: Belum kawin | J9: 34283 | L9: =2019-K9 -> 2019 | M9: Islam | O9: SD/MI | Q9: Pekerja lepas
C10: 81 | D10: Ayuni | E10: Anak | F10: 520101 5007950001 | G10: L | H10: Belum kawin | J10: 34890 | L10: =2019-K10 -> 2019 | M10: Islam | O10: SLTA/MA | Q10: -
D11: Sri Atun | E11: Anak | F11: 520101 4205920001 | G11: P | H11: Belum kawin | I11: Cemare | J11: 31777 | K11: 1986 | L11: =2019-K11 -> 33 | M11: Islam | N11: Sasak | O11: TAMAT SD/SEDERAJAT | Q11: WIRASWASTA
A12: RT 5 | B12: 520101 2301180010 | C12: 24 | D12: Abdul Kadir Jaelani | E12: KK | F12: 520101 2302961001 | G12: L | H12: Kawin | I12: KT. Cemara | J12: 35118 | K12: 1996 | L12: =2019-K12 -> 23 | M12: Islam | N12: Sasak | O12: SLTP/SEDERAJAT | Q12: WIRASWASTA
D13: Rena | E13: Istri | F13: 520103 5704010001 | G13: P | H13: Kawin | I13: Karang Taliwang | J13: 36998 | K13: 2001 | L13: =2019-K13 -> 18 | M13: Islam | N13: Sasak | O13: TAMAT SD/SEDERAJAT | Q13: MENGURUS RUMAH TANGGA
A14: RT 4 | B14: 520101 1110170002 | D14: Sardi | E14: KK | F14: 520101 2512920001 | G14: L | H14: Kawin | I14: Cemare | J14: 33800 | K14: 1992 | L14: =2019-K14 -> 27 | M14: Islam | N14: Sasak | O14: SLTP/SEDERAJAT | Q14: WIRASWASTA
D15: Haryati | E15: Istri | F15: 520101 4408890002 | G15: P | H15: Kawin | I15: Cemare | J15: 34185 | K15: 1993 | L15: =2019-K15 -> 26 | M15: Islam | N15: Sasak | O15: SLTP/SEDERAJAT | Q15: MENGURUS RUMAH TANGGA
C16: 160 | D16: Sahnan | E16: Anak | F16: 520101 1204880001 | G16: L | H16: Belum kawin | J16: 32245 | L16: =2019-K16 -> 2019 | M16: Islam | O16: SLTP/MTSN | Q16: Pekerja lepas
C17: 162 | D17: Salamn | E17: Anak | F17: 520101 1011910001 | G17: L | H17: Belum kawin | J17: 33552 | L17: =2019-K17 -> 2019 | M17: Islam | O17: SLTP/MTSN | Q17: -
A18: RT 5 | D18: 41 | E18: Misaah | F18: Anak | G18: 520101 5008900101 | H18: P | I18: Belum kawin | K18: 33095 | M18: =2019-L18 -> 2019 | N18: Islam | P18: SLTA/MA | R18: Pekerja lepas
D19: 42 | E19: Mudemah | F19: Anak | G19: 520101 5708910001 | H19: P | I19: Belum kawin | K19: 33467 | M19: =2019-L19 -> 2019 | N19: Islam | P19: SLTP/MTSN | R19: Pekerja lepas
D20: 43 | E20: Rohimah | F20: Anak | G20: 520101 6602930001 | H20: P | I20: Belum kawin | K20: 34026 | M20: =2019-L20 -> 2019 | N20: Islam | P20: SD/MI | R20: -
A21: RT 5 | D21: 7 | E21: Zohriah | F21: Istri | G21: 520101 4107330384 | H21: P | I21: Kawin | K21: 26846 | M21: =2019-L21 -> 2019 | N21: Islam | P21: - | R21: Pekerja lepas
A22: RT 4 | D22: 122 | E22: Rakmah | F22: Anak | G22: 520101 4107850250 | H22: P | I22: Janda | K22: 30133 | M22: =2019-L22 -> 2019 | N22: Islam | P22: - | R22: Pekerja lepas
A23: RT 4 | D23: 154 | E23: Ayuni | F23: Anak | G23: 520101 5006870001 | H23: P | I23: Belum kawin | K23: 31938 | M23: =2019-L23 -> 2019 | N23: Islam | P23: SLTA/MA | R23: -
E24: Suhaini | F24: Anak | G24: 520101 2501910003 | H24: L | I24: Belum kawin | J24: CEMARA | K24: 33263 | L24: 1991 | M24: =2019-L24 -> 28 | N24: Islam | O24: Sasak | P24: SLTP/SEDERAJAT | R24: WIRASWATA
E25: Nursin | F25: Anak | G25: 520101 11001830003 | H25: L | I25: Belum kawin | J25: CEMARA | K25: 33979 | L25: 1993 | M25: =2019-L25 -> 26 | N25: Islam | O25: Sasak | P25: SLTP/SEDERAJAT | R25: WIRASWATA
A26: RT 5 | D26: 115 | E26: Najah Nawati Apriana | F26: Anak | G26: 520101 6809900001 | H26: P | I26: Belum Kawin | J26: Tanjung Gunung | K26: 33346 | L26: 1991 | M26: =2019-L26 -> 28 | N26: Islam | O26: Sasak | P26: DIPLOMA IV/STRATA I | R26: BELUM/TIDAK BEKERJA
A27: RT 5 | E27: Masiah | F27: Anak | G27: 520101 4907900001 | H27: P | I27: Cerai Hidup | J27: CEMARA | K27: 33063 | L27: 1990 | M27: =2019-L27 -> 29 | N27: Islam | O27: Sasak | P27: SLTP/SEDERAJAT | R27: BURUH HARIAN LEPAS
