Workbook
Name _520101_1611170006: 'RT 02'!$C$301
Name _GoBack: 'RT 01'!$G$8

Sheet Rekap
B2: REKAP DATA PENDUDUK
B3: LINGKUNGAN CEMARA
B4: RT | C4: Jumlah Penduduk | E4: Total | F4: Jumlah KK | H4: Total | I4: Jumlah Duda / Janda | K4: Total | L4: Jumlah Lansia ( =>60 ) | N4: Total
C5: L | D5: P | F5: L | G5: P | I5: L | J5: P | L5: L | M5: P
B6: RT 1 | C6: =COUNTIF('RT 01'!$H$8:$H$329,"L") -> 152 | D6: =COUNTIF('RT 01'!$H$8:$H$329,"P") -> 170 | E6: =SUM(C6:D6) -> 322 | F6: =COUNTIFS('RT 01'!$F$8:$F$329,"KK",'RT 01'!$H$8:$H$329,"L") -> 86 | G6: =COUNTIFS('RT 01'!$F$8:$F$329,"KK",'RT 01'!$H$8:$H$329,"P") -> 32 | H6: =SUM(F6:G6) -> 118 | I6: =COUNTIFS('RT 01'!$I$8:$I$329,"Cerai Mati",'RT 01'!$H$8:$H$329,"L")+COUNTIFS('RT 01'!$I$8:$I$329,"Cerai Hidup",'RT 01'!$H$8:$H$329,"L")+COUNTIFS('RT 01'!$I$8:$I$329,"Duda",'RT 01'!$H$8:$H$329,"L") -> 4 | J6: =COUNTIFS('RT 01'!$I$8:$I$329,"Cerai Mati",'RT 01'!$H$8:$H$329,"P")+COUNTIFS('RT 01'!$I$8:$I$329,"Cerai Hidup",'RT 01'!$H$8:$H$329,"P")+COUNTIFS('RT 01'!$I$8:$I$329,"Janda",'RT 01'!$H$8:$H$329,"P") -> 31 | K6: =SUM(I6:J6) -> 35 | L6: 19 | M6: 29 | N6: =SUM(L6:M6) -> 48
B7: RT 2 | C7: =COUNTIF('RT 02'!$H$8:$H$324,"L") -> 165 | D7: =COUNTIF('RT 02'!$H$8:$H$324,"P") -> 152 | E7: =SUM(C7:D7) -> 317 | F7: =COUNTIFS('RT 02'!$F$8:$F$324,"KK",'RT 02'!$H$8:$H$324,"L") -> 82 | G7: =COUNTIFS('RT 02'!$F$8:$F$324,"KK",'RT 02'!$H$8:$H$324,"P") -> 15 | H7: =SUM(F7:G7) -> 97 | I7: =COUNTIFS('RT 02'!$I$8:$I$324,"Cerai Mati",'RT 02'!$H$8:$H$324,"L")+COUNTIFS('RT 02'!$I$8:$I$324,"Cerai Hidup",'RT 02'!$H$8:$H$324,"L")+COUNTIFS('RT 02'!$I$8:$I$324,"Duda",'RT 02'!$H$8:$H$324,"L") -> 8 | J7: =COUNTIFS('RT 02'!$I$8:$I$324,"Cerai Mati",'RT 02'!$H$8:$H$324,"P")+COUNTIFS('RT 02'!$I$8:$I$324,"Cerai Hidup",'RT 02'!$H$8:$H$324,"P")+COUNTIFS('RT 02'!$I$8:$I$324,"Janda",'RT 02'!$H$8:$H$324,"P") -> 16 | K7: =SUM(I7:J7) -> 24 | L7: 15 | M7: 13 | N7: =SUM(L7:M7) -> 28
B8: RT 3 | C8: =COUNTIF('RT 03'!$H$8:$H$223,"L") -> 100 | D8: =COUNTIF('RT 03'!$H$8:$H$223,"P") -> 116 | E8: =SUM(C8:D8) -> 216 | F8: =COUNTIFS('RT 03'!$F$8:$F$223,"KK",'RT 03'!$H$8:$H$223,"L") -> 53 | G8: =COUNTIFS('RT 03'!$F$8:$F$223,"KK",'RT 03'!$H$8:$H$223,"P") -> 19 | H8: =SUM(F8:G8) -> 72 | I8: =COUNTIFS('RT 03'!$I$8:$I$223,"Cerai Mati",'RT 03'!$H$8:$H$223,"L")+COUNTIFS('RT 03'!$I$8:$I$223,"Cerai Hidup",'RT 03'!$H$8:$H$223,"L")+COUNTIFS('RT 03'!$I$8:$I$223,"Duda",'RT 03'!$H$8:$H$223,"L") -> 3 | J8: =COUNTIFS('RT 03'!$I$8:$I$223,"Cerai Mati",'RT 03'!$H$8:$H$223,"P")+COUNTIFS('RT 03'!$I$8:$I$223,"Cerai Hidup",'RT 03'!$H$8:$H$223,"P")+COUNTIFS('RT 03'!$I$8:$I$223,"Janda",'RT 03'!$H$8:$H$223,"P") -> 19 | K8: =SUM(I8:J8) -> 22 | L8: 11 | M8: 9 | N8: =SUM(L8:M8) -> 20
B9: JUMLAH TOTAL | C9: =SUM(C6:C8) -> 417 | D9: =SUM(D6:D8) -> 438 | E9: =SUM(E6:E8) -> 855 | F9: =SUM(F6:F8) -> 221 | G9: =SUM(G6:G8) -> 66 | H9: =SUM(H6:H8) -> 287 | I9: =SUM(I6:I8) -> 15 | J9: =SUM(J6:J8) -> 66 | ... N9: =SUM(N6:N8) -> 96
C13: Mengetahui
C14: Lurah Dasan Geres | K14: Kepala Lingkungan
C18: Hulaifi, S.H. | K18: Sahiman
C19: NIP. 19841231 201101 1 023

Sheet RT 01
B1: DATA INDUK PENDUDUK KELURAHAN DASAN GERES
B2: TAHUN 2019
B3: LINGKUNGAN CEMARA
B4: RT 01
B5: No | C5: Nomor KK | D5: Jumlah Jiwa | E5: Nama Lengkap/ Panggilan | F5: Kedudukan dalam Keluarga | G5: NIK | H5: Jenis Kelamin (L/P) | I5: Status Perkawinan | J5: Lahir | M5: Usia | N5: Agama | O5: Etnis | P5: Pendidikan Terakhir | Q5: Jurusan | R5: Pekerjaan
J6: Tempat | K6: Tanggal | L6: Tahun
B8: 1 | C8: 520101 0503081465 | D8: 1 | E8: Imran Hadi | F8: KK | G8: 520101 0107820069 | H8: L | I8: Kawin | J8: Aik Ampat | K8: 27760 | L8: 1976 | M8: =2019-L8 -> 43 | N8: Islam | O8: Sasak | P8: Tidak/Belum Sekolah | R8: Buruh Harian Lepas
D9: 2 | E9: Rukyah | F9: Istri | G9: 520101 4107840052 | H9: P | I9: Kawin | J9: Cemare Karang Tengak | K9: 30864 | L9: 1984 | M9: =2019-L9 -> 35 | N9: Islam | O9: Sasak | P9: Tidak/Belum Sekolah | R9: Buruh Harian Lepas
D10: 3 | E10: Muhammad Ruhadian | F10: Anak | G10: 520101 1004090002 | H10: L | I10: Belum kawin | J10: Aik Ampat | K10: 39913 | L10: 2009 | M10: =2019-L10 -> 10 | N10: Islam | O10: Sasak | P10: Belum Tamat SD/Sederajat | R10: Pelajar/Mahasiswa
D11: 4 | E11: Adinda Septiani | F11: Anak | G11: 520101 6109180001 | H11: P | I11: Belum kawin | J11: Gerung | K11: 43364 | L11: 2018 | M11: =2019-L11 -> 1 | N11: Islam | O11: Sasak | P11: Tidak/Belum Sekolah | R11: Belum/Tidak Bekerja
B12: 2 | C12: 520101 0609131005 | D12: 5 | E12: Jalaludin | F12: KK | G12: 520101 0107870119 | H12: L | I12: Kawin | J12: Cemare Karang Tengak | K12: 31959 | L12: 1987 | M12: =2019-L12 -> 32 | N12: Islam | O12: Sasak | P12: SLTP/Sederajat | R12: Buruh Harian Lepas
D13: 6 | E13: Runiah | F13: Istri | G13: 520101 6504850001 | H13: P | I13: Kawin | J13: Aik Ampat | K13: 33103 | L13: 1990 | M13: =2019-L13 -> 29 | N13: Islam | O13: Sasak | P13: Tamat SD/Sederajat | R13: Buruh Harian Lepas
D14: 7 | E14: Wulan | F14: Anak | G14: 520101 5101100004 | H14: P | I14: Belum kawin | J14: Aik Ampat | K14: 40189 | L14: 2010 | M14: =2019-L14 -> 9 | N14: Islam | O14: Sasak | P14: Belum Tamat SD/Sederajat | R14: Pelajar/Mahasiswa
D15: 8 | E15: Azka Aulia | F15: Anak | G15: 520101 5012180001 | H15: P | I15: Belum kawin | J15: Aik Ampat | K15: 43444 | L15: 2018 | M15: =2019-L15 -> 1 | N15: Islam | O15: Sasak | P15: Tidak/Belum Sekolah | R15: Belum/Tidak Bekerja
B16: 3 | C16: 520101 2502141016 | D16: 9 | E16: Misa’ah | F16: KK | G16: 520101 5011781001 | H16: P | I16: Cerai Mati | J16: Aik Ampat | K16: 28804 | L16: 1978 | M16: =2019-L16 -> 41 | N16: Islam | O16: Sasak | P16: Tamat SD/Sederajat | R16: Buruh Harian Lepas
D17: 10 | E17: Eka Hilmiati | F17: Anak | G17: 520101 4802011001 | H17: P | I17: Belum kawin | J17: Bawak Gunung | K17: 36930 | L17: 2001 | M17: =2019-L17 -> 18 | N17: Islam | O17: Sasak | P17: Tamat SD/Sederajat | R17: Belum/Tidak Bekerja
B18: 4 | C18: 520101 2803120031 | D18: 11 | E18: Salim | F18: KK | G18: 520101 2707760002 | H18: L | I18: Kawin | J18: Aik Ampat | K18: 27968 | L18: 1976 | M18: =2019-L18 -> 43 | N18: Islam | O18: Sasak | P18: Tamat SD/Sederajat | R18: Buruh Harian Lepas
D19: 12 | E19: Sabariah | F19: Istri | G19: 520101 7112700184 | H19: P | I19: Kawin | J19: Aik Ampat | K19: 25933 | L19: 1970 | M19: =2019-L19 -> 49 | N19: Islam | O19: Sasak | P19: Tamat SD/Sederajat | R19: Buruh Harian Lepas
D20: 13 | E20: Risa Diana | F20: Anak | G20: 520101 4204030003 | H20: P | I20: Belum kawin | J20: Aik Ampat | K20: 37733 | L20: 2003 | M20: =2019-L20 -> 16 | N20: Islam | O20: Sasak | P20: Belum Tamat SD/Sederajat | R20: Pelajar/Mahasiswa
B21: 5 | D21: 14 | E21: Suparman | F21: KK | G21: 520101 2009920001 | H21: L | I21: Kawin | K21: 33867 | L21: =YEAR(K21) -> 1992 | M21: =2019-L21 -> 27 | N21: Islam | P21: SLTA/MA | R21: Pekerja lepas
D22: 15 | E22: Laila Kudriatun Agusyani | F22: Istri | G22: 520101 4109930002 | H22: P | I22: Kawin | K22: 34213 | L22: =YEAR(K22) -> 1993 | M22: =2019-L22 -> 26 | N22: Islam | P22: SLTA/MA | R22: Lainnya
D23: 16 | E23: Jihan Talitaulfa | F23: Anak | G23: 520101 6307140004 | H23: P | I23: Belum kawin | K23: 41843 | L23: =YEAR(K23) -> 2014 | M23: =2019-L23 -> 5 | N23: Islam | P23: - | R23: -
B24: 6 | C24: 520101 0503081862 | D24: 17 | E24: Sahabudin | F24: KK | G24: 520101 0107360166 | H24: L | I24: Kawin | J24: Kapek | K24: 13697 | L24: 1937 | M24: =2019-L24 -> 82 | N24: Islam | O24: Sasak | P24: Tamat SD/Sederajat | R24: Buruh Harian Lepas
D25: 18 | E25: Mustiah | F25: Istri | G25: 520101 4107570440 | H25: P | I25: Kawin | J25: Cemare Karang Tengak | K25: 21185 | L25: 1957 | M25: =2019-L25 -> 62 | N25: Islam | O25: Sasak | P25: Tidak/Belum Sekolah | R25: Buruh Harian Lepas
D26: 19 | E26: Fatakhurrahman | F26: Anak | G26: 520101 0107970343 | H26: L | I26: Belum kawin | J26: Cemare Karang Tengak | K26: 35612 | L26: 1997 | M26: =2019-L26 -> 22 | N26: Islam | O26: Sasak | P26: Belum Tamat SD/Sederajat | R26: Pelajar/Mahasiswa
B27: 7 | C27: 520101 2504110007 | D27: 20 | E27: Ramli | F27: KK | G27: 520101 3112730005 | H27: L | I27: Kawin | J27: Aik Ampat | K27: 27029 | L27: 1973 | M27: =2019-L27 -> 46 | N27: Islam | O27: Sasak | P27: Tamat SD/Sederajat | R27: Petani/Pekebun
D28: 21 | E28: Mahuni | F28: Istri | G28: 520101 7112750124 | H28: P | I28: Kawin | J28: Luwuk | K28: 27759 | L28: 1975 | M28: =2019-L28 -> 44 | N28: Islam | O28: Sasak | P28: Tamat SD/Sederajat | R28: Petani/Pekebun
D29: 22 | E29: Purniati | F29: Anak | G29: 520101 4707920003 | H29: P | I29: Belum kawin | J29: Aik Ampat | K29: 34157 | L29: 1993 | M29: =2019-L29 -> 26 | N29: Islam | O29: Sasak | P29: SLTP/Sederajat | R29: Belum/Tidak Bekerja
D30: 23 | E30: Ahmad Madani | F30: Anak | G30: 520101 0107120003 | H30: L | I30: Belum kawin | J30: Gerung | K30: 41091 | L30: 2012 | M30: =2019-L30 -> 7 | N30: Islam | O30: Sasak | P30: Tidak/Belum Sekolah | R30: Belum/Tidak Bekerja
B31: 8 | C31: 520101 1007140005 | D31: 24 | E31: Supardi | F31: KK | G31: 520101 0107890427 | H31: L | I31: Kawin | J31: Aik Ampat | K31: 32690 | L31: 1989 | M31: =2019-L31 -> 30 | N31: Islam | O31: Sasak | P31: SLTP/Sederajat | R31: Wiraswasta
D32: 25 | E32: Siti Soleha | F32: Istri | G32: 520101 6303960002 | H32: P | I32: Kawin | J32: Aik Ampat | K32: 35147 | L32: 1996 | M32: =2019-L32 -> 23 | N32: Islam | O32: Sasak | P32: SLTP/Sederajat | R32: Mengurus Rumah Tangga
D33: 26 | E33: Muhamad Isrol | F33: Anak | G33: 520101 2305140003 | H33: P | I33: Belum kawin | J33: Dasan Geres | K33: 41782 | L33: 2014 | M33: =2019-L33 -> 5 | N33: Islam | O33: Sasak | P33: Tidak/Belum Sekolah | R33: Belum/Tidak Bekerja
B34: 9 | C34: 520101 0503081771 | D34: 27 | E34: Jamil | F34: KK | G34: 520101 0107600040 | H34: L | I34: Kawin | J34: Cemare Karang Tengak | K34: 21002 | L34: 1957 | M34: =2019-L34 -> 62 | N34: Islam | O34: Sasak | P34: Tamat SD/Sederajat | R34: Buruh Harian Lepas
D35: 28 | E35: Senirah | F35: Istri | G35: 520101 4107590154 | H35: P | I35: Kawin | J35: Cemare Karang Tengak | K35: 21732 | L35: 1959 | M35: =2019-L35 -> 60 | N35: Islam | O35: Sasak | P35: Tamat SD/Sederajat | R35: Buruh Harian Lepas
B36: 10 | C36: 520101 0510120011 | D36: 29 | E36: Dahrum | F36: KK | G36: 520101 3112520002 | H36: L | I36: Cerai Hidup | J36: Aik Ampat | K36: 19359 | L36: 1952 | M36: =2019-L36 -> 67 | N36: Islam | O36: Sasak | P36: Tamat SD/Sederajat | R36: Buruh Harian Lepas
D37: 30 | E37: Burhanudin | F37: Anak | G37: 520101 3112950025 | H37: L | I37: Belum Kawin | J37: Aik Ampat | K37: 35064 | L37: 1995 | M37: =2019-L37 -> 24 | N37: Islam | O37: Sasak | P37: Tamat SD/Sederajat | R37: Belum/Tidak Bekerja
B38: 11 | C38: 520101 0503081784 | D38: 31 | E38: Sinarep | F38: KK | G38: 520101 0101741001 | H38: L | I38: Kawin | J38: Aik Ampat | K38: 27030 | L38: 1974 | M38: =2019-L38 -> 45 | N38: Islam | O38: Sasak | P38: Tidak/Belum Sekolah | R38: Petani/Pekebun
D39: 32 | E39: Sahenep | F39: Istri | G39: 520101 7112751001 | H39: P | I39: Kawin | J39: Aik Ampat | K39: 27759 | L39: 1975 | M39: =2019-L39 -> 44 | N39: Islam | O39: Sasak | P39: Tidak/Belum Sekolah | R39: Petani/Pekebun
B40: 12 | C40: 520101 1004150006 | D40: 33 | E40: Kasmiati | F40: KK | G40: 520101 5110850003 | H40: P | I40: Cerai Mati | J40: Cemare | K40: 31331 | L40: 1985 | M40: =2019-L40 -> 34 | N40: Islam | O40: Sasak | P40: Tamat SD/Sederajat | R40: Buruh Harian Lepas
D41: 34 | E41: Selfia Ramdani | F41: Anak | G41: 520101 4101080008 | H41: P | I41: Belum Kawin | J41: Cemare | K41: 39448 | L41: 2008 | M41: =2019-L41 -> 11 | N41: Islam | O41: Sasak | P41: Tidak/Belum Sekolah | R41: Belum/Tidak Bekerja
...

Sheet RT 02
B1: DATA INDUK PENDUDUK KELURAHAN DASAN GERES
B2: TAHUN 2019
B3: LINGKUNGAN CEMARA
B4: RT 02
B5: No | C5: Nomor KK | D5: Jumlah Jiwa | E5: Nama Lengkap/ Panggilan | F5: Kedudukan dalam Keluarga | G5: NIK | H5: Jenis Kelamin (L/P) | I5: Status Perkawinan | J5: Lahir | M5: Usia | N5: Agama | O5: Etnis | P5: Pendidikan Terakhir | Q5: Jurusan | R5: Pekerjaan
J6: Tempat | K6: Tanggal | L6: Tahun
B8: 1 | C8: 520101 0403110035 | D8: 1 | E8: Salmah | F8: KK | G8: 520101 7112650023 | H8: P | I8: Belum kawin | J8: Aik Ampat | K8: 24107 | L8: 1965 | M8: =2019-L8 -> 54 | N8: Islam | O8: Sasak | P8: Tidak/Belum Sekolah | R8: Belum/Tidak Bekerja
D9: 2 | E9: Sarilah | F9: Anak | G9: 520101 0304770001 | H9: P | I9: Cerai Hidup | J9: Cemare | K9: 28218 | L9: 1977 | M9: =2019-L9 -> 42 | N9: Islam | O9: Sasak | P9: Tamat SD/Sederajat | R9: Belum/Tidak Bekerja
D10: 3 | E10: Saparudin | F10: Anak | G10: 520101 0107950017 | H10: L | I10: Belum kawin | J10: Aik Ampat | K10: 34699 | L10: 1994 | M10: =2019-L10 -> 25 | N10: Islam | O10: Sasak | P10: SLTP/Sederajat | R10: Belum/Tidak Bekerja
B11: 2 | C11: 520101 0303110003 | D11: 4 | E11: Sahnan | F11: KK | G11: 520101 3009580001 | H11: L | I11: Kawin | J11: Aik Ampat | K11: 21458 | L11: 1958 | M11: =2019-L11 -> 61 | N11: Islam | O11: Sasak | P11: Tidak/Belum Sekolah | R11: Peteni/Pekebun
D12: 5 | E12: Midarah | F12: Istri | G12: 520101 5205630001 | H12: P | I12: Kawin | J12: Aik Ampat | K12: 23143 | L12: 1963 | M12: =2019-L12 -> 56 | N12: Islam | O12: Sasak | P12: Tamat SD/Sederajat | R12: Peteni/Pekebun
D13: 6 | E13: Kahpi | F13: Anak | G13: 520101 1007860001 | H13: L | I13: Belum kawin | J13: Aik Ampat | K13: 31603 | L13: 1986 | M13: =2019-L13 -> 33 | N13: Islam | O13: Sasak | P13: SLTA/Sederajat | R13: Peteni/Pekebun
D14: 7 | E14: Asmuniati | F14: Anak | G14: 520101 6204990002 | H14: P | I14: Belum kawin | J14: Aik Ampat | K14: 36182 | L14: 1999 | M14: =2019-L14 -> 20 | N14: Islam | O14: Sasak | P14: SLTA/Sederajat | R14: Pelajar/Mahasiswa
D15: 8 | E15: Hulbayan | F15: Anak | G15: 520101 3001020001 | H15: L | I15: Belum kawin | J15: Aik Ampat | K15: 37286 | L15: 2002 | M15: =2019-L15 -> 17 | N15: Islam | O15: Sasak | P15: SLTP/Sederajat | R15: Pelajar/Mahasiswa
B16: 3 | D16: 9 | F16: KK | G16: 520101 7112590015 | H16: L | I16: Janda | K16: 21915 | L16: =YEAR(K16) -> 1959 | M16: =2019-L16 -> 60 | N16: Islam | P16: - | R16: Pekerja lepas
D17: 10 | E17: Ardan | F17: Anak | G17: 520101 3112850019 | H17: P | I17: Belum kawin | K17: 31412 | L17: =YEAR(K17) -> 1985 | M17: =2019-L17 -> 34 | N17: Islam | P17: SLTP/MTSN | R17: Pekerja lepas
D18: 11 | E18: Rakmah | F18: Lain-lain | G18: 520101 7112600015 | H18: P | I18: Janda | K18: 31412 | L18: =YEAR(K18) -> 1985 | M18: =2019-L18 -> 34 | N18: Islam | P18: - | R18: Pekerja lepas
B19: 4 | C19: 520101 0503081900 | D19: 12 | E19: Rukiah | F19: KK | G19: 520101 4107690049 | H19: P | I19: Cerai Hidup | J19: Cemare Karang Tengak | K19: 25385 | L19: 1969 | M19: =2019-L19 -> 50 | N19: Islam | O19: Sasak | P19: Tidak/Belum Sekolah | R19: Buruh Harian Lepas
D20: 13 | E20: Masnah | F20: Anak | G20: 520101 4107920337 | H20: P | I20: Belum kawin | J20: Cemare Karang Tengak | K20: 33786 | L20: 1992 | M20: =2019-L20 -> 27 | N20: Islam | O20: Sasak | P20: SLTP/Sederajat | R20: Buruh Harian Lepas
B21: 5 | D21: 14 | E21: Nuriah | F21: KK | G21: 520101 7112400042 | H21: P | I21: Janda | K21: 14976 | L21: =YEAR(K21) -> 1940 | M21: =2019-L21 -> 79 | N21: Islam | P21: - | R21: Pekerja lepas
B22: 6 | D22: 15 | E22: Rafli | F22: KK | G22: 520101 1128201088 | H22: L | I22: Duda | K22: 30316 | L22: =YEAR(K22) -> 1982 | M22: =2019-L22 -> 37 | N22: Islam | P22: - | R22: Pekerja lepas
D23: 16 | E23: Abdul Rahim | F23: Anak | G23: 520101 2406050003 | H23: L | I23: Belum kawin | K23: 38527 | L23: =YEAR(K23) -> 2005 | M23: =2019-L23 -> 14 | N23: Islam | P23: - | R23: -
D24: 17 | E24: Abdul Rahman | F24: Anak | G24: 520101 2406050002 | H24: L | I24: Belum kawin | K24: 38527 | L24: =YEAR(K24) -> 2005 | M24: =2019-L24 -> 14 | N24: Islam | P24: - | R24: -
B25: 7 | C25: 520101 0608140009 | D25: 18 | E25: Muhsinin | F25: KK | G25: 520101 2104840004 | H25: L | I25: Kawin | J25: Aik Ampat | K25: 30793 | L25: 1984 | M25: =2019-L25 -> 35 | N25: Islam | O25: Sasak | P25: SLTP/Sederajat | R25: Buruh Harian Lepas
D26: 19 | E26: Siti Sahmin | F26: Istri | G26: 520101 4107940185 | H26: P | I26: Kawin | J26: Cemare | K26: 34048 | L26: 1993 | M26: =2019-L26 -> 26 | N26: Islam | O26: Sasak | P26: SLTA/Sederajat | R26: Mengurus Rumah Tangga
D27: 20 | E27: Ahmad Daffa Maulana | F27: Anak | G27: 520101 0804140002 | H27: L | I27: Belum kawin | J27: Dasan Geres | K27: 41737 | L27: 2014 | M27: =2019-L27 -> 5 | N27: Islam | O27: Sasak | P27: Tidak/Belum Sekolah | R27: Belum/Tidak Bekerja
B28: 8 | C28: 520101 0602150043 | D28: 21 | E28: Sadiah | F28: KK | G28: 520101 4107570152 | H28: P | I28: Cerai Hidup | J28: Cemare Karang Tengak | K28: 21002 | L28: 1957 | M28: =2019-L28 -> 62 | N28: Islam | O28: Sasak | P28: Tidak/Belum Sekolah | R28: Buruh Harian Lepas
B29: 9 | C29: 520101 0503081903 | D29: 22 | E29: Irun | F29: KK | G29: 520101 4107690064 | H29: P | I29: Kawin | J29: Cemare Karang Tengak | K29: 25568 | L29: 1969 | M29: =2019-L29 -> 50 | N29: Islam | O29: Sasak | P29: Tidak/Belum Sekolah | R29: Mengurus Rumah Tangga
D30: 23 | E30: Mawardi | F30: Anak | G30: 520101 0107930293 | H30: L | I30: Belum kawin | J30: Aik Ampat | K30: 34151 | L30: 1993 | M30: =2019-L30 -> 26 | N30: Islam | O30: Sasak | P30: SLTP/Sederajat | R30: Pelajar/Mahasiswa
D31: 24 | E31: Sukardi | F31: Anak | G31: 520101 0107970327 | H31: L | I31: Belum kawin | J31: Aik Ampat | K31: 35612 | L31: 1997 | M31: =2019-L31 -> 22 | N31: Islam | O31: Sasak | P31: Belum Tamat SD/Sederajat | R31: Pelajar/Mahasiswa
B32: 10 | C32: 520101 0302100040 | D32: 25 | E32: Nasrudin | F32: KK | G32: 520101 3112870018 | H32: L | I32: Kawin | J32: Aik Ampat | K32: 32142 | L32: 1987 | M32: =2019-L32 -> 32 | N32: Islam | O32: Sasak | P32: Tamat SD/Sederajat | R32: Wiraswasta
D33: 26 | E33: Faoziah | F33: Istri | G33: 520101 7112880026 | H33: P | I33: Kawin | J33: Aik Ampat | K33: 32508 | L33: 1988 | M33: =2019-L33 -> 31 | N33: Islam | O33: Sasak | P33: Tamat SD/Sederajat | R33: Mengurus Rumah Tangga
D34: 27 | E34: M. Adit Nasrul Ilham | F34: Anak | G34: 520101 1403100003 | H34: L | I34: Belum kawin | J34: Aik Ampat | K34: 40251 | L34: 2010 | M34: =2019-L34 -> 9 | N34: Islam | O34: Sasak | P34: Tidak/Belum Sekolah | R34: Belum/Tidak Bekerja
B35: 11 | C35: 520101 0503081908 | D35: 28 | E35: Syamsudin | F35: KK | G35: 520101 0609820001 | H35: L | I35: Kawin | J35: Karang Tengak Cemare | K35: 30200 | L35: 1982 | M35: =2019-L35 -> 37 | N35: Islam | O35: Sasak | P35: Tamat SD/Sederajat | R35: Wiraswasta
D36: 29 | E36: Marianah | F36: Istri | G36: 520101 4107880131 | H36: P | I36: Kawin | J36: Cemare Karang Tengak | K36: 32325 | L36: 1988 | M36: =2019-L36 -> 31 | N36: Islam | O36: Sasak | P36: SLTA/Sederajat | R36: Mengurus Rumah Tangga
D37: 30 | E37: Zahratullaili | F37: Anak | G37: 520101 5701090001 | H37: P | I37: Belum kawin | J37: Dasan Geres | K37: 39830 | L37: 2009 | M37: =2019-L37 -> 10 | N37: Islam | O37: Sasak | P37: Tidak/Belum Sekolah | R37: Belum/Tidak Bekerja
D38: 31 | E38: Sayyid Ahsanul Khaliq | F38: Anak | G38: 520101 1601120003 | H38: L | I38: Belum kawin | J38: Dasan Geres | K38: 40924 | L38: 2012 | M38: =2019-L38 -> 7 | N38: Islam | O38: Sasak | P38: Tidak/Belum Sekolah | R38: Belum/Tidak Bekerja
B39: 12 | C39: 520101 2601100019 | D39: 32 | E39: Ratiah | F39: KK | G39: 520101 1810470001 | H39: L | I39: Cerai | J39: Aik Ampat | K39: 17458 | L39: 1947 | M39: =2019-L39 -> 72 | N39: Islam | O39: Sasak | P39: Tamat SD/Sederajat | R39: Petani/Pekebun
B40: 13 | C40: 520101 2610110041 | D40: 33 | E40: Suriadi | F40: KK | G40: 520101 1012830002 | H40: L | I40: Kawin | J40: Aik Ampat | K40: 30660 | L40: 1983 | M40: =2019-L40 -> 36 | N40: Islam | O40: Sasak | P40: SLTP/Sederajat | R40: Belum/Tidak Bekerja
D41: 34 | E41: Haerani | F41: Istri | G41: 520101 7112840093 | H41: P | I41: Kawin | J41: Aik Ampat | K41: 31047 | L41: 1984 | M41: =2019-L41 -> 35 | N41: Islam | O41: Sasak | P41: SLTA/Sederajat | R41: Mengurus Rumah Tangga
...

Sheet RT 03
B1: DATA INDUK PENDUDUK KELURAHAN DASAN GERES
B2: TAHUN 2019
B3: LINGKUNGAN CEMARA
B4: RT 03
B5: No | C5: Nomor KK | D5: Jumlah Jiwa | E5: Nama Lengkap/panggilan | F5: Kedudukan dalam Keluarga | G5: NIK | H5: Jenis Kelamin (L/P) | I5: Status Perkawinan | J5: Lahir | M5: Usia | N5: Agama | O5: Etnis | P5: Pendidikan Terakhir | Q5: Jurusan | R5: Pekerjaan
J6: Tempat | K6: Tsnggal | L6: Tahun
B8: 1 | C8: 520101 0910100018 | D8: 1 | E8: Miderah | F8: KK | G8: 520101 0107680327 | H8: L | I8: Kawin | J8: Aik Ampat | K8: 25020 | L8: 1968 | M8: =2019-L8 -> 51 | N8: Islam | O8: Sasak | P8: Tamat SD/Sederajat | R8: Petani/Pekebun
D9: 2 | E9: Aniah | F9: Istri | G9: 520101 4107700556 | H9: P | I9: Kawin | J9: Aik Ampat | K9: 25750 | L9: 1970 | M9: =2019-L9 -> 49 | N9: Islam | O9: Sasak | P9: Tamat SD/Sederajat | R9: Mengurus Rumah Tangga
D10: 3 | E10: Tawahid Sarip | F10: Anak | G10: 520101 0905920001 | H10: L | I10: Belum kawin | J10: Aik Ampat | K10: 33733 | L10: 1992 | M10: =2019-L10 -> 27 | N10: Islam | O10: Sasak | P10: SLTP/Sederajat | R10: Belum/Tidak Bekerja
D11: 4 | E11: Supriadi | F11: Anak | G11: 520101 1111950001 | H11: L | I11: Belum kawin | J11: Aik Ampat | K11: 35014 | L11: 1995 | M11: =2019-L11 -> 24 | N11: Islam | O11: Sasak | P11: SLTP/Sederajat | R11: Belum/Tidak Bekerja
B12: 2 | C12: 520101 0503081881 | D12: 5 | E12: Munansah | F12: KK | G12: 520101 0107540085 | H12: L | I12: Kawin | J12: Cemare | K12: 19906 | L12: 1954 | M12: =2019-L12 -> 65 | N12: Islam | O12: Sasak | P12: Tamat SD/Sederajat | R12: Wiraswasta
D13: 6 | E13: Munariah | F13: Istri | G13: 520101 4107610072 | H13: P | I13: Kawin | J13: Cemare | K13: 22463 | L13: 1961 | M13: =2019-L13 -> 58 | N13: Islam | O13: Sasak | P13: Tamat SD/Sederajat | R13: Mengurus Rumah Tangga
D14: 7 | E14: M Fahrul Rozim | F14: Anak | G14: 520101 0107800439 | H14: L | I14: Belum kawin | J14: Cemare | K14: 29403 | L14: 1980 | M14: =2019-L14 -> 39 | N14: Islam | O14: Sasak | P14: Tamat SD/Sederajat | R14: Belum/Tidak Bekerja
D15: 8 | E15: Fahrizal Arif | F15: Anak | G15: 520101 0107890465 | H15: L | I15: Belum kawin | J15: Cemare | K15: 32690 | L15: 1989 | M15: =2019-L15 -> 30 | N15: Islam | O15: Sasak | P15: Tamat SD/Sederajat | R15: Belum/Tidak Bekerja
D16: 9 | E16: Fahri Husaini | F16: Anak | G16: 520101 1904940001 | H16: L | I16: Belum kawin | J16: Bandung | K16: 34443 | L16: 1994 | M16: =2019-L16 -> 25 | N16: Islam | O16: Sasak | P16: SLTP/Sederajat | R16: Belum/Tidak Bekerja
B17: 3 | C17: 520101 0503081567 | D17: 10 | E17: Kadri | F17: KK | G17: 520101 0107570378 | H17: L | I17: Kawin | J17: Aik Ampat | K17: 22281 | L17: 1960 | M17: =2019-L17 -> 59 | N17: Islam | O17: Sasak | P17: Tamat SD/Sederajat | R17: Buruh Harian Lepas
D18: 11 | E18: Mainah | F18: Istri | G18: 520101 7112620019 | H18: P | I18: Kawin | J18: Tempos | K18: 23011 | L18: 1962 | M18: =2019-L18 -> 57 | N18: Islam | O18: Sasak | P18: Tamat SD/Sederajat | R18: Mengurus Rumah Tangga
B19: 4 | C19: 520101 0503081808 | D19: 12 | E19: Muhajirin | F19: KK | G19: 520101 0107820107 | H19: L | I19: Kawin | J19: Cemare Karang Tengak | K19: 30316 | L19: 1982 | M19: =2019-L19 -> 37 | N19: Islam | O19: Sasak | P19: SLTP/Sederajat | R19: Buruh Harian Lepas
D20: 13 | E20: Siti Apadah | F20: Istri | G20: 520101 4107870484 | H20: P | I20: Kawin | J20: Cemare Karang Tengak | K20: 29951 | L20: 1981 | M20: =2019-L20 -> 38 | N20: Islam | O20: Sasak | P20: Tidak/Belum Sekolah | R20: Mengurus Rumah Tangga
D21: 14 | E21: Mulyani | F21: Anak | G21: 520101 5806040001 | H21: P | I21: Belum kawin | J21: Sumbawa | K21: 38156 | L21: 2004 | M21: =2019-L21 -> 15 | N21: Islam | O21: Sasak | P21: Tidak/Belum Sekolah | R21: Belum/Tidak Bekerja
D22: 15 | E22: Zul Fahmi | F22: Anak | G22: 520101 2007090004 | H22: L | I22: Belum kawin | J22: Aik Ampat | K22: 40014 | L22: 2009 | M22: =2019-L22 -> 10 | N22: Islam | O22: Sasak | P22: Tidak/Belum Sekolah | R22: Belum/Tidak Bekerja
B23: 5 | C23: 520101 0503081639 | D23: 16 | E23: Ayup | F23: KK | G23: 520101 0107720676 | H23: L | I23: Cerai Mati | J23: Cemare | K23: 19176 | L23: 1952 | M23: =2019-L23 -> 67 | N23: Islam | O23: Sasak | P23: Tidak/Belum Sekolah | R23: Buruh Harian Lepas
B24: 6 | C24: 520101 2205150001 | D24: 17 | E24: Saebah | F24: KK | G24: 520101 4107660155 | H24: P | I24: Cerai Mati | J24: Aik Ampat | K24: 24107 | L24: 1965 | M24: =2019-L24 -> 54 | N24: Islam | O24: Sasak | P24: Tidak/Belum Sekolah | R24: Buruh Harian Lepas
B25: 7 | C25: 520101 1202150077 | D25: 18 | E25: Sifakyah | F25: KK | G25: 520101 5909780001 | H25: P | I25: Cerai Hidup | J25: Cemare Karang Tengak | K25: 28752 | L25: 1978 | M25: =2019-L25 -> 41 | N25: Islam | O25: Sasak | P25: Tidak/Belum Sekolah | R25: Mengurus Rumah Tangga
B26: 8 | C26: 520101 0604160012 | D26: 19 | E26: Amirullah | F26: KK | G26: 520101 0607920003 | H26: L | I26: Kawin | J26: Karang Tengak | K26: 33791 | L26: 1992 | M26: =2019-L26 -> 27 | N26: Islam | O26: Sasak | P26: SLTA/Sederajat | R26: Wiraswasta
D27: 20 | E27: Nuruh Ismi Taharah | F27: Istri | G27: 520805 7008990001 | H27: P | I27: Kawin | J27: Bentek | K27: 36402 | L27: 1999 | M27: =2019-L27 -> 20 | N27: Islam | O27: Sasak | P27: SLTA/Sederajat | R27: Mengurus Rumah Tangga
B28: 9 | C28: 520101 0602150031 | D28: 21 | E28: Saminah | F28: KK | G28: 520101 4107520237 | H28: P | I28: Cerai Mati | J28: Cemare | K28: 19176 | L28: 1952 | M28: =2019-L28 -> 67 | N28: Islam | O28: Sasak | P28: Tidak/Belum Sekolah | R28: Mengurus Rumah Tangga
B29: 10 | C29: 520101 0503081876 | D29: 22 | E29: Kudin | F29: KK | G29: 520101 0107670305 | H29: L | I29: Kawin | J29: Aik Ampat | K29: 24654 | L29: 1967 | M29: =2019-L29 -> 52 | N29: Islam | O29: Sasak | P29: Tidak/Belum Sekolah | R29: Konstruksi
D30: 23 | E30: Saiun | F30: Istri | G30: 520101 4107670597 | H30: P | I30: Kawin | J30: Aik Ampat | K30: 25385 | L30: 1969 | M30: =2019-L30 -> 50 | N30: Islam | O30: Sasak | P30: Tidak/Belum Sekolah | R30: Mengurus Rumah Tangga
D31: 24 | E31: Intan Ayu Nuraini | F31: Anak | G31: 520101 4107050181 | H31: P | I31: Belum kawin | J31: Cemare Karang Tengak | K31: 38666 | L31: 2005 | M31: =2019-L31 -> 14 | N31: Islam | O31: Sasak | P31: Belum Tamat SD/Sederajat | R31: Pelajar/Mahasiswa
B32: 11 | D32: 25 | E32: Yuliani | F32: KK | G32: 520101 7112890057 | H32: P | I32: Janda | K32: 32873 | L32: =YEAR(K32) -> 1989 | M32: =2019-L32 -> 30 | N32: Islam | P32: SD/MI | R32: Pedagang
D33: 26 | E33: Muhammad Iqbal | F33: Anak | G33: 520101 2012080002 | H33: L | I33: Belum kawin | K33: 39802 | L33: =YEAR(K33) -> 2008 | M33: =2019-L33 -> 11 | N33: Islam | P33: - | R33: -
B34: 12 | D34: 27 | E34: Arman | F34: KK | G34: 520101 3112680084 | H34: L | I34: Kawin | K34: 25203 | L34: =YEAR(K34) -> 1968 | M34: =2019-L34 -> 51 | N34: Islam | P34: SLTA/MA | R34: PNS/TNI/ POLRI
D35: 28 | E35: HajahCahya Haerani S.H | F35: Istri | G35: 520101 5808670002 | H35: P | I35: Kawin | K35: 24702 | L35: =YEAR(K35) -> 1967 | M35: =2019-L35 -> 52 | N35: Islam | P35: SLTA/MA | R35: Wiraswasta
D36: 29 | E36: Nunang Fradana | F36: Anak | G36: 520101 2204890003 | H36: L | I36: Belum kawin | K36: 32620 | L36: =YEAR(K36) -> 1989 | M36: =2019-L36 -> 30 | N36: Islam | P36: PT/Akademi | R36: Wiraswasta
D37: 30 | E37: Yayak Fradana | F37: Anak | G37: 520101 0309020001 | H37: L | I37: Belum kawin | K37: 33850 | L37: =YEAR(K37) -> 1992 | M37: =2019-L37 -> 27 | N37: Islam | P37: - PT/Akademi | R37: PNS/TNI/ POLRI
D38: 31 | E38: Rizki Afriani Islamiyah | F38: Anak | G38: 520101 7404980003 | H38: P | I38: Belum kawin | K38: 35897 | L38: =YEAR(K38) -> 1998 | M38: =2019-L38 -> 21 | N38: Islam | P38: SD/MI | R38: -
B39: 13 | D39: 32 | E39: Hamni | F39: KK | G39: 520101 4107620406 | H39: P | I39: Janda | K39: 26602 | L39: =YEAR(K39) -> 1972 | M39: =2019-L39 -> 47 | N39: Islam | P39: - | R39: Pekerja lepas
D40: 33 | E40: Muhammad Mahsup | F40: Istri | G40: 520101 0107940290 | H40: L | I40: Belum kawin | K40: 35965 | L40: =YEAR(K40) -> 1998 | M40: =2019-L40 -> 21 | N40: Islam | P40: SLTP/MTSN | R40: -
D41: 34 | E41: Bilmah | F41: Anak | G41: 520101 4107720484 | H41: P | I41: Belum kawin | K41: 11871 | L41: =YEAR(K41) -> 1932 | M41: =2019-L41 -> 87 | N41: Islam | P41: - | R41: Pekerja lepas
...

Sheet S
A1: 97 | C1: 263
A2: 87 | C2: 274
A3: 70 | C3: 232
A4: 63 | C4: 193
A5: 24 | C5: 70
A6: =SUM(A1:A5) -> 341 | C6: =SUM(C1:C5) -> 1032

Sheet PINDAH KELUAR
A2: No | B2: Nomor KK | C2: Jumlah | D2: Nama Lengkap/panggilan | E2: Kedudukan dalam Keluarga | F2: NIK | G2: Jenis Kelamin (L/P) | H2: Status Perkawinan | I2: Lahir | L2: Usia | M2: Agama | N2: Etnis | O2: Pendidikan Terakhir | P2: Jurusan | Q2: Pekerjaan | R2: Cacat | T2: Ada
C3: Jiwa | I3: Tempat | J3: Tanggal | K3: Tahun | R3: Mental | S3: Fisik | T3: KK | U3: KTP / KIA | V3: Buku Nikah | W3: Akta Kelahiran
C4: 40 | D4: Susmita Dewi | E4: Anak | F4: 520101 4410981001 | G4: P | H4: Belum kawin | J4: 36072 | L4: =2019-K4 -> 2019 | M4: Islam | O4: SD/MI | Q4: -
C5: 26 | D5: Sukardi | E5: Anak | F5: 520101 0107970327 | G5: L | H5: Belum kawin | J5: 35612 | L5: =2019-K5 -> 2019 | M5: Islam | O5: SD/MI | Q5: Pekerja lepas
C6: 20 | D6: Rosihin | E6: Anak | F6: 520101 1005920001 | G6: P | H6: Belum kawin | J6: 33734 | L6: =2019-K6 -> 2019 | M6: Islam | O6: - | Q6: -
C7: 21 | D7: Zaitun | E7: Anak | F7: 520101 0510970001 | G7: P | H7: Belum kawin | J7: 35708 | L7: =2019-K7 -> 2019 | M7: Islam | O7: - | Q7: -
C8: 124 | D8: Muhamad Munawardi | E8: Anak | F8: 520101 1539100003 | G8: L | H8: Belum kawin | J8: 33312 | L8: =2019-K8 -> 2019 | M8: Islam | O8: SLTA/MA | Q8: Wiraswasta
C9: 164 | D9: Sahnan | E9: Anak | F9: 520101 1204880001 | G9: L | H9: Belum kawin | J9: 32245 | L9: =2019-K9 -> 2019 | M9: Islam | N9: Sasak | O9: SLTP/MTSN | Q9: Pekerja lepas
C10: 166 | D10: Salamn | E10: Anak | F10: 520101 1011910001 | G10: L | H10: Belum kawin | J10: 33552 | L10: =2019-K10 -> 2019 | M10: Islam | N10: Sasak | O10: SLTP/MTSN | Q10: -
C11: 168 | D11: Murtiah | E11: Anak | F11: 520101 4507950001 | G11: P | H11: Belum kawin | J11: 34885 | L11: =2019-K11 -> 2019 | M11: Islam | N11: Sasak | O11: - | Q11: -
C12: 33 | D12: Burhanudin | E12: Anak | F12: 520101 3112860025 | G12: L | H12: Belum kawin | J12: 33969 | L12: =2019-K12 -> 2019 | M12: Islam | O12: SD/MI | Q12: Pekerja lepas
A13: 42 | C13: 99 | D13: Puasi | E13: KK | F13: 520101 3112670143 | G13: L | H13: Kawin | J13: 24837 | L13: =2019-K13 -> 2019 | M13: Islam | O13: - | Q13: Pekerja lepas
C14: 48 | D14: Marhamah | E14: Anak | F14: 520101 7112800125 | G14: P | H14: Belum kawin | J14: 33238 | L14: =2019-K14 -> 2019 | M14: Islam | O14: SLTP/MTSN | Q14: Pekerja lepas
A15: 30 | C15: 73 | D15: Suhadi | E15: Lain-Lain | F15: 520101 0109890003 | G15: P | H15: Janda | J15: 32752 | K15: 1989 | L15: =2019-K15 -> 30 | M15: Islam | O15: SD/MI | Q15: Pedagang
C16: 10 | D16: Irma Hasanah | E16: Anak | F16: 520101 681281001 | G16: P | H16: Belum kawin | J16: 29948 | L16: =2019-K16 -> 2019 | M16: Islam | O16: SLTA/MA | Q16: -
C17: 7 | D17: Pahriah | E17: Anak | F17: 520101 6204990002 | G17: P | H17: Belum kawin | J17: 33969 | L17: =2019-K17 -> 2019 | M17: Islam | O17: SLTA/MA | Q17: Pekerja lepas
C18: 245 | D18: Nuradani | E18: Anak | F18: 520101 4107900547 | G18: P | H18: Belum kawin | J18: 33055 | L18: =2019-K18 -> 2019 | M18: Islam | O18: SLTP/MTSN | Q18: -
C19: 128 | D19: kamariah | E19: Anak | F19: 520101 0107920476 | G19: L | H19: Belum kawin | I19: Cemare Karang Tengak | J19: 33786 | K19: 1992 | L19: =2019-K19 -> 27 | M19: Islam | N19: Sasak | O19: SLTP/Sederajat | Q19: Belum/Tidak Bekerja
C20: 129 | D20: Nurman | E20: Anak | F20: 520101 0511940002 | G20: L | H20: Belum kawin | I20: Aik Ampat | J20: 34643 | K20: 1994 | L20: =2019-K20 -> 25 | M20: Islam | N20: Sasak | O20: Tamat SD/Sederajat | Q20: Buruh Harian Lepas
C21: 130 | D21: Budiah | E21: Anak | F21: 520101 5002980002 | G21: P | H21: Belum kawin | I21: Aik Ampat | J21: 35836 | K21: 1998 | L21: =2019-K21 -> 21 | M21: Islam | N21: Sasak | O21: SLTP/Sederajat | Q21: Belum/Tidak Bekerja
C22: 164 | D22: Kandiawan | E22: Anak | F22: 520101 0107880320 | G22: L | H22: Belum kawin | I22: Cemare Karang Tengak | J22: 32325 | K22: 1988 | L22: =2019-K22 -> 31 | M22: Islam | N22: Sasak | O22: Tidak/Belum Sekolah | Q22: Belum/Tidak Bekerja
C23: 55 | D23: Atikah | E23: Anak | F23: 520101 4501960003 | G23: P | H23: Belum kawin | J23: 35069 | K23: 1996 | L23: =2019-K23 -> 23 | M23: Islam | N23: Sasak | O23: SLTP/MTSN | Q23: Pekerja lepas
C24: 87 | D24: Fitriana | E24: Anak | F24: 520101 7112990001 | G24: P | H24: Belum kawin | J24: 36525 | K24: 1999 | L24: =2019-K24 -> 20 | M24: Islam | O24: SLTP/MTSN | Q24: --
C25: 92 | D25: Siti Mahrani | E25: Anak | F25: 520101 5604930002 | G25: P | H25: Belum kawin | J25: 34075 | L25: =2019-K25 -> 2019 | M25: Islam | O25: SLTA/MA | Q25: -
C26: 59 | D26: Rofiah | E26: Istri | F26: 520101 4710840001 | G26: P | H26: Belum kawin | J26: 30962 | L26: =2019-K26 -> 2019 | M26: Islam | O26: - | Q26: -
C27: 125 | D27: Nurul Hayati | E27: Anak | F27: 520101 5701980001 | G27: P | H27: Belum kawin | J27: 35812 | L27: =2019-K27 -> 2019 | M27: Islam | O27: SLTP/MTSN | Q27: -

Sheet Meninggal
A2: No | B2: Nomor KK | C2: Jumlah | D2: Nama Lengkap/panggilan | E2: Kedudukan dalam Keluarga | F2: NIK | G2: Jenis Kelamin (L/P) | H2: Status Perkawinan | I2: Lahir | L2: Usia | M2: Agama | N2: Etnis | O2: Pendidikan Terakhir | P2: Jurusan | Q2: Pekerjaan | R2: Cacat | T2: Ada
C3: Jiwa | I3: Tempat | J3: Tanggal | K3: Tahun | R3: Mental | S3: Fisik | T3: KK | U3: KTP / KIA | V3: Buku Nikah | W3: Akta Kelahiran
C4: 270 | D4: Mahyudin | E4: Suami | F4: 0 | G4: L | H4: Belum kawin | J4: 33238 | L4: =2019-K4 -> 2019 | M4: Islam | O4: SLTA/MA | Q4: Pekerja lepas
C5: 171 | D5: Arman Maulana | E5: Anak | F5: 520101 0008090002 | G5: L | H5: Belum kawin | J5: 40427 | L5: =2019-K5 -> 2019 | M5: Islam | O5: - | Q5: -
C6: 232 | D6: Haerudin | E6: KK | F6: 520101 2102820003 | G6: L | H6: Kawin | I6: Aik Ampat | J6: 30003 | K6: 1982 | L6: =2019-K6 -> 37 | M6: Islam | N6: Sasak | O6: Tamat SD/Sederajat | Q6: Buruh Harian Lepas
C7: 244 | D7: Satiah | E7: Istri | F7: 520101 4107730204 | G7: P | H7: Kawin | J7: 26846 | L7: =2019-K7 -> 2019 | M7: Islam | O7: - | Q7: Pekerja lepas
