Workbook

Sheet Rekap
B1: REKAP DATA PENDUDUK
B2: LINGKUNGAN DASAN GERES SELATAN
B3: RT | C3: Jumlah Penduduk | E3: Total | F3: Jumlah KK | H3: Total | I3: Jumlah Duda / Janda | K3: Total | L3: Jumlah Lansia ( =>60 ) | N3: Total
C4: L | D4: P | F4: L | G4: P | I4: L | J4: P | L4: L | M4: P
B5: RT 1 | C5: =COUNTIF('RT 01'!$H$8:$H$193,"L") -> 92 | D5: =COUNTIF('RT 01'!$H$8:$H$193,"P") -> 94 | E5: =SUM(C5:D5) -> 186 | F5: =COUNTIFS('RT 01'!$F$8:$F$193,"KK",'RT 01'!$H$8:$H$193,"L") -> 45 | G5: =COUNTIFS('RT 01'!$F$8:$F$193,"KK",'RT 01'!$H$8:$H$193,"P") -> 8 | H5: =SUM(F5:G5) -> 53 | I5: =COUNTIFS('RT 01'!$I$8:$I$193,"Cerai Mati",'RT 01'!$H$8:$H$193,"L")+COUNTIFS('RT 01'!$I$8:$I$193,"Cerai Hidup",'RT 01'!$H$8:$H$193,"L")+COUNTIFS('RT 01'!$I$8:$I$193,"Duda",'RT 01'!$H$8:$H$193,"L") -> 5 | J5: =COUNTIFS('RT 01'!$I$8:$I$193,"Cerai Mati",'RT 01'!$H$8:$H$193,"P")+COUNTIFS('RT 01'!$I$8:$I$193,"Cerai Hidup",'RT 01'!$H$8:$H$193,"P")+COUNTIFS('RT 01'!$I$8:$I$193,"Janda",'RT 01'!$H$8:$H$193,"P") -> 12 | K5: =SUM(I5:J5) -> 17 | L5: 10 | M5: 10 | N5: =SUM(L5:M5) -> 20
B6: RT 2 | C6: =COUNTIF('RT 02'!$H$8:$H$160,"L") -> 76 | D6: =COUNTIF('RT 02'!$H$8:$H$160,"P") -> 77 | E6: =SUM(C6:D6) -> 153 | F6: =COUNTIFS('RT 02'!$F$8:$F$160,"KK",'RT 02'!$H$8:$H$160,"L") -> 36 | G6: =COUNTIFS('RT 02'!$F$8:$F$160,"KK",'RT 02'!$H$8:$H$160,"P") -> 13 | H6: =SUM(F6:G6) -> 49 | I6: =COUNTIFS('RT 02'!$I$8:$I$160,"Cerai Mati",'RT 02'!$H$8:$H$160,"L")+COUNTIFS('RT 02'!$I$8:$I$160,"Cerai Hidup",'RT 02'!$H$8:$H$160,"L")+COUNTIFS('RT 02'!$I$8:$I$160,"Duda",'RT 02'!$H$8:$H$160,"L") -> 3 | J6: =COUNTIFS('RT 02'!$I$8:$I$160,"Cerai Mati",'RT 02'!$H$8:$H$160,"P")+COUNTIFS('RT 02'!$I$8:$I$160,"Cerai Hidup",'RT 02'!$H$8:$H$160,"P")+COUNTIFS('RT 02'!$I$8:$I$160,"Janda",'RT 02'!$H$8:$H$160,"P") -> 16 | K6: =SUM(I6:J6) -> 19 | L6: 5 | M6: 13 | N6: =SUM(L6:M6) -> 18
B7: RT 3 | C7: =COUNTIF('RT 03'!$H$8:$H$183,"L") -> 86 | D7: =COUNTIF('RT 03'!$H$8:$H$183,"P") -> 90 | E7: =SUM(C7:D7) -> 176 | F7: =COUNTIFS('RT 03'!$F$8:$F$183,"KK",'RT 03'!$H$8:$H$183,"L") -> 46 | G7: =COUNTIFS('RT 03'!$F$8:$F$183,"KK",'RT 03'!$H$8:$H$183,"P") -> 8 | H7: =SUM(F7:G7) -> 54 | I7: =COUNTIFS('RT 03'!$I$8:$I$183,"Cerai Mati",'RT 03'!$H$8:$H$183,"L")+COUNTIFS('RT 03'!$I$8:$I$183,"Cerai Hidup",'RT 03'!$H$8:$H$183,"L")+COUNTIFS('RT 03'!$I$8:$I$183,"Duda",'RT 03'!$H$8:$H$183,"L") -> 4 | J7: =COUNTIFS('RT 03'!$I$8:$I$183,"Cerai Mati",'RT 03'!$H$8:$H$183,"P")+COUNTIFS('RT 03'!$I$8:$I$183,"Cerai Hidup",'RT 03'!$H$8:$H$183,"P")+COUNTIFS('RT 03'!$I$8:$I$183,"Janda",'RT 03'!$H$8:$H$183,"P") -> 9 | K7: =SUM(I7:J7) -> 13 | L7: 11 | M7: 11 | N7: =SUM(L7:M7) -> 22
B8: RT 4 | C8: =COUNTIF('RT 04'!$H$8:$H$258,"L") -> 120 | D8: =COUNTIF('RT 04'!$H$8:$H$258,"P") -> 131 | E8: =SUM(C8:D8) -> 251 | F8: =COUNTIFS('RT 04'!$F$8:$F$258,"KK",'RT 04'!$H$8:$H$258,"L") -> 58 | G8: =COUNTIFS('RT 04'!$F$8:$F$258,"KK",'RT 04'!$H$8:$H$258,"P") -> 11 | H8: =SUM(F8:G8) -> 69 | I8: =COUNTIFS('RT 04'!$I$8:$I$258,"Cerai Mati",'RT 04'!$H$8:$H$258,"L")+COUNTIFS('RT 04'!$I$8:$I$258,"Cerai Hidup",'RT 04'!$H$8:$H$258,"L")+COUNTIFS('RT 04'!$I$8:$I$258,"Duda",'RT 04'!$H$8:$H$258,"L") -> 1 | J8: =COUNTIFS('RT 04'!$I$8:$I$258,"Cerai Mati",'RT 04'!$H$8:$H$258,"P")+COUNTIFS('RT 04'!$I$8:$I$258,"Cerai Hidup",'RT 04'!$H$8:$H$258,"P")+COUNTIFS('RT 04'!$I$8:$I$258,"Janda",'RT 04'!$H$8:$H$258,"P") -> 13 | K8: =SUM(I8:J8) -> 14 | L8: 10 | M8: 18 | N8: =SUM(L8:M8) -> 28
B9: JUMLAH TOTAL | C9: =SUM(C5:C8) -> 374 | D9: =SUM(D5:D8) -> 392 | E9: =SUM(E5:E8) -> 766 | F9: =SUM(F5:F8) -> 185 | G9: =SUM(G5:G8) -> 40 | H9: =SUM(H5:H8) -> 225 | I9: =SUM(I5:I8) -> 13 | J9: =SUM(J5:J8) -> 50 | ... N9: =SUM(N5:N8) -> 88
C13: Mengetahui
C14: Lurah Dasan Geres | K14: Kepala Lingkungan
C18: Hulaifi, S.H. | K18: H. M. Maliki
C19: NIP. 19841231 201101 1 023

Sheet RT 01
B1: DATA INDUK PENDUDUK KELURAHAN DASAN GERES
B2: TAHUN 2019
B3: LINGKUNGAN DASN GERES SELATAN
B4: RT 01
B5: No | C5: Nomor KK | D5: Jumlah Jiwa | E5: Nama Lengkap/panggilan | F5: Kedudukan dalam Keluarga | G5: NIK | H5: Jenis Kelamin (L/P) | I5: Status Perkawinan | J5: Lahir | M5: Usia | N5: Agama | O5: Etnis | P5: Pendidikan Terakhir | Q5: Jurusan | R5: Pekerjaan
J6: Tempat | K6: Tanggal | L6: tahun
B8: 1 | D8: 1 | E8: Abdul Haris | F8: KK | G8: 520101 3112650037 | H8: L | I8: Kawin | K8: 23011 | L8: 1962 | M8: =2019-L8 -> 57 | N8: Islam | P8: PT/Akademi | R8: PNS/TNI/ POLRI
D9: 2 | E9: Hajjah Siti Hadijah | F9: Istri | G9: 520101 7112760041 | H9: P | I9: Kawin | K9: 28125 | L9: 1976 | M9: =2019-L9 -> 43 | N9: Islam | P9: SD/MI | R9: Wiraswasta
D10: 3 | E10: Nurul Dian F | F10: Anak | G10: 520101 5304020001 | H10: P | I10: Belum kawin | K10: 37359 | L10: 2002 | M10: =2019-L10 -> 17 | N10: Islam | P10: SD/MI | R10: -
D11: 4 | E11: Mohammad Ridho Adilla F | F11: Anak | G11: 520101 0211040001 | H11: L | I11: Belum kawin | K11: 38293 | L11: 2004 | M11: =2019-L11 -> 15 | N11: Islam | P11: - | R11: -
D12: 5 | E12: A Zulfan Hafiz | F12: Anak | G12: 520101 1206120002 | H12: L | I12: Belum kawin | K12: 41072 | L12: 2012 | M12: =2019-L12 -> 7 | N12: Islam | P12: - | R12: -
B13: 2 | C13: 520101 0503083290 | D13: 6 | E13: Saleh Sayuthi, S.Pd | F13: KK | G13: 520101 0107560095 | H13: L | I13: Kawin | J13: DASAN GERES BARAT | K13: 20820 | L13: 1956 | M13: =2019-L13 -> 63 | N13: Islam | O13: Sasak | P13: DIPLOMA IV/STRATA I | R13: Guru
D14: 7 | E14: Syuhadah | F14: Istri | G14: 520101 4107620283 | H14: P | I14: Kawin | J14: DASAN GERES BARAT | K14: 23011 | L14: 1962 | M14: =2019-L14 -> 57 | N14: Islam | O14: Sasak | P14: SLTP/SEDERAJAT | R14: Mengurus Rumah Tangga
D15: 8 | E15: Marlianis Shalihah | F15: Anak | G15: 520101 5805820001 | H15: P | I15: Belum kawin | J15: DASAN GERES BARAT | K15: 30089 | L15: 1982 | M15: =2019-L15 -> 37 | N15: Islam | O15: Sasak | P15: AKADEMI/DIPLOMA III/SERJANA MUDA | R15: Karyawan Honorer
D16: 9 | E16: Shufia Prihatini S | F16: Anak | G16: 520101 5002980001 | H16: P | I16: Belum kawin | J16: DASAN GERES BARAT | K16: 35836 | L16: 1998 | M16: =2019-L16 -> 21 | N16: Islam | O16: Sasak | P16: SLTA/SEDERAJAT | R16: Pelajar/Mahasiswa
B17: 3 | D17: 10 | E17: Ahmad Syauqi Zafrullah | F17: Anak | G17: 520101 0604090001 | H17: L | I17: Kawin | K17: 29583 | L17: 1980 | M17: =2019-L17 -> 39 | N17: Islam | P17: PT/Akademi | R17: PNS/TNI/ POLRI
D18: 11 | E18: Nurul Hidayah | F18: KK | G18: 520101 0107710109 | H18: P | I18: Kawin | K18: 31542 | L18: 1986 | M18: =2019-L18 -> 33 | N18: Islam | P18: SLTA/MA | R18: -
D19: 12 | E19: Ahmad Zaidan Hafidzonasyari | F19: Istri | G19: 520101 6608770001 | H19: L | I19: Belum kawin | K19: 38941 | L19: 2006 | M19: =2019-L19 -> 13 | N19: Islam | P19: - | R19: -
D20: 13 | E20: Ahmad Ziad Nuri Syauqani | F20: Anak | G20: 520101 0609020001 | H20: L | I20: Belum kawin | K20: 41278 | L20: 2013 | M20: =2019-L20 -> 6 | N20: Islam | P20: - | R20: -
B21: 4 | C21: 520101 0503083313 | D21: 14 | E21: Suhaemi | F21: KK | G21: 520101 0302740001 | H21: L | I21: Kawin | J21: DASAN GERES | K21: 27063 | L21: 1974 | M21: =2019-L21 -> 45 | N21: Islam | O21: Sasak | P21: SLTA/SEDERAJAT | R21: Wiraswasta
D22: 15 | E22: Muhimmah | F22: Istri | G22: 520101 4405740001 | H22: P | I22: Belum kawin | J22: DASAN GERES | K22: 27163 | L22: 1974 | M22: =2019-L22 -> 45 | N22: Islam | O22: Sasak | P22: SLTA/SEDERAJAT | R22: Guru
D23: 16 | E23: Ahmad Fikri Ramadhani | F23: Anak | G23: 520101 2312000001 | H23: L | I23: Belum kawin | J23: DASAN GERES | K23: 36883 | L23: 2000 | M23: =2019-L23 -> 19 | N23: Islam | O23: Sasak | P23: TAMAT SD/SEDERAJAT | R23: Pelajar/Mahasiswa
D24: 17 | E24: Ahmad Mizan Asrori Zain | F24: Anak | G24: 520101 2804070001 | H24: L | I24: Belum kawin | J24: DASAN GERES | K24: 39200 | L24: 2007 | M24: =2019-L24 -> 12 | N24: Islam | O24: Sasak | P24: BELUM TAMAT SD/SEDERAJAT | R24: Pelajar/Mahasiswa
B25: 5 | C25: 520101 0503082568 | D25: 18 | E25: Muhammad Fadil | F25: KK | G25: 520101 0504740001 | H25: L | I25: Kawin | J25: DASAN GERES | K25: 27125 | L25: 1974 | M25: =2019-L25 -> 45 | N25: Islam | O25: Sasak | P25: SLTP/SEDERAJAT | R25: Wiraswasta
D26: 19 | E26: Siti Aminah | F26: Istri | G26: 520101 4107770539 | H26: P | I26: Kawin | J26: DASAN GERES SELATAN | K26: 28522 | L26: 1978 | M26: =2019-L26 -> 41 | N26: Islam | O26: Sasak | P26: SLTA/SEDERAJAT | R26: Guru
D27: 20 | E27: Nisrina Fadila | F27: Anak | G27: 520101 6110050001 | H27: P | I27: Belum kawin | J27: DASAN GERES | K27: 38646 | L27: 2005 | M27: =2019-L27 -> 14 | N27: Islam | O27: Sasak | P27: BELUM TAMAT SD/SEDERAJAT | R27: Pelajar/Mahasiswa
D28: 21 | E28: Maulidya Fakhira | F28: Anak | G28: 520101 4403100004 | H28: P | I28: Belum kawin | J28: DASAN GERES | K28: 40241 | L28: 2010 | M28: =2019-L28 -> 9 | N28: Islam | O28: Sasak | P28: TIDAK/BELUM SEKOLAH | R28: Belum/Tidak Bekerja
D29: 22 | E29: Muhammad Daffa Waiz | F29: Anak | G29: 520101 2102190002 | H29: L | I29: Belum kawin | J29: DASAN GERES | K29: 43517 | L29: 2019 | M29: =2019-L29 -> 0 | N29: Islam | O29: Sasak | P29: TIDAK/BELUM SEKOLAH | R29: Belum/Tidak Bekerja
B30: 6 | D30: 23 | E30: Umar Syarapudin S.Pd | F30: KK | G30: 520101 0201840002 | H30: L | I30: Kawin | K30: 30683 | L30: 1984 | M30: =2019-L30 -> 35 | N30: Islam | P30: PT/Akademi | R30: PNS/TNI/ POLRI
D31: 24 | E31: Hajjah Azizah | F31: Istri | G31: 520101 7112850158 | H31: P | I31: Kawin | K31: 31412 | L31: 1985 | M31: =2019-L31 -> 34 | N31: Islam | P31: SLTA/MA | R31: Wiraswasta
B32: 7 | D32: 25 | E32: Haji Zainudin Ikhsan | F32: KK | G32: 520101 0803740001 | H32: L | I32: Kawin | K32: 27096 | L32: 1974 | M32: =2019-L32 -> 45 | N32: Islam | P32: SLTA/MA | R32: Wiraswasta
D33: 26 | E33: Zahroni | F33: Istri | G33: 520101 4902840001 | H33: L | I33: Kawin | K33: 30721 | L33: 1984 | M33: =2019-L33 -> 35 | N33: Islam | P33: SLTA/MA | R33: Wiraswasta
B34: 8 | D34: 27 | E34: Haji Mursyid | F34: KK | G34: 520101 3112320002 | H34: L | I34: Duda | K34: 12054 | L34: 1932 | M34: =2019-L34 -> 87 | N34: Islam | P34: - | R34: -
D35: 28 | E35: Jamilah | F35: Lainnya | G35: 520101 6711890001 | H35: P | I35: Belum kawin | K35: 32839 | L35: 1989 | M35: =2019-L35 -> 30 | N35: Islam | P35: PT/Akademi | R35: -
D36: 29 | E36: Khairun Nida | F36: Lainnya | G36: 520101 4110940001 | H36: P | I36: Belum kawin | K36: 34608 | L36: 1994 | M36: =2019-L36 -> 25 | N36: Islam | P36: SLTA/MA | R36: Pegawai swasta
D37: 30 | E37: Ahmad Muzaipi | F37: Lainnya | H37: L | I37: Belum kawin | K37: 36147 | L37: 1998 | M37: =2019-L37 -> 21 | N37: Islam | P37: SLTP/MTSN | R37: -
D38: 31 | E38: Haji Muhammad Yusup | F38: Anak | G38: 0 | H38: L | I38: Duda | K38: 35064 | L38: 1995 | M38: =2019-L38 -> 24 | N38: Islam | P38: SLTP/MTSN | R38: -
B39: 9 | C39: 520101 0503084063 | D39: 32 | E39: M Salim Sungkar | F39: KK | G39: 520101 0107780001 | H39: L | I39: Kawin | J39: DASAN GERES BARAT | K39: 28625 | L39: 1978 | M39: =2019-L39 -> 41 | N39: Islam | O39: Sasak | P39: SLTA/SEDERAJAT | R39: Sopir
D40: 33 | E40: Ruka'yah | F40: Istri | G40: 520101 4107840322 | H40: P | I40: Kawin | J40: DASAN GERES BARAT | K40: 30677 | L40: 1983 | M40: =2019-L40 -> 36 | N40: Islam | O40: Sasak | P40: SLTA/SEDERAJAT | R40: Mengurus Rumah Tangga
B41: 10 | C41: 520101 3103110023 | D41: 34 | E41: Ali Mansur | F41: KK | G41: 520101 4107840322 | H41: L | I41: Kawin | J41: DASAN GERES | K41: 25568 | L41: 1969 | M41: =2019-L41 -> 50 | N41: Islam | O41: Sasak | P41: DIPLOMA IV/STRATA I | R41: Pegawai Negeri Sipil
...

Sheet RT 02
B1: DATA INDUK PENDUDUK KELURAHAN DASAN GERES
B2: TAHUN 2019
B3: LINGKUNGAN DASN GERES SELATAN
B4: RT 02
B5: No | C5: Nomor KK | D5: Jumlah Jiwa | E5: Nama Lengkap/ Panggilan | F5: Kedudukan dalam Keluarga | G5: NIK | H5: Jenis Kelamin (L/P) | I5: Status Perkawinan | J5: Lahir | M5: Usia | N5: Agama | O5: Etnis | P5: Pendidikan Terakhir | Q5: Jurusan | R5: Pekerjaan
J6: Tempat | K6: Tanggal | L6: tahun
B8: 1 | C8: 520101 0503083074 | D8: 1 | E8: Abdul Manan | F8: KK | G8: 520101 0107660016 | H8: L | I8: Kawin | J8: DASAN GERES BARAT | K8: 24289 | L8: 1966 | M8: =2019-L8 -> 53 | N8: Islam | O8: Sasak | P8: SLTA/SEDERAJAT | R8: Tukang Kayu
D9: 2 | E9: Siti Maryam | F9: Istri | G9: 520101 410690046 | H9: P | I9: Kawin | J9: DASAN GERES BARAT | K9: 25385 | L9: 1969 | M9: =2019-L9 -> 50 | N9: Islam | O9: Sasak | P9: TAMAT SD/SEDERAJAT | R9: Mengurus Rumah Tangga
D10: 3 | E10: Muhammad Wildan | F10: Anak | G10: 520101 2404890001 | H10: L | I10: Belum kawin | J10: DASAN GERES BARAT | K10: 32622 | L10: 1989 | M10: =2019-L10 -> 30 | N10: Islam | O10: Sasak | P10: SLTA/SEDERAJAT | R10: Wiraswasta
D11: 4 | E11: Laila Solatin | F11: Anak | G11: 520101 5212930002 | H11: P | I11: Janda | K11: 34315 | L11: 1993 | M11: =2019-L11 -> 26 | N11: Islam | P11: SLTA/MA | R11: -
D12: 5 | E12: M Fathir Galih Assyidiq | F12: Lainnya | G12: 520108 0804130000 | H12: L | I12: Belum kawin | K12: 41372 | L12: 2013 | M12: =2019-L12 -> 6 | N12: Islam | P12: - | R12: -
B13: 2 | D13: 6 | E13: Mariadi Muslim | F13: KK | G13: 520101 2105840003 | H13: L | I13: Kawin | K13: 30823 | L13: 1984 | M13: =2019-L13 -> 35 | N13: Islam | P13: SLTA/MA | R13: Pekerja lepas
D14: 7 | E14: Nurul Hidayah | F14: Istri | G14: 0 | H14: P | I14: Kawin | K14: 29351 | L14: 1980 | M14: =2019-L14 -> 39 | N14: Islam | P14: SLTA/MA | R14: -
D15: 8 | E15: Adinda Maharani | F15: Anak | G15: 0 | H15: P | I15: Belum kawin | K15: 40050 | L15: 2009 | M15: =2019-L15 -> 10 | N15: Islam | P15: - | R15: -
B16: 3 | C16: 520101 0503082456 | D16: 9 | E16: Muhidin | F16: KK | G16: 520101 0107650231 | H16: L | I16: Kawin | J16: DASAN GERES | K16: 23743 | L16: 1965 | M16: =2019-L16 -> 54 | N16: Islam | O16: Sasak | P16: TAMAT SD/SEDERAJAT | R16: Petani / Pekebun
D17: 10 | E17: Sahni | F17: Istri | G17: 520101 5101710001 | H17: P | I17: Kawin | J17: GERUNG | K17: 25944 | L17: 1971 | M17: =2019-L17 -> 48 | N17: Islam | O17: Sasak | P17: TAMAT SD/SEDERAJAT | R17: Mengurus Rumah Tangga
D18: 11 | E18: Suryaningsih | F18: Anak | G18: 520101 5010971001 | H18: P | I18: Belum kawin | J18: DASAN GERES | K18: 35713 | L18: 1997 | M18: =2019-L18 -> 22 | N18: Islam | O18: Sasak | P18: SLTA/SEDERAJAT | R18: Belum / Tidak Bekerja
D19: 12 | E19: Fitri Rahmawati | F19: Anak | G19: 520101 5106030001 | H19: P | I19: Belum kawin | J19: DASAN GERES | K19: 37783 | L19: 2003 | M19: =2019-L19 -> 16 | N19: Islam | O19: Sasak | P19: SLTP/SEDERAJAT | R19: Belum / Tidak Bekerja
B20: 4 | C20: 520101 2705111239 | D20: 13 | E20: M. Sadli | F20: KK | G20: 520101 0101650002 | H20: L | I20: Kawin | J20: DASAN GERES SELATAN | K20: 23743 | L20: 1965 | M20: =2019-L20 -> 54 | N20: Islam | O20: Sasak | P20: SLTA/SEDERAJAT | R20: Wiraswasta
D21: 14 | E21: Patmah | F21: Istri | G21: 520101 4107600419 | H21: P | I21: Kawin | J21: DASAN GERES SELATAN | K21: 22098 | L21: 1960 | M21: =2019-L21 -> 59 | N21: Islam | O21: Sasak | P21: TIDAK/BELUM SEKOLAH | R21: Mengurus Rumah Tangga
D22: 15 | E22: Zainudin Ihsan | F22: Anak | G22: 520101 0107980367 | H22: L | I22: Belum kawin | J22: DASAN GERES | K22: 34651 | L22: 1994 | M22: =2019-L22 -> 25 | N22: Islam | O22: Sasak | P22: SLTA/SEDERAJAT | R22: Belum / Tidak Bekerja
D23: 16 | E23: Khairul Rizal | F23: Anak | G23: 520101 5310120004 | H23: L | I23: Belum kawin | J23: GERUNG | K23: 41195 | L23: 2012 | M23: =2019-L23 -> 7 | N23: Islam | O23: Sasak | P23: TIDAK/BELUM SEKOLAH | R23: Belum / Tidak Bekerja
B24: 5 | D24: 17 | E24: Muhamad Taufik | F24: KK | G24: 520101 0503830003 | H24: L | I24: Kawin | K24: 30380 | L24: 1983 | M24: =2019-L24 -> 36 | N24: Islam | P24: SLTA/MA | R24: Wiraswasta
D25: 18 | E25: Sabariah | F25: Istri | G25: 520101 5203840005 | H25: P | I25: Kawin | K25: 30753 | L25: 1984 | M25: =2019-L25 -> 35 | N25: Islam | P25: SD/MI | R25: -
D26: 19 | E26: Firman Aditya Ramdhan | F26: Anak | G26: 520101 1008090002 | H26: L | I26: Belum kawin | K26: 40035 | L26: 2009 | M26: =2019-L26 -> 10 | N26: Islam | P26: - | R26: -
D27: 20 | E27: Agil Abdul Khaliq | F27: Anak | G27: 520101 3003120002 | H27: L | I27: Belum kawin | K27: 40998 | L27: 2012 | M27: =2019-L27 -> 7 | N27: Islam | P27: - | R27: -
B28: 6 | D28: 21 | E28: Ahmad Rumi Shadiqin | F28: KK | G28: 520101 1401840002 | H28: L | I28: Kawin | K28: 30695 | L28: 1984 | M28: =2019-L28 -> 35 | N28: Islam | P28: PT/Akademi | R28: Wiraswasta
D29: 22 | E29: Emi Surya Teti S.Pd | F29: Istri | G29: 520101 5404860006 | H29: P | I29: Kawin | K29: 31526 | L29: 1986 | M29: =2019-L29 -> 33 | N29: Islam | P29: PT/Akademi | R29: Wiraswasta
D30: 23 | E30: Roha Emilia Qatrunnada | F30: Anak | G30: 520101 4607110003 | H30: P | K30: 40730 | L30: 2011 | M30: =2019-L30 -> 8 | N30: Islam | P30: - | R30: -
B31: 7 | D31: 24 | E31: Munisah | F31: KK | G31: 520101 8506750002 | H31: P | I31: Janda | K31: 27570 | L31: 1975 | M31: =2019-L31 -> 44 | N31: Islam | P31: - | R31: Pekerja lepas
D32: 25 | E32: Laili Zarwati | F32: Anak | G32: 520101 7108990002 | H32: P | I32: Belum kawin | K32: 36403 | L32: 1999 | M32: =2019-L32 -> 20 | N32: Islam | P32: SLTP/MTSN | R32: -
B33: 8 | C33: 520101 2705111793 | D33: 26 | E33: Herjan | F33: KK | G33: 520101 0107700567 | H33: L | I33: Kawin | J33: DASAN GERES SELATAN | K33: 25750 | L33: 1970 | M33: =2019-L33 -> 49 | N33: Islam | O33: Sasak | P33: TAMAT SD/SEDERAJAT | R33: Tukang Kayu
D34: 27 | E34: Rudiah | F34: Istri | G34: 520101 4107750586 | H34: P | I34: Kawin | J34: DASAN GERES SELATAN | K34: 27576 | L34: 1975 | M34: =2019-L34 -> 44 | N34: Islam | O34: Sasak | P34: TAMAT SD/SEDERAJAT | R34: Mengurus Rumah Tangga
D35: 28 | E35: Muhamat Roni | F35: Anak | G35: 520101 1005990002 | H35: L | I35: Belum kawin | J35: DASAN GERES | K35: 35700 | L35: 1997 | M35: =2019-L35 -> 22 | N35: Islam | O35: Sasak | P35: SLTA/SEDERAJAT | R35: Pelajar/Mahasiswa
D36: 29 | E36: Aniza Amylia | F36: Anak | G36: 520101 6505130002 | H36: P | I36: Belum kawin | J36: DASAN GERES | K36: 41419 | L36: 2013 | M36: =2019-L36 -> 6 | N36: Islam | O36: Sasak | P36: TIDAK/BELUM SEKOLAH | R36: Belum / Tidak Bekerja
B37: 9 | D37: 30 | E37: Muhammad Fadli | F37: KK | G37: 520101 0312810002 | H37: L | I37: Kawin | K37: 29923 | L37: 1981 | M37: =2019-L37 -> 38 | N37: Islam | P37: SD/MI | R37: Wiraswasta
D38: 31 | E38: Sabenah | F38: Istri | G38: 520101 7112830125 | H38: P | I38: Kawin | K38: 30681 | L38: 1983 | M38: =2019-L38 -> 36 | N38: Islam | P38: SD/MI | R38: Wiraswasta
D39: 32 | E39: Muhamad Fikri | F39: Anak | G39: 520101 1505050001 | H39: L | I39: Belum kawin | K39: 38487 | L39: 2005 | M39: =2019-L39 -> 14 | N39: Islam | P39: - | R39: -
D40: 33 | E40: Lily Aprianti | F40: Anak | G40: 520101 4104120001 | H40: P | I40: Belum kawin | K40: 41006 | L40: 2012 | M40: =2019-L40 -> 7 | N40: Islam | P40: - | R40: -
B41: 10 | D41: 34 | E41: Nusimah | F41: KK | G41: 0 | H41: P | I41: Janda | K41: 18628 | L41: 1950 | M41: =2019-L41 -> 69 | N41: Islam | P41: - | R41: -
...

Sheet RT 03
B1: DATA INDUK PENDUDUK KELURAHAN DASAN GERES
B2: TAHUN 2019
B3: LINGKUNGAN DASN GERES SELATAN
B4: RT 03
B5: No | C5: Nomor KK | D5: Jumlah Jiwa | E5: Nama Lengkap/ Panggilan | F5: Kedudukan dalam Keluarga | G5: NIK | H5: Jenis Kelamin (L/P) | I5: Status Perkawinan | J5: Lahir | M5: Usia | N5: Agama | O5: Etnis | P5: Pendidikan Terakhir | Q5: Jurusan | R5: Pekerjaan
J6: Tempat | K6: Tanggal | L6: tahun
B8: 1 | D8: 1 | E8: Saimah | F8: KK | H8: P | I8: Janda | K8: 11323 | L8: 1930 | M8: =2019-L8 -> 89 | N8: Islam | P8: - | R8: -
B9: 2 | D9: 2 | E9: Samsul Hadi | F9: KK | G9: 520101 2204790001 | H9: L | I9: Kawin | K9: 28967 | L9: 1979 | M9: =2019-L9 -> 40 | N9: Islam | P9: PT/Akademi | R9: Wiraswasta
D10: 3 | E10: Mutamainah | F10: Istri | G10: 520101 5610790001 | H10: P | I10: Kawin | K10: 29144 | L10: 1979 | M10: =2019-L10 -> 40 | N10: Islam | P10: - | R10: -
D11: 4 | E11: Muhammad Zikrullah Hadi | F11: Anak | G11: 520101 1612070002 | H11: L | I11: Belum kawin | K11: 39432 | L11: 2007 | M11: =2019-L11 -> 12 | N11: Islam | P11: - | R11: -
D12: 5 | E12: Nindita Fitriana Hadi | F12: Anak | G12: 520101 5308110001 | H12: P | I12: Belum kawin | K12: 37383 | L12: 2002 | M12: =2019-L12 -> 17 | N12: Islam | P12: - | R12: -
D13: 6 | E13: Majidah | F13: Anak | G13: 520101 2402040001 | H13: P | I13: Belum kawin | K13: 38041 | L13: 2004 | M13: =2019-L13 -> 15 | N13: Islam | P13: - | R13: -
B14: 3 | C14: 520101 1008090020 | D14: 7 | E14: Haris Darmawan | F14: KK | G14: 520101 3112680003 | H14: L | I14: Kawin | J14: DASAN GERES | K14: 25203 | L14: 1968 | M14: =2019-L14 -> 51 | N14: Islam | O14: Sasak | P14: TIDAK/BELUM SEKOLAH | R14: Wiraswasta
D15: 8 | E15: Mauizah | F15: Istri | G15: 520101 4404840001 | H15: P | I15: Kawin | J15: CAKRANEGARA | K15: 30786 | L15: 1984 | M15: =2019-L15 -> 35 | N15: Islam | O15: Sasak | P15: SLTP/SEDERAJAT | R15: Wiraswasta
D16: 9 | E16: Vina Nabila Khaerina | F16: Anak | G16: 520101 5510030001 | H16: P | I16: Belum kawin | J16: DASAN GERES | K16: 37909 | L16: 2003 | M16: =2019-L16 -> 16 | N16: Islam | O16: Sasak | P16: TIDAK/BELUM SEKOLAH | R16: Belum/Tidak Bekerja
D17: 10 | E17: Atatia Jaunuarti | F17: Anak | G17: 520101 4801090001 | H17: P | I17: Belum kawin | J17: DASAN GERES | K17: 39821 | L17: 2009 | M17: =2019-L17 -> 10 | N17: Islam | O17: Sasak | P17: TIDAK/BELUM SEKOLAH | R17: Belum/Tidak Bekerja
B18: 4 | D18: 11 | E18: Abdur Rahman | F18: KK | H18: L | I18: Belum kawin | K18: 28490 | L18: 1977 | M18: =2019-L18 -> 42 | N18: Islam | P18: - | R18: Pekerja lepas
D19: 12 | E19: Faozan Hadi | F19: Lain-lain | G19: 520101 0107430301 | H19: L | I19: Belum kawin | K19: 34842 | L19: 1995 | M19: =2019-L19 -> 24 | N19: Islam | P19: SLTA/MA | R19: -
B20: 5 | D20: 13 | E20: Haji Abdus Satar | F20: KK | G20: 520101 3112450043 | H20: L | I20: Kawin | K20: 16802 | L20: 1945 | M20: =2019-L20 -> 74 | N20: Islam | P20: SD/MI | R20: Petani
D21: 14 | E21: Hajjah Maliah | F21: Istri | G21: 520101 4407500045 | H21: P | I21: Kawin | K21: 18445 | L21: 1950 | M21: =2019-L21 -> 69 | N21: Islam | P21: SD/MI | R21: Petani
B22: 6 | D22: 15 | E22: Haji Muhammad Hersan | F22: KK | G22: 520101 1109760001 | H22: L | I22: Kawin | K22: 28014 | L22: 1976 | M22: =2019-L22 -> 43 | N22: Islam | P22: SLTA/MA | R22: Wiraswasta
D23: 16 | E23: Muliana | F23: Istri | G23: 520101 6408770001 | H23: P | I23: Kawin | K23: 28361 | L23: 1977 | M23: =2019-L23 -> 42 | N23: Islam | P23: SLTA/MA | R23: Pedagang
D24: 17 | E24: Nurul Izzati | F24: Anak | G24: 520101 6904990001 | H24: p | I24: Belum kawin | K24: 36279 | L24: 1999 | M24: =2019-L24 -> 20 | N24: Islam | P24: SLTP/MTSN | R24: -
D25: 18 | E25: Muhammad Febrian Haikal | F25: Anak | G25: 520101 2402040003 | H25: L | I25: Belum kawin | K25: 38041 | L25: 2004 | M25: =2019-L25 -> 15 | N25: Islam | P25: - | R25: -
D26: 19 | E26: Fathin Kamelia | F26: Anak | G26: 520101 6409120003 | H26: P | I26: Belum kawin | K26: 41176 | L26: 2012 | M26: =2019-L26 -> 7 | N26: Islam | P26: - | R26: -
D27: 20 | E27: Alwiyah | F27: Lain-lain | G27: 520101 4107650010 | H27: P | I27: Kawin | K27: 23924 | L27: 1965 | M27: =2019-L27 -> 54 | N27: Islam | P27: - | R27: Pedagang
B28: 7 | C28: 520101 0503083167 | D28: 21 | E28: Muhamad Lailan | F28: KK | G28: 520101 0107790191 | H28: L | I28: Kawin | J28: DASAN GERES BARAT | K28: 29009 | L28: 1979 | M28: =2019-L28 -> 40 | N28: Islam | O28: Sasak | P28: SLTA/SEDERAJAT | R28: Karyawan Swasta
D29: 22 | E29: Muniah | F29: Istri | G29: 520101 4107830205 | H29: P | I29: Kawin | J29: DASAN GERES BARAT | K29: 30681 | L29: 1983 | M29: =2019-L29 -> 36 | N29: Islam | O29: Sasak | P29: SLTA/SEDERAJAT | R29: Mengurus Rumah Tangga
D30: 23 | E30: Muhamad Azril Hidayat | F30: Anak | G30: 520101 0801050004 | H30: L | I30: Belum kawin | J30: DASAN GERES | K30: 38360 | L30: 2005 | M30: =2019-L30 -> 14 | N30: Islam | O30: Sasak | P30: BELUM TAMAT SD/SEDERAJAT | R30: Pelajar/Mahasiswa
D31: 24 | E31: Syamila Al tafunnisa | F31: Anak | G31: 520101 4805110003 | H31: P | I31: Belum kawin | J31: DASAN GERES | K31: 40671 | L31: 2011 | M31: =2019-L31 -> 8 | N31: Islam | O31: Sasak | P31: TIDAK/BELUM SEKOLAH | R31: Belum/Tidak Bekerja
B32: 8 | D32: 25 | E32: Bohari | F32: KK | H32: L | I32: Kawin | K32: 15706 | L32: 1942 | M32: =2019-L32 -> 77 | N32: Islam | P32: - | R32: Pekerja lepas
D33: 26 | E33: Rabiah | F33: Istri | G33: 520101 4107460073 | H33: P | I33: Kawin | K33: 16984 | L33: 1946 | M33: =2019-L33 -> 73 | N33: Islam | P33: - | R33: -
D34: 27 | E34: Haerani | F34: Anak | G34: 520101 4107800667 | H34: P | I34: Belum kawin | K34: 29403 | L34: 1980 | M34: =2019-L34 -> 39 | N34: Islam | P34: - | R34: Pedagang
D35: 28 | E35: Fitri Ayu Wahyuni | F35: Lain-lain | H35: P | I35: Belum kawin | K35: 35816 | L35: 1998 | M35: =2019-L35 -> 21 | N35: Islam | P35: SLTP/MTSN | R35: -
B36: 9 | D36: 29 | E36: Ahmad Maliki | F36: KK | H36: L | I36: Duda | K36: 28855 | L36: 1978 | M36: =2019-L36 -> 41 | N36: Islam | P36: SLTP/MTS | R36: -
B37: 10 | D37: 30 | E37: Jamilah | F37: KK | H37: P | I37: Janda | K37: 17167 | L37: 1946 | M37: =2019-L37 -> 73 | N37: Islam | P37: - | R37: -
B38: 11 | D38: 31 | E38: Munaim | F38: KK | G38: 520101 0107430031 | H38: L | I38: Kawin | K38: 15888 | L38: 1943 | M38: =2019-L38 -> 76 | N38: Islam | P38: SD/MI | R38: Petani
D39: 32 | E39: Sakrah | F39: Istri | G39: 520101 4107590164 | H39: P | I39: Kawin | K39: 21732 | L39: 1959 | M39: =2019-L39 -> 60 | N39: Islam | P39: SD/MI | R39: Pedagang
B40: 12 | C40: 520101 0503083190 | D40: 33 | E40: Muna’an | F40: KK | G40: 520101 0107580169 | H40: L | I40: Kawin | J40: DASAN GERES BARAT | K40: 21367 | L40: 1958 | M40: =2019-L40 -> 61 | N40: Islam | O40: Sasak | P40: TAMAT SD/SEDERAJAT | R40: Petani/Pekebun
D41: 34 | E41: Mardiah | F41: Istri | G41: 520101 4107620275 | H41: P | I41: Kawin | J41: DASAN GERES BARAT | K41: 22828 | L41: 1962 | M41: =2019-L41 -> 57 | N41: Islam | O41: Sasak | P41: TAMAT SD/SEDERAJAT | R41: Buruh Tani/Perkebunan
...

Sheet RT 04
B1: DATA INDUK PENDUDUK KELURAHAN DASAN GERES
B2: TAHUN 2019
B3: LINGKUNGAN DASN GERES SELATAN
B4: RT 04
B5: No | C5: Nomor KK | D5: Jumlah Jiwa | E5: Nama Lengkap/Panggilan | F5: Kedudukan Dalam Keluarga | G5: NIK | H5: Jenis Kelamin L/P | I5: Status Perkawinan | J5: Lahir | M5: Usia | N5: Agama | O5: Etnis | P5: Pendidikan Terakhir | Q5: Jurusan | R5: Pekerjaan
J6: Tempat | K6: Tanggal | L6: Tahun
B8: 1 | D8: 1 | E8: Ir. Muhur Zukhri | F8: KK | G8: 520101 3012630002 | H8: L | I8: Kawin | K8: 23375 | L8: 1963 | M8: =2019-L8 -> 56 | P8: PT/Akademi | R8: PNS/TNI/ POLRI
D9: 2 | E9: Khairun Nisak | F9: Istri | G9: 520101 5705700002 | H9: P | I9: Kawin | K9: 25712 | L9: 1970 | M9: =2019-L9 -> 49 | P9: PT/Akademi | R9: Wiraswasta
D10: 3 | E10: Ahmad Yunuari Firdaus | F10: Anak | G10: 520101 0101920002 | H10: L | I10: Belum kawin | K10: 33604 | L10: 1992 | M10: =2019-L10 -> 27 | P10: SLTA/MA | R10: -
D11: 4 | E11: Dwi Septiani Fatimatuzzakra | F11: Anak | G11: 520101 5109950003 | H11: P | I11: Belum kawin | K11: 34953 | L11: 1995 | M11: =2019-L11 -> 24 | P11: SLTA/MA | R11: -
D12: 5 | E12: Ahmad Rizki Hidayat | F12: Anak | G12: 520101 0101030004 | H12: L | I12: Belum kawin | K12: 37622 | L12: 2003 | M12: =2019-L12 -> 16 | P12: - | R12: -
D13: 6 | E13: Sunaah | F13: Lainnya | G13: 0 | H13: P | I13: Janda | K13: 22646 | L13: 1961 | M13: =2019-L13 -> 58 | P13: - | R13: -
B14: 2 | D14: 7 | E14: Nurhidayah | F14: KK | G14: 0 | H14: P | I14: Janda | K14: 26664 | L14: 1972 | M14: =2019-L14 -> 47 | P14: SLTP/MTSN | R14: -
B15: 3 | D15: 8 | E15: Muhammad Saleh Effendi S.Pd | F15: KK | G15: 520101 1104770001 | H15: L | I15: Kawin | K15: 28226 | L15: 1977 | M15: =2019-L15 -> 42 | P15: PT/Akademi | R15: PNS/TNI/ POLRI
D16: 9 | E16: Fadlina Azmi | F16: Istri | G16: 520101 6409810001 | H16: P | I16: Kawin | K16: 29853 | L16: 1981 | M16: =2019-L16 -> 38 | P16: PT/Akademi | R16: Pegawai swasta
D17: 10 | E17: Rajih Alfasam | F17: Anak | G17: 520101 1109060001 | H17: L | I17: Belum kawin | K17: 2446 | L17: 1996 | M17: =2019-L17 -> 23 | P17: - | R17: -
D18: 11 | E18: Hajjah Raodah | F18: Lainnya | G18: 0 | H18: P | I18: Janda | K18: 13149 | L18: 1935 | M18: =2019-L18 -> 84 | P18: - | R18: -
B19: 4 | D19: 12 | E19: Hakim Usman S.Pd | F19: KK | G19: 0 | H19: L | I19: Kawin | K19: 27098 | L19: 1974 | M19: =2019-L19 -> 45 | P19: PT/Akademi | R19: PNS/TNI/ POLRI
D20: 13 | E20: Sukartini | F20: Istri | G20: 0 | H20: P | I20: Kawin | K20: 30116 | L20: 1982 | M20: =2019-L20 -> 37 | P20: PT/Akademi | R20: Pegawai swasta
D21: 14 | E21: Silva Najla Fatin | F21: Anak | G21: 0 | H21: P | I21: Belum kawin | K21: 38705 | L21: 2005 | M21: =2019-L21 -> 14 | P21: - | R21: -
D22: 15 | E22: Ziarahmanita | F22: Anak | G22: 0 | H22: P | I22: Belum kawin | K22: 40468 | L22: 2010 | M22: =2019-L22 -> 9 | P22: - | R22: -
B23: 5 | D23: 16 | E23: Hasan Utsman | F23: KK | G23: 0 | H23: L | I23: Kawin | K23: 14245 | L23: 1938 | M23: =2019-L23 -> 81 | P23: SLTA/MA | R23: Pensiunan
D24: 17 | E24: Saimah | F24: Istri | G24: 0 | H24: P | I24: Kawin | K24: 16802 | L24: 1945 | M24: =2019-L24 -> 74 | P24: SLTP/MTSN | R24: -
B25: 6 | D25: 18 | E25: Haji Asmah | F25: KK | G25: 0 | H25: P | I25: Belum kawin | K25: 16802 | L25: 1945 | M25: =2019-L25 -> 74 | P25: - | R25: -
B26: 7 | D26: 19 | E26: Muhammad Ali Hidayat S.Ag | F26: KK | G26: 520101 1008750002 | H26: L | I26: Kawin | K26: 27616 | L26: 1975 | M26: =2019-L26 -> 44 | P26: PT/Akademi | R26: Wiraswasta
D27: 20 | E27: Maemanah | F27: Istri | G27: 520101 7112860112 | H27: P | I27: Kawin | K27: 31777 | L27: 1986 | M27: =2019-L27 -> 33 | P27: SLTA/MA | R27: Wiraswasta
D28: 21 | E28: Anggun Zulaikha | F28: Anak | G28: 520101 5712060004 | H28: P | I28: Belum kawin | K28: 39078 | L28: 2006 | M28: =2019-L28 -> 13 | P28: - | R28: -
D29: 22 | E29: Nesya Amelia Putri | F29: Anak | G29: 520101 4112110002 | H29: P | I29: Belum kawin | K29: 40878 | L29: 2011 | M29: =2019-L29 -> 8 | P29: - | R29: -
B30: 8 | D30: 23 | E30: Haji Muksin Usman | F30: KK | G30: 0 | H30: L | I30: Kawin | K30: 14245 | L30: 1938 | M30: =2019-L30 -> 81 | P30: SLTA/MA | R30: Pensiunan
D31: 24 | E31: Hajjah Mukminah | F31: Istri | G31: 0 | H31: P | I31: Kawin | K31: 15706 | L31: 1942 | M31: =2019-L31 -> 77 | P31: SD/MI | R31: -
B32: 9 | D32: 25 | E32: Muhammad Zamroni S.Ag | F32: KK | G32: 0 | H32: L | I32: Kawin | K32: 27029 | L32: 1973 | M32: =2019-L32 -> 46 | P32: PT/Akademi | R32: PNS/TNI/ POLRI
D33: 26 | E33: Sri Yuniarti | F33: Istri | G33: 0 | H33: P | I33: Kawin | K33: 27759 | L33: 1975 | M33: =2019-L33 -> 44 | P33: PT/Akademi | R33: -
D34: 27 | E34: Muhammad Febrian Haikal | F34: Anak | G34: 0 | H34: L | I34: Belum kawin | K34: 38384 | L34: 2005 | M34: =2019-L34 -> 14 | P34: - | R34: -
D35: 28 | E35: Salsa Zafira | F35: Anak | G35: 0 | H35: P | I35: Belum kawin | K35: 39098 | L35: 2007 | M35: =2019-L35 -> 12 | P35: - | R35: -
D36: 29 | E36: Afika Feliza Lusia | F36: Anak | G36: 0 | H36: P | I36: Belum kawin | K36: 40982 | L36: 2012 | M36: =2019-L36 -> 7 | P36: - | R36: -
B37: 10 | D37: 30 | E37: Ahmad Ansori S.Pd | F37: KK | G37: 520101 0710680001 | H37: L | I37: Kawin | K37: 25118 | L37: 1968 | M37: =2019-L37 -> 51 | P37: PT/Akademi | R37: PNS/TNI/ POLRI
D38: 31 | E38: KaRTini | F38: Istri | G38: 520101 7112780011 | H38: P | I38: Kawin | K38: 28855 | L38: 1978 | M38: =2019-L38 -> 41 | P38: SD/MI | R38: -
D39: 32 | E39: Nur Maulidiya Kamila | F39: Anak | G39: 520101 4306000001 | H39: P | I39: Belum kawin | K39: 36680 | L39: 2000 | M39: =2019-L39 -> 19 | P39: SD/MI | R39: -
D40: 33 | E40: Adelwais Rahma Medwina | F40: Anak | G40: 520101 6605070001 | H40: p | I40: Belum kawin | K40: 39228 | L40: 2007 | M40: =2019-L40 -> 12 | P40: - | R40: -
B41: 11 | D41: 34 | E41: Hajjah Rabiatun | F41: KK | G41: 0 | H41: P | I41: Janda | K41: 21550 | L41: 1958 | M41: =2019-L41 -> 61 | P41: SD/MI | R41: Wiraswasta
...

Sheet Sheet1
A1: 53 | C1: 195
A2: 45 | C2: 146
A3: 49 | C3: 161
A4: 66 | C4: 240
A5: =SUM(A1:A4) -> 213 | C5: =SUM(C1:C4) -> 742

Sheet pindah keluar
B2: No | C2: NO. KK | D2: Jumlah Jiwa | E2: Nama Lengkap/Panggilan | F2: Kedudukan Dalam Keluarga | G2: NIK | H2: Jenis Kelamin L/P | I2: Status Perkawinan | J2: Lahir | M2: Usia | N2: Agama | O2: Etnis | P2: Pendidikan Terakhir | Q2: Jurusan | R2: Pekerjaan | S2: Cacat | U2: Ada/tidak
J3: Tempat | K3: Tanggal | L3: Tahun | S3: Mental | T3: Fisik | U3: KK | V3: KTP/KIA | W3: Buku Niikah
A5: rt 3 | C5: 43 | D5: Ramli | E5: Anak | F5: 0 | G5: L | H5: Belum kawin | I5: Pekerja lepas | J5: 28125 | M5: Islam | O5: SD/MI
A6: rt 2 | C6: 49 | D6: Erna Nurmawati | E6: Anak | F6: 520101 4303890001 | G6: P | H6: Belum kawin | J6: 32601 | L6: =2019-K6 -> 2019 | M6: Islam | O6: PT/Akademi | Q6: Pegawai swasta
A7: RT 3 | C7: 94 | D7: Muhammad Saleh | E7: Anak | F7: 520101 3112910006 | G7: L | H7: Belum kawin | J7: 33603 | L7: =2019-K7 -> 2019 | M7: Islam | O7: SLTA/MA | Q7: -
D9: 62 | E9: Siti Sakrah | F9: Anak | G9: 520101 6407980001 | H9: P | I9: Belum kawin | K9: 36000 | M9: =2019-L9 -> 2019 | N9: Islam | P9: SLTP/MTSN | R9: -
D10: 42 | E10: Lina Apriani | F10: Anak | G10: 0 | H10: P | I10: Belum kawin | K10: 32976 | M10: =2019-L10 -> 2019 | P10: PT/Akademi | R10: -
A11: rt 4 | D11: 85 | E11: Muhammad Taqiyuddin | F11: Anak | G11: 520101 0107900106 | H11: L | I11: Belum kawin | J11: DASAN GERES BARAT | K11: 32903 | L11: 1990 | M11: =2019-L11 -> 29 | N11: Islam | O11: Sasak | P11: SLTA/SEDERAJAT | R11: Pelajar/Mahasiswa
A12: rt 1 | D12: 9 | E12: Ahmad Rozi Ashiddiqqi | F12: Anak | G12: 520101 1405860001 | H12: L | I12: Belum kawin | K12: 35929 | M12: =2019-L12 -> 2019 | N12: Islam | P12: PT/Akademi | R12: -
A13: rt 1 | D13: 148 | E13: Idham Halid | F13: Anak | G13: 520101 010790055 | H13: L | I13: Belum kawin | J13: DASAN GERES BARAT | K13: 32977 | L13: 1990 | M13: =2019-L13 -> 29 | N13: Islam | O13: Sasak | P13: SLTA/SEDERAJAT | R13: Wiraswasta
A14: rt 2 | D14: 12 | E14: Fatimi | F14: Anak | G14: 520101 4510880001 | H14: P | I14: Belum kawin | K14: 32421 | M14: =2019-L14 -> 2019 | N14: Islam | P14: SLTA/MA | R14: -

Sheet Sheet2
A3: No | B3: NO. KK | C3: Jumlah Jiwa | D3: Nama Lengkap/panggilan | E3: Kedudukan dalam Keluarga | F3: NIK | G3: Jenis Kelamin (L/P) | H3: Status Perkawinan | I3: Lahir | L3: Usia | M3: Agama | N3: Etnis | O3: Pendidikan Terakhir | P3: Jurusan | Q3: Pekerjaan | R3: Cacat | T3: Ada/tidak
I4: Tempat | J4: Tanggal | K4: tahun | R4: Mental | S4: Fisik | T4: KK | U4: KTP/KIA | V4: Buku Niikah
C6: 131 | D6: Suriani | E6: Anak | F6: 520101 5007800003 | G6: P | H6: Belum kawin | J6: 29412 | K6: 1980 | L6: =2019-K6 -> 39 | M6: Islam | O6: SLTA/MA | Q6: Wiraswasta
D7: M. Sadikin | E7: Anak | F7: 520101 0505880001 | G7: L | H7: Belum kawin | I7: DASAN GERES BARAT | J7: 32268 | K7: 1988 | L7: =2019-K7 -> 31 | M7: Islam | N7: Sasak | O7: SLTA/SEDERAJAT | Q7: Wiraswasta
C8: 136 | D8: Istiana Maisyarah | E8: Anak | F8: 520101 5205950004 | G8: P | H8: Belum kawin | J8: 34831 | L8: =2019-K8 -> 2019 | M8: Islam | O8: SLTA/MA | Q8: -
C9: 137 | D9: Ida Ayu Made Saptariani | E9: Anak | F9: 520101 5908940002 | G9: P | H9: Belum kawin | J9: 34593 | L9: =2019-K9 -> 2019 | M9: Islam | O9: SLTA/MA | Q9: -
C10: 111 | D10: Nurhayati | E10: Anak | F10: 520101 5207980002 | G10: P | H10: Belum kawin | J10: 35638 | L10: =2019-K10 -> 2019 | M10: Islam | O10: SLTP/MTSN | Q10: -
C11: 142 | D11: Reni Mardiyanti | E11: Anak | F11: 520101 4107960130 | G11: P | H11: Belum kawin | J11: 35256 | L11: =2019-K11 -> 2019 | M11: Islam | O11: SLTA/MA | Q11: -

Sheet meninggal
A2: No | B2: NO. KK | C2: Jumlah Jiwa | D2: Nama Lengkap/panggilan | E2: Kedudukan dalam Keluarga | F2: NIK | G2: Jenis Kelamin (L/P) | H2: Status Perkawinan | I2: Lahir | L2: Usia | M2: Agama | N2: Etnis | O2: Pendidikan Terakhir | P2: Jurusan | Q2: Pekerjaan | R2: Cacat | T2: Ada/tidak
I3: Tempat | J3: Tanggal | K3: tahun | R3: Mental | S3: Fisik | T3: KK | U3: KTP/KIA | V3: Buku Niikah
C5: 169 | D5: Haji Lalu Ridwan Ba | E5: KK | F5: 520101 3112530009 | G5: L | H5: Kawin | J5: 19724 | L5: =2019-K5 -> 2019 | O5: PT/Akademi | Q5: Pensiunan
A6: rt 1 | D6: 147 | E6: Patmah | F6: Istri | G6: 520101 4107600104 | H6: P | I6: Kawin | J6: DASAN GERES BARAT | K6: 22098 | L6: 1960 | M6: =2019-L6 -> 59 | N6: Islam | O6: Sasak | P6: TAMAT SD/SEDERAJAT | R6: Mengurus Rumah Tangga
