Workbook

Sheet Rekap
B2: REKAP DATA PENDUDUK
B3: LINGKUNGAN DASAN GERES TIMUR
B4: RT | C4: Jumlah Penduduk | E4: Total | F4: Jumlah KK | H4: Total | I4: Jumlah Duda / Janda | K4: Total | L4: Jumlah Lansia ( =>60 ) | N4: Total
C5: L | D5: P | F5: L | G5: P | I5: L | J5: P | L5: L | M5: P
B6: RT 1 | C6: =COUNTIF('RT 01'!$H$8:$H$244,"L") -> 112 | D6: =COUNTIF('RT 01'!$H$8:$H$244,"P") -> 124 | E6: =SUM(C6:D6) -> 236 | F6: =COUNTIFS('RT 01'!$F$8:$F$244,"KK",'RT 01'!$H$8:$H$244,"L") -> 61 | G6: =COUNTIFS('RT 01'!$F$8:$F$244,"KK",'RT 01'!$H$8:$H$244,"P") -> 10 | H6: =SUM(F6:G6) -> 71 | I6: =COUNTIFS('RT 01'!$I$8:$I$244,"Cerai Mati",'RT 01'!$H$8:$H$244,"L")+COUNTIFS('RT 01'!$I$8:$I$244,"Cerai Hidup",'RT 01'!$H$8:$H$244,"L")+COUNTIFS('RT 01'!$I$8:$I$244,"Duda",'RT 01'!$H$8:$H$244,"L") -> 6 | J6: =COUNTIFS('RT 01'!$I$8:$I$244,"Cerai Mati",'RT 01'!$H$8:$H$244,"P")+COUNTIFS('RT 01'!$I$8:$I$244,"Cerai Hidup",'RT 01'!$H$8:$H$244,"P")+COUNTIFS('RT 01'!$I$8:$I$244,"Janda",'RT 01'!$H$8:$H$244,"P") -> 13 | K6: =SUM(I6:J6) -> 19 | L6: 12 | M6: 13 | N6: =SUM(L6:M6) -> 25
B7: RT 2 | C7: =COUNTIF('RT 02'!$H$8:$H$184,"L") -> 83 | D7: =COUNTIF('RT 02'!$H$8:$H$184,"P") -> 94 | E7: =SUM(C7:D7) -> 177 | F7: =COUNTIFS('RT 02'!$F$8:$F$184,"KK",'RT 02'!$H$8:$H$184,"L") -> 37 | G7: =COUNTIFS('RT 02'!$F$8:$F$184,"KK",'RT 02'!$H$8:$H$184,"P") -> 11 | H7: =SUM(F7:G7) -> 48 | I7: =COUNTIFS('RT 02'!$I$8:$I$184,"Cerai Mati",'RT 02'!$H$8:$H$184,"L")+COUNTIFS('RT 02'!$I$8:$I$184,"Cerai Hidup",'RT 02'!$H$8:$H$184,"L")+COUNTIFS('RT 02'!$I$8:$I$184,"Duda",'RT 02'!$H$8:$H$184,"L") -> 5 | J7: =COUNTIFS('RT 02'!$I$8:$I$184,"Cerai Mati",'RT 02'!$H$8:$H$184,"P")+COUNTIFS('RT 02'!$I$8:$I$184,"Cerai Hidup",'RT 02'!$H$8:$H$184,"P")+COUNTIFS('RT 02'!$I$8:$I$184,"Janda",'RT 02'!$H$8:$H$184,"P") -> 10 | K7: =SUM(I7:J7) -> 15 | L7: 6 | M7: 10 | N7: =SUM(L7:M7) -> 16
B8: RT 3 | C8: =COUNTIF('RT 03'!$H$8:$H$161,"L") -> 70 | D8: =COUNTIF('RT 03'!$H$8:$H$161,"P") -> 84 | E8: =SUM(C8:D8) -> 154 | F8: =COUNTIFS('RT 03'!$F$8:$F$161,"KK",'RT 03'!$H$8:$H$161,"L") -> 36 | G8: =COUNTIFS('RT 03'!$F$8:$F$161,"KK",'RT 03'!$H$8:$H$161,"P") -> 7 | H8: =SUM(F8:G8) -> 43 | I8: =COUNTIFS('RT 03'!$I$8:$I$161,"Cerai Mati",'RT 03'!$H$8:$H$161,"L")+COUNTIFS('RT 03'!$I$8:$I$161,"Cerai Hidup",'RT 03'!$H$8:$H$161,"L")+COUNTIFS('RT 03'!$I$8:$I$161,"Duda",'RT 03'!$H$8:$H$161,"L") -> 1 | J8: =COUNTIFS('RT 03'!$I$8:$I$161,"Cerai Mati",'RT 03'!$H$8:$H$161,"P")+COUNTIFS('RT 03'!$I$8:$I$161,"Cerai Hidup",'RT 03'!$H$8:$H$161,"P")+COUNTIFS('RT 03'!$I$8:$I$161,"Janda",'RT 03'!$H$8:$H$161,"P") -> 9 | K8: =SUM(I8:J8) -> 10 | L8: 6 | M8: 5 | N8: =SUM(L8:M8) -> 11
B9: RT 4 | C9: =COUNTIF('RT 04'!$H$8:$H$266,"L") -> 128 | D9: =COUNTIF('RT 04'!$H$8:$H$266,"P") -> 131 | E9: =SUM(C9:D9) -> 259 | F9: =COUNTIFS('RT 04'!$F$8:$F$266,"KK",'RT 04'!$H$8:$H$266,"L") -> 66 | G9: =COUNTIFS('RT 04'!$F$8:$F$266,"KK",'RT 04'!$H$8:$H$266,"P") -> 12 | H9: =SUM(F9:G9) -> 78 | I9: =COUNTIFS('RT 04'!$I$8:$I$266,"Cerai Mati",'RT 04'!$H$8:$H$266,"L")+COUNTIFS('RT 04'!$I$8:$I$266,"Cerai Hidup",'RT 04'!$H$8:$H$266,"L")+COUNTIFS('RT 04'!$I$8:$I$266,"Duda",'RT 04'!$H$8:$H$266,"L") -> 1 | J9: =COUNTIFS('RT 04'!$I$8:$I$266,"Cerai Mati",'RT 04'!$H$8:$H$266,"P")+COUNTIFS('RT 04'!$I$8:$I$266,"Cerai Hidup",'RT 04'!$H$8:$H$266,"P")+COUNTIFS('RT 04'!$I$8:$I$266,"Janda",'RT 04'!$H$8:$H$266,"P") -> 16 | K9: =SUM(I9:J9) -> 17 | L9: 8 | M9: 7 | N9: =SUM(L9:M9) -> 15
B10: JUMLAH TOTAL | C10: =SUM(C6:C9) -> 393 | D10: =SUM(D6:D9) -> 433 | E10: =SUM(E6:E9) -> 826 | F10: =SUM(F6:F9) -> 200 | G10: =SUM(G6:G9) -> 40 | H10: =SUM(H6:H9) -> 240 | I10: =SUM(I6:I9) -> 13 | J10: =SUM(J6:J9) -> 48 | ... N10: =SUM(N6:N9) -> 67
C14: Mengetahui
C15: Lurah Dasan Geres | K15: Kepala Lingkungan
C19: Hulaifi, S.H. | K19: Muh. Saleh
C20: NIP. 19841231 201101 1 023

Sheet RT 01
B1: DATA INDUK PENDUDUK KELURAHAN DASAN GERES
B2: TAHUN 2019
B3: LINGKUNGAN DASAN GERES TIMUR
B4: RT 01
B5: No | C5: Nomor KK | D5: Jumlah Jiwa | E5: Nama Lengkap/ Panggilan | F5: Kedudukan dalam Keluarga | G5: NIK | H5: Jenis Kelamin (L/P) | I5: Status Perkawinan | J5: Lahir | M5: Usia | N5: Agama | O5: Etnis | P5: Pendidikan Terakhir | Q5: Jurusan | R5: Pekerjaan
J6: Tempat | K6: Tanggal | L6: Tahun
B8: 1 | C8: 520101 0809120035 | D8: 1 | E8: Nasrudin | F8: KK | G8: 520101 0312730001 | H8: L | I8: Kawin | J8: DASAN GERES | K8: 27001 | L8: 1973 | M8: =2019-L8 -> 46 | N8: Islam | O8: Sasak | P8: TAMAT SD/SEDERAJAT | R8: Pedagang
D9: 2 | E9: Sahmin | F9: Istri | G9: 520101 6203840002 | H9: P | I9: Kawin | J9: DASAN GERES | K9: 30764 | L9: 1984 | M9: =2019-L9 -> 35 | N9: Islam | O9: Sasak | P9: TAMAT SD/SEDERAJAT | R9: Mengurus Rumah Tangga
D10: 3 | E10: Endang Widiawati | F10: Anak | G10: 520101 4107020036 | H10: P | I10: Belum kawin | J10: DASAN GERES | K10: 37615 | L10: 2002 | M10: =2019-L10 -> 17 | N10: Islam | O10: Sasak | P10: SLTP/SEDERAJAT | R10: Pelajar / Mahasiswa
D11: 4 | E11: Salsa Nova Maulia | F11: Anak | G11: 520101 6011170001 | H11: P | I11: Belum kawin | J11: DASAN GERES TIMUR | K11: 43059 | L11: 2017 | M11: =2019-L11 -> 2 | N11: Islam | O11: Sasak | P11: TIDAK/BELUM SEKOLAH | R11: Belum / Tidak Bekerja
B12: 2 | C12: 520101 1803141002 | D12: 5 | E12: Adi Darma | F12: KK | G12: 520101 0107930279 | H12: L | I12: Kawin | J12: DASAN GERES | K12: 34523 | L12: 1994 | M12: =2019-L12 -> 25 | N12: Islam | O12: Sasak | P12: SLTP/SEDERAJAT | R12: Buruh Harian Lepas
D13: 6 | E13: Mariani | F13: Istri | G13: 520113 5604950003 | H13: P | I13: Kawin | J13: SERUMBUNG | K13: 34805 | L13: 1995 | M13: =2019-L13 -> 24 | N13: Islam | O13: Sasak | P13: SLTP/SEDERAJAT | R13: Mengurus Rumah Tangga
D14: 7 | E14: Yusuf Jayadi | F14: Anak | G14: 520101 1908131002 | H14: L | I14: Belum kawin | J14: DASAN GERES | K14: 41505 | L14: 2013 | M14: =2019-L14 -> 6 | N14: Islam | O14: Sasak | P14: TIDAK/BELUM SEKOLAH | R14: Belum / Tidak Bekerja
B15: 3 | C15: 520101 0503083193 | D15: 8 | E15: Suparlan | F15: KK | G15: 520101 3112810124 | H15: L | I15: Kawin | J15: DASAN GERES TIMUR | K15: 29220 | L15: 1979 | M15: =2019-L15 -> 40 | N15: Islam | O15: Sasak | P15: TAMAT SD/SEDERAJAT | R15: Buruh Harian Lepas
D16: 9 | E16: Murini | F16: Istri | G16: 520101 7112900119 | H16: P | I16: Kawin | J16: TEMPOS | K16: 30681 | L16: 1983 | M16: =2019-L16 -> 36 | N16: Islam | O16: Sasak | P16: TAMAT SD/SEDERAJAT | R16: Petani / Pekebun
D17: 10 | E17: Rizal | F17: Anak | G17: 520101 0305040005 | H17: L | I17: Belum kawin | J17: DASAN GERES TIMUR | K17: 38110 | L17: 2004 | M17: =2019-L17 -> 15 | N17: Islam | O17: Sasak | P17: BELUM TAMAT SD/SEDERAJAT | R17: Pelajar / Mahasiswa
D18: 11 | E18: Riska Dewi Yanti | F18: Anak | G18: 520101 5807060001 | H18: P | I18: Belum kawin | J18: DASAN GERES TIMUR | K18: 38815 | L18: 2006 | M18: =2019-L18 -> 13 | N18: Islam | O18: Sasak | P18: TIDAK/BELUM SEKOLAH | R18: Belum / Tidak Bekerja
D19: 12 | E19: Rizka | F19: Anak | G19: 520101 5907080002 | H19: P | I19: Belum kawin | J19: DASAN GERES TIMUR | K19: 39546 | L19: 2008 | M19: =2019-L19 -> 11 | N19: Islam | O19: Sasak | P19: TIDAK/BELUM SEKOLAH | R19: Belum / Tidak Bekerja
D20: 13 | E20: Johari | F20: Anak | G20: 520101 0804100001 | H20: L | I20: Belum kawin | J20: DASAN GERES TIMUR | K20: 40377 | L20: 2010 | M20: =2019-L20 -> 9 | N20: Islam | O20: Sasak | P20: TIDAK/BELUM SEKOLAH | R20: Belum / Tidak Bekerja
B21: 4 | C21: 520101 2206100033 | D21: 14 | E21: Samsiah | F21: KK | G21: 520101 3112780058 | H21: L | I21: Kawin | J21: DASAN GERES TENGAH | K21: 28855 | L21: 1978 | M21: =2019-L21 -> 41 | N21: Islam | O21: Sasak | P21: SLTA/SEDERAJAT | R21: Wiraswasta
D22: 15 | E22: Samsuriyah | F22: Istri | G22: 520101 7112790084 | H22: P | I22: Kawin | J22: TEMPOS | K22: 29220 | L22: 1979 | M22: =2019-L22 -> 40 | N22: Islam | O22: Sasak | P22: SLTA/SEDERAJAT | R22: Wiraswasta
D23: 16 | E23: Moh. Sahril | F23: Anak | G23: 520101 0505040001 | H23: L | I23: Belum kawin | J23: DASAN GERES TIMUR | K23: 38112 | L23: 2004 | M23: =2019-L23 -> 15 | N23: Islam | O23: Sasak | P23: TIDAK/BELUM SEKOLAH | R23: Belum / Tidak Bekerja
B24: 5 | C24: 520101 0503083158 | D24: 17 | E24: Samsudin | F24: KK | G24: 520101 0107800469 | H24: L | I24: Kawin | J24: DASAN GERES | K24: 27759 | L24: 1975 | M24: =2019-L24 -> 44 | N24: Islam | O24: Sasak | P24: BELUM TAMAT SD/SEDERAJAT | R24: Buruh Harian Lepas
D25: 18 | E25: Sarinah | F25: Istri | G25: 520101 7112820037 | H25: P | I25: Kawin | J25: DASAN GERES | K25: 30316 | L25: 1982 | M25: =2019-L25 -> 37 | N25: Islam | O25: Sasak | P25: TAMAT SD/SEDERAJAT | R25: Mengurus Rumah Tangga
D26: 19 | E26: Jahratul Sita | F26: Anak | G26: 520101 4108060003 | H26: P | I26: Belum kawin | J26: DASAN GERES | K26: 39661 | L26: 2008 | M26: =2019-L26 -> 11 | N26: Islam | O26: Sasak | P26: TAMAT SD/SEDERAJAT | R26: Pelajar / Mahasiswa
D27: 20 | E27: Muhamad Jainul Ilmi | F27: Anak | G27: 520101 1210100002 | H27: L | I27: Belum kawin | J27: DASAN GERES | K27: 40463 | L27: 2010 | M27: =2019-L27 -> 9 | N27: Islam | O27: Sasak | P27: TIDAK/BELUM SEKOLAH | R27: Belum / Tidak Bekerja
D28: 21 | E28: Muzakki | F28: Anak | G28: 520101 2803130002 | H28: L | I28: Belum kawin | J28: DASAN GERES | K28: 41361 | L28: 2013 | M28: =2019-L28 -> 6 | N28: Islam | O28: Sasak | P28: TIDAK/BELUM SEKOLAH | R28: Belum / Tidak Bekerja
B29: 6 | C29: 520101 0703110151 | D29: 22 | E29: Amenah | F29: KK | G29: 520101 0107690395 | H29: P | I29: Cerai Hidup | J29: DASAN GERES TIMUR | K29: 19359 | L29: 1952 | M29: =2019-L29 -> 67 | N29: Islam | O29: Sasak | P29: TIDAK/BELUM SEKOLAH | R29: Buruh Tani / Perkebunan
D30: 23 | E30: Rusnan | F30: Anak | G30: 520101 1209900001 | H30: L | I30: Belum kawin | J30: DASAN GERES TIMUR | K30: 33128 | L30: 1990 | M30: =2019-L30 -> 29 | N30: Islam | O30: Sasak | P30: SLTP/SEDERAJAT | R30: Wiraswasta
D31: 24 | E31: Siti Soleha | F31: Anak | G31: 520101 4101940004 | H31: P | I31: Belum kawin | J31: DASAN GERES TIMUR | K31: 34335 | L31: 1994 | M31: =2019-L31 -> 25 | N31: Islam | O31: Sasak | P31: SLTP/SEDERAJAT | R31: Wiraswasta
B32: 7 | C32: 520101 2302110013 | D32: 25 | E32: Sahar | F32: KK | G32: 520101 1908750004 | H32: L | I32: Kawin | J32: DASAN GERES TENGAH | K32: 27625 | L32: 1975 | M32: =2019-L32 -> 44 | N32: Islam | O32: Sasak | P32: TAMAT SD/SEDERAJAT | R32: Wiraswasta
D33: 26 | E33: Maemunah | F33: Istri | G33: 520101 6911780001 | H33: P | I33: Kawin | J33: DASAN GERES TENGAH | K33: 28823 | L33: 1978 | M33: =2019-L33 -> 41 | N33: Islam | O33: Sasak | P33: TAMAT SD/SEDERAJAT | R33: Mengurus Rumah Tangga
D34: 27 | E34: Muhamad Sahid Mahmud | F34: Anak | G34: 520101 1908980001 | H34: L | I34: Belum kawin | J34: DASAN GERES TENGAH | K34: 36016 | L34: 1998 | M34: =2019-L34 -> 21 | N34: Islam | O34: Sasak | P34: SLTA/SEDERAJAT | R34: Pelajar / Mahasiswa
D35: 28 | E35: M. Harpujarrin | F35: Anak | G35: 520101 2904010002 | H35: L | I35: Belum kawin | J35: DASAN GERES | K35: 37010 | L35: 2001 | M35: =2019-L35 -> 18 | N35: Islam | O35: Sasak | P35: TAMAT SD/SEDERAJAT | R35: Pelajar / Mahasiswa
D36: 29 | E36: Unduan Lestari | F36: Anak | G36: 520101 4511080002 | H36: P | I36: Belum kawin | J36: DASAN GERES | K36: 39757 | L36: 2008 | M36: =2019-L36 -> 11 | N36: Islam | O36: Sasak | P36: BELUM TAMAT SD/SEDERAJAT | R36: Pelajar / Mahasiswa
D37: 30 | E37: Muhammad Panduan Aguna | F37: Anak | G37: 520101 2008140004 | H37: L | I37: Belum kawin | J37: DASAN GERES | K37: 41871 | L37: 2014 | M37: =2019-L37 -> 5 | N37: Islam | O37: Sasak | P37: TIDAK/BELUM SEKOLAH | R37: Belum / Tidak Bekerja
B38: 8 | C38: 520101 0703110209 | D38: 31 | E38: Ramli | F38: KK | G38: 520101 0201910003 | H38: L | I38: Kawin | J38: DASAN GERES TIMUR | K38: 33240 | L38: 1991 | M38: =2019-L38 -> 28 | N38: Islam | O38: Sasak | P38: SLTP/SEDERAJAT | R38: Buruh Harian Lepas
D39: 32 | E39: Nurhayati | F39: Istri | G39: 520101 7001930001 | H39: P | I39: Kawin | J39: DASAN GERES TIMUR | K39: 33614 | L39: 1992 | M39: =2019-L39 -> 27 | N39: Islam | O39: Sasak | P39: TAMAT SD/SEDERAJAT | R39: Mengurus Rumah Tangga
D40: 33 | E40: Muammad Ali Januardi | F40: Anak | G40: 520101 0901110002 | H40: L | I40: Belum kawin | J40: DASAN GERES | K40: 40552 | L40: 2011 | M40: =2019-L40 -> 8 | N40: Islam | O40: Sasak | P40: TIDAK/BELUM SEKOLAH | R40: Belum / Tidak Bekerja
B41: 9 | C41: 520101 0503083118 | D41: 34 | E41: Naharudin | F41: KK | G41: 520101 0107610121 | H41: L | I41: Kawin | J41: DASAN GERES | K41: 22463 | L41: 1961 | M41: =2019-L41 -> 58 | N41: Islam | O41: Sasak | P41: TAMAT SD/SEDERAJAT | R41: Buruh Harian Lepas
...

Sheet RT 02
B1: DATA INDUK PENDUDUK KELURAHAN DASAN GERES
B2: TAHUN 2019
B3: LINGKUNGAN DASAN GERES TIMUR
B4: RT 02
B5: No | C5: Nomor KK | D5: Jumlah Jiwa | E5: Nama Lengkap/ Panggilan | F5: Kedudukan dalam Keluarga | G5: NIK | H5: Jenis Kelamin (L/P) | I5: Status Perkawinan | J5: Lahir | M5: Usia | N5: Agama | O5: Etnis | P5: Pendidikan Terakhir | Q5: Jurusan | R5: Pekerjaan
J6: Tempat | K6: Tanggal | L6: Tahun
B8: 1 | C8: 520101 0503083160 | D8: 1 | E8: Redwan | F8: KK | G8: 520101 0107680339 | H8: L | I8: Kawin | J8: DASAN GERES | K8: 25020 | L8: 1968 | M8: =2019-L8 -> 51 | N8: Islam | O8: Sasak | P8: SLTP/SEDERAJAT | R8: Petani / Pekebun
D9: 2 | E9: Almah | F9: Istri | G9: 520101 4107800366 | H9: P | I9: Kawin | J9: DASAN GERES | K9: 25750 | L9: 1970 | M9: =2019-L9 -> 49 | N9: Islam | O9: Sasak | P9: TIDAK/BLM SEKOLAH | R9: Mengurus Rumah Tangga
D10: 3 | E10: Sopian Hadi | F10: Anak | G10: 520101 0107970328 | H10: L | I10: Belum kawin | J10: DASAN GERES | K10: 35838 | L10: 1998 | M10: =2019-L10 -> 21 | N10: Islam | O10: Sasak | P10: SLTA/SEDERAJAT | R10: Pelajar / Mahasiswa
B11: 2 | C11: 520101 0503083165 | D11: 4 | E11: Satarudin | F11: KK | G11: 520101 010762065 | H11: L | I11: Kawin | J11: DASAN GERES TIMUR | K11: 22828 | L11: 1962 | M11: =2019-L11 -> 57 | N11: Islam | O11: Sasak | P11: TAMAT SD/SEDERAJAT | R11: Buruh Harian Lepas
D12: 5 | E12: Aremah | F12: Istri | G12: 520101 4107780495 | H12: L | I12: Kawin | J12: DASAN GERES TIMUR | K12: 28672 | L12: 1978 | M12: =2019-L12 -> 41 | N12: Islam | O12: Sasak | P12: BELUM TAMAT SD/SEDERAJAT | R12: Mengurus Rumah Tangga
D13: 6 | E13: Kartini | F13: Anak | G13: 520101 4187060220 | H13: P | I13: Belum kawin | J13: DASAN GERES TIMUR | K13: 35977 | L13: 1998 | M13: =2019-L13 -> 21 | N13: Islam | O13: Sasak | P13: SLTP/SEDERAJAT | R13: Pelajar / Mahasiswa
D14: 7 | E14: Roni Parlan | F14: Anak | G14: 520101 2108030002 | H14: L | I14: Belum kawin | J14: DASAN GERES TIMUR | K14: 37854 | L14: 2003 | M14: =2019-L14 -> 16 | N14: Islam | O14: Sasak | P14: BELUM TAMAT SD/SEDERAJAT | R14: Pelajar / Mahasiswa
D15: 8 | E15: Rina Safitri | F15: Anak | G15: 520101 4708060004 | H15: P | I15: Belum kawin | J15: DASAN GERES TIMUR | K15: 38936 | L15: 2006 | M15: =2019-L15 -> 13 | N15: Islam | O15: Sasak | P15: TIDAK/BLM SEKOLAH | R15: Belum / Tidak Bekerja
B16: 3 | C16: 520101 2608140011 | D16: 9 | E16: Hambali | F16: KK | G16: 520101 0107890418 | H16: L | I16: Kawin | J16: DASAN GERES | K16: 32228 | L16: 1988 | M16: =2019-L16 -> 31 | N16: Islam | O16: Sasak | P16: SLTA/SEDERAJAT | R16: Wiraswasta
D17: 10 | E17: Siti Zubaedah | F17: Anak | G17: 520101 7009900001 | H17: P | I17: Kawin | J17: SENTRAL SARI SULTENG | K17: 33146 | L17: 1990 | M17: =2019-L17 -> 29 | N17: Islam | O17: Sasak | P17: SLTA/SEDERAJAT | R17: Mengurus Rumah Tangga
D18: 11 | E18: Aulia Syafari | F18: Anak | G18: 520101 5712140001 | H18: P | I18: Belum kawin | J18: DASAN GERES | K18: 41990 | L18: 2014 | M18: =2019-L18 -> 5 | N18: Islam | O18: Sasak | P18: TIDAK/BLM SEKOLAH | R18: Belum / Tidak Bekerja
D19: 12 | E19: Gibran Tabrani | F19: Anak | G19: 520101 2007160002 | H19: L | I19: Belum kawin | J19: DASAN GERES | K19: 42571 | L19: 2016 | M19: =2019-L19 -> 3 | N19: Islam | O19: Sasak | P19: TIDAK/BLM SEKOLAH | R19: Belum / Tidak Bekerja
B20: 4 | C20: 520101 0501100022 | D20: 13 | E20: Hamdi Afandi Putra | F20: KK | G20: 520101 1808740001 | H20: L | I20: Kawin | J20: DASAN GERES TIMUR | K20: 27269 | L20: 1974 | M20: =2019-L20 -> 45 | N20: Islam | O20: Sasak | P20: SLTP/SEDERAJAT | R20: Karyawan Swasta
D21: 14 | E21: Nursehan Husen | F21: Istri | G21: 520101 6201780001 | H21: P | I21: Kawin | J21: KEDIRI | K21: 28512 | L21: 1978 | M21: =2019-L21 -> 41 | N21: Islam | O21: Sasak | P21: SLTP/SEDERAJAT | R21: Mengurus Rumah Tangga
D22: 15 | E22: Aditya Pranata | F22: Anak | G22: 520101 2007010003 | H22: L | I22: Belum kawin | J22: DASAN GERES TIMUR | K22: 37092 | L22: 2001 | M22: =2019-L22 -> 18 | N22: Islam | O22: Sasak | P22: BELUM TAMAT SD/SEDERAJAT | R22: Pelajar / Mahasiswa
D23: 16 | E23: Wariq Prihatin Nupus | F23: Anak | G23: 520101 6611100001 | H23: P | I23: Belum kawin | J23: DASAN GERES | K23: 40508 | L23: 2010 | M23: =2019-L23 -> 9 | N23: Islam | O23: Sasak | P23: TIDAK/BLM SEKOLAH | R23: Belum / Tidak Bekerja
B24: 5 | D24: 17 | E24: Suriah | F24: KK | H24: P | I24: Belum kawin | K24: 27260 | L24: 1974 | M24: =2019-L24 -> 45 | N24: Islam
D25: 18 | E25: Mukinah | F25: Lain-lain | H25: P | I25: Belum kawin | K25: 27164 | L25: 1974 | M25: =2019-L25 -> 45 | N25: Islam
D26: 19 | E26: H.Tawahid | F26: Lain-lain | H26: L | I26: Kawin | K26: 15706 | L26: 1942 | M26: =2019-L26 -> 77 | N26: Islam
B27: 6 | C27: 520101 0503083168 | D27: 20 | E27: Amrullah | F27: Anak | G27: 520101 2007920008 | H27: L | I27: Belum kawin | J27: DASAN GERES | K27: 33439 | L27: 1991 | M27: =2019-L27 -> 28 | N27: Islam | O27: Sasak | P27: SLTA/SEDERAJAT | R27: Belum / Tidak Bekerja
D28: 21 | E28: Anisa Lestari | F28: Anak | G28: 520101 4107020043 | H28: P | I28: Belum kawin | J28: DASAN GERES | K28: 37438 | L28: 2002 | M28: =2019-L28 -> 17 | N28: Islam | O28: Sasak | P28: BELUM TAMAT SD/SEDERAJAT | R28: Pelajar / Mahasiswa
B29: 7 | C29: 520101 1810160013 | D29: 22 | E29: Maryam | F29: KK | G29: 520101 4107691002 | H29: P | I29: Cerai Mati | J29: DASAN GERES TENGAH | K29: 25385 | L29: 1969 | M29: =2019-L29 -> 50 | N29: Islam | O29: Sasak | P29: TIDAK/BLM SEKOLAH | R29: Petani / Pekebun
D30: 23 | E30: Muhamad Rifa'i | F30: Anak | G30: 520101 0107870120 | H30: L | I30: Belum kawin | J30: DASAN GERES TIMUR | K30: 33670 | L30: 1992 | M30: =2019-L30 -> 27 | N30: Islam | O30: Sasak | P30: TAMAT SD/SEDERAJAT | R30: Wiraswasta
D31: 24 | E31: Muhamad Patho Yasin | F31: Anak | G31: 520101 0107880020 | H31: L | I31: Belum kawin | J31: DASAN GERES TENGAH | K31: 35795 | L31: 1997 | M31: =2019-L31 -> 22 | N31: Islam | O31: Sasak | P31: SLTP/SEDERAJAT | R31: Buruh Harian Lepas
D32: 25 | E32: Yulia Ningsih | F32: Anak | G32: 520101 6308051001 | H32: P | I32: Belum kawin | J32: DASAN GERES TENGAH | K32: 38587 | L32: 2005 | M32: =2019-L32 -> 14 | N32: Islam | O32: Sasak | P32: TAMAT SD/SEDERAJAT | R32: Pelajar / Mahasiswa
D33: 26 | E33: Nurul azizah | F33: Anak | G33: 520101 4106121001 | H33: P | I33: Belum kawin | J33: DASAN GERES TENGAH | K33: 41061 | L33: 2012 | M33: =2019-L33 -> 7 | N33: Islam | O33: Sasak | P33: TIDAK/BLM SEKOLAH | R33: Belum / Tidak Bekerja
B34: 8 | C34: 520101 0703110145 | D34: 27 | E34: Saharudin | F34: KK | G34: 520101 0112870002 | H34: L | I34: Kawin | J34: DASAN GERES | K34: 28825 | L34: 1978 | M34: =2019-L34 -> 41 | N34: Islam | O34: Sasak | P34: SLTA/SEDERAJAT | R34: Wiraswasta
D35: 28 | E35: Kamariah | F35: Istri | G35: 520101 6402900002 | H35: P | I35: Kawin | J35: WAJE GESENG | K35: 32928 | L35: 1990 | M35: =2019-L35 -> 29 | N35: Islam | O35: Sasak | P35: SLTP/SEDERAJAT | R35: Mengurus Rumah Tangga
D36: 29 | E36: Nayma Putri Hartanti | F36: Anak | G36: 520101 6208090001 | H36: L | I36: Belum kawin | J36: DASAN GERES | K36: 40047 | L36: 2009 | M36: =2019-L36 -> 10 | N36: Islam | O36: Sasak | P36: BELUM TAMAT SD/SEDERAJAT | R36: Pelajar /Mahasiswa
D37: 30 | E37: Aldin Hardiansyah | F37: Anak | G37: 520101 0211160005 | H37: P | I37: Belum kawin | J37: DASAN GERES | K37: 42676 | L37: 2016 | M37: =2019-L37 -> 3 | N37: Islam | O37: Sasak | P37: TIDAK/BLM SEKOLAH | R37: Belum / Tidak Bekerja
B38: 9 | D38: 31 | E38: Mujemal | F38: KK | G38: 520101 3112840189 | H38: L | I38: Kawin | K38: 31047 | L38: 1984 | M38: =2019-L38 -> 35 | N38: Islam
D39: 32 | E39: Masoah | F39: Istri | G39: 520101 7112780195 | H39: P | I39: Kawin | K39: 28855 | L39: 1978 | M39: =2019-L39 -> 41 | N39: Islam
D40: 33 | E40: Muhamad Marzuki | F40: Anak | G40: 520101 1610120002 | H40: L | I40: Belum kawin | K40: 41200 | L40: 2012 | M40: =2019-L40 -> 7 | N40: Islam
B41: 10 | C41: 520101 0804150019 | D41: 34 | E41: Rukiyah | F41: KK | G41: 520101 7112450025 | H41: P | I41: Cerai Mati | J41: DASAN GERES TIMUR | K41: 16802 | L41: 1945 | M41: =2019-L41 -> 74 | N41: Islam | O41: Sasak | P41: TIDAK/BLM SEKOLAH | R41: Belum / Tidak Bekerja
...

Sheet RT 03
B1: DATA INDUK PENDUDUK KELURAHAN DASAN GERES
B2: TAHUN 2019
B3: LINGKUNGAN DASAN GERES TIMUR
B4: RT 03
B5: No | C5: Nomor KK | D5: Jumlah Jiwa | E5: Nama Lengkap/ Panggilan | F5: Kedudukan dalam Keluarga | G5: NIK | H5: Jenis Kelamin (L/P) | I5: Status Perkawinan | J5: Lahir | M5: Usia | N5: Agama | O5: Etnis | P5: Pendidikan Terakhir | Q5: Jurusan | R5: Pekerjaan
J6: Tempat | K6: Tanggal | L6: Tahun
B8: 1 | C8: 520101 0503082031 | D8: 1 | E8: Rusli | F8: KK | G8: 520101 0107750517 | H8: L | I8: Kawin | J8: Dasan Geres | K8: 27576 | L8: 1975 | M8: =2019-L8 -> 44 | N8: Islam | O8: Sasak | P8: Tamat SD/Sederajat | R8: Buruh Tani/Pekebun
D9: 2 | E9: Hikmah | F9: Istri | G9: 520101 4309780001 | H9: P | I9: Kawin | J9: Peturunan Puntik | K9: 28736 | L9: 1978 | M9: =2019-L9 -> 41 | N9: Islam | O9: Sasak | P9: Tamat SD/Sederajat | R9: Mengurus Rumah Tangga
D10: 3 | E10: Mariatun | F10: Anak | G10: 520101 5911980001 | H10: P | I10: Belum kawin | J10: Dasan Geres | K10: 36118 | L10: 1998 | M10: 21 | N10: Islam | O10: Sasak | P10: SLTP/Sederajat | R10: Pelajar/Mahasiswa
D11: 4 | E11: Siti Zora Maratu Soleha | F11: Anak | G11: 510101 5208090004 | H11: P | I11: Belum kawin | J11: Dasan Geres | K11: 40078 | L11: 2009 | M11: =2019-L11 -> 10 | N11: Islam | O11: Sasak | P11: Tidak belum sekolah | R11: Belum/Tidak Bekerja
B12: 2 | C12: 520101 2206110013 | D12: 5 | E12: Muhadi | F12: KK | G12: 520101 3001810001 | H12: L | I12: Kawin | J12: Dasan Geres | K12: 29920 | L12: 1981 | M12: =2019-L12 -> 38 | N12: Islam | O12: Sasak | P12: Tamat SD/Sederajat | R12: Wiraswasta
D13: 6 | E13: Rabitah | F13: Istri | G13: 520101 7112840052 | H13: P | I13: Kawin | J13: Beleke | K13: 31047 | L13: 1984 | M13: =2019-L13 -> 35 | N13: Islam | O13: Sasak | P13: Tamat SD/Sederajat | R13: Wiraswasta
D14: 7 | E14: Muhamad Haekal Ramadhan | F14: Anak | G14: 520101 0408100001 | H14: L | I14: Belum kawin | J14: Dasan Geres | K14: 40394 | L14: 2010 | M14: =2019-L14 -> 9 | N14: Islam | O14: Sasak | P14: Tidak belum sekolah | R14: Belum/Tidak Bekerja
D15: 8 | E15: Adila rabiatun zahra | F15: Anak | H15: P
B16: 3 | C16: 520101 0703110127 | D16: 9 | E16: Awaludin | F16: KK | G16: 520101 3112700062 | H16: L | I16: Kawin | J16: Dasan Geres Tengah | K16: 25933 | L16: 1970 | M16: =2019-L16 -> 49 | N16: Islam | O16: Sasak | P16: SLTP/Sederajat | R16: Petani/Pekebun
D17: 10 | E17: Muriah | F17: Istri | G17: 520101 7112720012 | H17: P | I17: Kawin | J17: Dasan Geres Tengah | K17: 26664 | L17: 1972 | M17: =2019-L17 -> 47 | N17: Islam | O17: Sasak | P17: SD/Sederajat | R17: Petani/Pekebun
D18: 11 | E18: Indrawati | F18: Anak | G18: 520101 5001000003 | H18: P | I18: Belum kawin | J18: Dasan Geres Tengah | K18: 36535 | L18: 2000 | M18: =2019-L18 -> 19 | N18: Islam | O18: Sasak | P18: Belum tamat SD/Sederajat | R18: Pelajar/Mahasiswa
D19: 12 | E19: Taufik Hidayat | F19: Anak | G19: 520101 2307040002 | H19: L | I19: Belum kawin | J19: Dasan Geres Tengah | K19: 38191 | L19: 2004 | M19: =2019-L19 -> 15 | N19: Islam | O19: Sasak | P19: Belum tamat SD/Sederajat | R19: Pelajar/Mahasiswa
B20: 4 | D20: 13 | E20: Suahrdi | F20: KK | G20: 520101 1107870004 | H20: L | I20: Kawin | K20: 31969 | L20: 1987 | M20: =2019-L20 -> 32 | N20: Islam | P20: SLTP/MTSN
D21: 14 | E21: Irawati | F21: Istri | G21: 520101 3103120001 | H21: P | I21: Kawin | K21: 33826 | L21: 1992 | M21: =2019-L21 -> 27 | N21: Islam | P21: SLTA/MA
D22: 15 | E22: Arfa Ardi Nata | F22: Anak | G22: 520101 3103120001 | H22: L | I22: Belum kawin | K22: 40999 | L22: 2012 | M22: =2019-L22 -> 7 | N22: Islam | P22: -
B23: 5 | C23: 520101 0503083014 | D23: 16 | E23: Ahmad | F23: KK | G23: 520101 0107550211 | H23: L | I23: Kawin | J23: Dasan Geres | K23: 20271 | L23: 1955 | M23: =2019-L23 -> 64 | N23: Islam | O23: Sasak | P23: Tidak/Belun Sekolah | R23: Buruh Tani/Perkebun
D24: 17 | E24: Sitiah | F24: Istri | G24: 520101 4107500247 | H24: P | I24: Kawin | J24: Dasan Geres | K24: 18445 | L24: 1950 | M24: =2019-L24 -> 69 | N24: Islam | O24: Sasak | P24: Tidak/Belun Sekolah | R24: Buruh Tani/Perkebun
D25: 18 | E25: Jaknah | F25: Anak | G25: 520101 4107860349 | H25: P | I25: Belum kawin | J25: Dasan Geres | K25: 31594 | L25: 1986 | M25: 33 | N25: Islam | O25: Sasak | P25: SLTP/Sederajat | R25: Belum/Tidak Bekerja
D26: 19 | E26: Rahman | F26: Anak | G26: 520101 702870001 | H26: L | I26: Belum kawin | J26: Dasan Geres | K26: 31815 | L26: 1987 | M26: =2019-L26 -> 32 | N26: Islam | O26: Sasak | P26: SLTP/Sederajat | R26: Wiraswasta
B27: 6 | C27: 520101 1406080001 | D27: 20 | E27: Sahnun | F27: KK | G27: 520101 0107550212 | H27: L | I27: Kawin | J27: Dasan Geres Tengah | K27: 20089 | L27: 1954 | M27: =2019-L27 -> 65 | N27: Islam | O27: Sasak | P27: Tamat SD/Sederajat | R27: Petani / Pekebun
D28: 21 | E28: Alemah | F28: Istri | G28: 520101 4107570538 | H28: P | I28: Kawin | J28: Dasan Geres Tengah | K28: 23742 | L28: 1964 | M28: =2019-L28 -> 55 | N28: Islam | O28: Sasak | P28: Tamat SD/Sederajat | R28: Petani / Pekebun
B29: 7 | D29: 22 | E29: Hernan | F29: KK | G29: 520317 2504810000 | H29: L | I29: Kawin | K29: 29701 | L29: 1981 | M29: =2019-L29 -> 38 | N29: Islam | P29: -
D30: 23 | E30: Almah | F30: Istri | G30: 520317 7112870240 | H30: P | I30: Kawin | K30: 32142 | L30: 1987 | M30: =2019-L30 -> 32 | N30: Islam | P30: -
D31: 24 | E31: Maeka Salmah Airani | F31: Anak | H31: P | I31: Belum kawin | K31: 40689 | L31: 2011 | M31: =2019-L31 -> 8 | N31: Islam | P31: -
B32: 8 | C32: 520101 0503083071 | D32: 25 | E32: Muhur Zohri | F32: KK | G32: 520101 0107690089 | H32: L | I32: Kawin | J32: Dasan Geres Timur | K32: 25385 | L32: 1969 | M32: =2019-L32 -> 50 | N32: Islam | O32: Sasak | P32: Tamat SD/Sederajat | R32: Wiraswasta
D33: 26 | E33: Sakmah | F33: Istri | G33: 520101 4107790321 | H33: P | I33: Kawin | J33: DASAN GERES | K33: 29037 | L33: 1979 | M33: =2019-L33 -> 40 | N33: Islam | O33: Sasak | P33: Tamat SD/Sederajat | R33: Petani / Pekebun
D34: 27 | E34: Selamet Hadi | F34: Anak | G34: 520101 1012940122 | H34: L | I34: Belum kawin | J34: DASAN GERES | K34: 34678 | L34: 1994 | M34: =2019-L34 -> 25 | N34: Islam | O34: Sasak | P34: SLTP/Sederajat | R34: Pelajar / Mahasiswa
D35: 28 | E35: Anisa | F35: Anak | G35: 520101 4107040092 | H35: P | I35: Belum kawin | J35: Dasan Geres Timur | K35: 38169 | L35: 2004 | M35: =2019-L35 -> 15 | N35: Islam | O35: Sasak | P35: Tidak/Belun Sekolah | R35: Belum/Tidak Bekerja
B36: 9 | C36: 520101 0503083089 | D36: 29 | E36: Sahugi | F36: KK | G36: 520101 0107770302 | H36: L | I36: Kawin | J36: Dasan Geres Tengah | K36: 27890 | L36: 1976 | M36: =2019-L36 -> 43 | N36: Islam | O36: Sasak | P36: Tamat SD/Sederajat | R36: Wiraswasta
D37: 30 | E37: Susilawati | F37: Isri | G37: 520101 7112850041 | H37: P | I37: Kawin | J37: Berambang | K37: 31412 | L37: 1985 | M37: =2019-L37 -> 34 | N37: Islam | O37: Sasak | P37: Tamat SD/Sederajat | R37: Mengurus Rumah Tangga
D38: 31 | E38: Herwin Sunardi | F38: Anak | G38: 520101 0107960335 | H38: L | I38: Belum kawin | J38: Dasan Geres Tengah | K38: 35247 | L38: 1996 | M38: =2019-L38 -> 23 | N38: Islam | O38: Sasak | P38: SLTA/Sederajat | R38: Pelajar/Mahasiswa
D39: 32 | E39: M. Sandika Yusup | F39: Anak | G39: 520101 0510040001 | H39: L | I39: Belum kawin | J39: Dasan Geres Tengah | K39: 38265 | L39: 2004 | M39: =2019-L39 -> 15 | N39: Islam | O39: Sasak | P39: Belum tamat SD/Sederajat | R39: Pelajar/Mahasiswa
D40: 33 | E40: Kiki Nabila Safiri | F40: Anak | G40: 520101 6706100001 | H40: P | I40: Belum kawin | J40: Dasan Geres Tengah | K40: 40356 | L40: 2010 | M40: 9 | N40: Islam | O40: Sasak | P40: Tidak/Belun Sekolah | R40: Belum/Tidak Bekerja
D41: 34 | E41: Mohammad Faisal | F41: Anak | G41: 520101 1505120002 | H41: L | I41: Belum kawin | J41: Dasan Geres | K41: 41044 | L41: 2012 | M41: =2019-L41 -> 7 | N41: Islam | O41: Sasak | P41: - | R41: Belum/Tidak Bekerja
...

Sheet RT 04
B1: DATA INDUK PENDUDUK KELURAHAN DASAN GERES
B2: TAHUN 2019
B3: LINGKUNGAN DASAN GERES TIMUR
B4: RT 04
B5: No | C5: Nomor KK | D5: Jumlah Jiwa | E5: Nama Lengkap/ Panggilan | F5: Kedudukan dalam Keluarga | G5: NIK | H5: Jenis Kelamin (L/P) | I5: Status Perkawinan | J5: Lahir | M5: Usia | N5: Agama | O5: Etnis | P5: Pendidikan Terakhir | Q5: Jurusan | R5: Pekerjaan
J6: Tempat | K6: Tanggal | L6: Tahun
B8: 1 | D8: 1 | E8: Jumenah | F8: KK | G8: 520101 1005850007 | H8: L | I8: Kawin | K8: 30446 | L8: 1983 | M8: =2019-L8 -> 36 | N8: Islam | P8: PT/Akademik
D9: 2 | E9: Nikmah | F9: Istri | G9: 520101 6512850002 | H9: P | I9: Kawin | K9: 31404 | L9: 1985 | M9: =2019-L9 -> 34 | N9: Islam | P9: PT/Akademi
D10: 3 | E10: Maulana Anwar Habib | F10: Anak | G10: 520101 2302110001 | H10: L | I10: Belum kawin | K10: 40597 | L10: 2011 | M10: =2019-L10 -> 8 | N10: Islam | P10: -
B11: 2 | C11: 520101 0703110106 | D11: 4 | E11: Burhanudin | F11: KK | G11: 520101 2704830003 | H11: L | I11: Kawin | J11: Dasan Geres Tengah | K11: 30433 | L11: 1983 | M11: =2019-L11 -> 36 | N11: Islam | O11: Sasak | P11: SLTA/Sederajat | R11: Wiraswasta
D12: 5 | E12: Siti Maryam | F12: Istri | G12: 520101 4403890002 | H12: P | I12: Kawin | J12: Dasan Geres Tengah | K12: 32571 | L12: 1989 | M12: =2019-L12 -> 30 | N12: Islam | O12: Sasak | P12: SLTA/Sederajat | R12: Wiraswasta
D13: 6 | E13: Sastia Yulia ningsih | F13: Anak | G13: 520101 5006090002 | H13: p | I13: Belum kawin | J13: Dasan Geres Tengah | K13: 39974 | L13: 2009 | M13: =2019-L13 -> 10 | N13: Islam | O13: Sasak | P13: Tidak/Belum Sekolah | R13: Belum/Tidak Sekolah
D14: 7 | E14: Amelia azzahra | F14: Anak | G14: 520101 5902160001 | H14: p | I14: Belum Kawin | J14: Dasan Geres | K14: 42419 | L14: 2016 | M14: =2019-L14 -> 3 | N14: Islam | O14: Sasak | P14: Tidak/Belum Sekolah | R14: Belum/Tidak Sekolah
B15: 3 | C15: 520101 3103160002 | D15: 8 | E15: Muhamad | F15: KK | G15: 520101 2005800006 | H15: L | I15: Kawin | J15: Dasan Geres | K15: 29361 | L15: 1980 | M15: =2019-L15 -> 39 | N15: Islam | O15: Sasak | P15: SLTA/Sederajat | R15: Wiraswasta
D16: 9 | E16: Suharnik | F16: Istri | G16: 520101 5104850003 | H16: P | I16: Kawin | J16: Puyung | K16: 31148 | L16: 1985 | M16: =2019-L16 -> 34 | N16: Islam | O16: Sasak | P16: Tamat SD/Sederajat | R16: Mengurus Rumah Tangga
D17: 10 | E17: Fitri Ramadani | F17: Anak | G17: 520101 5010070002 | H17: P | I17: Belum kawin | J17: Dasan Geres | K17: 39365 | L17: 2007 | M17: =2019-L17 -> 12 | N17: Islam | O17: Sasak | P17: Belum Tamat SD/Sederajat | R17: Pelajar/Mahasiswa
D18: 11 | E18: Rizki NikmatulLah | F18: Anak | G18: 520101 1208120006 | H18: L | I18: Belum kawin | J18: Dasan Geres | K18: 41133 | L18: 2012 | M18: =2019-L18 -> 7 | N18: Islam | O18: Sasak | P18: Tidak/Belum Sekolah | R18: Belum/Tidak Sekolah
B19: 4 | C19: 520101 0604180008 | D19: 12 | E19: Ibrahim | F19: KK | G19: 520101 0107900125 | H19: L | I19: Kawin | J19: Dasan Geres Tengah | K19: 31594 | L19: 1986 | M19: =2019-L19 -> 33 | N19: Islam | O19: Sasak | P19: SLTA/Sederajat | R19: Wiraswasta
D20: 13 | E20: Rodiah | F20: Istri | G20: 520113 7112860238 | H20: P | I20: Kawin | J20: Teluk Waru | K20: 31777 | L20: 1986 | M20: =2019-L20 -> 33 | N20: Islam | O20: Sasak | P20: SLTA/Sederajat | R20: Mengurus Rumah Tangga
B21: 5 | C21: 520101 0703110279 | D21: 14 | E21: Saiun | F21: KK | G21: 520101 0107750533 | H21: L | I21: Kawin | J21: Dasan Geres Timur | K21: 27576 | L21: 1975 | M21: =2019-L21 -> 44 | N21: Islam | O21: Sasak | P21: SLTA/Sederajat | R21: Wiraswasta
D22: 15 | E22: Junuriah | F22: Istri | G22: 520101 4107800726 | H22: P | I22: Kawin | J22: Dasan Geres Timur | K22: 29768 | L22: 1981 | M22: =2019-L22 -> 38 | N22: Islam | O22: Sasak | P22: Tamat SD/Sederajat | R22: Pedagang
D23: 16 | E23: Fujeriatun Oktariani | F23: Anak | G23: 520101 5910980001 | H23: P | I23: Belum Kawin | J23: Dasan Geres Timur | K23: 36087 | L23: 1998 | M23: =2019-L23 -> 21 | N23: Islam | O23: Sasak | P23: SLTP/Sederajat | R23: Pelajar/Mahasiswa
D24: 17 | E24: Dian Komala Dewi | F24: Anak | G24: 520101 6501050002 | H24: P | I24: Belum kawin | J24: Dasan Geres Timur | K24: 38011 | L24: 2004 | M24: =2019-L24 -> 15 | N24: Islam | O24: Sasak | P24: Belum Tamat SD/Sederajat | R24: Pelajar/Mahasiswa
D25: 18 | E25: Ummi Zakrah | F25: Anak | G25: 520101 5003100001 | H25: P | I25: Belum kawin | J25: Dasan Geres Timur | K25: 40247 | L25: 2010 | M25: =2019-L25 -> 9 | N25: Islam | O25: Sasak | P25: Tidak/Belum Sekolah | R25: Belum/Tidak Sekolah
B26: 6 | D26: 19 | E26: Murdan | F26: KK | H26: L | I26: Kawin | K26: 16500 | L26: 1945 | M26: =2019-L26 -> 74 | N26: Islam | P26: -
D27: 20 | E27: Budiyah | F27: Istri | H27: P | I27: Kawin | K27: 18272 | L27: 1950 | M27: =2019-L27 -> 69 | N27: Islam | P27: -
B28: 7 | D28: 21 | E28: Mulhakim | F28: KK | G28: 520101 0107940293 | H28: L | I28: kawin | K28: 33487 | L28: 1991 | M28: =2019-L28 -> 28 | N28: Islam | P28: SLTA/MA
D29: 22 | E29: Sri Wijayanti | F29: Istri | G29: 520101 1010140002 | H29: P | I29: Kawin | K29: 33000 | L29: 1990 | M29: =2019-L29 -> 29 | N29: Islam | P29: SLTA/MA
D30: 23 | E30: Muhamad Satria Hakim | F30: Anak | G30: 520101 1010140002 | H30: L | I30: Belum kawin | K30: 41913 | L30: 2014 | M30: =2019-L30 -> 5 | N30: Islam | P30: -
B31: 8 | C31: 520101 0503082023 | D31: 24 | E31: Riadi | F31: KK | G31: 520101 0107690390 | H31: L | I31: Kawin | J31: Dasab Geres Timur | K31: 25385 | L31: 1969 | M31: =2019-L31 -> 50 | N31: Islam | O31: Sasak | P31: Tamat SD/Sederajat | R31: Wiraswasta
D32: 25 | E32: Soleha | F32: Istri | G32: 520101 4107700603 | H32: P | I32: Kawin | J32: Tempos | K32: 25750 | L32: 1970 | M32: =2019-L32 -> 49 | N32: Islam | O32: Sasak | P32: SLTA/Sederajat | R32: Peternak
D33: 26 | E33: Manik Agung | F33: Anak | G33: 520101 0505950005 | H33: L | I33: Belum kawin | J33: Dasan Geres Timur | K33: 34824 | L33: 1995 | M33: =2019-L33 -> 24 | N33: Islam | O33: Sasak | P33: SLTA/Sederajat | R33: Wiraswasta
D34: 27 | E34: Firman Firdaus | F34: Anak | G34: 520101 1208000001 | H34: L | I34: Belum kawin | J34: Dasan Geres Timur | K34: 36750 | L34: 2000 | M34: =2019-L34 -> 19 | N34: Islam | O34: Sasak | P34: SLTA/Sederajat | R34: Pelajar/Mahasiswa
D35: 28 | E35: Wahyu Kalam | F35: Anak | G35: 520101 2511050002 | H35: L | I35: Belum kawin | J35: Dasan Geres | K35: 38589 | L35: 2005 | M35: =2019-L35 -> 14 | N35: Islam | O35: Sasak | P35: Belum Tamat SD/Sederajat | R35: Pelajar/Mahasiswa
B36: 9 | C36: 520101 0503085072 | D36: 29 | E36: Rejan | F36: KK | G36: 520101 0107580146 | H36: L | I36: Kawin | J36: Dasan Geres | K36: 21367 | L36: 1958 | M36: =2019-L36 -> 61 | N36: Islam | O36: Sasak | P36: Tidak/Belum Sekolah | R36: Buruh Harian Lepas
D37: 30 | E37: Idah | F37: Istri | G37: 520101 4107690229 | H37: P | I37: Kawin | J37: Dasan Geres | K37: 25385 | L37: 1969 | M37: =2019-L37 -> 50 | N37: Islam | O37: Sasak | P37: Tidak/Belum Sekolah | R37: Mengurus Rumah Tangga
B38: 10 | D38: 31 | E38: Hariadi | F38: KK | G38: 520101 2105840005 | H38: L | I38: kawin | K38: 30823 | L38: 1984 | M38: =2019-L38 -> 35 | N38: Islam | P38: SLTA/MA
D39: 32 | E39: Nurhaini | F39: Istri | G39: 520101 6102910001 | H39: P | I39: Kawin | K39: 33280 | L39: 1991 | M39: =2019-L39 -> 28 | N39: Islam | P39: SLTA/MA
D40: 33 | E40: M Yusuf Fazuri | F40: Anak | G40: 520101 1405130003 | H40: L | I40: Belum Kawin | K40: 41405 | L40: 2013 | M40: =2019-L40 -> 6 | N40: Islam | P40: -
B41: 11 | C41: 520101 0503085076 | D41: 34 | E41: Janoar | F41: KK | G41: 520101 1011770001 | H41: L | I41: Kawin Belum Tercatat | J41: Dasan Geres | K41: 28439 | L41: 1977 | M41: =2019-L41 -> 42 | N41: Islam | O41: Sasak | P41: Tamat SD/Sederajat | R41: Buruh Tani/Perkebunan
...

Sheet Sheet1
A1: 64 | C1: 210
A2: 42 | C2: 152
A3: 32 | C3: 115
A4: 61 | C4: 208
A5: =SUM(A1:A4) -> 199 | C5: =SUM(C1:C4) -> 685

Sheet Pindah Keluar
B2: No | C2: Nomor KK | D2: Jumlah Jiwa | E2: Nama Lengkap/panggilan | F2: Kedudukan dalam Keluarga | G2: NIK | H2: Jenis Kelamin (L/P) | I2: Status Perkawinan | J2: Lahir | M2: Usia | N2: Agama | O2: Etnis | P2: Pendidikan Terakhir | Q2: Jurusan | R2: Pekerjaan | S2: Cacat | U2: Ada/tidak
J3: Tempat | K3: Tanggal | L3: Tahun | S3: Mental | T3: Fisik | U3: KK | V3: KTP/KIA | W3: Buku Niikah
D5: 114 | E5: Siti Khadijah | F5: Anak | G5: 520101 5990496001 | H5: P | I5: Belum kawin | K5: 35174 | M5: =2019-L5 -> 2019 | N5: Islam | P5: SLTA/MA
D6: 104 | E6: Nia Wahyuni | F6: Lainnya | G6: 0 | H6: P | I6: Janda | K6: 34989 | M6: =2019-L6 -> 2019 | N6: Islam | P6: SD/MI
E7: Hasanah | F7: Anak | G7: 520101 4107840041 | H7: P | I7: Belum kawin | K7: 29586 | L7: 29586 | M7: =2019-L7 -> -27567 | N7: Islam | O7: Sasak | P7: SLTA/Sederajat
D8: 166 | E8: Mutini | F8: Anak | G8: 520101 4388899001 | H8: P | I8: Belum Kawin | K8: 36222 | M8: =2019-L8 -> 2019 | N8: Islam | P8: SLTP/MTSN
B9: rt 2 | D9: 132 | E9: Rozi Budiman | F9: Lainnya | G9: 0 | H9: L | I9: Belum kawin | K9: 35098 | M9: =2019-L9 -> 2019 | N9: Islam
B10: rt 2 | D10: 133 | E10: Roza komalasari | F10: Lainnya | G10: 0 | H10: P | I10: Belum kawin | K10: 35978 | M10: =2019-L10 -> 2019 | N10: Islam
B11: rt 4 | D11: 175 | E11: Maryani | F11: Anak | G11: 520101 4203890002 | H11: P | I11: Janda | K11: 32569 | M11: =2019-L11 -> 2019 | N11: Islam | P11: SLTP/MTSN
B12: rt 4 | D12: 177 | E12: Ade Zulhaaa | F12: Anak | G12: 520101 0208890002 | H12: L | I12: Belu kawin | K12: 35279 | M12: =2019-L12 -> 2019 | N12: Islam | P12: SLTP/MTSN
B13: rt 1 | D13: 116 | E13: Munawarah | F13: Anak | G13: 520101 4101880004 | H13: P | I13: Belum kawin | K13: 32143 | M13: =2019-L13 -> 2019 | N13: Islam | P13: SLTA/MA
B14: rt 3 | D14: 68 | E14: Herna Sari | F14: Anak | G14: 520101 200403338 | H14: P | I14: Belum kawin | K14: 33340 | M14: =2019-L14 -> 2019 | N14: Islam | P14: SLTP/MTSN
B15: rt 3 | D15: 69 | E15: Muhamad Indra | F15: Anak | G15: 520101 200403339 | H15: L | I15: Belum kawin | K15: 33800 | M15: =2019-L15 -> 2019 | N15: Islam | P15: SLTP/MTSN
B16: RT 2 | D16: 60 | E16: Ranni wati | F16: Anak | G16: 520101 4107870486 | H16: P | I16: Belum kawin | J16: DASAN GERES | K16: 33790 | L16: 1992 | M16: =2019-L16 -> 27 | N16: Islam | O16: Sasak

Sheet Meninggal
B2: No | C2: Nomor KK | D2: Jumlah Jiwa | E2: Nama Lengkap/panggilan | F2: Kedudukan dalam Keluarga | G2: NIK | H2: Jenis Kelamin (L/P) | I2: Status Perkawinan | J2: Lahir | M2: Usia | N2: Agama | O2: Etnis | P2: Pendidikan Terakhir | Q2: Jurusan | R2: Pekerjaan | S2: Cacat | U2: Ada/tidak
J3: Tempat | K3: Tanggal | L3: Tahun | S3: Mental | T3: Fisik | U3: KK | V3: KTP/KIA | W3: Buku Niikah
B5: rt 2 | D5: 28 | E5: Sarah | F5: Lainnya | G5: 0 | H5: P | I5: Belum kawin | K5: 14950 | M5: =2019-L5 -> 2019 | N5: Islam
B6: rt 2 | D6: 20 | E6: Mahnip | F6: KK | G6: 520101 4107700648 | H6: P | I6: Janda | K6: 29067 | M6: =2019-L6 -> 2019 | N6: Islam
B7: rt 2 | D7: 73 | E7: Badrun abidin | F7: KK | G7: 520101 1307650001 | H7: L | I7: Kawin | K7: 23936 | M7: =2019-L7 -> 2019 | N7: Islam
