Workbook

Sheet Rekap
B2: REKAP DATA PENDUDUK
B3: LINGKUNGAN DASAN GERES BARAT
B4: RT | C4: Jumlah Penduduk | E4: Total | F4: Jumlah KK | H4: Total | I4: Jumlah Duda / Janda | K4: Total | L4: Jumlah Lansia ( =>60 ) | N4: Total
C5: L | D5: P | F5: L | G5: P | I5: L | J5: P | L5: L | M5: P
B6: RT 1 | C6: =COUNTIF('RT 01'!$H$8:$H$332,"L") -> 160 | D6: =COUNTIF('RT 01'!$H$8:$H$332,"P") -> 164 | E6: =SUM(C6:D6) -> 324 | F6: =COUNTIFS('RT 01'!$F$8:$F$332,"KK",'RT 01'!$H$8:$H$332,"L") -> 76 | G6: =COUNTIFS('RT 01'!$F$8:$F$332,"KK",'RT 01'!$H$8:$H$332,"P") -> 14 | H6: =SUM(F6:G6) -> 90 | I6: =COUNTIFS('RT 01'!$I$8:$I$332,"Cerai Mati",'RT 01'!$H$8:$H$332,"L")+COUNTIFS('RT 01'!$I$8:$I$332,"Cerai Hidup",'RT 01'!$H$8:$H$332,"L")+COUNTIFS('RT 01'!$I$8:$I$332,"Duda",'RT 01'!$H$8:$H$332,"L") -> 4 | J6: =COUNTIFS('RT 01'!$I$8:$I$332,"Cerai Mati",'RT 01'!$H$8:$H$332,"P")+COUNTIFS('RT 01'!$I$8:$I$332,"Cerai Hidup",'RT 01'!$H$8:$H$332,"P")+COUNTIFS('RT 01'!$I$8:$I$332,"Janda",'RT 01'!$H$8:$H$332,"P") -> 15 | K6: =SUM(I6:J6) -> 19 | L6: 19 | M6: 13 | N6: =SUM(L6:M6) -> 32
B7: RT 2 | C7: =COUNTIF('RT 02'!$H$8:$H$188,"L") -> 90 | D7: =COUNTIF('RT 02'!$H$8:$H$188,"P") -> 91 | E7: =SUM(C7:D7) -> 181 | F7: =COUNTIFS('RT 02'!$F$8:$F$188,"KK",'RT 02'!$H$8:$H$188,"L") -> 42 | G7: =COUNTIFS('RT 02'!$F$8:$F$188,"KK",'RT 02'!$H$8:$H$188,"P") -> 11 | H7: =SUM(F7:G7) -> 53 | I7: =COUNTIFS('RT 02'!$I$8:$I$188,"Cerai Mati",'RT 02'!$H$8:$H$188,"L")+COUNTIFS('RT 02'!$I$8:$I$188,"Cerai Hidup",'RT 02'!$H$8:$H$188,"L")+COUNTIFS('RT 02'!$I$8:$I$188,"Duda",'RT 02'!$H$8:$H$188,"L") -> 2 | J7: =COUNTIFS('RT 02'!$I$8:$I$188,"Cerai Mati",'RT 02'!$H$8:$H$188,"P")+COUNTIFS('RT 02'!$I$8:$I$188,"Cerai Hidup",'RT 02'!$H$8:$H$188,"P")+COUNTIFS('RT 02'!$I$8:$I$188,"Janda",'RT 02'!$H$8:$H$188,"P") -> 11 | K7: =SUM(I7:J7) -> 13 | L7: 7 | M7: 11 | N7: =SUM(L7:M7) -> 18
B8: RT 3 | C8: =COUNTIF('RT 03'!$H$8:$H$252,"L") -> 110 | D8: =COUNTIF('RT 03'!$H$8:$H$252,"P") -> 135 | E8: =SUM(C8:D8) -> 245 | F8: =COUNTIFS('RT 03'!$F$8:$F$252,"KK",'RT 03'!$H$8:$H$252,"L") -> 45 | G8: =COUNTIFS('RT 03'!$F$8:$F$252,"KK",'RT 03'!$H$8:$H$252,"P") -> 20 | H8: =SUM(F8:G8) -> 65 | I8: =COUNTIFS('RT 03'!$I$8:$I$252,"Cerai Mati",'RT 03'!$H$8:$H$252,"L")+COUNTIFS('RT 03'!$I$8:$I$252,"Cerai Hidup",'RT 03'!$H$8:$H$252,"L")+COUNTIFS('RT 03'!$I$8:$I$252,"Duda",'RT 03'!$H$8:$H$252,"L") -> 3 | J8: =COUNTIFS('RT 03'!$I$8:$I$252,"Cerai Mati",'RT 03'!$H$8:$H$252,"P")+COUNTIFS('RT 03'!$I$8:$I$252,"Cerai Hidup",'RT 03'!$H$8:$H$252,"P")+COUNTIFS('RT 03'!$I$8:$I$252,"Janda",'RT 03'!$H$8:$H$252,"P") -> 24 | K8: =SUM(I8:J8) -> 27 | L8: 6 | M8: 13 | N8: =SUM(L8:M8) -> 19
B9: RT 4 | C9: =COUNTIF('RT 04'!$H$8:$H$223,"L") -> 112 | D9: =COUNTIF('RT 04'!$H$8:$H$223,"P") -> 104 | E9: =SUM(C9:D9) -> 216 | F9: =COUNTIFS('RT 04'!$F$8:$F$223,"KK",'RT 04'!$H$8:$H$223,"L") -> 49 | G9: =COUNTIFS('RT 04'!$F$8:$F$223,"KK",'RT 04'!$H$8:$H$223,"P") -> 13 | H9: =SUM(F9:G9) -> 62 | I9: =COUNTIFS('RT 04'!$I$8:$I$223,"Cerai Mati",'RT 04'!$H$8:$H$223,"L")+COUNTIFS('RT 04'!$I$8:$I$223,"Cerai Hidup",'RT 04'!$H$8:$H$223,"L")+COUNTIFS('RT 04'!$I$8:$I$223,"Duda",'RT 04'!$H$8:$H$223,"L") -> 1 | J9: =COUNTIFS('RT 04'!$I$8:$I$223,"Cerai Mati",'RT 04'!$H$8:$H$223,"P")+COUNTIFS('RT 04'!$I$8:$I$223,"Cerai Hidup",'RT 04'!$H$8:$H$223,"P")+COUNTIFS('RT 04'!$I$8:$I$223,"Janda",'RT 04'!$H$8:$H$223,"P") -> 12 | K9: =SUM(I9:J9) -> 13 | L9: 10 | M9: 14 | N9: =SUM(L9:M9) -> 24
B10: RT 5 | C10: =COUNTIF('RT 05'!$H$8:$H$152,"L") -> 77 | D10: =COUNTIF('RT 05'!$H$8:$H$152,"P") -> 68 | E10: =SUM(C10:D10) -> 145 | F10: =COUNTIFS('RT 05'!$F$8:$F$152,"KK",'RT 05'!$H$8:$H$152,"L") -> 30 | G10: =COUNTIFS('RT 05'!$F$8:$F$152,"KK",'RT 05'!$H$8:$H$152,"P") -> 10 | H10: =SUM(F10:G10) -> 40 | I10: =COUNTIFS('RT 05'!$I$8:$I$152,"Cerai Mati",'RT 05'!$H$8:$H$152,"L")+COUNTIFS('RT 05'!$I$8:$I$152,"Cerai Hidup",'RT 05'!$H$8:$H$152,"L")+COUNTIFS('RT 05'!$I$8:$I$152,"Duda",'RT 05'!$H$8:$H$152,"L") -> 1 | J10: =COUNTIFS('RT 05'!$I$8:$I$152,"Cerai Mati",'RT 05'!$H$8:$H$152,"P")+COUNTIFS('RT 05'!$I$8:$I$152,"Cerai Hidup",'RT 05'!$H$8:$H$152,"P")+COUNTIFS('RT 05'!$I$8:$I$152,"Janda",'RT 05'!$H$8:$H$152,"P") -> 11 | K10: =SUM(I10:J10) -> 12 | L10: 5 | M10: 7 | N10: =SUM(L10:M10) -> 12
B11: JUMLAH TOTAL | C11: =SUM(C6:C10) -> 549 | D11: =SUM(D6:D10) -> 562 | E11: =SUM(E6:E10) -> 1111 | F11: =SUM(F6:F10) -> 242 | G11: =SUM(G6:G10) -> 68 | H11: =SUM(H6:H10) -> 310 | I11: =SUM(I6:I10) -> 11 | J11: =SUM(J6:J10) -> 73 | ... N11: =SUM(N6:N10) -> 105
C15: Mengetahui
C16: Lurah Dasan Geres | K16: Kepala Lingkungan
C20: Hulaifi, S.H. | K20: Halawi
C21: NIP. 19841231 201101 1 023

Sheet RT 01
B1: DATA INDUK PENDUDUK KELURAHAN DASAN GERES
B2: TAHUN 2019
B3: LINGKUNGAN DASAN GERES BARAT
B4: RT 01
B5: No | C5: NO. KK | D5: Jumlah Jiwa | E5: Nama Lengkap/ Panggilan | F5: Kedudukan dalam Keluarga | G5: NIK | H5: Jenis Kelamin (L/P) | I5: Status Perkawinan | J5: Lahir | M5: Usia | N5: Agama | O5: Etnis | P5: Pendidikan Terakhir | Q5: Jurusan | R5: Pekerjaan
J6: Tempat | K6: Tanggal | L6: Tahun
B8: 1 | C8: 520101 0503082772 | D8: 1 | E8: Syamsudin | F8: KK | G8: 520101 0901650002 | H8: L | I8: Kawin | J8: sumbawa | K8: 23986 | L8: 1965 | M8: =2019-1965 -> 54 | N8: Islam | O8: Sasak | P8: SLTA/Sederajat | R8: Wiraswasta
D9: 2 | E9: Saerah | F9: Istri | G9: 520101 4707650001 | H9: P | I9: Kawin | J9: Dasan Geres Barat | K9: 23930 | L9: 1965 | M9: =2019-1965 -> 54 | N9: Islam | O9: Sasak | P9: SLTA/Sederajat | R9: Wiraswasta
D10: 3 | E10: Budi Setiawan | F10: Anak | G10: 520101 2007880001 | H10: L | I10: Belum kawin | J10: Dasan Geres Barat | K10: 32344 | L10: 1988 | M10: =2019-1988 -> 31 | N10: Islam | O10: Sasak | P10: SLTA/Sederajat | R10: Wiraswasta
D11: 4 | E11: Suhardi | F11: Lain-lain | G11: 520101 0410780001 | H11: L | I11: Belum kawin | J11: Dasan Geres Barat | K11: 28590 | L11: 1978 | M11: =2019-1978 -> 41 | N11: Islam | O11: Sasak | P11: SLTA/Sederajat | R11: Wiraswasta
B12: 2 | C12: 5.2010115e+15 | D12: 5 | E12: Muhammadun | F12: KK | G12: 520101 1009700001 | H12: L | I12: Kawin | J12: Denpasar | K12: 43686 | L12: 1970 | M12: =2019-L12 -> 49 | N12: Islam | O12: Sasak | P12: SLTA/MA | R12: Wiraswasta
D13: 6 | E13: Nurjannah | F13: Istri | G13: 520101 6104700001 | H13: p | I13: Kawin | J13: Dasan Geres | K13: 25679 | L13: 1970 | M13: =2019-L13 -> 49 | N13: Islam | O13: Sasak | P13: SLTA/MA | R13: Pedagang
D14: 7 | E14: Muhammad Cahyadi Putra | F14: Anak | G14: 520101 0603950001 | H14: L | I14: Belum kawin | J14: Denpasar | K14: 34764 | L14: 1995 | M14: =2019-L14 -> 24 | N14: Islam | O14: Sasak | P14: SLTA/MA | R14: Pelajar/Mahasiswa
D15: 8 | E15: Muhammad Nur Alfaridzi | F15: Anak | G15: 520101 0302990003 | H15: L | I15: Belum kawin | J15: Dasan Geres | K15: 36194 | L15: 1999 | M15: =2019-L15 -> 20 | N15: Islam | O15: Sasak | P15: SLTP/MTSN
D16: 9 | E16: Salsabila Norma Seftiana | F16: Anak | G16: 520101 6609050001 | H16: P | I16: Belum kawin | J16: Denpasar | K16: 38621 | L16: 2005 | M16: =2019-L16 -> 14 | N16: Islam | O16: Sasak | R16: -
B17: 3 | C17: 520101 0503082767 | D17: 10 | E17: Fauzi | F17: KK | G17: 520101 1506650002 | H17: L | I17: Kawin | J17: Dasan Geres Barat | K17: 23908 | L17: 1965 | M17: =2019-1965 -> 54 | N17: Islam | O17: Sasak | P17: Tamat SD/Sederajat | R17: Pedagang
D18: 11 | E18: Hasanah | F18: Istri | G18: 520101 5006660001 | H18: P | I18: Kawin | J18: Dasan Geres Barat | K18: 24386 | L18: 1966 | M18: =2019-1966 -> 53 | N18: Islam | O18: Sasak | P18: Tidak/Belum Sekolah | R18: Pedagang
D19: 12 | E19: M. Hendrayadi | F19: Anak | G19: 520101 3003890001 | H19: L | I19: Belum kawin | J19: Dasan Geres Barat | K19: 32597 | L19: 1989 | M19: =2019-1989 -> 30 | N19: Islam | O19: Sasak | P19: SLTA/Sederajat | R19: Wiraswasta
D20: 13 | E20: Nurhalis Aji Majid | F20: Anak | G20: 520101 2703990002 | H20: L | I20: Belum kawin | J20: Dasan Geres Barat | K20: 36246 | L20: 1999 | M20: =2019-1999 -> 20 | N20: Islam | O20: Sasak | P20: SLTP/Sederajat | R20: Pelajar/Mahasiswa
D21: 14 | E21: Dewi Rahmawati | F21: Cucu | G21: 520101 4610060001 | H21: P | I21: Belum kawin | J21: Dasan Geres | K21: 38995 | L21: 2006 | M21: =2019-2006 -> 13 | N21: Islam | O21: Sasak | P21: Belum Tamat SD/Sederajat | R21: Pelajar/Mahasiswa
B22: 4 | C22: 520101 2710160025 | D22: 15 | E22: Hasan Basri | F22: KK | G22: 520101 1506650001 | H22: L | I22: Kawin | J22: Dasan Geres Barat | K22: 28345 | L22: 1977 | M22: =2019-1977 -> 42 | N22: Islam | O22: Sasak | P22: Belum Tamat SD/Sederajat | R22: Wiraswasta
D23: 16 | E23: Misnawati | F23: Istri | G23: 520101 4107670554 | H23: P | I23: Kawin | J23: Dasan Geres | K23: 29586 | L23: 1980 | M23: =2019-1980 -> 39 | N23: Islam | O23: Sasak | P23: SLTA/Sederajat | R23: Wiraswasta
D24: 17 | E24: Maulana Ibrahim Hasan | F24: Anak | G24: 520101 1112060002 | H24: L | I24: Belum kawin | J24: Dasan Geres | K24: 39062 | L24: 2006 | M24: =2019-2006 -> 13 | N24: Islam | O24: Sasak | P24: Tidak/Belum Bekerja | R24: Belum/Tidak Bekerja
D25: 18 | E25: Maizar Algifari | F25: Anak | G25: 520101 0811120002 | H25: L | I25: Belum kawin | J25: Dasan Geres | K25: 41221 | L25: 2012 | M25: =2019-2012 -> 7 | N25: Islam | O25: Sasak | P25: Tidak/Belum Sekolah | R25: Belum/Tidak Bekerja
D26: 19 | E26: Muhamad | F26: Orang Tua | G26: 520101 0606310001 | H26: L | I26: Kawin | J26: Dasan Geres Barat | K26: 11480 | L26: 1931 | M26: =2019-1931 -> 88 | N26: Islam | O26: Sasak | P26: Tidak Belum Sekolah | R26: Buruh Harian Lepas
D27: 20 | E27: Sahnun | F27: Orang Tua | G27: 520101 5506400001 | H27: P | I27: Kawin | J27: Dasan Geres Barat | K27: 14777 | L27: 1940 | M27: =2019-1940 -> 79 | N27: Islam | O27: Sasak | P27: Tidak/Belum Sekolah | R27: Buruh Harian Lepas
B28: 5 | C28: 520101 0503082847 | D28: 21 | E28: Azhar | F28: KK | G28: 520101 0107510029 | H28: L | I28: Kawin | J28: Dasan Geres Barat | K28: 18810 | L28: 1951 | M28: =2019-1958 -> 61 | N28: Islam | O28: Sasak | P28: Tamat SD/Sederajat | R28: Tukang Kayu
D29: 22 | E29: Sahariyah | F29: Istri | G29: 520101 7112580025 | H29: L | I29: Kawin | J29: Dasan Geres Barat | K29: 21550 | L29: 1958 | M29: =2019-1958 -> 61 | N29: Islam | O29: Sasak | P29: Belum Tamat SD/Sederajat | R29: Mengurus Rumah Tangga
D30: 23 | E30: M. Iqbal | F30: Anak | G30: 520101 0709890001 | H30: L | I30: Belum kawin | J30: Dasan Geres Barat | K30: 32758 | L30: 1989 | M30: =2019-1989 -> 30 | N30: Islam | O30: Sasak | P30: SLTA/Sederajat | R30: Pelajar/Mahasiswa
D31: 24 | E31: Fahmi Idris | F31: Anak | G31: 520101 2209000002 | H31: L | I31: Belum kawin | J31: Dasan Geres Barat | K31: 36791 | L31: 2000 | M31: =2019-2000 -> 19 | N31: Islam | O31: Sasak | P31: SLTA/Sederajat | R31: Pelajar/Mahasiswa
B32: 6 | C32: 520101 0503082860 | D32: 25 | E32: Mahzan | F32: KK | G32: 520101 0204580002 | H32: L | I32: Kawin | J32: Dasan Geres Barat | K32: 21277 | L32: 1958 | M32: =2019-L32 -> 61 | N32: Islam | O32: Sasak | P32: SD/MI | R32: Pedagang
D33: 26 | E33: Sairah | F33: Istri | G33: 520101 4607630002 | H33: P | I33: Kawin | J33: Bug Bug | K33: 23198 | L33: 1963 | M33: =2019-L33 -> 56 | N33: Islam | O33: Sasak | P33: Belum Tamat SD/Sederajat | R33: Pembantu Rumah Tangga
D34: 27 | E34: Hayu Nurpa | F34: Anak | G34: 520101 5805920001 | H34: P | I34: Belum kawin | J34: Dasan Geres Barat | K34: 33742 | L34: 1992 | M34: =2019-L34 -> 27 | N34: Islam | O34: Sasak | P34: Belum Tamat SD/Sederajat | R34: Belum/Tidak Bekerja
D35: 28 | E35: Luh Marzana | F35: Anak | G35: 520101 4209940004 | H35: P | I35: Belum kawin | J35: Dasan Geres Barat | K35: 34579 | L35: 1994 | M35: =2019-L35 -> 25 | N35: Islam | O35: Sasak | P35: SLTP/Sederajat | R35: Pelajar/Mahasiswa
B36: 7 | C36: 520101 0304130001 | D36: 29 | E36: Muhammad Fahrizal | F36: KK | G36: 520101 1010790001 | H36: L | I36: Kawin | J36: Dasan geres barat | K36: 29138 | L36: 1979 | M36: =2019-1979 -> 40 | N36: Islam | O36: Sasak | P36: SLTA/Sederajat | R36: Karyawan Honorer
D37: 30 | E37: Baiq Fitrianingsih | F37: Istri | G37: 520805 6906840001 | H37: P | I37: Kawin | J37: Karang Baro | K37: 30862 | L37: 1984 | M37: =2019-1984 -> 35 | N37: Islam | O37: Sasak | P37: SLTA/Sederajat | R37: Wiraswasta
B38: 8 | D38: 31 | E38: Muhammad Ali Jedi,S.Ip | F38: KK | G38: 520101 1509770003 | H38: L | I38: Kawin | K38: 28171 | L38: =YEAR(K38) -> 1977 | M38: =2019-L38 -> 42 | N38: Islam | P38: PT/Akademi | R38: Pegawai swasta
D39: 32 | E39: Evi Silvia | F39: Istri | G39: 520101 5701770003 | H39: P | I39: Kawin | K39: 28142 | L39: =YEAR(K39) -> 1977 | M39: =2019-L39 -> 42 | N39: Islam | P39: SLTA/MA | R39: Pekerja lepas
D40: 33 | E40: Shabriena Alvi Ghassani | F40: Anak | G40: 520101 5932050004 | H40: P | I40: Belum kawin | K40: 37662 | L40: =YEAR(K40) -> 2003 | M40: =2019-L40 -> 16 | N40: Islam | P40: - | R40: -
D41: 34 | E41: Rafiq Alvi Ghassani | F41: Anak | G41: 520101 1736090003 | H41: L | I41: Belum kawin | K41: 39950 | L41: =YEAR(K41) -> 2009 | M41: =2019-L41 -> 10 | N41: Islam | P41: - | R41: -
...

Sheet RT 02
B1: DATA INDUK PENDUDUK KELURAHAN DASAN GERES
B2: TAHUN 2019
B3: LINGKUNGAN DASAN GERES BARAT
B4: RT 02
B5: No | C5: Nomor KK | D5: Jumlah Jiwa | E5: Nama Lengkap/ Panggilan | F5: Kedudukan dalam Keluarga | G5: NIK | H5: Jenis Kelamin (L/P) | I5: Status Perkawinan | J5: Lahir | M5: Usia | N5: Agama | O5: Etnis | P5: Pendidikan Terakhir | Q5: Jurusan | R5: Pekerjaan
J6: Tempat | K6: Tanggal | L6: Tahun
B8: 1 | D8: 1 | E8: Nurholis Jamil | F8: KK | G8: 520101 2901850001 | H8: L | I8: Kawin | K8: 31071 | L8: =YEAR(K8) -> 1985 | M8: =2019-L8 -> 34 | N8: Islam | P8: SLTA/MA | R8: PNS/TNI/ POLRI
D9: 2 | E9: Juliyanti | F9: Istri | G9: 527101 4507900000 | H9: P | I9: Kawin | K9: 33059 | L9: =YEAR(K9) -> 1990 | M9: =2019-L9 -> 29 | N9: Islam | P9: PT/Akademi | R9: Pegawai swasta
B10: 2 | D10: 3 | E10: Hajjah Nurhidayah | F10: KK | G10: 520101 4107590149 | H10: P | I10: Janda | K10: 21915 | L10: =YEAR(K10) -> 1959 | M10: =2019-L10 -> 60 | N10: Islam | P10: SLTA/MA | R10: Petani
D11: 4 | E11: Anis Sujudi | F11: Anak | G11: 520101 2007920001 | H11: L | I11: Belum kawin | K11: 33805 | L11: =YEAR(K11) -> 1992 | M11: =2019-L11 -> 27 | N11: Islam | P11: SLTA/MA | R11: -
D12: 5 | E12: Wazir Fahmi | F12: Anak | G12: 520101 2908950001 | H12: L | I12: Belum kawin | K12: 34935 | L12: =YEAR(K12) -> 1995 | M12: =2019-L12 -> 24 | N12: Islam | P12: SLTA/MA | R12: -
B13: 3 | D13: 6 | E13: M Tauhid S.P | F13: KK | G13: 520101 3009700002 | H13: L | I13: Kawin | K13: 25841 | L13: =YEAR(K13) -> 1970 | M13: =2019-L13 -> 49 | N13: Islam | P13: PT/Akademi | R13: Wiraswasta
D14: 7 | E14: Nurhasanah S.Pd | F14: Istri | G14: 520101 4806820001 | H14: P | I14: Kawin | K14: 30110 | L14: =YEAR(K14) -> 1982 | M14: =2019-L14 -> 37 | N14: Islam | P14: PT/Akademi | R14: PNS/TNI/ POLRI
D15: 8 | E15: M Nabil Asnawi | F15: Anak | G15: 520101 2108060001 | H15: L | I15: Belum kawin | K15: 38889 | L15: =YEAR(K15) -> 2006 | M15: =2019-L15 -> 13 | N15: Islam | P15: - | R15: -
D16: 9 | E16: M Rizki Firdaus | F16: Anak | G16: 520101 0806111002 | H16: L | I16: Belum kawin | K16: 40702 | L16: =YEAR(K16) -> 2011 | M16: =2019-L16 -> 8 | N16: Islam | P16: - | R16: -
D17: 10 | E17: M Ammar Sya’bani | F17: Anak | G17: 520101 1906131004 | H17: L | I17: Belum kawin | K17: 41444 | L17: =YEAR(K17) -> 2013 | M17: =2019-L17 -> 6 | N17: Islam | P17: - | R17: -
B18: 4 | C18: 520101 0503084555 | D18: 11 | E18: Halawi | F18: KK | G18: 520101 0107730241 | H18: L | I18: Kawin | J18: Dasan Geres Barat | K18: 28125 | L18: 1976 | M18: =2019-L18 -> 43 | N18: Islam | O18: Sasak | P18: SLTA/Sederajat | R18: Wiraswasta
D19: 12 | E19: Maemunah | F19: Istri | G19: 520101 4107800377 | H19: P | I19: Kawin | J19: Dasan Geres Barat | K19: 29373 | L19: 1980 | M19: =2019-L19 -> 39 | N19: Islam | O19: Sasak | P19: SLTP/Sederajat | R19: Mengurus Rumah Tangga
D20: 13 | E20: Mutia Sakina | F20: Anak | G20: 520101 6303050001 | H20: P | I20: Belum kawin | J20: Dasan Geres Barat | K20: 38414 | L20: 2005 | M20: =2019-L20 -> 14 | N20: Islam | O20: Sasak | P20: Belum Tamat SD/Sederajat | R20: Pelajar/Mahasiswa
D21: 14 | E21: Nur Salisa | F21: Anak | G21: 520101 4206070001 | H21: P | I21: Belum kawin | J21: Dasan Geres Barat | K21: 39265 | L21: 2007 | M21: =2019-L21 -> 12 | N21: Islam | O21: Sasak | P21: Belum Tamat SD/Sederajat | R21: Pelajar/Mahasiswa
D22: 15 | E22: Madina Latifa | F22: Anak | G22: 520101 6702110003 | H22: P | I22: Belum kawin | J22: Dasan Geres Barat | K22: 40601 | L22: 2011 | M22: =2019-L22 -> 8 | N22: Islam | O22: Sasak | P22: Tidak/Belum Sekolah | R22: Belum/Tidak Bekerja
D23: 16 | E23: Sadariah | F23: Orang Tua | G23: 520101 7112430034 | H23: P | I23: Cerai Mati | J23: Dasan Geres Barat | K23: 16802 | L23: 1945 | M23: =2019-L23 -> 74 | N23: Islam | O23: Sasak | P23: Tidak/Belum Sekolah | R23: Belum/Tidak Bekerja
B24: 5 | C24: 520101 0503084551 | D24: 17 | E24: Saefudin | F24: KK | G24: 520101 0107780066 | H24: L | I24: Kawin | J24: Dasan Geres | K24: 29325 | L24: 1980 | M24: =2019-L24 -> 39 | N24: Islam | O24: Sasak | P24: SLTA/Sederajat | R24: Wiraswasta
D25: 18 | E25: Asturiyanti | F25: Istri | G25: 520101 4107860089 | H25: P | I25: Kawin | J25: Bangket Gawah | K25: 31430 | L25: 1986 | M25: =2019-L25 -> 33 | N25: Islam | O25: Sasak | P25: SLTA/Sederajat | R25: Wiraswasta
D26: 19 | E26: Najib Afriyandi | F26: Anak | G26: 520101 2306090003 | H26: L | I26: Belum kawin | J26: Dasan Geres | K26: 39987 | L26: 2009 | M26: =2019-L26 -> 10 | N26: Islam | O26: Sasak | P26: Belum Tamat SD/Sederajat | R26: Pelajar/Mahasiswa
B27: 6 | D27: 20 | E27: Haji Nazar Naamy M. Si | F27: KK | G27: 520101 0107720166 | H27: L | I27: Kawin | K27: 26330 | L27: =YEAR(K27) -> 1972 | M27: =2019-L27 -> 47 | N27: Islam | P27: PT/Akademi | R27: PNS/TNI/ POLRI
D28: 21 | E28: Hajjah Zuhaeranah S. Ag | F28: Istri | G28: 520101 4107770505 | H28: P | I28: Kawin | K28: 28260 | L28: =YEAR(K28) -> 1977 | M28: =2019-L28 -> 42 | N28: Islam | P28: PT/Akademi | R28: -
D29: 22 | E29: A Irfan Ghifary | F29: Anak | G29: 520101 0407031002 | H29: L | I29: Belum kawin | K29: 37806 | L29: =YEAR(K29) -> 2003 | M29: =2019-L29 -> 16 | N29: Islam | P29: - | R29: -
D30: 23 | E30: Luna Febriana S | F30: Anak | G30: 520101 4402081001 | H30: P | I30: Belum kawin | K30: 39482 | L30: =YEAR(K30) -> 2008 | M30: =2019-L30 -> 11 | N30: Islam | P30: - | R30: -
D31: 24 | E31: Muhammad Nizar Fatria | F31: Anak | G31: 520101 1202141003 | H31: L | I31: Belum kawin | K31: 41682 | L31: =YEAR(K31) -> 2014 | M31: =2019-L31 -> 5 | N31: Islam | P31: - | R31: -
B32: 7 | D32: 25 | E32: Junainah | F32: KK | G32: 520101 7112630030 | H32: P | I32: Janda | K32: 23376 | L32: =YEAR(K32) -> 1963 | M32: =2019-L32 -> 56 | N32: Islam | P32: SLTP/MTSN | R32: Pedagang
D33: 26 | E33: Siti Rahmi | F33: Anak | G33: 520103 6011850000 | H33: P | I33: Janda | K33: 31371 | L33: =YEAR(K33) -> 1985 | M33: =2019-L33 -> 34 | N33: Islam | P33: PT/Akademi | R33: Lainnya
D34: 27 | E34: Auro Zakia Andini | F34: Lain-lain | G34: 520103 5709110000 | H34: P | I34: Belum kawin | K34: 40803 | L34: =YEAR(K34) -> 2011 | M34: =2019-L34 -> 8 | N34: Islam | P34: - | R34: -
B35: 8 | C35: 520101 0503084573 | D35: 28 | E35: Buniamin | F35: KK | G35: 520101 0107660136 | H35: L | I35: Kawin | J35: Dasan Geres Barat | K35: 24114 | L35: 1966 | M35: =2019-L35 -> 53 | N35: Islam | P35: SLTA/Sederajat | R35: Petani/Pekebun
D36: 29 | E36: Masitah | F36: Istri | G36: 520101 4107730296 | H36: P | I36: Kawin | J36: Dasan Geres Barat | K36: 28862 | L36: 1979 | M36: =2019-L36 -> 40 | N36: Islam | P36: SLTA/Sederajat | R36: Mengurus Rumah Tangga
D37: 30 | E37: Zainul Anam | F37: Anak | G37: 520101 0706010001 | H37: L | I37: Belum kawin | J37: Dasan Geres | K37: 37078 | L37: 2001 | M37: =2019-L37 -> 18 | N37: Islam | P37: Tamat SD/Sederajat | R37: Pelajar/Mahasiswa
D38: 31 | E38: Ulia Hopipah | F38: Anak | G38: 520101 4107050151 | H38: P | I38: Belum kawin | J38: Dasan Geres | K38: 38499 | L38: 2005 | M38: =2019-L38 -> 14 | N38: Islam | P38: Belum Tamat SD/Sederajat | R38: Pelajar/Mahasiswa
D39: 32 | E39: Muhammad Riadil Jinan | F39: Anak | G39: 520101 2112090003 | H39: L | I39: Belum kawin | J39: Gerung | K39: 40168 | L39: 2009 | M39: =2019-L39 -> 10 | N39: Islam | P39: Tidak/Belum Sekolah | R39: Belum/Tidak Bekerja
B40: 9 | D40: 33 | E40: Haji Ridwan | F40: KK | G40: 520101 3112560003 | H40: L | I40: Kawin | K40: 31412 | L40: =YEAR(K40) -> 1985 | M40: =2019-L40 -> 34 | N40: Islam | P40: SLTA/MA | R40: Pensiunan
D41: 34 | E41: Rohaniah | F41: Istri | G41: 520101 5303660001 | H41: P | I41: Kawin | K41: 24179 | L41: =YEAR(K41) -> 1966 | M41: =2019-L41 -> 53 | N41: Islam | P41: SLTP/MTSN | R41: -
...

Sheet RT 03
B1: DATA INDUK PENDUDUK KELURAHAN DASAN GERES
B2: TAHUN 2019
B3: LINGKUNGAN DASAN GERES BARAT
B4: RT 03
B5: No | C5: No.KK | D5: Jumlah Jiwa | E5: Nama Lengkap/ Panggilan | F5: Kedudukan dalam Keluarga | G5: NIK | H5: Jenis Kelamin (L/P) | I5: Status Perkawinan | J5: Tanggal Lahir | N5: Agama | O5: Etnis | P5: Pendidikan Terakhir | Q5: Jurusan | R5: Pekerjaan
J6: Tempat | K6: Tanggal | L6: tahun | M6: usia
B8: 1 | D8: 1 | E8: Khairudin, S.Ag | F8: KK | G8: 520101 200403236 | H8: L | I8: Kawin | K8: 26893 | L8: =YEAR(K8) -> 1973 | M8: =2019-L8 -> 46 | N8: Islam | P8: PT/Akademi | R8: Pegawai swasta
D9: 2 | E9: Muslimah | F9: Istri | G9: 520101 200403237 | H9: P | I9: Kawin | K9: 28125 | L9: =YEAR(K9) -> 1976 | M9: =2019-L9 -> 43 | N9: Islam | P9: PT/Akademi | R9: PNS/TNI/ POLRI
D10: 3 | E10: Farhan Nauval Rifqy Firdaus | F10: Anak | G10: 520101 200403238 | H10: L | I10: Belum kawin | K10: 38268 | L10: =YEAR(K10) -> 2004 | M10: =2019-L10 -> 15 | N10: Islam | P10: - | R10: Lainnya
D11: 4 | E11: Aisya Ihsan Bilqisti | F11: Anak | G11: 520101 200403239 | H11: P | I11: Janda | K11: 39844 | L11: =YEAR(K11) -> 2009 | M11: =2019-L11 -> 10 | N11: Islam | P11: - | R11: -
D12: 5 | E12: Muhammad Farras Habiburrahman | F12: Lain-lain | G12: 520101 200403240 | H12: L | I12: Belum kawin | K12: 41918 | L12: =YEAR(K12) -> 2014 | M12: =2019-L12 -> 5 | N12: Islam | P12: - | R12: Lainnya
B13: 2 | D13: 6 | E13: Hj. Siti Hawari | F13: KK | G13: 520101 6307731001 | H13: P | I13: Janda | K13: 26868 | L13: =YEAR(K13) -> 1973 | M13: =2019-L13 -> 46 | N13: Islam | P13: SLTA/MA | R13: Pekerja lepas
D14: 7 | E14: Fadilah | F14: Anak | G14: 520101 5508931001 | H14: P | I14: Belum kawin | K14: 34196 | L14: =YEAR(K14) -> 1993 | M14: =2019-L14 -> 26 | N14: Islam | P14: PT/Akademi | R14: -
D15: 8 | E15: Fahmi | F15: Anak | G15: 520101 1802971001 | H15: L | I15: Belum kawin | K15: 35479 | L15: =YEAR(K15) -> 1997 | M15: =2019-L15 -> 22 | N15: Islam | P15: SLTA/MA | R15: -
D16: 9 | E16: Yusriah | F16: Anak | G16: 520101 7009991001 | H16: P | I16: Belum kawin | K16: 36433 | L16: =YEAR(K16) -> 1999 | M16: =2019-L16 -> 20 | N16: Islam | P16: SLTP/MTSN | R16: -
B17: 3 | C17: 520101 1703150021 | D17: 10 | E17: Hj. Siti Patimah | F17: KK | G17: 520101 4107520233 | H17: P | I17: Cerai Mati | J17: Rumak | K17: 18628 | L17: =YEAR(K17) -> 1950 | M17: =2019-L17 -> 69 | N17: Islam | O17: Sasak | P17: Tamat SD/Sederajat | R17: Mengurus Rumah Tangga
D18: 11 | E18: Rukyah | F18: Anak | G18: 520101 4107760284 | H18: P | I18: Belum kawin | J18: Dasan Geres | K18: 28589 | L18: =YEAR(K18) -> 1978 | M18: =2019-L18 -> 41 | N18: Islam | O18: Sasak | P18: SLTA/Sederajat | R18: Wiraswasta
D19: 12 | E19: Dewi Santi Suryani, SE | F19: Anak | G19: 520101 5402890007 | H19: P | I19: Belum kawin | J19: Dasan Geres | K19: 32691 | L19: =YEAR(K19) -> 1989 | M19: =2019-L19 -> 30 | N19: Islam | O19: Sasak | P19: DPLOMA IV | R19: Wiraswasta
B20: 4 | D20: 13 | E20: Saripah | F20: KK | G20: 520101 3112360002 | H20: P | I20: Janda | K20: 13515 | L20: =YEAR(K20) -> 1936 | M20: =2019-L20 -> 83 | N20: Islam | P20: - | R20: -
D21: 14 | E21: Rabitah | F21: Anak | G21: 520101 7112380003 | H21: P | I21: Janda | K21: 28418 | L21: =YEAR(K21) -> 1977 | M21: =2019-L21 -> 42 | N21: Islam | P21: SLTA/MA | R21: Pedagang
B22: 5 | C22: 520101 0503082273 | D22: 15 | E22: Marjanah | F22: KK | G22: 520101 0107730032 | H22: P | I22: Cerai Mati | J22: Dasan Geres Barat | K22: 28132 | L22: =YEAR(K22) -> 1977 | M22: =2019-L22 -> 42 | N22: Islam | O22: Sasak | P22: Tamat SD/Sederajat | R22: Pedagang
D23: 16 | E23: Muhammad . Amrulloh | F23: Lain-lain | G23: 520101 2304961001 | H23: L | I23: Belum kawin | J23: Dasan Geres Barat | K23: 35178 | L23: =YEAR(K23) -> 1996 | M23: =2019-L23 -> 23 | N23: Islam | O23: Sasak | P23: SLTP/Sederajat | R23: Pelajar/Mahasiswa
B24: 6 | C24: 520101 0503083822 | D24: 17 | E24: Sahwan | F24: KK | G24: 520101 0107680089 | H24: L | I24: Kawin | J24: Dasan Geres Barat | K24: 24844 | L24: =YEAR(K24) -> 1968 | M24: =2019-L24 -> 51 | N24: Islam | O24: Sasak | P24: SLTA/Sederajat | R24: Wiraswasta
D25: 18 | E25: Niswati | F25: Istri | G25: 520101 4107700259 | H25: p | I25: Kawin | J25: Gerung | K25: 25576 | L25: =YEAR(K25) -> 1970 | M25: =2019-L25 -> 49 | N25: Islam | O25: Sasak | P25: Diplomat 1V | R25: PNS
B26: 7 | C26: 520101 0503083817 | D26: 19 | E26: Hj. Nurhalimah | F26: KK | G26: 520101 4107580070 | H26: P | I26: Cerai Mati | J26: Dasan Geres | K26: 24844 | L26: =YEAR(K26) -> 1968 | M26: =2019-L26 -> 51 | N26: Islam | O26: Sasak | P26: TAMAT SD/SEDERAJAT | R26: Pedagang
D27: 20 | E27: Hj. Wahidah | F27: Anak | G27: 520101 5504790003 | H27: P | I27: Belum kawin | J27: Dasan Geres | K27: 28960 | L27: =YEAR(K27) -> 1979 | M27: =2019-L27 -> 40 | N27: Islam | O27: Sasak | P27: SLTA/SEDERAJAT | R27: Belum/Tidak Bekerja
D28: 21 | E28: Hainiah | F28: Anak | G28: 520101 5504790002 | H28: P | I28: Belum kawin | J28: Dasan Geres | K28: 28960 | L28: =YEAR(K28) -> 1979 | M28: =2019-L28 -> 40 | N28: Islam | O28: Sasak | P28: DIPLOMA IV/STRATA I | R28: Karyawan Honorer
D29: 22 | E29: Siti Aisah | F29: Anak | G29: 520101 4906890001 | H29: P | I29: Belum kawin | J29: Dasan Geres | K29: 32757 | L29: =YEAR(K29) -> 1989 | M29: =2019-L29 -> 30 | N29: Islam | O29: Sasak | P29: DIPLOMA IV/STRATA I | R29: Karyawan Honorer
B30: 8 | D30: 23 | E30: Iksan | F30: KK | G30: 520101 2512730004 | H30: L | I30: Kawin | K30: 27023 | L30: =YEAR(K30) -> 1973 | M30: =2019-L30 -> 46 | N30: Islam | P30: SLTA/MA | R30: PNS/TNI/ POLRI
D31: 24 | E31: Apriah | F31: Istri | G31: 520101 6204800004 | H31: P | I31: Kawin | K31: 29333 | L31: =YEAR(K31) -> 1980 | M31: =2019-L31 -> 39 | N31: Islam | P31: SLTP/MTSN | R31: Pedagang
D32: 25 | E32: Aisyah Ria Baeduri | F32: Anak | G32: 520101 6003040001 | H32: P | I32: Belum kawin | K32: 38066 | L32: =YEAR(K32) -> 2004 | M32: =2019-L32 -> 15 | N32: Islam | P32: - | R32: -
D33: 26 | E33: Ferdian Asramil Huda | F33: Anak | G33: 520101 0102060004 | H33: L | I33: Belum kawin | K33: 38384 | L33: =YEAR(K33) -> 2005 | M33: =2019-L33 -> 14 | N33: Islam | P33: - | R33: -
D34: 27 | E34: M. Taopan Satriaji | F34: Anak | G34: 520101 2911080002 | H34: L | I34: Belum kawin | K34: 39780 | L34: =YEAR(K34) -> 2008 | M34: =2019-L34 -> 11 | N34: Islam | P34: - | R34: -
D35: 28 | E35: Apriali Suci | F35: Anak | G35: 520101 4204120002 | H35: P | I35: Belum kawin | K35: 41001 | L35: =YEAR(K35) -> 2012 | M35: =2019-L35 -> 7 | N35: Islam | P35: - | R35: -
B36: 9 | C36: 520101 0503084613 | D36: 29 | E36: Akmal | F36: KK | G36: 520101 0107660126 | H36: L | I36: Kawin | J36: Dasan Geres Barat | K36: 24114 | L36: =YEAR(K36) -> 1966 | M36: =2019-L36 -> 53 | N36: Islam | O36: Sasak | P36: SLTA/Sederajat | R36: Karyawan SWASTA
D37: 30 | E37: Siti Patimah | F37: Istri | G37: 520101 4107710115 | H37: P | I37: Kawin | J37: Lemokek | K37: 26146 | L37: =YEAR(K37) -> 1971 | M37: =2019-L37 -> 48 | N37: Islam | O37: Sasak | P37: SLTA/Sederajat | R37: Wiraswasta
D38: 31 | E38: Fatmi Maliham | F38: anak | G38: 520101 0909960002 | H38: p | I38: Belum kawin | J38: Dasan Geres Barat | K38: 35317 | L38: =YEAR(K38) -> 1996 | M38: =2019-L38 -> 23 | N38: Islam | O38: Sasak | P38: SLTA/Sederajat | R38: Pelajar/Mahasiswa
D39: 32 | E39: Dina Malika | F39: Anak | G39: 520101 6005040002 | H39: P | I39: Belum kawin | J39: Dasan Geres Barat | K39: 38127 | L39: =YEAR(K39) -> 2004 | M39: =2019-L39 -> 15 | N39: Islam | O39: Sasak | P39: Tamat SD/Sederajat | R39: Pelajar/Mahasiswa
B40: 10 | D40: 33 | E40: Muhali | F40: KK | G40: 520101 3112450010 | H40: L | I40: Duda | K40: 16802 | L40: =YEAR(K40) -> 1945 | M40: =2019-L40 -> 74 | N40: Islam | P40: SD/MI | R40: -
D41: 34 | E41: Amenah | F41: Anak | G41: 520101 4107620016 | H41: P | I41: Janda | K41: 22828 | L41: =YEAR(K41) -> 1962 | M41: =2019-L41 -> 57 | N41: Islam | P41: SD/MI | R41: Pekerja lepas
...

Sheet RT 04
B1: DATA INDUK PENDUDUK KELURAHAN DASAN GERES
B2: TAHUN 2019
B3: LINGKUNGAN DASAN GERES BARAT
B4: RT 04
B5: No | C5: No. KK | D5: Jumlah Jiwa | E5: Nama Lengkap/ Panggilan | F5: Kedudukan dalam Keluarga | G5: NIK | H5: Jenis Kelamin (L/P) | I5: Status Perkawinan | J5: Lahir | M5: usia | N5: Agama | O5: etnis | P5: Pendidikan Terakhir | Q5: Jurusan | R5: Pekerjaan
J6: tempat | K6: tanggal | L6: tahun
B8: 1 | D8: 1 | E8: Ramli | F8: KK | G8: 520101 2808840001 | H8: L | I8: Kawin | K8: 30922 | L8: =YEAR(K8) -> 1984 | M8: =2019-L8 -> 35 | N8: Islam | P8: SLTA/MA | R8: Wiraswasta
D9: 2 | E9: Juriah | F9: Istri | G9: 520101 5203870004 | H9: P | I9: Kawin | K9: 31848 | L9: =YEAR(K9) -> 1987 | M9: =2019-L9 -> 32 | N9: Islam | P9: SLTA/MA | R9: Pekerja lepas
D10: 3 | E10: Muhammad Rizki Maulana | F10: Anak | G10: 520101 1503220001 | H10: L | I10: Belum kawin | K10: 40983 | L10: =YEAR(K10) -> 2012 | M10: =2019-L10 -> 7 | N10: Islam | P10: - | R10: -
B11: 2 | C11: 520101 0503083439 | D11: 4 | E11: Muhali | F11: KK | G11: 520101 0107540099 | H11: L | I11: Kawin | J11: Dasan Geres Barat | K11: 19731 | L11: 1954 | M11: =2019-L11 -> 65 | N11: Islam | O11: Sasak | P11: Tamat SD/Sederajat | R11: Buruh Tani/Perkebunan
D12: 5 | E12: Safiah | F12: Istri | G12: 520101 4107580085 | H12: P | I12: Kawin | J12: Dasan Geres Barat | K12: 21192 | L12: 1958 | M12: =2019-L12 -> 61 | N12: Islam | O12: Sasak | P12: Tamat SD/Sederajat | R12: Buruh Tani/Perkebunan
D13: 6 | E13: Nikmatul Akairani | F13: Anak | G13: 520101 5503860001 | H13: P | I13: Belum kawin | J13: Lombok Barat | K13: 30817 | L13: 1984 | M13: =2019-L13 -> 35 | N13: Islam | O13: Sasak | P13: SLTP/Sederajat | R13: Karyawan Swasta
D14: 7 | E14: Roaida | F14: Anak | G14: 520101 4107930140 | H14: P | I14: Belum kawin | J14: Dasan Geres | K14: 34253 | L14: 1993 | M14: =2019-L14 -> 26 | N14: Islam | O14: Sasak | P14: DIPLOMA IV | R14: Pelajar/Mahasiswa
B15: 3 | D15: 8 | E15: Muhammad Salehudin | F15: KK | G15: 520101 2108710001 | H15: L | I15: Kawin | K15: 26166 | L15: =YEAR(K15) -> 1971 | M15: =2019-L15 -> 48 | N15: Islam | P15: SLTA/MA | R15: Wiraswasta
D16: 9 | E16: Yuhaeni | F16: Istri | G16: 520101 4202780001 | H16: P | I16: Kawin | K16: 28543 | L16: =YEAR(K16) -> 1978 | M16: =2019-L16 -> 41 | N16: Islam | P16: SLTA/MA | R16: Wiraswasta
D17: 10 | E17: Yazid Albastomy | F17: Anak | G17: 520101 2104880001 | H17: L | I17: Belum kawin | K17: 35906 | L17: =YEAR(K17) -> 1998 | M17: =2019-L17 -> 21 | N17: Islam | P17: SD/MI | R17: -
D18: 11 | E18: Muladi Rawalidya Putra | F18: Anak | G18: 520101 2808990003 | H18: L | I18: Belum kawin | K18: 36308 | L18: =YEAR(K18) -> 1999 | M18: =2019-L18 -> 20 | N18: Islam | P18: SD/MI | R18: -
D19: 12 | E19: Trimannisa Shabrina | F19: Anak | G19: 520101 4101070003 | H19: P | I19: Belum kawin | K19: 39103 | L19: =YEAR(K19) -> 2007 | M19: =2019-L19 -> 12 | N19: Islam | P19: - | R19: -
B20: 4 | D20: 13 | E20: Asmu’i | F20: KK | G20: 520101 2012690001 | H20: L | I20: Kawin | K20: 25557 | L20: =YEAR(K20) -> 1969 | M20: =2019-L20 -> 50 | N20: Islam | P20: SLTA/MA | R20: PNS/TNI/
D21: 14 | E21: Raodah | F21: Istri | G21: 520101 7112720246 | H21: P | I21: Kawin | K21: 26664 | L21: =YEAR(K21) -> 1972 | M21: =2019-L21 -> 47 | N21: Islam | P21: SLTA/MA | R21: Wiraswasta
D22: 15 | E22: Muhammad Ray Andiko | F22: Anak | G22: 520101 1601930001 | H22: L | I22: Belum kawin | K22: 33985 | L22: =YEAR(K22) -> 1993 | M22: =2019-L22 -> 26 | N22: Islam | P22: SLTA/MA | R22: PNS/TNI/
D23: 16 | E23: Muhammad Rovan Andrianto | F23: Anak | G23: 520101 1606940003 | H23: L | I23: Belum kawin | K23: 34470 | L23: =YEAR(K23) -> 1994 | M23: =2019-L23 -> 25 | N23: Islam | P23: SLTA/MA | R23: -
D24: 17 | E24: Muhammad Agi As’attrio | F24: Anak | G24: 520101 0303990001 | H24: L | I24: Belum kawin | K24: 36222 | L24: =YEAR(K24) -> 1999 | M24: =2019-L24 -> 20 | N24: Islam | P24: SLTP/MTSN | R24: -
D25: 18 | E25: Asmara Yauma Putri Farahdia | F25: Anak | G25: 520101 0312010001 | H25: P | I25: Belum kawin | K25: 37248 | L25: =YEAR(K25) -> 2001 | M25: =2019-L25 -> 18 | N25: Islam | P25: SD/MI | R25: -
D26: 19 | E26: Andina Maharani Putri | F26: Anak | G26: 520101 3311120003 | H26: P | I26: Belum kawin | K26: 41228 | L26: =YEAR(K26) -> 2012 | M26: =2019-L26 -> 7 | N26: Islam | P26: - | R26: -
B27: 5 | C27: 520101 0303150005 | D27: 20 | E27: Suhirman | F27: KK | G27: 520112 0107840413 | H27: L | I27: Kawin | J27: Lingsar-Keling | K27: 29586 | L27: 1980 | M27: =2019-L27 -> 39 | N27: Islam | O27: Sasak | P27: Tamat SD/Sederajat | R27: Buruh Harian Lepas
D28: 21 | E28: Sakdiah | F28: Istri | G28: 520101 7112690246 | H28: P | I28: Kawin | J28: Dasan Geres | K28: 25568 | L28: 1969 | M28: =2019-L28 -> 50 | N28: Islam | O28: Sasak | P28: Belum Tamat SD/Sederajat | R28: Buruh Harian Lepas
D29: 22 | E29: Sri yanti Faradila | F29: Anak | G29: 520101 5101900002 | H29: P | I29: Belum kawin | J29: Dasan Geres Barat | K29: 33178 | L29: 1990 | M29: =2019-L29 -> 29 | N29: Islam | O29: Sasak | P29: SLTP/Sederajat | R29: Wiraswasta
B30: 6 | D30: 23 | E30: Hajjah Nafizah | F30: KK | G30: 520101 7112540010 | H30: P | I30: Janda | K30: 20089 | L30: =YEAR(K30) -> 1954 | M30: =2019-L30 -> 65 | N30: Islam | P30: SD/MI | R30: Wiraswata
B31: 7 | C31: 520101 0503083434 | D31: 24 | E31: Muhidi | F31: KK | G31: 520101 0107620075 | H31: L | I31: Kawin | J31: Dasan Geres Barat | K31: 22653 | L31: 1962 | M31: =2019-L31 -> 57 | N31: Islam | O31: Sasak | P31: SLTP/MTSN | R31: Wiraswasta
D32: 25 | E32: Hj. Zuriatun Toibah | F32: Istri | G32: 520101 5506610002 | H32: P | I32: Kawin | J32: Dasan Geres Barat | K32: 22447 | L32: 1961 | M32: =2019-L32 -> 58 | N32: Islam | O32: Sasak | P32: Tamat SD/Sederajat | R32: Pedagang
D33: 26 | E33: Muhammad Takdir Rizal | F33: Anak | G33: 520101 2609961001 | H33: L | I33: Belum kawin | J33: Dasan Geres Barat | K33: 35334 | L33: 1996 | M33: =2019-L33 -> 23 | N33: Islam | O33: Sasak | P33: SLTA/Sederajat | R33: Wiraswasta
D34: 27 | E34: Ferawati | F34: Anak | G34: 520101 7005993331 | H34: P | I34: Belum kawin | J34: Dasan Geres Barat | K34: 36310 | L34: 1999 | M34: =2019-L34 -> 20 | N34: Islam | O34: Sasak | P34: SLTP/Sederajat | R34: Pelajar/Mahasiswa
B35: 8 | C35: 520101 0503083860 | D35: 28 | E35: Radiah | F35: KK | G35: 520101 4107390025 | H35: P | I35: Belum kawin | J35: Dasan Geres Barat | K35: 21192 | L35: 1958 | M35: =2019-L35 -> 61 | N35: Islam | O35: Sasak | P35: Tidak/Belum Sekolah | R35: Buruh Tani/Perkebunan
D36: 29 | E36: HJ. Rosita | F36: Famili Lain | G36: 520101 4112600004 | H36: P | I36: Belum kawin | J36: Dasan Geres Barat | K36: 20820 | L36: 1956 | M36: =2019-L36 -> 63 | N36: Islam | O36: Sasak | P36: Tamat SD/Sederajat | R36: Buruh Harian Lepas
B37: 9 | C37: 520101 0503082293 | D37: 30 | E37: Sahir | F37: KK | G37: 520101 0107730081 | H37: L | I37: Kawin | J37: Dasan Geres Barat | K37: 27061 | L37: 1974 | M37: =2019-L37 -> 45 | N37: Islam | O37: Sasak | P37: Tamat SD/Sederajat | R37: Wiraswasta
D38: 31 | E38: Hajjah Anisah | F38: Istri | G38: 520101 4107730293 | H38: P | I38: Kawin | J38: Dasan Geres Barat | K38: 27266 | L38: 1974 | M38: =2019-L38 -> 45 | N38: Islam | O38: Sasak | P38: Tamat SD/Sederajat | R38: Pedagang
D39: 32 | E39: Anang Sahrial | F39: Anak | G39: 520101 2203000001 | H39: L | I39: Belum kawin | J39: Dasan Geres | K39: 36607 | L39: 2000 | M39: =2019-L39 -> 19 | N39: Islam | O39: Sasak | P39: Tamat SD/Sederajat | R39: Pelajar/Mahasiswa
D40: 33 | E40: Ananda Sahira | F40: Anak | G40: 520101 4206060003 | H40: P | I40: Belum kawin | J40: Dasan Geres | K40: 38754 | L40: 2006 | M40: =2019-L40 -> 13 | N40: Islam | O40: Sasak | P40: Belum Tamat SD/Sederajat | R40: Pelajar/Mahasiswa
D41: 34 | E41: Sucita Anisa | F41: Anak | G41: 520101 6011140001 | H41: P | I41: Belum kawin | J41: Dasan Geres | K41: 41963 | L41: 2014 | M41: =2019-L41 -> 5 | N41: Islam | O41: Sasak | P41: Tidak/Belum Sekolah | R41: Tidak/Belum Sekolah
...

Sheet RT 05
B1: DATA INDUK PENDUDUK KELURAHAN DASAN GERES
B2: TAHUN 2019
B3: LINGKUNGAN DASAN GERES BARAT
B4: RT 05
B5: No | C5: Nomor KK | D5: Jumlah Jiwa | E5: Nama Lengkap/ Panggilan | F5: Kedudukan dalam Keluarga | G5: NIK | H5: Jenis Kelamin (L/P) | I5: Status Perkawinan | J5: Lahir | M5: Usia | N5: Agama | O5: Etnis | P5: Pendidikan Terakhir | Q5: Jurusan | R5: Pekerjaan
J6: Tempat | K6: Tanggal | L6: Tahun
B8: 1 | D8: 1 | E8: Lalu Masrinudin | F8: KK | G8: 520101 7977230001 | H8: L | I8: Kawin | K8: 26857 | L8: =YEAR(K8) -> 1973 | M8: =2019-L8 -> 46 | N8: Islam | P8: SLTP/MTSN | R8: Wiraswasta
D9: 2 | E9: Baiq Nismayati Darmawan | F9: Istri | G9: 520101 7001790001 | H9: P | I9: Kawin | K9: 28885 | L9: =YEAR(K9) -> 1979 | M9: =2019-L9 -> 40 | N9: Islam | P9: SLTA/MA | R9: PNS/ TNI/ POLRI
D10: 3 | E10: Baiq Puspita Ayu Anggini | F10: Anak | G10: 520101 6810980001 | H10: P | I10: Belum kawin | K10: 36086 | L10: =YEAR(K10) -> 1998 | M10: =2019-L10 -> 21 | N10: Islam | P10: SLTP/MTSN | R10: -
D11: 4 | E11: Baiq Dwi Ayu Lestari | F11: Anak | G11: 520101 6902040001 | H11: P | I11: Belum kawin | K11: 38037 | L11: =YEAR(K11) -> 2004 | M11: =2019-L11 -> 15 | N11: Islam | P11: SD/MI | R11: -
D12: 5 | E12: Baiq Desta Asri Ayu Anjani | F12: Anak | G12: 520101 6312080001 | H12: P | I12: Belum kawin | K12: 39805 | L12: =YEAR(K12) -> 2008 | M12: =2019-L12 -> 11 | N12: Islam | P12: - | R12: -
D13: 6 | E13: Lalu Faksi Widjaksa Darma | F13: Anak | G13: 520101 1704120002 | H13: L | I13: Belum kawin | K13: 41016 | L13: =YEAR(K13) -> 2012 | M13: =2019-L13 -> 7 | N13: Islam | P13: - | R13: -
B14: 2 | D14: 7 | E14: Lalu Nuhri | F14: KK | G14: 520101 0107600020 | H14: L | I14: Kawin | K14: 22251 | L14: =YEAR(K14) -> 1960 | M14: =2019-L14 -> 59 | N14: Islam | P14: SLTP/MTSN | R14: Petani
D15: 8 | E15: Saimah | F15: Istri | G15: 520101 4107740189 | H15: P | I15: Kawin | K15: 27211 | L15: =YEAR(K15) -> 1974 | M15: =2019-L15 -> 45 | N15: Islam | P15: SD/MI | R15: Lainnya
D16: 9 | E16: Baiq Maryani | F16: Anak | G16: 520101 4108820005 | H16: P | I16: Belum kawin | K16: 30164 | L16: =YEAR(K16) -> 1982 | M16: =2019-L16 -> 37 | N16: Islam | P16: SLTA/MA | R16: Wiraswasta
D17: 10 | E17: Lalu Sukmiardi | F17: Anak | G17: 520101 0108870002 | H17: L | I17: Belum kawin | K17: 31990 | L17: =YEAR(K17) -> 1987 | M17: =2019-L17 -> 32 | N17: Islam | P17: PT/ Akademi | R17: -
D18: 11 | E18: Baiq Sucitawati | F18: Anak | G18: 520101 6311870001 | H18: P | I18: Belum kawin | K18: 35757 | L18: =YEAR(K18) -> 1997 | M18: =2019-L18 -> 22 | N18: Islam | P18: SLTP/MTSN | R18: -
D19: 12 | E19: Baiq Nurul Hidayah | F19: Anak | G19: 520101 4802000001 | H19: P | I19: Belum kawin | K19: 36533 | L19: =YEAR(K19) -> 2000 | M19: =2019-L19 -> 19 | N19: Islam | P19: SD/MI | R19: -
D20: 13 | E20: Lalu Alfin Juliansah | F20: Anak | G20: 520101 3007090002 | H20: L | I20: Belum kawin | K20: 40024 | L20: =YEAR(K20) -> 2009 | M20: =2019-L20 -> 10 | N20: Islam | P20: - | R20: -
B21: 3 | D21: 14 | E21: Saparudin | F21: KK | G21: 520101 3112700079 | H21: L | I21: Kawin | K21: 25933 | L21: =YEAR(K21) -> 1970 | M21: =2019-L21 -> 49 | N21: Islam | P21: SD/MI | R21: Pekerja lepas
D22: 15 | E22: Suryah | F22: Istri | G22: 520101 7112750078 | H22: P | I22: Kawin | K22: 27759 | L22: =YEAR(K22) -> 1975 | M22: =2019-L22 -> 44 | N22: Islam | P22: SLTP/MTSN | R22: Lainnya
D23: 16 | E23: Nina Handayani | F23: Anak | G23: 520101 6106030001 | H23: P | I23: Belum kawin | K23: 37793 | L23: =YEAR(K23) -> 2003 | M23: =2019-L23 -> 16 | N23: Islam | P23: - | R23: -
D24: 17 | E24: Muhammad Handani Saputra | F24: Anak | G24: 520101 0103080005 | H24: L | I24: Belum kawin | K24: 39508 | L24: =YEAR(K24) -> 2008 | M24: =2019-L24 -> 11 | N24: Islam | P24: - | R24: -
D25: 18 | E25: Saofa Aulia Marwa | F25: Anak | G25: 520101 5611100001 | H25: P | I25: Belum kawin | K25: 40498 | L25: =YEAR(K25) -> 2010 | M25: =2019-L25 -> 9 | N25: Islam | P25: - | R25: -
B26: 4 | D26: 19 | E26: Rusdin | F26: KK | G26: 520101 3112800243 | H26: L | I26: Kawin | K26: 29586 | L26: =YEAR(K26) -> 1980 | M26: =2019-L26 -> 39 | N26: Islam | P26: SLTA/MA | R26: Wiraswasta
D27: 20 | E27: Nani Herawati | F27: Istri | G27: 520101 6402770003 | H27: P | I27: Kawin | K27: 28180 | L27: =YEAR(K27) -> 1977 | M27: =2019-L27 -> 42 | N27: Islam | P27: SLTA/MA | R27: PNS/ TNI/ POLRI
D28: 21 | E28: Haikal Aiman Tahir | F28: Anak | G28: 520101 3103130001 | H28: L | I28: Belum kawin | K28: 41364 | L28: =YEAR(K28) -> 2013 | M28: =2019-L28 -> 6 | N28: Islam | P28: - | R28: -
B29: 5 | D29: 22 | E29: Lalu Muhlil | F29: KK | G29: 520101 0107720162 | H29: L | I29: Kawin | K29: 25933 | L29: =YEAR(K29) -> 1970 | M29: =2019-L29 -> 49 | N29: Islam | P29: SLTA/MA | R29: Pekerja lepas
D30: 23 | E30: Baiq Fatmah | F30: Istri | G30: 520101 4107750399 | H30: P | I30: Kawin | K30: 27759 | L30: =YEAR(K30) -> 1975 | M30: =2019-L30 -> 44 | N30: Islam | P30: SLTA/MA | R30: Lainnya
D31: 24 | E31: Lalu Budi Hartawan | F31: Anak | G31: 520101 0711961001 | H31: L | I31: Belum kawin | K31: 35376 | L31: =YEAR(K31) -> 1996 | M31: =2019-L31 -> 23 | N31: Islam | P31: SLTA/MA | R31: -
D32: 25 | E32: Lalu Indra Hartawan | F32: Anak | G32: 520101 3009060002 | H32: L | I32: Belum kawin | K32: 37894 | L32: =YEAR(K32) -> 2003 | M32: =2019-L32 -> 16 | N32: Islam | P32: - | R32: -
D33: 26 | E33: Baiq Lizia Andini | F33: Anak | G33: 520101 4306120003 | H33: P | I33: Belum kawin | K33: 41063 | L33: =YEAR(K33) -> 2012 | M33: =2019-L33 -> 7 | N33: Islam | P33: - | R33: -
B34: 6 | C34: 520101 0503082330 | D34: 27 | E34: Lalu Muhlis | F34: KK | G34: 520101 3112590001 | H34: L | I34: Kawin | J34: Dasan Geres | K34: 21915 | L34: 1959 | M34: =2019-1959 -> 60 | N34: Islam | O34: Sasak | P34: SLTA/Sederajat | R34: Tukang Kayu
D35: 28 | E35: Rohanah | F35: Istri | G35: 520101 7112650050 | H35: P | I35: Kawin | J35: Dasan Geres | K35: 25568 | L35: 1969 | M35: =2019-1969 -> 50 | N35: Islam | O35: Sasak | P35: Tamat SD/Sederajat | R35: Pedagang
D36: 29 | E36: Lalu Heri Kuswanto | F36: Anak | G36: 520101 0502900001 | H36: L | I36: Belum kawin | J36: Dasan Geres Barat | K36: 34463 | L36: 1994 | M36: =2019-1994 -> 25 | N36: Islam | O36: Sasak | P36: Diploma lll | R36: Wiraswasta
D37: 30 | E37: Baiq Lilis Septiana | F37: Anak | G37: 520101 5409940002 | H37: P | I37: Belum kawin | J37: Dasan Geres | K37: 34591 | L37: 1994 | M37: =2019-1994 -> 25 | N37: Islam | O37: Sasak | P37: Diploma lll | R37: Pelajar/Mahasiswa
D38: 31 | E38: Baiq Yuli Desti Lisnawati | F38: Anak | G38: 520101 5212960001 | H38: P | I38: Belum kawin | J38: Dasan Geres Barat | K38: 35412 | L38: 1996 | M38: =2019-1996 -> 23 | N38: Islam | O38: Sasak | P38: Diploma lll | R38: Pelajar/Mahasiswa
B39: 7 | D39: 32 | E39: Lalu Mawardi | F39: KK | G39: 520101 3112740145 | H39: L | I39: Kawin | K39: 27394 | L39: =YEAR(K39) -> 1974 | M39: =2019-L39 -> 45 | N39: Islam | P39: SD/MI | R39: Pekerja lepas
D40: 33 | E40: Baiq Suyarni | F40: Istri | G40: 520101 5503740001 | H40: P | I40: Kawin | K40: 27225 | L40: =YEAR(K40) -> 1974 | M40: =2019-L40 -> 45 | N40: Islam | P40: SD/MI | R40: Lainnya
D41: 34 | E41: Lalu Fahrurozzi | F41: Anak | G41: 520101 0305870001 | H41: L | I41: Belum kawin | K41: 35584 | L41: =YEAR(K41) -> 1997 | M41: =2019-L41 -> 22 | N41: Islam | P41: SD/MI | R41: -
...

Sheet pindah kk
A1: No | B1: No. KK | C1: Jumlah | D1: Nama Lengkap/panggilan | E1: Kedudukan dalam Keluarga | F1: NIK | G1: Jenis Kelamin (L/P) | H1: Status Perkawinan | I1: Lahir | L1: Usia | M1: Agama | N1: Etnis | O1: Pendidikan Terakhir | P1: Jurusan | Q1: Pekerjaan | R1: Cacat | T1: Ada / Tidak
C2: Jiwa | I2: Tempat | J2: Tanggal | K2: Tahun | R2: Mental | S2: Fisik | T2: KK | U2: KTP/KIA | V2: Buku Nikah | W2: Akte Kelahiran
R3: 18 | S3: 19 | T3: 18 | U3: 19 | V3: 18 | W3: 19
D4: Muhamad Iksan Asgar | E4: Anak | F4: 520101 2609961001 | G4: L | I4: Dasan Geres Barat | J4: 26/09/1996 | K4: 1996 | L4: =2019-K4 -> 23 | M4: Islam | N4: sasak | O4: SLTA/Sederajat | Q4: Wiraswasta
C5: 16 | D5: Zuryati | E5: Anak | F5: 520101 4401800001 | G5: P | H5: Kawin | J5: 29224 | M5: Islam | O5: SLTP/MTSN | Q5: Pekerja lepas
C6: 17 | D6: Zaenap | E6: Anak | F6: 520101 4401830001 | G6: P | H6: Janda | J6: 30320 | M6: Islam | O6: SLTP/MTSN | Q6: Pekerja lepas
C7: 50 | D7: Nurul Anti | E7: Anak | F7: 520101 4107700250 | G7: P | H7: Belum kawin | I7: Dasan Geres | J7: 34171 | L7: =2019-K7 -> 2019 | M7: Islam | O7: SLTA/MA | Q7: - | R7: WNI | S7: Lingkungan Dasan Geres Barat No 12 RT 03 RW 01
C8: 58 | D8: Lalu Wirantana | E8: Anak | F8: 520101 1305920001 | G8: L | H8: Belum kawin | J8: 33737 | M8: Islam | O8: SLTA/MA | Q8: Pegawai swasta
C9: 4 | D9: Elisa Damasari | E9: Anak | F9: 520101 200403239 | G9: P | H9: Janda | J9: 33303 | M9: Islam | O9: SLTA/MA | Q9: -
C10: 205 | D10: Ayu Nurlianingsih | E10: Anak | F10: 520101 43 | G10: P | H10: Belum kawin | J10: 34488 | M10: Islam | N10: Sasak | O10: Belum Tamat SD/Sederajat | Q10: -
C11: 180 | D11: Muhammad Arfan | E11: Anak | G11: L | H11: Belum kawin | J11: 30498 | L11: =2019-K11 -> 2019 | M11: Islam | O11: SLTP/MTSN | Q11: Pekerja lepas | R11: WNI | S11: Lingkungan Dasan Geres Barat No 44 RT 03 RW 01
C12: 99 | D12: Suri Jawati | E12: Anak | F12: 520101 6803880001 | G12: P | H12: Kawin | J12: 32230 | M12: Islam | O12: SLTA/MA | Q12: Wiraswasta
C13: 174 | D13: Muhamad Rozi | E13: Anak | F13: 520101 0104900001 | G13: L | H13: Belum kawin | J13: 32964 | M13: Islam | O13: SLTA/MA | Q13: Pegawai swasta
C14: 216 | D14: Suhartini | E14: Anak | F14: 520101 4405970001 | G14: P | H14: Belum kawin | J14: 35554 | M14: Islam | O14: SLTP/MTSN | Q14: -
C15: 67 | D15: Lukmanudin | E15: Anak | F15: 520101 2104880001 | G15: L | H15: Belum kawin | J15: 30780 | L15: =2019-K15 -> 2019 | M15: Islam | O15: SLTA/MA | Q15: Wiraswasta
C16: 54 | D16: Alimuaddin | E16: Anak | F16: 520101 0808920001 | G16: L | H16: Belum kawin | J16: 33824 | L16: =2019-K16 -> 2019 | M16: Islam | O16: SLTA/MA | Q16: -
C17: 71 | D17: Mukinah | E17: Anak | F17: 520101 4402740001 | G17: P | H17: Belum kawin | J17: 27064 | M17: Islam | O17: SD/MI | Q17: -
C18: 73 | D18: Ramli | E18: Anak | F18: 520101 1004840001 | G18: L | H18: Belum kawin | J18: 30782 | M18: Islam | O18: SLTP/MTSN | Q18: PNS/TNI/ POLRI
C19: 137 | D19: Hamidah | E19: Anak | F19: 520101 5203340002 | G19: P | H19: Belum kawin | J19: 30906 | L19: =2019-K19 -> 2019 | M19: Islam | O19: SLTA/MA | Q19: PNS/TNI/ POLRI
C20: 138 | D20: Faozan | E20: Anak | F20: 520101 1003880002 | G20: L | H20: Belum kawin | J20: 31634 | L20: =2019-K20 -> 2019 | M20: Islam | O20: SLTA/MA | Q20: Pegawai swasta
C21: 17 | D21: Lana Mali’ah | E21: Anak | F21: 520101 6212970002 | G21: P | H21: Belum kawin | J21: 35786 | L21: =2019-K21 -> 2019 | M21: Islam | O21: SLTP/MTSN | Q21: -
C22: 149 | D22: Nurhayati | E22: Anak | F22: 520101 4304780001 | G22: L | H22: Belum kawin | J22: 28583 | L22: =2019-K22 -> 2019 | M22: Islam | O22: SD/MI | Q22: Pegawai swasta
C23: 150 | D23: Masyhun Safwan | E23: Anak | F23: 520101 1102870001 | G23: L | H23: Belum kawin | J23: 31819 | L23: =2019-K23 -> 2019 | M23: Islam | O23: PT/Akademi | Q23: Pekerja lepas
C24: 93 | D24: Yuliyarni | E24: Anak | F24: 520101 6707891001 | G24: P | H24: Belum kawin | J24: 32716 | L24: =2019-K24 -> 2019 | M24: Islam | O24: SLTA/MA | Q24: - | R24: WNI | S24: Lingkungan Dasan Geres Barat No 21 RT 03 RW 01

Sheet Sheet1
A1: 82 | C1: 303
A2: 48 | C2: 168
A3: 53 | C3: 201
A4: 58 | C4: 212
A5: 38 | C5: 139
A6: =SUM(A1:A5) -> 279 | C6: =SUM(C1:C5) -> 1023

Sheet MENINGGAL
C1: 110 | D1: Nikmah | E1: Istri | F1: 0 | G1: P | H1: Kawin | J1: 16619 | M1: Islam | O1: - | Q1: Petani

Sheet Rekap form
B2: REKAP DATA PENDUDUK
B3: LINGKUNGAN : ………………………………………….
B4: RT | C4: Jumlah Penduduk | E4: Total | F4: Jumlah KK | H4: Total | I4: Jumlah Duda / Janda | K4: Total | L4: Jumlah Lansia ( =>60 ) | N4: Total
C5: L | D5: P | F5: L | G5: P | I5: L | J5: P | L5: L | M5: P
B11: JUMLAH TOTAL
C15: Mengetahui
C16: Lurah Dasan Geres | K16: Kepala Lingkungan
C20: Hulaifi, S.H. | K20: ( )
C21: NIP. 19841231 201101 1 023

Sheet form tabel
B1: DATA INDUK PENDUDUK KELURAHAN DASAN GERES
B2: TAHUN 2021
B3: LINGKUNGAN :
B4: RT :
B5: No | C5: NO. KK | D5: Jumlah Jiwa | E5: Nama Lengkap/ Panggilan | F5: Kedudukan dalam Keluarga | G5: NIK | H5: Jenis Kelamin (L/P) | I5: Status Perkawinan | J5: Lahir | M5: Usia | N5: Agama | O5: Etnis | P5: Pendidikan Terakhir | Q5: Jurusan | R5: Pekerjaan
J6: Tempat | K6: Tanggal | L6: Tahun
B8: 1
B12: 2
B17: 3
B22: 4
B28: 5
B32: 6
B36: 7
B38: 8
B43: 9
D45: Mengetahui
D46: Lurah Dasan Geres | P46: Kepala Lingkungan
D48: Hulaifi, S.H. | P48: ( )
D49: NIP. 19841231 201101 1 023

Sheet Sheet2
