Workbook
Name _GoBack: 'RT 2'!$E$31

Sheet Rekap
B2: REKAP DATA PENDUDUK
B3: LINGKUNGAN DASAN GERES TENGAH
B4: RT | C4: Jumlah Penduduk | E4: Total | F4: Jumlah KK | H4: Total | I4: Jumlah Duda / Janda | K4: Total | L4: Jumlah Lansia ( =>60 ) | N4: Total
C5: L | D5: P | F5: L | G5: P | I5: L | J5: P | L5: L | M5: P
B6: RT 1 | C6: =COUNTIF('RT 1'!$H$8:$H$260,"L") -> 121 | D6: =COUNTIF('RT 1'!$H$8:$H$260,"P") -> 132 | E6: =SUM(C6:D6) -> 253 | F6: =COUNTIFS('RT 1'!$F$8:$F$260,"KK",'RT 1'!$H$8:$H$260,"L") -> 63 | G6: =COUNTIFS('RT 1'!$F$8:$F$260,"KK",'RT 1'!$H$8:$H$260,"P") -> 11 | H6: =SUM(F6:G6) -> 74 | I6: =COUNTIFS('RT 1'!$I$8:$I$260,"Cerai Mati",'RT 1'!$H$8:$H$260,"L")+COUNTIFS('RT 1'!$I$8:$I$260,"Cerai Hidup",'RT 1'!$H$8:$H$260,"L")+COUNTIFS('RT 1'!$I$8:$I$260,"Duda",'RT 1'!$H$8:$H$260,"L") -> 4 | J6: =COUNTIFS('RT 1'!$I$8:$I$260,"Cerai Mati",'RT 1'!$H$8:$H$260,"P")+COUNTIFS('RT 1'!$I$8:$I$260,"Cerai Hidup",'RT 1'!$H$8:$H$260,"P")+COUNTIFS('RT 1'!$I$8:$I$260,"Janda",'RT 1'!$H$8:$H$260,"P") -> 11 | K6: =SUM(I6:J6) -> 15 | L6: 11 | M6: 13 | N6: =SUM(L6:M6) -> 24
B7: RT 2 | C7: =COUNTIF('RT 2'!$H$8:$H$240,"L") -> 115 | D7: =COUNTIF('RT 2'!$H$8:$H$240,"P") -> 118 | E7: =SUM(C7:D7) -> 233 | F7: =COUNTIFS('RT 2'!$F$8:$F$240,"KK",'RT 2'!$H$8:$H$240,"L") -> 58 | G7: =COUNTIFS('RT 2'!$F$8:$F$240,"KK",'RT 2'!$H$8:$H$240,"P") -> 13 | H7: =SUM(F7:G7) -> 71 | I7: =COUNTIFS('RT 2'!$I$8:$I$240,"Cerai Mati",'RT 2'!$H$8:$H$240,"L")+COUNTIFS('RT 2'!$I$8:$I$240,"Cerai Hidup",'RT 2'!$H$8:$H$240,"L")+COUNTIFS('RT 2'!$I$8:$I$240,"Duda",'RT 2'!$H$8:$H$240,"L") -> 3 | J7: =COUNTIFS('RT 2'!$I$8:$I$240,"Cerai Mati",'RT 2'!$H$8:$H$240,"P")+COUNTIFS('RT 2'!$I$8:$I$240,"Cerai Hidup",'RT 2'!$H$8:$H$240,"P")+COUNTIFS('RT 2'!$I$8:$I$240,"Janda",'RT 2'!$H$8:$H$240,"P") -> 16 | K7: =SUM(I7:J7) -> 19 | L7: 11 | M7: 11 | N7: =SUM(L7:M7) -> 22
B8: RT 3 | C8: =COUNTIF('RT 3'!$H$8:$H$174,"L") -> 87 | D8: =COUNTIF('RT 3'!$H$8:$H$174,"P") -> 80 | E8: =SUM(C8:D8) -> 167 | F8: =COUNTIFS('RT 3'!$F$8:$F$174,"KK",'RT 3'!$H$8:$H$174,"L") -> 42 | G8: =COUNTIFS('RT 3'!$F$8:$F$174,"KK",'RT 3'!$H$8:$H$174,"P") -> 2 | H8: =SUM(F8:G8) -> 44 | I8: =COUNTIFS('RT 3'!$I$8:$I$174,"Cerai Mati",'RT 3'!$H$8:$H$174,"L")+COUNTIFS('RT 3'!$I$8:$I$174,"Cerai Hidup",'RT 3'!$H$8:$H$174,"L")+COUNTIFS('RT 3'!$I$8:$I$174,"Duda",'RT 3'!$H$8:$H$174,"L") -> 1 | J8: =COUNTIFS('RT 3'!$I$8:$I$174,"Cerai Mati",'RT 3'!$H$8:$H$174,"P")+COUNTIFS('RT 3'!$I$8:$I$174,"Cerai Hidup",'RT 3'!$H$8:$H$174,"P")+COUNTIFS('RT 3'!$I$8:$I$174,"Janda",'RT 3'!$H$8:$H$174,"P") -> 5 | K8: =SUM(I8:J8) -> 6 | L8: 10 | M8: 10 | N8: =SUM(L8:M8) -> 20
B9: RT 4 | C9: =COUNTIF('RT 4'!$H$8:$H$237,"L") -> 126 | D9: =COUNTIF('RT 4'!$H$8:$H$237,"P") -> 104 | E9: =SUM(C9:D9) -> 230 | F9: =COUNTIFS('RT 4'!$F$8:$F$237,"KK",'RT 4'!$H$8:$H$237,"L") -> 55 | G9: =COUNTIFS('RT 4'!$F$8:$F$237,"KK",'RT 4'!$H$8:$H$237,"P") -> 7 | H9: =SUM(F9:G9) -> 62 | I9: =COUNTIFS('RT 4'!$I$8:$I$237,"Cerai Mati",'RT 4'!$H$8:$H$237,"L")+COUNTIFS('RT 4'!$I$8:$I$237,"Cerai Hidup",'RT 4'!$H$8:$H$237,"L")+COUNTIFS('RT 4'!$I$8:$I$237,"Duda",'RT 4'!$H$8:$H$237,"L") -> 5 | J9: =COUNTIFS('RT 4'!$I$8:$I$237,"Cerai Mati",'RT 4'!$H$8:$H$237,"P")+COUNTIFS('RT 4'!$I$8:$I$237,"Cerai Hidup",'RT 4'!$H$8:$H$237,"P")+COUNTIFS('RT 4'!$I$8:$I$237,"Janda",'RT 4'!$H$8:$H$237,"P") -> 10 | K9: =SUM(I9:J9) -> 15 | L9: 8 | M9: 10 | N9: =SUM(L9:M9) -> 18
B10: JUMLAH TOTAL | C10: =SUM(C6:C9) -> 449 | D10: =SUM(D6:D9) -> 434 | E10: =SUM(E6:E9) -> 883 | F10: =SUM(F6:F9) -> 218 | G10: =SUM(G6:G9) -> 33 | H10: =SUM(H6:H9) -> 251 | I10: =SUM(I6:I9) -> 13 | J10: =SUM(J6:J9) -> 42 | ... N10: =SUM(N6:N9) -> 84
C14: Mengetahui
C15: Lurah Dasan Geres | K15: Kepala Lingkungan
C19: Hulaifi, S.H. | K19: M. Fahrizal
C20: NIP. 19841231 201101 1 023

Sheet RT 1
B1: DATA INDUK PENDUDUK KELURAHAN DASAN GERES
B2: TAHUN 2019
B3: LINGKUNGAN DASAN GERES TENGAH
B4: RT 01
B5: No | C5: Nomor KK | D5: Jumlah Jiwa | E5: Nama | F5: Status Dalam Keluarga | G5: NIK | H5: Jenis Kelamin | I5: Status Perkawinan | J5: Lahir | M5: Usia | N5: Agama | O5: Etnis | P5: Pendidikan | Q5: Jurusan | R5: Pekerjaan
J6: Tempat | K6: Tanggal | L6: Tahun
B8: 1 | D8: 1 | E8: Baiq Sarwati | F8: KK | G8: 520101 7112550000 | H8: P | I8: Janda | K8: 20454 | L8: 1955 | M8: =2019-L8 -> 64 | N8: Islam | P8: Tamat SD/Sederajat | R8: Lainnya
D9: 2 | E9: Baiq Trasning Ayumas Quraini | F9: Anak | G9: 520101 1661194003 | H9: P | I9: Kawin | K9: 34664 | L9: 1994 | M9: =2019-L9 -> 25 | N9: Islam | P9: PT/Akademi | R9: -
D10: 3 | E10: Alicia Ayu Khumaira | F10: Lain-lain | H10: P | I10: Belum kawin | K10: 41910 | L10: 2014 | M10: =2019-L10 -> 5 | N10: Islam | P10: - | R10: -
B11: 2 | C11: 520101 2705111425 | D11: 4 | E11: Lalu Edi Astawan | F11: KK | G11: 520101 0101840004 | H11: L | I11: Kawin | J11: Emere | K11: 30682 | L11: 1984 | M11: =2019-L11 -> 35 | N11: Islam | O11: Sasak | P11: SLTA/Sederajat | R11: Pegawai Negeri Sipil (PNS)
D12: 5 | E12: Herawati | F12: Istri | G12: 520101 7112860006 | H12: P | I12: Kawin | J12: Dasan Nyate | K12: 31777 | L12: 1986 | M12: =2019-L12 -> 33 | N12: Islam | O12: Sasak | P12: SLTA/Sederajat | R12: Mengurus Rumah Tangga
D13: 6 | E13: Baiq Siti Dira Kartika | F13: Anak | G13: 520101 5512080003 | H13: P | I13: Belum kawin | J13: Dasan Geres | K13: 39807 | L13: 2008 | M13: =2019-L13 -> 11 | N13: Islam | O13: Sasak | P13: Belum Tamat SD/Sederajat | R13: Pelajar/Mahasiswa
D14: 7 | E14: Baiq Silmi Ayudia Inara | F14: Anak | G14: 520101 4312150001 | H14: P | I14: Belum kawin | J14: Dasan Geres | K14: 42341 | L14: 2015 | M14: =2019-L14 -> 4 | N14: Islam | O14: Sasak | P14: Tidak/Belum Sekolah | R14: Belum/Tidak Bekerja
B15: 3 | C15: 520101 0503085270 | D15: 8 | E15: Lalu Muhamad Darmupik | F15: KK | G15: 520101 0107680068 | H15: L | I15: Kawin | J15: Kediri | K15: 25343 | L15: 1969 | M15: =2019-L15 -> 50 | N15: Islam | O15: Sasak | P15: SLTA/Sederajat | R15: Wiraswasta
D16: 9 | E16: Baiq Seniasih | F16: Istri | G16: 520101 4107740181 | H16: P | I16: Kawin | J16: Dasan Geres | K16: 25203 | L16: 1968 | M16: =2019-L16 -> 51 | N16: Islam | O16: Sasak | P16: SLTA/Sederajat | R16: Mengurus Rumah Tangga
D17: 10 | E17: Baiq Liza Anggraini | F17: Anak | G17: 520101 4107890437 | H17: P | I17: Belum kawin | J17: Mataram | K17: 32603 | L17: 1989 | M17: =2019-L17 -> 30 | N17: Islam | O17: Sasak | P17: SLTA/Sederajat | R17: Pelajar/Mahasiswa
D18: 11 | E18: Baiq Winda Andriani | F18: Anak | G18: 520101 4107910086 | H18: P | I18: Belum kawin | J18: Labuapi | K18: 33831 | L18: 1992 | M18: =2019-L18 -> 27 | N18: Islam | O18: Sasak | P18: SLTA/Sederajat | R18: Pelajar/Mahasiswa
D19: 12 | E19: Baiq Windi Handayani | F19: Anak | G19: 520101 4107940169 | H19: P | I19: Belum kawin | J19: Labuapi | K19: 35093 | L19: 1996 | M19: =2019-L19 -> 23 | N19: Islam | O19: Sasak | P19: SLTP/Sederajat | R19: Pelajar/Mahasiswa
D20: 13 | E20: Baiq Silvia Septiana | F20: Anak | G20: 520101 4107030202 | H20: P | I20: Belum kawin | J20: Dasan Geres | K20: 38248 | L20: 2004 | M20: =2019-L20 -> 15 | N20: Islam | O20: Sasak | P20: Belum Tamat SD/Sederajat | R20: Pelajar/Mahasiswa
D21: 14 | E21: Baiq Efril Maulidiya Putri | F21: Anak | G21: 520101 4107060195 | H21: P | I21: Belum kawin | J21: Dasan Geres | K21: 38824 | L21: 2006 | M21: =2019-L21 -> 13 | N21: Islam | O21: Sasak | P21: Belum Tamat SD/Sederajat | R21: Pelajar/Mahasiswa
B22: 4 | C22: 520101 3001150023 | D22: 15 | E22: Muksin | F22: KK | G22: 520101 0107720217 | H22: L | I22: Kawin | J22: Dasan Geres Tengah | K22: 28855 | L22: 1978 | M22: =2019-L22 -> 41 | N22: Islam | O22: Sasak | P22: Tamat SD/Sederajat | R22: Wiraswasta
D23: 16 | E23: Saniah | F23: Istri | G23: 520101 4404910006 | H23: P | I23: Kawin | J23: Sumbawa | K23: 33332 | L23: 1991 | M23: =2019-L23 -> 28 | N23: Islam | O23: Sasak | P23: SLTP/Sederajat | R23: Karyawan Swasta
D24: 17 | E24: Muhamad Alwan Taufiqurahman | F24: Anak | G24: 520101 0208080006 | H24: L | I24: Belum kawin | J24: Dasan Geres Tengah | K24: 39662 | L24: 2008 | M24: =2019-L24 -> 11 | N24: Islam | O24: Sasak | P24: Tidak/Belum Sekolah | R24: Belum/Tidak Bekerja
D25: 18 | E25: Muhammad Irwan Safwandi | F25: Anak | G25: 520101 0311150002 | H25: L | I25: Belum kawin | J25: Dasan Geres Tengah | K25: 42311 | L25: 2015 | M25: =2019-L25 -> 4 | N25: Islam | O25: Sasak | P25: Tidak/Belum Sekolah | R25: Belum/Tidak Bekerja
B26: 5 | C26: 520101 0503083751 | D26: 19 | E26: Alif | F26: KK | G26: 520101 0107570396 | H26: L | I26: Kawin | J26: Dasan Geres Tengah | K26: 21002 | L26: 1957 | M26: =2019-L26 -> 62 | N26: Islam | O26: Sasak | P26: Tidak/Belum Sekolah | R26: Buruh Harian Lepas
D27: 20 | E27: Rabiah | F27: Istri | G27: 520101 4107600091 | H27: P | I27: Kawin | J27: Dasan Geres Tengah | K27: 22098 | L27: 1960 | M27: =2019-L27 -> 59 | N27: Islam | O27: Sasak | P27: Tidak/Belum Sekolah | R27: Mengurus Rumah Tangga
B28: 6 | C28: 520101 1009120033 | D28: 21 | E28: Zaenal Abidin | F28: KK | G28: 520101 2707800005 | H28: L | I28: Kawin | J28: Dasan Geres | K28: 31985 | L28: 1987 | M28: =2019-L28 -> 32 | N28: Islam | O28: Sasak | P28: Tamat SD/Sederajat | R28: Wiraswasta
D29: 22 | E29: Sriatin Andriani | F29: Istri | G29: 520101 5005870007 | H29: P | I29: Kawin | J29: Dasan Geres | K29: 31907 | L29: 1987 | M29: =2019-L29 -> 32 | N29: Islam | O29: Sasak | P29: SLTA/Sederajat | R29: Wiraswasta
D30: 23 | E30: Argian Neza Adrian | F30: Anak | G30: 520101 2306090002 | H30: L | I30: Belum kawin | J30: Dasan Geres | K30: 39987 | L30: 2009 | M30: =2019-L30 -> 10 | N30: Islam | O30: Sasak | P30: Tidak/Belum Sekolah | R30: Belum/Tidak Bekerja
D31: 24 | E31: Indria Nielza Izzatin | F31: Anak | G31: 520101 4108180001 | H31: P | I31: Belum kawin | J31: Dasan Geres | K31: 43313 | L31: 2018 | M31: =2019-L31 -> 1 | N31: Islam | O31: Sasak | P31: Tidak/Belum Sekolah | R31: Belum/Tidak Bekerja
B32: 7 | C32: 520101 1411170024 | D32: 25 | E32: Saipudin | F32: KK | G32: 520113 0509700003 | H32: L | I32: Kawin | J32: Praya | K32: 25816 | L32: 1970 | M32: =2019-L32 -> 49 | N32: Islam | O32: Sasak | P32: SLTA/Sederajat | R32: Sopir
D33: 26 | E33: Masitah | F33: Istri | G33: 520113 7112750320 | H33: P | I33: Kawin | J33: Dasan Geres | K33: 27759 | L33: 1975 | M33: =2019-L33 -> 44 | N33: Islam | O33: Sasak | P33: SLTP/Sederajat | R33: Mengurus Rumah Tangga
D34: 27 | E34: Mohammad Ridho Suriyatama | F34: Anak | G34: 520113 2008050002 | H34: L | I34: Belum kawin | J34: Jembatan Kembar | K34: 38593 | L34: 2005 | M34: =2019-L34 -> 14 | N34: Islam | O34: Sasak | P34: Tamat SD/Sederajat | R34: Pelajar/Mahasiswa
D35: 28 | E35: Moh. Arif Sittaful Sohih | F35: Anak | G35: 520113 0109080001 | H35: L | I35: Belum kawin | J35: Jembatan Kembar | K35: 39692 | L35: 2008 | M35: =2019-L35 -> 11 | N35: Islam | O35: Sasak | P35: Belum Tamat SD/Sederajat | R35: Pelajar/Mahasiswa
D36: 29 | E36: Lingga Al Fatih | F36: Anak | G36: 520113 0906150001 | H36: L | I36: Belum kawin | J36: Dasan Geres | K36: 42164 | L36: 2015 | M36: =2019-L36 -> 4 | N36: Islam | O36: Sasak | P36: Tidak/Belum Sekolah | R36: Belum/Tidak Bekerja
B37: 8 | C37: 520101 0503082553 | D37: 30 | E37: Suandi | F37: KK | G37: 520101 0107840250 | H37: L | I37: Kawin | J37: Dasan Geres | K37: 30864 | L37: 1984 | M37: =2019-L37 -> 35 | N37: Islam | O37: Sasak | P37: Tamat SD/Sederajat | R37: Karyawan Swasta
D38: 31 | E38: Suryani | F38: Istri | G38: 520101 4107890018 | H38: P | I38: Kawin | J38: Gerung | K38: 32690 | L38: 1989 | M38: =2019-L38 -> 30 | N38: Islam | O38: Sasak | P38: SLTP/Sederajat | R38: Mengurus Rumah Tangga
D39: 32 | E39: Ervina Andriani | F39: Anak | G39: 520101 5805080001 | H39: P | I39: Belum kawin | J39: Dasan Geres | K39: 39586 | L39: 2008 | M39: =2019-L39 -> 11 | N39: Islam | O39: Sasak | P39: Tidak/Belum Sekolah | R39: Belum/Tidak Bekerja
D40: 33 | E40: M. Yandi Bilal Saputra | F40: Anak | G40: 520101 1410110003 | H40: L | I40: Belum kawin | J40: Gerung | K40: 40830 | L40: 2011 | M40: =2019-L40 -> 8 | N40: Islam | O40: Sasak | P40: Tidak/Belum Sekolah | R40: Belum/Tidak Bekerja
B41: 9 | C41: 520101 0503082409 | D41: 34 | E41: Syafi'in | F41: KK | G41: 520101 0107760273 | H41: L | I41: Kawin | J41: Dasan Geres | K41: 27942 | L41: 1976 | M41: =2019-L41 -> 43 | N41: Islam | O41: Sasak | P41: Tamat SD/Sederajat | R41: Buruh Harian Lepas
...

Sheet RT 2
B1: DATA INDUK PENDUDUK KELURAHAN DASAN GERES
B2: TAHUN 2019
B3: LINGKUNGAN DASAN GERES TENGAH
B4: RT 02
B5: No | C5: Nomor KK | D5: Jumlah Jiwa | E5: Nama | F5: Status Dalam Keluarga | G5: NIK | H5: Jenis Kelamin | I5: Status Perkawinan | J5: Lahir | M5: Usia | N5: Agama | O5: Etnis | P5: Pendidikan | Q5: Jurusan | R5: Pekerjaan
J6: tempat | K6: tanggal | L6: Tahun
B8: 1 | C8: 520101 1009120036 | D8: 1 | E8: Herman Jayadi | F8: KK | G8: 520101 1010800005 | H8: L | I8: Kawin | J8: Dasan Geres Tengah | K8: 29504 | L8: 1980 | M8: =2019-L8 -> 39 | N8: Islam | O8: Sasak | P8: Tamat SD/Sederajat | R8: Wiraswasta
D9: 2 | E9: Yopi Ariani | F9: Istri | G9: 520101 4101780005 | H9: P | I9: Kawin | J9: Kebumen | K9: 28491 | L9: 1978 | M9: =2019-L9 -> 41 | N9: Islam | O9: Sasak | P9: SLTP/Sederajat | R9: Mengurus Rumah Tangga
B10: 2 | D10: 3 | E10: Herwanto | F10: KK | G10: 520101 0708940003 | H10: L | I10: Kawin | K10: 34521 | L10: 1994 | M10: =2019-L10 -> 25 | N10: Islam | P10: SLTP/Sederajat | R10: Pekerja lepas
D11: 4 | E11: Nunung Januarti | F11: Istri | G11: 520101 6801940002 | H11: P | I11: Kawin | K11: 43493 | L11: 1994 | M11: =2019-L11 -> 25 | N11: Islam | P11: SLTP/Sederajat | R11: Lainnya
D12: 5 | E12: Oktavia Windari | F12: Anak | G12: 520101 6310120002 | H12: P | I12: Belum kawin | K12: 40978 | L12: 2012 | M12: =2019-L12 -> 7 | N12: Islam | P12: - | R12: -
B13: 3 | C13: 520101 0503082596 | D13: 6 | E13: Sanip | F13: KK | G13: 520101 0107570638 | H13: L | I13: Kawin | J13: Dasan Geres | K13: 21002 | L13: 1957 | M13: =2019-L13 -> 62 | N13: Islam | O13: Sasak | P13: Tamat SD/Sederajat | R13: Buruh harian Lepas
D14: 7 | E14: Misah | F14: Istri | G14: 520101 4107610171 | H14: P | I14: Kawin | J14: Jembatan Kembar | K14: 22463 | L14: 1961 | M14: =2019-L14 -> 58 | N14: Islam | O14: Sasak | P14: Tamat SD/Sederajat | R14: Buruh Tani/Perkebunan
B15: 4 | C15: 520101 1611110004 | D15: 8 | E15: Agus Rudiawan | F15: KK | G15: 520101 0708850005 | H15: L | I15: Kawin | J15: Dasan Geres Tengah | K15: 31266 | L15: 1985 | M15: =2019-L15 -> 34 | N15: Islam | O15: Sasak | P15: SLTP/Sederajat | R15: Wiraswasta
D16: 9 | E16: Eka Hurdiana | F16: Istri | G16: 520101 6301910001 | H16: P | I16: Kawin | N16: Islam
D17: 10 | E17: Anita Radiana | F17: Anak | G17: 520101 5810110001 | H17: P | I17: Belum kawin | J17: Dasan Geres Tengah | K17: 40834 | L17: 2011 | M17: =2019-L17 -> 8 | N17: Islam | O17: Sasak | P17: Tidak/Belum Sekolah | R17: Belum/Tidak Bekerja
B18: 5 | C18: 520101 0503082789 | D18: 11 | E18: Muhasan | F18: KK | G18: 520101 3112780046 | H18: L | I18: Kawin | J18: Dasan Geres | K18: 28206 | L18: 1977 | M18: =2019-L18 -> 42 | N18: Islam | O18: Sasak | P18: SLTA/Sederajat | R18: Wiraswasta
D19: 12 | E19: Mahuni | F19: Istri | G19: 520101 4107810148 | H19: P | I19: Kawin | J19: Dasan Lekong | K19: 29695 | L19: 1981 | M19: =2019-L19 -> 38 | N19: Islam | O19: Sasak | P19: Tamat SD/Sederajat | R19: Mengurus Rumah Tangga
B20: 6 | C20: 520101 0503082792 | D20: 13 | E20: Muhammat Tauhid | F20: KK | G20: 520101 0107690074 | H20: L | I20: Kawin | J20: Dasan Geres | K20: 31047 | L20: 1984 | M20: =2019-L20 -> 35 | N20: Islam | O20: Sasak | P20: Tamat SD/Sederajat | R20: Wiraswasta
D21: 14 | E21: Jama'ah | F21: Istri | G21: 520101 4107720471 | H21: P | I21: Kawin | J21: Tanjung | K21: 26481 | L21: 1972 | M21: =2019-L21 -> 47 | N21: Islam | O21: Sasak | P21: Tamat SD/Sederajat | R21: Mengurus Rumah Tangga
D22: 15 | E22: Isnawati | F22: Anak | G22: 520101 5611940001 | H22: P | I22: Belum kawin | J22: Dasan Geres | K22: 33797 | L22: 1992 | M22: =2019-L22 -> 27 | N22: Islam | O22: Sasak | P22: Diploma IV/ Strata I | R22: Pelajar/Mahasiswa
B23: 7 | C23: 520101 0907150008 | D23: 16 | E23: Hj. Nur'aini | F23: KK | G23: 520101 4107650354 | H23: P | I23: Cerai Mati | J23: Luwuk | K23: 27029 | L23: 1973 | M23: =2019-L23 -> 46 | N23: Islam | O23: Sasak | P23: SLTP/Sederajat | R23: Petani/Pekebun
D24: 17 | E24: Zuhurmah | F24: Anak | G24: 520101 4107930162 | H24: P | I24: Belum kawin | J24: Dasan Geres Tengah | K24: 34073 | L24: 1993 | M24: =2019-L24 -> 26 | N24: Islam | O24: Sasak | P24: SLTA/Sederajat | R24: Pelajar/Mahasiswa
D25: 18 | E25: Marpu'ah | F25: Anak | G25: 520101 6109951001 | H25: P | I25: Belum kawin | J25: Dasan Geres Tengah | K25: 34963 | L25: 1995 | M25: =2019-L25 -> 24 | N25: Islam | O25: Sasak | P25: SLTA/Sederajat | R25: Pelajar/Mahasiswa
D26: 19 | E26: Najamudin | F26: Anak | G26: 520101 0107990174 | H26: L | I26: Belum kawin | J26: Dasan Geres Tengah | K26: 36243 | L26: 1998 | M26: =2019-L26 -> 21 | N26: Islam | O26: Sasak | P26: SLTP/Sederajat | R26: Pelajar/Mahasiswa
D27: 20 | E27: Namilawati | F27: Anak | G27: 520101 4107030074 | H27: P | I27: Belum kawin | J27: Dasan Geres Tengah | K27: 37850 | L27: 2003 | M27: =2019-L27 -> 16 | N27: Islam | O27: Sasak | P27: Belum Tamat SD/Sederajat | R27: Pelajar/Mahasiswa
B28: 8 | D28: 21 | E28: Ratnaseh | F28: KK | G28: 520101 0202970001 | H28: L | I28: Kawin | K28: 11112 | L28: 1930 | M28: =2019-L28 -> 89 | N28: Islam | P28: - | R28: Pekerja lepas
D29: 22 | E29: Baiq Wirasaseh | F29: Istri | H29: P | I29: Kawin | K29: 11116 | L29: 1930 | M29: =2019-L29 -> 89 | N29: Islam | P29: - | R29: Lainnya
B30: 9 | C30: 520101 181115009 | D30: 23 | E30: Kariadi | F30: KK | G30: 520101 2508860002 | H30: L | I30: Kawin | J30: Dasan Geres Tengah | K30: 18270 | L30: 1986 | M30: =2019-L30 -> 33 | N30: Islam | O30: Sasak | P30: SLTP/Sederajat | R30: Wiraswasta
D31: 24 | E31: Nurhidayah | F31: Istri | G31: 520802 4303810001 | H31: P | I31: Kawin | J31: Papak | K31: 29648 | L31: 1981 | M31: =2019-L31 -> 38 | N31: Islam | O31: Sasak | P31: Tamat SD/Sederajat | R31: Mengurus Rumah Tangga
D32: 25 | E32: Nurpaza | F32: Anak | G32: 520302 6006040000 | H32: P | I32: Belum kawin | J32: Papak | K32: 38158 | L32: 2004 | M32: =2019-L32 -> 15 | N32: Islam | O32: Sasak | P32: Belum Tamat SD/Sederajat | R32: Pelajar/Mahasiswa
D33: 26 | E33: Aden Saputra | F33: Anak | G33: 520101 3101100001 | H33: L | I33: Belum kawin | J33: Dasan Geres Tengah | K33: 40209 | L33: 2010 | M33: =2019-L33 -> 9 | N33: Islam | O33: Sasak | P33: Tidak/Belum Sekolah | R33: Belum/Tidak Bekerja
B34: 10 | C34: 520101 2409120002 | D34: 27 | E34: Syari'ah | F34: KK | G34: 520101 4112640001 | H34: P | I34: Cerai Mati | J34: Aik Ampat | K34: 23712 | L34: 1964 | M34: =2019-L34 -> 55 | N34: Islam | O34: Sasak | P34: SLTP/Sederajat | R34: Pedagang
D35: 28 | E35: Muhammad Sodikin | F35: Anak | G35: 520101 2708990001 | H35: L | I35: Belum kawin | J35: Dasan Geres | K35: 36399 | L35: 1999 | M35: =2019-L35 -> 20 | N35: Islam | O35: Sasak | P35: Tamat SD/Sederajat | R35: Pelajar/Mahasiswa
D36: 29 | E36: Amelia Putri | F36: Anak | G36: 520101 4101070001 | H36: P | I36: Belum kawin | J36: Dasan Geres | K36: 39083 | L36: 2007 | M36: =2019-L36 -> 12 | N36: Islam | O36: Sasak | P36: Belum Tamat SD/Sederajat | R36: Pelajar/Mahasiswa
B37: 11 | C37: 520101 2808170013 | D37: 30 | E37: Hardi Wandi | F37: KK | G37: 520101 1005950003 | H37: L | I37: Kawin | J37: Dasan Geres Tengah | K37: 33311 | L37: 1991 | M37: =2019-L37 -> 28 | N37: Islam | O37: Sasak | P37: SLTP/Sederajat | R37: Wiraswasta
D38: 31 | E38: Mutiani | F38: Istri | G38: 520107 7112930146 | H38: P | I38: Kawin | J38: Lemer | K38: 34334 | L38: 1993 | M38: =2019-L38 -> 26 | N38: Islam | O38: Sasak | P38: Tamat SD/Sederajat | R38: Mengurus Rumah Tangga
D39: 32 | E39: Hamzah Sadeva | F39: Anak | G39: 520101 2806150003 | H39: L | I39: Belum kawin | J39: Sekotong | K39: 42183 | L39: 2015 | M39: =2019-L39 -> 4 | N39: Islam | O39: Sasak | P39: Tidak/Belum Sekolah | R39: Belum/Tidak Bekerja
B40: 12 | C40: 520101 0503082590 | D40: 33 | E40: Husnan | F40: KK | G40: 520101 0107800431 | H40: L | I40: Kawin | J40: Dasan Geres | K40: 28201 | L40: 1977 | M40: =2019-L40 -> 42 | N40: Islam | O40: Sasak | P40: SLTA/Sederajat | R40: Buruh harian Lepas
D41: 34 | E41: Minawati | F41: Istri | G41: 520101 7108830001 | H41: P | I41: Kawin | J41: Jelateng | K41: 30559 | L41: 1983 | M41: =2019-L41 -> 36 | N41: Islam | O41: Sasak | P41: SLTP/Sederajat | R41: Mengurus Rumah Tangga
...

Sheet RT 3
B1: DATA INDUK PENDUDUK KELURAHAN DASAN GERES
B2: TAHUN 2019
B3: LINGKUNGAN DASAN GERES TENGAH
B4: RT 03
B5: No | C5: Nomor KK | D5: Jumlah Jiwa | E5: Nama | F5: Status Dalam Keluarga | G5: NIK | H5: Jenis Kelamin | I5: Status Perkawinan | J5: Lahir | N5: Agama | O5: Etnis | P5: Pendidikan | Q5: Jurusan | R5: Pekerjaan
J6: Tempat | K6: Tanggal | L6: Tahun | M6: Umur
B8: 1 | C8: 520101 1805110016 | D8: 1 | E8: Lalu Kardi | F8: KK | G8: 520101 3112610034 | H8: L | I8: Kawin | J8: Dasan Geres | K8: 22646 | L8: 1961 | M8: =2019-L8 -> 58 | N8: Islam | O8: Sasak | P8: SLTA/Sederajat | R8: Pegawai Negeri Sipil (PNS)
D9: 2 | E9: Baiq Nurtiaman | F9: Istri | G9: 520101 6311650001 | H9: P | I9: Kawin | J9: Gerung | K9: 24069 | L9: 1965 | M9: =2019-L9 -> 54 | N9: Islam | O9: Sasak | P9: SLTA/Sederajat | R9: Mengurus Rumah Tangga
D10: 3 | E10: Lalu Banu Karisma Setiaji | F10: Anak | G10: 520101 0601940001 | H10: L | I10: Belum kawin | J10: Dasan Geres | K10: 34340 | L10: 1994 | M10: =2019-L10 -> 25 | N10: Islam | O10: Sasak | P10: SLTA/Sederajat | R10: Pelajar/Mahasiswa
D11: 4 | E11: Baiq Tri Kurniasih Lestari | F11: Anak | G11: 520101 4612010003 | H11: P | I11: Belum kawin | J11: Dasan Geres | K11: 37231 | L11: 2001 | M11: =2019-L11 -> 18 | N11: Islam | O11: Sasak | P11: Belum Tamat SD/Sederajat | R11: Pelajar/Mahasiswa
D12: 5 | E12: Lalu Nata Kusuma Wijaya | F12: Anak | G12: 520101 2602040003 | H12: L | I12: Belum kawin | J12: Dasan Geres | K12: 38043 | L12: 2004 | M12: =2019-L12 -> 15 | N12: Islam | O12: Sasak | P12: Belum Tamat SD/Sederajat | R12: Pelajar/Mahasiswa
B13: 2 | C13: 520101 0301180002 | D13: 6 | E13: Lalu Kadarisman Bayuaji M.Pd | F13: KK | G13: 520101 2001880003 | H13: L | I13: Kawin | J13: Dasan Geres | K13: 32162 | L13: 1988 | M13: =2019-L13 -> 31 | N13: Islam | O13: Sasak | P13: Strata-II | R13: Guru
D14: 7 | E14: Miftahul Aidni S.Pd | F14: Istri | G14: 527101 6711880003 | H14: P | I14: Kawin | J14: Mataram | K14: 32169 | L14: 1988 | M14: =2019-L14 -> 31 | N14: Islam | O14: Sasak | P14: Diploma IV/Strata I | R14: Mengurus Rumah Tangga
D15: 8 | E15: Lalu Gagasaji Nazlan Syakbana | F15: Anak | G15: 520101 0305180002 | H15: L | I15: Belum kawin | J15: Dasan Geres | K15: 43223 | L15: 2018 | M15: =2019-L15 -> 1 | N15: Islam | O15: Sasak | P15: Tidak/Belum Sekolah | R15: Belum/Tidak Bekerja
B16: 3 | C16: 520101 0503083570 | D16: 9 | E16: H. Lalu Dulhakim | F16: KK | G16: 520101 0107550147 | H16: L | I16: Kawin | J16: Dasan Geres | K16: 20454 | L16: 1955 | M16: =2019-L16 -> 64 | N16: Islam | O16: Sasak | P16: SLTA/Sederajat | R16: Pensiunan
D17: 10 | E17: Hj. Baiq Halwiyah | F17: Istri | G17: 520101 4107570406 | H17: P | I17: Kawin | J17: Dasan Geres | K17: 21550 | L17: 1958 | M17: =2019-L17 -> 61 | N17: Islam | O17: Sasak | P17: Tamat SD/Sederajat | R17: Mengurus Rumah Tangga
B18: 4 | C18: 520101 0503083675 | D18: 11 | E18: Lalu Sapwan | F18: KK | G18: 520101 0107630086 | H18: L | I18: Kawin | J18: Dasan Geres | K18: 23376 | L18: 1963 | M18: =2019-L18 -> 56 | N18: Islam | O18: Sasak | P18: SLTA/Sederajat | R18: Pegawai Negeri Sipil (PNS)
D19: 12 | E19: Sarmah | F19: Istri | G19: 520101 4106680001 | H19: P | I19: Kawin | J19: Dasan Geres | K19: 25720 | L19: 1970 | M19: =2019-L19 -> 49 | N19: Islam | O19: Sasak | P19: SLTA/Sederajat | R19: Mengurus Rumah Tangga
D20: 13 | E20: Lalu Muhammad Saepul | F20: Anak | G20: 520101 1803910001 | H20: L | I20: Belum kawin | J20: Dasan Geres | K20: 33315 | L20: 1991 | M20: =2019-L20 -> 28 | N20: Islam | O20: Sasak | P20: SLTA/Sederajat | R20: Wiraswasta
D21: 14 | E21: Lalu Amrullah Ali Seftawan | F21: Anak | G21: 520101 0209000003 | H21: L | I21: Belum kawin | J21: Dasan Geres Tengah | K21: 36771 | L21: 2000 | M21: =2019-L21 -> 19 | N21: Islam | O21: Sasak | P21: SLTP/Sederajat | R21: Pelajar/Mahasiswa
D22: 15 | E22: Lalu Habib Akbar | F22: Anak | G22: 520101 2505090003 | H22: L | I22: Belum kawin | J22: Dasan Geres | K22: 39958 | L22: 2009 | M22: =2019-L22 -> 10 | N22: Islam | O22: Sasak | P22: Belum Tamat SD/Sederajat | R22: Pelajar/Mahasiswa
B23: 5 | C23: 520101 0503082774 | D23: 16 | E23: Lalu Rustamaji | F23: KK | G23: 520101 0107700590 | H23: L | I23: Kawin | J23: Dasan Geres | K23: 25933 | L23: 1970 | M23: =2019-L23 -> 49 | N23: Islam | O23: Sasak | P23: SLTA/Sederajat | R23: Pegawai Negeri Sipil (PNS)
D24: 17 | E24: Baiq Nurul Hidayati | F24: Istri | G24: 520101 5001730001 | H24: P | I24: Kawin | J24: Lemokek | K24: 26674 | L24: 1973 | M24: =2019-L24 -> 46 | N24: Islam | O24: Sasak | P24: SLTA/Sederajat | R24: Mengurus Rumah Tangga
D25: 18 | E25: Lalu Virgian Ajiyatma | F25: Anak | G25: 520101 2608930001 | H25: L | I25: Belum kawin | J25: Dompu | K25: 34207 | L25: 1993 | M25: =2019-L25 -> 26 | N25: Islam | O25: Sasak | P25: SLTP/Sederajat | R25: Pelajar/Mahasiswa
D26: 19 | E26: Baiq Zahraeni Safitri | F26: Anak | G26: 520101 5401990001 | H26: P | I26: Belum kawin | J26: Dasan Geres | K26: 36174 | L26: 1999 | M26: =2019-L26 -> 20 | N26: Islam | O26: Sasak | P26: Tamat SD/MI | R26: Pelajar/Mahasiswa
D27: 20 | E27: Lalu Imam Sahbandi | F27: Anak | G27: 520101 0110050002 | H27: L | I27: Belum kawin | J27: Dasan Geres | K27: 38626 | L27: 2005 | M27: =2019-L27 -> 14 | N27: Islam | O27: Sasak | P27: Belum Tamat SD/Sederajat | R27: Pelajar/Mahasiswa
D28: 21 | E28: Baiq Zirwa Amanina | F28: Anak | G28: 520101 4505150001 | H28: P | I28: Belum kawin | J28: Gerung | K28: 42129 | L28: 2015 | M28: =2019-L28 -> 4 | N28: Islam | O28: Sasak | P28: Tidak/Belum Sekolah | R28: Belum/Tidak Bekerja
B29: 6 | C29: 520101 3112090004 | D29: 22 | E29: Lalu Ahmad Saufi | F29: KK | G29: 520101 3112760010 | H29: L | I29: Kawin | J29: Dasan Geres | K29: 28125 | L29: 1976 | M29: =2019-L29 -> 43 | N29: Islam | O29: Sasak | P29: SLTA/Sederajat | R29: Pegawai Negeri Sipil (PNS)
D30: 23 | E30: Baiq Markisah Murijati | F30: Istri | G30: 520101 5010810001 | H30: P | I30: Kawin | J30: Kediri Lobar | K30: 29869 | L30: 1981 | M30: =2019-L30 -> 38 | N30: Islam | O30: Sasak | P30: SLTA/Sederajat | R30: Mengurus Rumah Tangga
D31: 24 | E31: Lalu Indrabraja Samudera | F31: Anak | G31: 520101 1405050001 | H31: L | I31: Belum kawin | J31: Dasan Geres | K31: 38486 | L31: 2005 | M31: =2019-L31 -> 14 | N31: Islam | O31: Sasak | P31: Belum Tamat SD/Sederajat | R31: Pelajar/Mahasiswa
D32: 25 | E32: Baiq Rizkania Putri Zahra | F32: Anak | G32: 520101 5511090001 | H32: P | I32: Belum kawin | J32: Dasan Geres | K32: 40132 | L32: 2009 | M32: =2019-L32 -> 10 | N32: Islam | O32: Sasak | P32: Tidak/Belum Sekolah | R32: Belum/Tidak Bekerja
D33: 26 | E33: Baiq Nilam Lalita Gantari | F33: Anak | G33: 520101 5005170001 | H33: P | I33: Belum kawin | J33: Dasan Geres | K33: 42865 | L33: 2017 | M33: =2019-L33 -> 2 | N33: Islam | O33: Sasak | P33: Tidak/Belum Sekolah | R33: Belum/Tidak Bekerja
B34: 7 | C34: 520101 0302070007 | D34: 27 | E34: Lalu Jenar | F34: KK | G34: 520101 3112480006 | H34: L | I34: Cerai Mati | J34: Dasan Geres | K34: 17898 | L34: 1948 | M34: =2019-L34 -> 71 | N34: Islam | O34: Sasak | P34: Tamat SD/Sederajat | R34: Pensiunan
D35: 28 | E35: Baiq Rahmawati | F35: Anak | G35: 520101 5704880001 | H35: P | I35: Belum kawin | J35: Dasan Geres | K35: 32250 | L35: 1988 | M35: =2019-L35 -> 31 | N35: Islam | O35: Sasak | P35: SLTP/Sederajat | R35: Pelajar/Mahasiswa
D36: 29 | E36: Baiq Risma Agustina | F36: Anak | G36: 520101 4208980002 | H36: P | I36: Belum kawin | J36: Dasan Geres | K36: 36009 | L36: 1998 | M36: =2019-L36 -> 21 | N36: Islam | O36: Sasak | P36: Tamat SD/Sederajat | R36: Pelajar/Mahasiswa
B37: 8 | C37: 520101 2705111466 | D37: 30 | E37: Lalu Bambang | F37: KK | G37: 5201013112881023 | H37: L | I37: Kawin | J37: Dasan Gereng | K37: 32508 | L37: 1988 | M37: =2019-L37 -> 31 | N37: Islam | O37: Sasak | P37: SLTP/Sederajat | R37: Wiraswasta
D38: 31 | E38: Marhanah | F38: Istri | G38: 5201016002821002 | H38: P | I38: Kawin | J38: Bebidas | K38: 30002 | L38: 1982 | M38: =2019-L38 -> 37 | N38: Islam | O38: Sasak | P38: SLTP/Sederajat | R38: Mengurus Rumah Tangga
D39: 32 | E39: Lalu M. Irfandi | F39: Anak | G39: 5201010711090002 | H39: L | I39: Belum kawin | J39: Dasan Geres | K39: 40124 | L39: 2009 | M39: =2019-L39 -> 10 | N39: Islam | O39: Sasak | P39: Tidak/Belum Sekolah | R39: Belum/Tidak Bekerja
D40: 33 | E40: Lalu M. Rozikazawali | F40: Anak | G40: 5201011903141001 | H40: L | I40: Belum kawin | J40: Mataram | K40: 41717 | L40: 2014 | M40: =2019-L40 -> 5 | N40: Islam | O40: Sasak | P40: Tidak/Belum Sekolah | R40: Belum/Tidak Bekerja
B41: 9 | C41: 520101 0503082612 | D41: 34 | E41: Lalu Sukarmin | F41: KK | G41: 520101 0107770298 | H41: L | I41: Kawin | J41: Dasan Geres | K41: 29534 | L41: 1980 | M41: =2019-L41 -> 39 | N41: Islam | O41: Sasak | P41: SLTP/Sederajat | R41: Wiraswasta
...

Sheet RT 4
B1: DATA INDUK PENDUDUK KELURAHAN DASAN GERES
B2: TAHUN 2019
B3: LINGKUNGAN DASAN GERES TENGAH
B4: RT 04
B5: No | C5: Nomor KK | D5: Jumlah Jiwa | E5: Nama Lengkap/panggilan | F5: Kedudukan dalam Keluarga | G5: NIK | H5: Jenis Kelamin (L/P) | I5: Status Perkawinan | J5: Lahir | M5: Usia | N5: Agama | O5: Etnis | P5: Pendidikan | Q5: Jurusan | R5: Pekerjaan
J6: Tempat | K6: Tanggal | L6: Tahun
B8: 1 | C8: 520101 0503083804 | D8: 1 | E8: Dirawi | F8: KK | G8: 520101 0107490065 | H8: L | I8: Kawin | J8: Dasan Geres Tengah | K8: 18080 | L8: 1949 | M8: =2019-L8 -> 70 | N8: Islam | O8: Sasak | P8: Tidak/Belum Sekolah | R8: Buruh Tani/Perkebunan
D9: 2 | E9: Nuriah | F9: Istri | G9: 520101 4107530092 | H9: P | I9: Kawin | J9: Dasan Geres Tengah | K9: 19541 | L9: 1953 | M9: =2019-L9 -> 66 | N9: Islam | O9: Sasak | P9: Tidak/Belum Sekolah | R9: Buruh Tani/Perkebunan
D10: 3 | E10: Raodah | F10: Anak | G10: 520101 7112800438 | H10: P | I10: Cerai Hidup | J10: Dasan Geres | K10: 29586 | L10: 1980 | M10: =2019-L10 -> 39 | N10: Islam | O10: Sasak | P10: Tidak/Belum Sekolah | R10: Pedagang
D11: 4 | E11: Yuda Saputra | F11: Cucu | G11: 520101 0107050283 | H11: L | I11: Belum kawin | J11: Dasan Geres Tengah | K11: 38534 | L11: 2005 | M11: =2019-L11 -> 14 | N11: Islam | O11: Sasak | P11: Tidak/Belum Sekolah | R11: Belum/Tidak Bekerja
B12: 2 | C12: 520101 2404120013 | D12: 5 | E12: Iwan | F12: KK | G12: 520101 1208810002 | H12: L | I12: Kawin | J12: Dasan Geres Tengah | K12: 29810 | L12: 1981 | M12: =2019-L12 -> 38 | N12: Islam | O12: Sasak | P12: Tamat SD/Sederajat | R12: Buruh Tani/Perkebunan
D13: 6 | E13: Sakmah | F13: Istri | G13: 520101 7112880131 | H13: P | I13: Kawin | J13: Dasan Geres Tengah | K13: 32508 | L13: 1988 | M13: =2019-L13 -> 31 | N13: Islam | O13: Sasak | P13: Tamat SD/Sederajat | R13: Mengurus Rumah Tangga
D14: 7 | E14: Sucilawati | F14: Anak | G14: 520101 5008110001 | H14: P | I14: Belum kawin | J14: Gerung | K14: 40765 | L14: 2011 | M14: =2019-L14 -> 8 | N14: Islam | O14: Sasak | P14: Tidak/Belum Sekolah | R14: Belum/Tidak Bekerja
B15: 3 | C15: 520101 2705111342 | D15: 8 | E15: H. Zainudin | F15: KK | G15: 520101 0107650449 | H15: L | I15: Kawin | J15: Dasan Geres | K15: 23924 | L15: 1965 | M15: =2019-L15 -> 54 | N15: Islam | O15: Sasak | P15: Tamat SD/Sederajat | R15: Petani/Pekebun
D16: 9 | E16: Hj. Siti Jamilah | F16: Istri | G16: 520101 4107700609 | H16: P | I16: Kawin | J16: Dasan Geres | K16: 22252 | L16: 1960 | M16: =2019-L16 -> 59 | N16: Islam | O16: Sasak | P16: Tamat SD/Sederajat | R16: Pedagang
D17: 10 | E17: Azrin Hadi | F17: Anak | G17: 520101 1708870001 | H17: L | I17: Belum kawin | J17: Dasan Geres | K17: 32006 | L17: 1987 | M17: =2019-L17 -> 32 | N17: Islam | O17: Sasak | P17: SLTA/Sederajat | R17: Belum/Tidak Bekerja
D18: 11 | E18: Saihul Muttaqin | F18: Anak | G18: 520101 0205030001 | H18: L | I18: Belum kawin | J18: Dasan Geres | K18: 37743 | L18: 2003 | M18: =2019-L18 -> 16 | N18: Islam | O18: Sasak | P18: SLTP/Sederajat | R18: Pelajar/Mahasiswa
D19: 12 | E19: Husnul Yakin | F19: Anak | G19: 520101 0205030002 | H19: L | I19: Belum kawin | J19: Dasan Geres | K19: 37743 | L19: 2003 | M19: =2019-L19 -> 16 | N19: Islam | O19: Sasak | P19: SLTP/Sederajat | R19: Pelajar/Mahasiswa
B20: 4 | D20: 13 | E20: Hajjah Halimah | F20: KK | H20: P | I20: Janda | K20: 13149 | L20: 1935 | M20: =2019-L20 -> 84 | N20: Islam | O20: Sasak | P20: - | R20: Lainnya
B21: 5 | C21: 520101 1404141018 | D21: 14 | E21: Azwar Hamid | F21: KK | G21: 520101 2101840001 | H21: L | I21: Kawin | J21: Dasan Geres | K21: 34355 | L21: 1994 | M21: =2019-L21 -> 25 | N21: Islam | O21: Sasak | P21: SLTA/Sederajat | R21: Karyawan Honorer
D22: 15 | E22: Maznil Azmi | F22: Istri | G22: 520101 4107890267 | H22: P | I22: Kawin | J22: Mesanggok | K22: 32873 | L22: 1989 | M22: =2019-L22 -> 30 | N22: Islam | O22: Sasak | P22: SLTP/Sederajat | R22: Belum/Tidak Bekerja
D23: 16 | E23: Alifa Hibatillah | F23: Anak | G23: 520101 4704150001 | H23: P | I23: Belum kawin | J23: Dasan Geres | K23: 42101 | L23: 2015 | M23: =2019-L23 -> 4 | N23: Islam | O23: Sasak | P23: Tidak/Belum Sekolah | R23: Belum/Tidak Bekerja
D24: 17 | E24: Lutfi Hidayat | F24: Anak | G24: 520101 0512180001 | H24: L | I24: Belum kawin | J24: Dasan Geres | K24: 43439 | L24: 2018 | M24: =2019-L24 -> 1 | N24: Islam | O24: Sasak | P24: Tidak/Belum Sekolah | R24: Belum/Tidak Bekerja
D25: 18 | E25: Amni | F25: Famili Lain | G25: 520101 4107640124 | H25: P | I25: Belum kawin | J25: Dasan Geres Tengah | K25: 23559 | L25: 1964 | M25: =2019-L25 -> 55 | N25: Islam | O25: Sasak | P25: Tidak/Belum Sekolah | R25: Buruh Tani/Perkebunan
B26: 6 | C26: 520101 1208150013 | D26: 19 | E26: Satimah | F26: KK | G26: 520101 4107560106 | H26: P | I26: Cerai Mati | J26: Dasan Geres Tengah | K26: 20637 | L26: 1956 | M26: =2019-L26 -> 63 | N26: Islam | O26: Sasak | P26: Tidak/Belum Sekolah | R26: Buruh Harian Lepas
B27: 7 | D27: 20 | E27: Maryam | F27: KK | G27: 520101 7112650040 | H27: P | I27: Janda | J27: Dasan Geres | K27: 24107 | L27: 1965 | M27: =2019-L27 -> 54 | N27: Islam | O27: Sasak | P27: Tamat SD/Sederajat | R27: Buruh Harian Lepas
D28: 21 | E28: Hambali | F28: Anak | G28: 520101 3112940007 | H28: L | I28: Belum kawin | J28: Dasan Geres | K28: 34699 | L28: 1994 | M28: =2019-L28 -> 25 | N28: Islam | O28: Sasak | P28: Tamat SD/Sederajat | R28: Buruh Harian Lepas
D29: 22 | E29: Muhammad Taufik | F29: Anak | G29: 520101 3112970002 | H29: L | I29: Belum kawin | J29: Dasan Geres | K29: 35795 | L29: 1997 | M29: =2019-L29 -> 22 | N29: Islam | O29: Sasak | P29: Tamat SD/Sederajat | R29: Buruh Harian Lepas
D30: 23 | E30: Marwan | F30: Anak | G30: 520101 3110390002 | H30: L | I30: Belum kawin | J30: Dasan Geres | K30: 32963 | L30: 1990 | M30: =2019-L30 -> 29 | N30: Islam | O30: Sasak | P30: Tamat SD/Sederajat | R30: Buruh Harian Lepas
B31: 8 | C31: 520101 1011090029 | D31: 24 | E31: Muh Nasir | F31: KK | G31: 520101 3112650002 | H31: L | I31: Kawin | J31: Dasan Geres | K31: 23376 | L31: 1963 | M31: =2019-L31 -> 56 | N31: Islam | O31: Sasak | P31: Tamat SD/Sederajat | R31: Buruh Harian Lepas
D32: 25 | E32: Rafiah | F32: Istri | G32: 520101 7112710003 | H32: P | I32: Kawin | J32: Dasan Geres | K32: 26298 | L32: 1971 | M32: =2019-L32 -> 48 | N32: Islam | O32: Sasak | P32: Tamat SD/Sederajat | R32: Buruh Harian Lepas
D33: 26 | E33: Mahsun | F33: Anak | G33: 520101 1301880001 | H33: L | I33: Belum kawin | J33: Dasan Geres | K33: 32155 | L33: 1988 | M33: =2019-L33 -> 31 | N33: Islam | O33: Sasak | P33: SLTP/Sederajat | R33: Pelajar/Mahasiswa
D34: 27 | E34: Abdurrahman | F34: Anak | G34: 520101 0605970001 | H34: L | I34: Belum kawin | J34: Dasan Geres | K34: 35556 | L34: 1997 | M34: =2019-L34 -> 22 | N34: Islam | O34: Sasak | P34: Tamat SD/Sederajat | R34: Pelajar/Mahasiswa
D35: 28 | E35: Miftahul Janah | F35: Anak | G35: 520101 4101080001 | H35: P | I35: Belum kawin | J35: Dasan Geres | K35: 37622 | L35: 2003 | M35: =2019-L35 -> 16 | N35: Islam | O35: Sasak | P35: Tidak/Belum Sekolah | R35: Belum/Tidak Bekerja
B36: 9 | D36: 29 | E36: Badrun | F36: KK | G36: 520101 3112580000 | H36: L | I36: Kawin | K36: 21550 | L36: 1958 | M36: =2019-L36 -> 61 | N36: Islam | O36: Sasak | P36: SD/MI | R36: Wirswasta
D37: 30 | E37: Baiq Suliah | F37: Istri | G37: 520101 7112610000 | H37: P | I37: Kawin | K37: 22646 | L37: 1961 | M37: =2019-L37 -> 58 | N37: Islam | O37: Sasak | P37: SD/MI | R37: Lainnya
D38: 31 | E38: Sahirudin | F38: Anak | G38: 520101 0612880001 | H38: P | I38: Belum kawin | K38: 31575 | L38: 1986 | M38: =2019-L38 -> 33 | N38: Islam | O38: Sasak | P38: SLTP/MTSN | R38: Pekerja lepas
D39: 32 | E39: Ahmad Dani Usman | F39: Anak | G39: 520101 2810030001 | H39: L | I39: Belum kawin | K39: 37922 | L39: 2003 | M39: =2019-L39 -> 16 | N39: Islam | O39: Sasak | P39: - | R39: -
B40: 10 | C40: 520101 0503083797 | D40: 33 | E40: Halil | F40: KK | G40: 520101 1508781001 | H40: L | I40: Kawin | J40: Dasan Geres Tengah | K40: 28717 | L40: 1978 | M40: =2019-L40 -> 41 | N40: Islam | O40: Sasak | P40: Tamat SD/Sederajat | R40: Wiraswasta
D41: 34 | E41: Nurasiah | F41: Istri | G41: 520101 5208831001 | H41: P | I41: Kawin | J41: Tanjung Gunung | K41: 30540 | L41: 1983 | M41: =2019-L41 -> 36 | N41: Islam | O41: Sasak | P41: Tamat SD/Sederajat | R41: Wiraswasta
...

Sheet Sheet1
A1: 64 | C1: 225
A2: 62 | C2: 203
A3: 33 | C3: 138
A4: 51 | C4: 197
A5: =SUM(A1:A4) -> 210 | C5: =SUM(C1:C4) -> 763

Sheet Meninggal
A5: 45 | C5: 163 | D5: Haji Munawar | E5: KK | F5: 520101 3112470040 | G5: L | H5: Kawin | I5: 31-12-1947 | M5: Islam | O5: SD/MI | Q5: Pedagang | X5: RT 1
A6: 50 | B6: Tauhid | C6: Lain-lain | D6: 0 | E6: L | F6: Belum kawin | G6: 31-12-1968 | K6: Islam | M6: SD/MI | N6: Pekerja lepas | X6: RT 2
D7: Markan Ramadan | E7: Anak | F7: - | G7: L | H7: Belum kawin | I7: Dasan Geres Tengah | J7: 0 | K7: 0 | L7: =2019-K7 -> 2019 | M7: Islam | N7: Sasak | O7: - | P7: Wiraswasta
C8: 72 | D8: Jawariyah | E8: Lain-lain | F8: 520101 4107610067 | G8: P | H8: Kawin | I8: 31-12-1961 | L8: =2019-K8 -> 2019 | M8: Islam | O8: SD/MI | P8: Lainnya
A9: 59 | C9: 193 | D9: Lalu Wirantana | E9: KK | F9: 520101 0000710003 | G9: L | H9: Kawin | I9: 31-12-1971 | L9: =2019-K9 -> 2019 | M9: Islam | O9: SLTA/Sederajat | P9: PNS/TNI/POLRI
A10: 53 | C10: 165 | D10: Mahyam | E10: KK | F10: 0 | G10: P | H10: Janda | I10: 31-12-1980 | L10: =2019-K10 -> 2019 | M10: Islam | O10: Tamat SD/Sederajat | P10: Pekerja lepas
C11: 124 | D11: Baiq Faoziah | E11: Lain-lain | F11: 0 | G11: P | H11: Janda | J11: 31-12-1972 | L11: =2019-K11 -> 2019 | M11: Islam | N11: Sasak | O11: SLTA/MA | Q11: Pekerja lepas
C12: 139 | D12: Inaq Sitah | E12: Lain-lain | F12: 520101 7112370003 | G12: P | H12: Janda | J12: 31-12-1937 | L12: =2019-K12 -> 2019 | M12: Islam | N12: Sasak | O12: -
C13: 90 | D13: Hajjah Raodah | E13: Lain-lain | F13: 0 | G13: P | H13: Janda | J13: 14617 | L13: =2019-K13 -> 2019 | M13: Islam | N13: Sasak | O13: - | Q13: -

Sheet kawin
C5: 193 | D5: Maria Ulfa | E5: Anak | F5: 520101 6801970001 | G5: P | H5: Belum kawin | I5: 28-01-1997 | M5: Islam | O5: SLTA/MA | Q5: -
C6: 180 | D6: Muriah | E6: Anak | F6: 520101 4107850178 | G6: P | H6: Kawin | I6: 31-12-1988 | M6: Islam | O6: SLTP/MTSN | P6: -
C7: 118 | D7: Raehanah | E7: Anak | F7: 520101 4806910001 | G7: P | H7: Belum kawin | I7: 33455 | M7: Islam | O7: SLTA/MA | Q7: -
C8: 115 | D8: Fatimatuzzakrah | E8: Anak | F8: 520101 4203940001 | G8: P | H8: Belum kawin | J8: 34368 | M8: Islam | O8: SLTA/Sederajat | Q8: -
D9: Muh. Dian Saputra | E9: Anak | F9: 5201010403000002 | G9: L | H9: Belum Kawin | I9: Dasan Geres | J9: 43528 | K9: 2000 | L9: =2019-K9 -> 19 | M9: Islam | N9: Sasak | O9: SLTP/Sederajat | Q9: Pelajar/Mahasiswa
C10: 139 | D10: Zuryati | E10: Anak | F10: 520101 6807880002 | G10: P | H10: Kawin | I10: 28-07-1988 | L10: =2019-K10 -> 2019 | M10: Islam | O10: SLTA/Sederajat | P10: Lainnya
C11: 26 | D11: Wirasari | E11: Anak | F11: 0 | G11: P | H11: Janda | I11: 33976 | L11: =2019-K11 -> 2019 | M11: Islam | O11: SLTP/Sederajat | P11: Wiraswasta
C12: 198 | D12: Munisah | E12: Anak | F12: 520101 1106850001 | G12: L | H12: Belum kawin | I12: 31357 | L12: =2019-K12 -> 2019 | M12: Islam | O12: SLTA/Sederajat | P12: Wiraswasta
C13: 133 | D13: Siti Hadijah | E13: Anak | F13: 520101 4503940004 | G13: P | H13: Belum kawin | I13: 34457 | L13: =2019-K13 -> 2019 | M13: Islam | O13: SLTP/Sederajat | P13: Wiraswasta
C14: 56 | D14: Lalu Ambar Pusaka | E14: Anak | F14: 5201011307910003 | G14: L | H14: Belum kawin | I14: Dasan Geres | J14: 43659 | K14: 1991 | L14: =2019-K14 -> 28 | M14: Islam | N14: Sasak | O14: SLTA/Sederajat | Q14: Pelajar/Mahasiswa
C15: 161 | D15: Baiq Rahman Wahyuni | E15: Anak | F15: 520101 5408961001 | G15: P | H15: Belum kawin | J15: 14-08-1996 | L15: =2019-K15 -> 2019 | M15: Islam | N15: Sasak | O15: SLTP/MTSN | Q15: -
C16: 152 | D16: Baiq Muslehaini | E16: Anak | F16: 0 | G16: P | H16: Janda | J16: 31-12-1982 | L16: =2019-K16 -> 2019 | M16: Islam | N16: Sasak | O16: SLTA/Sederajat | Q16: Pekerja lepas
C17: 100 | D17: Muhasan | E17: Anak | F17: 520101 1003820001 | G17: L | H17: Belum kawin | J17: 30227 | L17: =2019-K17 -> 2019 | M17: Islam | N17: Sasak | O17: SLTA/MA | Q17: Pekerja lepas
C18: 114 | D18: Mawarni S.Pd | E18: Anak | F18: 520101 4107890389 | G18: P | H18: Belum kawin | J18: 31879 | L18: =2019-K18 -> 2019 | M18: Islam | N18: Sasak | O18: PT/Akademi | Q18: Pegawai swasta
C19: 115 | D19: Saean | E19: Anak | F19: 520101 1012920008 | G19: L | H19: Belum kawin | J19: 34619 | L19: =2019-K19 -> 2019 | M19: Islam | N19: Sasak | O19: SLTA/MA | Q19: -
C20: 119 | D20: Ahmad Habibi | E20: Anak | F20: 520101 1905840001 | G20: L | H20: Belum kawin | J20: 19-05-1984 | L20: =2019-K20 -> 2019 | M20: Islam | N20: Sasak | O20: PT/Akademi | Q20: Pekerja lepas

Sheet pindah keluar
A1: No | B1: NO. KK | C1: No Urut | D1: Nama | E1: Status Dalam Keluarga | F1: NIK | G1: Jenis Kelamin | H1: Status Perkawinan | I1: Lahir | M1: Agama | N1: Etnis | O1: Pendidikan | P1: Jurusan | Q1: Pekerjaan | R1: Cacat | T1: Ada/Tidak
I2: Tempat | J2: Tanggal | K2: Tahun | L2: Umur | R2: Memntal | S2: Fisik | T2: KTP/KIA | U2: Buku Nikah | V2: Akte Kelahiran
C3: 224 | D3: Maesarah | E3: Lain-lain | F3: 0 | G3: P | H3: Janda | J3: 18635 | M3: Islam | O3: - | Q3: -
C4: 225 | D4: Mustajab | E4: Lain-lain | F4: 0 | G4: L | H4: Belum kawin | J4: 29227 | M4: Islam | O4: SLTP/MTSN | Q4: -
C5: 222 | D5: Angga Julianto | E5: Lain-lain | F5: 0 | G5: L | H5: Belum kawin | J5: 37659 | L5: =2019-K5 -> 2019 | M5: Islam | O5: - | Q5: -
C6: 143 | D6: M Rizki Aditiya | E6: Lain-lain | F6: 0 | G6: L | H6: Belum kawin | I6: 41458 | L6: =2019-K6 -> 2019 | M6: Islam | O6: - | P6: -
C7: 62 | D7: Lalu Kukuh | E7: Lain-lain | F7: 0 | G7: L | H7: Belum kawin | J7: 36898 | L7: =2019-K7 -> 2019 | M7: Islam | N7: Sasak | O7: SD/MI | Q7: -
