Workbook
Name _GoBack: 'RT 01'!$F$8

Sheet Rekap
B2: REKAP DATA PENDUDUK
B3: LINGKUNGAN MENANG TIMUR
B4: RT | C4: Jumlah Penduduk | E4: Total | F4: Jumlah KK | H4: Total | I4: Jumlah Duda / Janda | K4: Total | L4: Jumlah Lansia ( =>60 ) | N4: Total
C5: L | D5: P | F5: L | G5: P | I5: L | J5: P | L5: L | M5: P
B6: RT 1 | C6: =COUNTIF('RT 01'!$H$8:$H$106,"L") -> 46 | D6: =COUNTIF('RT 01'!$H$8:$H$106,"P") -> 53 | E6: =SUM(C6:D6) -> 99 | F6: =COUNTIFS('RT 01'!$F$8:$F$106,"KK",'RT 01'!$H$8:$H$106,"L") -> 28 | G6: =COUNTIFS('RT 01'!$F$8:$F$106,"KK",'RT 01'!$H$8:$H$106,"P") -> 6 | H6: =SUM(F6:G6) -> 34 | I6: =COUNTIFS('RT 01'!$I$8:$I$106,"Cerai Mati",'RT 01'!$H$8:$H$106,"L")+COUNTIFS('RT 01'!$I$8:$I$106,"Cerai Hidup",'RT 01'!$H$8:$H$106,"L")+COUNTIFS('RT 01'!$I$8:$I$106,"Duda",'RT 01'!$H$8:$H$106,"L") -> 1 | J6: =COUNTIFS('RT 01'!$I$8:$I$106,"Cerai Mati",'RT 01'!$H$8:$H$106,"P")+COUNTIFS('RT 01'!$I$8:$I$106,"Cerai Hidup",'RT 01'!$H$8:$H$106,"P")+COUNTIFS('RT 01'!$I$8:$I$106,"Janda",'RT 01'!$H$8:$H$106,"P") -> 9 | K6: =SUM(I6:J6) -> 10 | L6: 6 | M6: 6 | N6: =SUM(L6:M6) -> 12
B7: RT 2 | C7: =COUNTIF('RT 02'!$H$8:$H$76,"L") -> 39 | D7: =COUNTIF('RT 02'!$H$8:$H$76,"P") -> 30 | E7: =SUM(C7:D7) -> 69 | F7: =COUNTIFS('RT 02'!$F$8:$F$76,"KK",'RT 02'!$H$8:$H$76,"L") -> 19 | G7: =COUNTIFS('RT 02'!$F$8:$F$76,"KK",'RT 02'!$H$8:$H$76,"P") -> 2 | H7: =SUM(F7:G7) -> 21 | I7: =COUNTIFS('RT 02'!$I$8:$I$76,"Cerai Mati",'RT 02'!$H$8:$H$76,"L")+COUNTIFS('RT 02'!$I$8:$I$76,"Cerai Hidup",'RT 02'!$H$8:$H$76,"L")+COUNTIFS('RT 02'!$I$8:$I$76,"Duda",'RT 02'!$H$8:$H$76,"L") -> 1 | J7: =COUNTIFS('RT 02'!$I$8:$I$76,"Cerai Mati",'RT 02'!$H$8:$H$76,"P")+COUNTIFS('RT 02'!$I$8:$I$76,"Cerai Hidup",'RT 02'!$H$8:$H$76,"P")+COUNTIFS('RT 02'!$I$8:$I$76,"Janda",'RT 02'!$H$8:$H$76,"P") -> 1 | K7: =SUM(I7:J7) -> 2 | L7: 6 | M7: 2 | N7: =SUM(L7:M7) -> 8
B8: RT 3 | C8: =COUNTIF('RT 03'!$H$8:$H$94,"L") -> 39 | D8: =COUNTIF('RT 03'!$H$8:$H$94,"P") -> 48 | E8: =SUM(C8:D8) -> 87 | F8: =COUNTIFS('RT 03'!$F$8:$F$94,"KK",'RT 03'!$H$8:$H$94,"L") -> 23 | G8: =COUNTIFS('RT 03'!$F$8:$F$94,"KK",'RT 03'!$H$8:$H$94,"P") -> 3 | H8: =SUM(F8:G8) -> 26 | I8: =COUNTIFS('RT 03'!$I$8:$I$94,"Cerai Mati",'RT 03'!$H$8:$H$94,"L")+COUNTIFS('RT 03'!$I$8:$I$94,"Cerai Hidup",'RT 03'!$H$8:$H$94,"L")+COUNTIFS('RT 03'!$I$8:$I$94,"Duda",'RT 03'!$H$8:$H$94,"L") -> 3 | J8: =COUNTIFS('RT 03'!$I$8:$I$94,"Cerai Mati",'RT 03'!$H$8:$H$94,"P")+COUNTIFS('RT 03'!$I$8:$I$94,"Cerai Hidup",'RT 03'!$H$8:$H$94,"P")+COUNTIFS('RT 03'!$I$8:$I$94,"Janda",'RT 03'!$H$8:$H$94,"P") -> 4 | K8: =SUM(I8:J8) -> 7 | L8: 2 | M8: 3 | N8: =SUM(L8:M8) -> 5
B9: JUMLAH TOTAL | C9: =SUM(C6:C8) -> 124 | D9: =SUM(D6:D8) -> 131 | E9: =SUM(E6:E8) -> 255 | F9: =SUM(F6:F8) -> 70 | G9: =SUM(G6:G8) -> 11 | H9: =SUM(H6:H8) -> 81 | I9: =SUM(I6:I8) -> 5 | J9: =SUM(J6:J8) -> 14 | ... N9: =SUM(N6:N8) -> 25
C13: Mengetahui
C14: Lurah Dasan Geres | K14: Kepala Lingkungan
C18: Hulaifi, S.H. | K18: Khairul Ansori
C19: NIP. 19841231 201101 1 023

Sheet RT 01
B1: DATA INDUK PENDUDUK KELURAHAN DASAN GERES
B2: TAHUN 2019
B3: LINGKUNGAN MENANG TIMUR
B4: RT : 01
B5: No | C5: Nomor KK | D5: Jumlah Jiwa | E5: Nama Lengkap/ Panggilan | F5: Kedudukan dalam Keluarga | G5: NIK | H5: Jenis Kelamin (L/P) | I5: Status Perkawinan | J5: Lahir | M5: Usia | N5: Agama | O5: Etnis | P5: Pendidikan Terakhir | Q5: Jurusan | R5: Pekerjaan
J6: Tempat | K6: Tanggal | L6: Tahun
B8: 1 | C8: 5201011309120030 | D8: 1 | E8: Khaerul Ansori | F8: KK | G8: 520101 0803880002 | H8: L | I8: Kawin | J8: menang timur | K8: 8 maret | L8: 1988 | M8: =2019-L8 -> 31 | N8: Islam | O8: sasak | P8: SLTA/MA | Q8: P A I | R8: Pegawai Pemerintah Non PNS
D9: 2 | E9: Siti Aisyah | F9: Istri | G9: 520101 6811910005 | H9: P | I9: Kawin | J9: kediri | K9: 28 November | L9: 1991 | M9: =2019-L9 -> 28 | N9: Islam | O9: sasak | P9: SLTA/MA | Q9: P A I | R9: Lainnya
D10: 3 | E10: Ahmad Danyal Ansori | F10: Anak | G10: 520101 3101131001 | H10: L | I10: Belum kawin | J10: menang timur | K10: 31 Januari | L10: 2013 | M10: =2019-L10 -> 6 | N10: Islam | O10: sasak | P10: TK | Q10: - | R10: Pelajar
B11: 2 | C11: 5201010503086886 | D11: 4 | E11: Haji Muhsinin | F11: KK | G11: 520101 0107650206 | H11: L | I11: Kawin | J11: menang timur | K11: 1 juli | L11: 1965 | M11: =2019-L11 -> 54 | N11: Islam | O11: sasak | P11: SLTP/MTSN | R11: Wiraswasta
D12: 5 | E12: Rohimah | F12: Istri | G12: 520101 4107700236 | H12: P | I12: Kawin | J12: menang timur | K12: 1 Juli | L12: 1970 | M12: =2019-L12 -> 49 | N12: Islam | O12: sasak | P12: SD/MI | R12: Pedagang
D13: 6 | E13: Rosida Nursanti | F13: Anak | G13: 520101 5006990002 | H13: P | I13: Belum kawin | J13: menang timur | K13: 10 Juni | L13: 1999 | M13: =2019-L13 -> 20 | N13: Islam | O13: sasak | P13: SLTA/MA | Q13: ilmu politik | R13: Mahasiswa
D14: 7 | E14: Halwatun Nisa | F14: Anak | G14: 520101 4403080003 | H14: P | I14: Belum kawin | J14: menang timur | K14: 4 Maret | L14: 2008 | M14: =2019-L14 -> 11 | N14: Islam | O14: sasak | P14: BLM TMT SD | R14: pelajar
B15: 3 | C15: 5201010503086856 | D15: 8 | E15: Saipulah | F15: KK | G15: 520101 0309620001 | H15: L | I15: Kawin | J15: menang timur | K15: 3 september | L15: 1962 | M15: =2019-L15 -> 57 | N15: Islam | O15: sasak | P15: SD/MI | Q15: - | R15: Pekerja lepas
D16: 9 | E16: Buniari | F16: Istri | G16: 520101 4107650248 | H16: P | I16: Kawin | J16: menang timur | K16: 1 juli | L16: 1965 | M16: =2019-L16 -> 54 | N16: Islam | O16: sasak | P16: SD/MI | Q16: - | R16: Pekerja lepas
D17: 10 | E17: Nurul Hidayah | F17: Anak | G17: 520101 6307980001 | H17: P | I17: Belum kawin | J17: menang timur | K17: 23 Juli | L17: 1998 | M17: =2019-L17 -> 21 | N17: Islam | O17: sasak | P17: SLTa/MTSN | Q17: administrasi | R17: mahasiswa
B18: 4 | C18: 5201010503086864 | D18: 11 | E18: Salihin | F18: KK | G18: 520101 0106670003 | H18: L | I18: Kawin | J18: menang timur | K18: 31 desember | L18: 1955 | M18: =2019-L18 -> 64 | N18: Islam | O18: sasak | P18: - | R18: Petani
D19: 12 | E19: Halimah | F19: Istri | G19: 520101 4507720002 | H19: P | I19: Kawin | J19: menang timur | K19: 31 desember | L19: 1957 | M19: =2019-L19 -> 62 | N19: Islam | O19: sasak | P19: - | R19: Petani
D20: 13 | E20: Zulkaraen | F20: Anak | G20: 520101 0310970001 | H20: L | I20: Belum kawin | J20: menang | K20: 9 juli | L20: 1995 | M20: =2019-L20 -> 24 | N20: Islam | O20: sasak | P20: SLTA/MA | R20: TKI ( Malaysia)
B21: 5 | C21: 5201010904150001 | D21: 14 | E21: Zulaimi | F21: KK | G21: 5201010312820002 | H21: L | I21: Kawin | J21: menang timur | K21: 2 juni | L21: 1985 | M21: =2019-L21 -> 34 | N21: Islam | O21: sasak | P21: SD/MI | R21: Buruh Tani
D22: 15 | E22: Makyah | F22: Istri | G22: 5201014506920003 | H22: P | I22: Kawin | J22: menang timur | K22: 5 juni | L22: 1992 | M22: =2019-L22 -> 27 | N22: Islam | O22: sasak | P22: SD/MI | R22: ibu rumah tangga
D23: 16 | E23: Yasmita Zahira | F23: anak | G23: 5201014311100002 | H23: P | I23: Belum kawin | J23: menang timur | K23: 3 januari | L23: 2011 | M23: =2019-L23 -> 8 | N23: Islam | O23: sasak | P23: - | R23: -
B24: 6 | C24: 5201010503086873 | D24: 17 | E24: Arbain | F24: KK | G24: 5201010107770238 | H24: L | I24: Kawin | J24: menang timur | K24: 1 juli | L24: 1977 | M24: =2019-L24 -> 42 | N24: Islam | O24: sasak | P24: SD/MI | R24: Buruh Tani
D25: 18 | E25: Sahni | F25: Istri | G25: 5201014107800327 | H25: P | I25: Kawin | J25: menang timur | K25: 1 juli | L25: 1980 | M25: =2019-L25 -> 39 | N25: Islam | O25: sasak | P25: SD/MI | R25: ibu rumah tangga
D26: 19 | E26: Nurhaini | F26: Anak | G26: 5201014107980334 | H26: P | I26: Belum kawin | J26: menang timur | K26: ;3 juni | L26: 1999 | M26: =2019-L26 -> 20 | N26: Islam | O26: sasak | P26: SLTA | Q26: Dakwah Mu'amalah | R26: Mahasiswi
B27: 7 | C27: 5201010503086839 | D27: 20 | E27: Ratiah | F27: KK | G27: 5201011902820002 | H27: L | I27: Kawin | J27: menang timur | K27: 31 desember | L27: 1978 | M27: =2019-L27 -> 41 | N27: Islam | O27: sasak | P27: - | R27: Pekerja lepas
D28: 21 | E28: Samiah | F28: Istri | G28: 5201017107860353 | H28: P | I28: Kawin | J28: menang timur | K28: 31 desember | L28: 1980 | M28: =2019-L28 -> 39 | N28: Islam | O28: sasak | P28: - | R28: Pekerja lepas
D29: 22 | E29: Najwatul Husna | F29: Anak | G29: 5201016011100001 | H29: P | I29: Belum kawin | J29: menang timur | K29: 3 Desember | L29: 2009 | M29: =2019-L29 -> 10 | N29: Islam | O29: sasak | P29: - | R29: -
B30: 8 | C30: 5201010503086779 | D30: 23 | E30: Jumadil | F30: KK | G30: 520101 1511790002 | H30: L | I30: Kawin | J30: menang timur | K30: 15 november | L30: 1997 | M30: =2019-L30 -> 22 | N30: Islam | O30: sasak | P30: SD/MI | R30: TKI ( Malaysia)
D31: 24 | E31: Mukiah | F31: Istri | G31: 520101 4102820005 | H31: P | I31: Kawin | J31: menang timur | K31: 1 februari | L31: 1982 | M31: =2019-L31 -> 37 | N31: Islam | O31: sasak | P31: - | R31: Pekerja lepas
D32: 25 | E32: Juliawan | F32: Anak | G32: 520101 1207970007 | H32: L | I32: Belum kawin | J32: menang timur | K32: 12 juli | L32: 1997 | M32: =2019-L32 -> 22 | N32: Islam | O32: sasak | P32: SD/MI | R32: TKI ( Malaysia)
D33: 26 | E33: Riadatul Janah | F33: Anak | G33: 520101 5305130001 | H33: P | I33: Belum kawin | J33: dasan geres | K33: 23 Mei | L33: 2013 | M33: =2019-L33 -> 6 | N33: Islam | O33: sasak | P33: SD/MI | R33: Pelajar
B34: 9 | C34: 5201012009120056 | D34: 27 | E34: Safiah | F34: KK | G34: 5201017112500093 | H34: P | I34: Cerai Mati | J34: menang timur | K34: 31 desember | L34: 1950 | M34: =2019-L34 -> 69 | N34: Islam | O34: sasak | P34: - | R34: Pekerja lepas
D35: 28 | E35: Makyah | F35: Anak | G35: 5201015503700001 | H35: P | I35: Cerai Mati | J35: menang timur | K35: 15 Maret | L35: 1970 | M35: =2019-L35 -> 49 | N35: Islam | O35: sasak | P35: - | R35: Pekerja lepas
B36: 10 | D36: 29 | E36: Hajjah Pertiwi | F36: KK | G36: 0 | H36: P | I36: Cerai Mati | J36: menang timur | K36: 31 desember | L36: 1975 | M36: =2019-L36 -> 44 | N36: Islam | P36: SD/MI | R36: Pedagang
B37: 11 | C37: 5201012009120062 | D37: 30 | E37: Ruslan | F37: KK | G37: 520101 1010870009 | H37: L | I37: Kawin | J37: menang timur | K37: 10 Oktober | L37: 1987 | M37: =2019-L37 -> 32 | N37: Islam | O37: sasak | P37: SD/MI | R37: Pekerja lepas
D38: 31 | E38: Maharani | F38: Istri | G38: 5201017112890123 | H38: P | I38: Kawin | J38: aik ampat | K38: 31 desember | L38: 1989 | M38: =2019-L38 -> 30 | N38: Islam | O38: sasak | P38: SD/MI | R38: Pedagang
D39: 32 | E39: Muhamad Ilham | F39: Anak | G39: 5201011002100001 | H39: L | I39: Belum kawin | J39: menang timur | K39: 16 November | L39: 2008 | M39: =2019-L39 -> 11 | N39: Islam | O39: sasak | P39: SD/MI | R39: pelajar
D40: 33 | E40: Muhamad Ipan Rijlan | F40: Anak | G40: 5201010603160002 | H40: L | I40: Belum kawin | J40: menang timur | K40: 6 Maret | L40: 2016 | M40: =2019-L40 -> 3 | N40: Islam | O40: sasak | P40: - | R40: -
B41: 12 | C41: 5201012009120057 | D41: 34 | E41: Amaq Noar | F41: KK | G41: 5201013112500131 | H41: L | I41: Kawin | J41: menang timur | K41: 31 desember 1950 | L41: 1950 | M41: =2019-L41 -> 69 | N41: Islam | O41: sasak | P41: - | R41: Pekerja lepas
...

Sheet RT 02
B1: DATA INDUK PENDUDUK KELURAHAN DASAN GERES
B2: TAHUN 2019
B3: LINGKUNGAN MENANG TIMUR
B4: RT 02
B5: No | C5: Nomor KK | D5: Jumlah Jiwa | E5: Nama Lengkap/ panggilan | F5: Kedudukan dalam Keluarga | G5: NIK | H5: Jenis Kelamin (L/P) | I5: Status Perkawinan | J5: Lahir | M5: Usia | N5: Agama | O5: Etnis | P5: Pendidikan Terakhir | Q5: jurusan | R5: Pekerjaan
J6: tempat | K6: Tanggal | L6: Tahun
B8: 1 | C8: 5201011511160003 | D8: 1 | E8: Ehsan | F8: KK | G8: 5201010803881116 | H8: L | I8: Kawin | J8: menang timur | K8: 43532 | L8: 1988 | M8: =2019-L8 -> 31 | N8: Islam | O8: sasak | P8: SLTA/MA | Q8: P A I | R8: Pegawai Pemerintah Non PNS
D9: 2 | E9: kamarudin | F9: Anak | G9: 520101 6811910005 | H9: P | I9: Kawin | J9: kediri | K9: 43797 | L9: 1991 | M9: =2019-L9 -> 28 | N9: Islam | O9: sasak | P9: SLTA/MA | Q9: P A I | R9: Lainnya
D10: 3 | E10: riki wahyudi | F10: cucu | G10: 520101 3101131001 | H10: L | I10: Belum kawin | J10: menang timur | K10: 43496 | L10: 2013 | M10: =2019-L10 -> 6 | N10: Islam | O10: sasak | P10: TK | Q10: - | R10: Pelajar
B11: 2 | C11: 5201010503086886 | D11: 4 | E11: Haji Muhsinin | F11: KK | G11: 520101 0107650206 | H11: L | I11: Kawin | J11: menang timur | K11: 43647 | L11: 1965 | M11: =2019-L11 -> 54 | N11: Islam | O11: sasak | P11: SLTP/MTSN | R11: Wiraswasta
D12: 5 | E12: Rohimah | F12: Istri | G12: 520101 4107700236 | H12: P | I12: Kawin | J12: menang timur | K12: 43647 | L12: 1970 | M12: =2019-L12 -> 49 | N12: Islam | O12: sasak | P12: SD/MI | R12: Pedagang
D13: 6 | E13: Rosida Nursanti | F13: Anak | G13: 520101 5006990002 | H13: P | I13: Belum kawin | J13: menang timur | K13: 43626 | L13: 1999 | M13: =2019-L13 -> 20 | N13: Islam | O13: sasak | P13: SLTA/MA | Q13: ilmu politik | R13: Mahasiswa
D14: 7 | E14: Halwatun Nisa | F14: Anak | G14: 520101 4403080003 | H14: P | I14: Belum kawin | J14: menang timur | K14: 43559 | L14: 2008 | M14: =2019-L14 -> 11 | N14: Islam | O14: sasak | P14: BLM TMT SD | R14: pelajar
B15: 3 | C15: 5201010503086856 | D15: 8 | E15: Saipulah | F15: KK | G15: 520101 0309620001 | H15: L | I15: Kawin | J15: menang timur | K15: 43711 | L15: 1962 | M15: =2019-L15 -> 57 | N15: Islam | O15: sasak | P15: SD/MI | Q15: - | R15: Pekerja lepas
D16: 9 | E16: Buniari | F16: Istri | G16: 520101 4107650248 | H16: P | I16: Kawin | J16: menang timur | K16: 43647 | L16: 1965 | M16: =2019-L16 -> 54 | N16: Islam | O16: sasak | P16: SD/MI | Q16: - | R16: Pekerja lepas
D17: 10 | E17: Nurul Hidayah | F17: Anak | G17: 520101 6307980001 | H17: P | I17: Belum kawin | J17: menang timur | K17: 43669 | L17: 1998 | M17: =2019-L17 -> 21 | N17: Islam | O17: sasak | P17: SLTA/MA | Q17: administrasi | R17: mahasiswa
B18: 4 | C18: 5201010503086864 | D18: 11 | E18: Salihin | F18: KK | G18: 520101 0106670003 | H18: L | I18: Kawin | J18: menang timur | K18: 43830 | L18: 1955 | M18: =2019-L18 -> 64 | N18: Islam | O18: sasak | P18: Tidak Sekolah | R18: Petani
D19: 12 | E19: Halimah | F19: Istri | G19: 520101 4507720002 | H19: P | I19: Kawin | J19: menang timur | K19: 43830 | L19: 1957 | M19: =2019-L19 -> 62 | N19: Islam | O19: sasak | P19: Tidak Sekolah | R19: Petani
D20: 13 | E20: Zulkaraen | F20: Anak | G20: 520101 0310970001 | H20: L | I20: Belum kawin | J20: menang | K20: 43655 | L20: 1995 | M20: =2019-L20 -> 24 | N20: Islam | O20: sasak | P20: SLTA/MA | R20: TKI ( Malaysia)
B21: 5 | C21: 5201010904150001 | D21: 14 | E21: Zulaimi | F21: KK | G21: 5201010312820002 | H21: L | I21: Kawin | J21: menang timur | K21: 43618 | L21: 1985 | M21: =2019-L21 -> 34 | N21: Islam | O21: sasak | P21: SD/MI | R21: Buruh Tani
D22: 15 | E22: Makyah | F22: Istri | G22: 5201014506920003 | H22: P | I22: Kawin | J22: menang timur | K22: 43621 | L22: 1992 | M22: =2019-L22 -> 27 | N22: Islam | O22: sasak | P22: SD/MI | R22: ibu rumah tangga
D23: 16 | E23: Yasmita Zahira | F23: anak | G23: 5201014311100002 | H23: P | I23: Belum kawin | J23: menang timur | K23: 43468 | L23: 2011 | M23: =2019-L23 -> 8 | N23: Islam | O23: sasak | P23: SD/MI | R23: Pelajar
B24: 6 | C24: 5201010503086673 | D24: 17 | E24: Serianto | F24: KK | G24: 5201013007750002 | H24: L | I24: Kawin | J24: menang timur | K24: 43676 | L24: 1968 | M24: =2019-L24 -> 51 | N24: Islam | O24: sasak | P24: SD/MI | R24: Buruh harian Lepas
D25: 18 | E25: Aeriah | F25: Istri | G25: 5201015205770001 | H25: P | I25: Kawin | J25: menang timur | K25: 43597 | L25: 1977 | M25: =2019-L25 -> 42 | N25: Islam | O25: sasak | P25: Tidak Sekolah | R25: Pembantu RT
D26: 19 | E26: Sahabudin | F26: Anak | G26: 5201011012920001 | H26: L | I26: Belum kawin | J26: menang timur | K26: 43813 | L26: 1992 | M26: =2019-L26 -> 27 | N26: Islam | O26: sasak | P26: SD/MI | R26: Buruh harian Lepas
D27: 20 | E27: Misaah | F27: Anak | G27: 5201016110940002 | H27: P | I27: Belum kawin | J27: Aik Ampat | K27: 43619 | L27: 1994 | M27: =2019-L27 -> 25 | N27: Islam | O27: sasak | P27: SLTA/MA | R27: Pelajar
B28: 7 | C28: 5201011409120008 | D28: 21 | E28: Mahli | F28: KK | G28: 5201013112750284 | H28: L | I28: Kawin | J28: Menang Timur | K28: 43830 | L28: 1954 | M28: =2019-L28 -> 65 | N28: Islam | O28: sasak | P28: SD/MI | R28: Wiraswasta
D29: 22 | E29: Sriani | F29: Istri | G29: 5201017112800273 | H29: P | I29: Kawin | J29: menang timur | K29: 43830 | L29: 1980 | M29: =2019-L29 -> 39 | N29: Islam | O29: sasak | P29: SD/MI | R29: ibu rumah tangga
D30: 23 | E30: Serlina | F30: Anak | G30: 5201016809040001 | H30: P | I30: Belum kawin | J30: menang timur | K30: 43734 | L30: 2004 | M30: =2019-L30 -> 15 | N30: Islam | O30: sasak | P30: SLTP/MTSN | R30: Pelajar
D31: 24 | E31: Abdul Azis | F31: Anak | G31: 5201012405100006 | H31: L | I31: Belum kawin | J31: menang timur | K31: 43609 | L31: 2010 | M31: =2019-L31 -> 9 | N31: Islam | O31: sasak | P31: SD/MI | R31: Pelajar
D32: 25 | E32: Rademah | F32: Anak | G32: 5201017101750001 | H32: P | I32: Belum kawin | J32: menang timur | K32: 43616 | L32: 1965 | M32: =2019-L32 -> 54 | N32: Islam | O32: sasak | P32: Tidak Sekolah | R32: Pelajar
B33: 8 | C33: 5201010503086964 | D33: 26 | E33: Ahmad | F33: KK | G33: 5201012011630001 | H33: L | I33: Kawin | J33: menang timur | K33: 43789 | L33: 1963 | M33: =2019-L33 -> 56 | N33: Islam | O33: sasak | P33: SD/MI | R33: Buruh harian Lepas
D34: 27 | E34: Alimah | F34: Istri | G34: 5201015005680002 | H34: P | I34: Kawin | J34: menang timur | K34: 43595 | L34: 1968 | M34: =2019-L34 -> 51 | N34: Islam | O34: sasak | P34: SD/MI | R34: Buruh harian Lepas
D35: 28 | E35: Hambali | F35: Anak | G35: 52010111203970004 | H35: L | I35: Belum kawin | J35: menang timur | K35: 43689 | L35: 1997 | M35: =2019-L35 -> 22 | N35: Islam | O35: sasak | P35: SLTP/MTSN | R35: Wiraswasta
B36: 9 | C36: 5201013108160003 | D36: 29 | E36: Saimah | F36: KK | G36: 5201017112680038 | H36: P | I36: Belum kawin | J36: menang timur | K36: 43830 | L36: 1968 | M36: =2019-L36 -> 51 | N36: Islam | O36: sasak | P36: Tidak Sekolah | R36: Buruh harian Lepas
B37: 10 | C37: 5201011109140181 | D37: 30 | E37: Mahnim | F37: KK | G37: 5201017112560005 | H37: L | I37: Cerai Mati | J37: menang timur | K37: 43830 | L37: 1956 | M37: =2019-L37 -> 63 | N37: Islam | O37: sasak | P37: SD/MI | R37: Buruh harian Lepas
D38: 31 | E38: Maksum Abuandi | F38: Istri | G38: 5201013112910025 | H38: L | I38: Belum kawin | J38: menang timur | K38: 43830 | L38: 1991 | M38: =2019-L38 -> 28 | N38: Islam | O38: sasak | P38: SLTA/MA | R38: Buruh harian Lepas
B39: 11 | C39: 5201010308100015 | D39: 32 | E39: Suhaimi | F39: Kk | G39: 5201013112750146 | H39: L | I39: Kawin | J39: menang timur | K39: 43830 | L39: 1975 | M39: =2019-L39 -> 44 | N39: Islam | O39: sasak | P39: SD/MI | R39: Wiraswasta
D40: 33 | E40: Rohani | F40: Istri | G40: 5201015011800006 | H40: P | I40: Kawin | J40: menang timur | K40: 43779 | L40: 1980 | M40: =2019-L40 -> 39 | N40: Islam | O40: sasak | P40: SD/MI | R40: Tidak Bekerja
D41: 34 | E41: Erni Johan | F41: Anak | G41: 5201016008000001 | H41: P | I41: Belum kawin | J41: menang timur | K41: 43689 | L41: 2000 | M41: =2019-L41 -> 19 | N41: Islam | O41: sasak | P41: SD/MI | R41: Pelajar
...

Sheet RT 03
B1: DATA INDUK PENDUDUK KELURAHAN DASAN GERES
B2: TAHUN 2019
B3: LINGKUNGAN MENANG TIMUR
B4: RT : 03
B5: No | C5: NIK | D5: Jumlah Jiwa | E5: Nama Lengkap/ Panggilan | F5: Kedudukan dalam Keluarga | G5: NIK | H5: Jenis Kelamin (L/P) | I5: Status Perkawinan | J5: Lahir | N5: Agama | O5: Etnis | P5: Pendidikan Terakhir | Q5: Jurusan | R5: Pekerjaan
J6: Tempat | K6: Tanggal | L6: Tahun | M6: Umur
B8: 1 | C8: 5201012706120007 | D8: 1 | E8: Redwan | F8: KK | G8: 520101 3112880099 | H8: L | I8: Kawin | J8: Aik Ampat | K8: 43830 | L8: 1988 | M8: =2019-L8 -> 31 | N8: Islam | O8: Sasak | P8: SD/MI | R8: Buruh Harian Lepas
D9: 2 | E9: Horiah | F9: Istri | G9: 520101 5011920007 | H9: P | I9: Kawin | J9: Aik Ampat | K9: 43779 | L9: 1992 | M9: =2019-L9 -> 27 | N9: Islam | O9: Sasak | P9: SD/MI | R9: Ibu Rumah Tangga
D10: 3 | E10: Siti Raehanun | F10: Anak | G10: 520101 5302090001 | H10: P | I10: Belum kawin | J10: Aik Ampat | K10: 43509 | L10: 2009 | M10: =2019-L10 -> 10 | N10: Islam | O10: Sasak | P10: SD/MI | R10: Pelajar
B11: 2 | C11: 520101 0503086683 | D11: 4 | E11: Kadir | F11: KK | G11: 520101 1502600004 | H11: L | I11: Kawin | J11: Menang Timur | K11: 12830 | L11: 1935 | M11: =2019-L11 -> 84 | N11: Islam | O11: Sasak | P11: TAMAT SD/SEDERAJAT | R11: Petani
D12: 5 | E12: Muniah | F12: Istri | G12: 520101 4105720001 | H12: P | I12: Kawin | J12: Menang Timur | K12: 12905 | L12: 1935 | M12: =2019-L12 -> 84 | N12: Islam | O12: Sasak | P12: TAMAT SD/SEDERAJAT | R12: Mengurus Rumah Tangga
D13: 6 | E13: Selemah | F13: Anak | G13: 520101 5112630001 | H13: P | I13: Janda | J13: Menang Timur | K13: 23356 | L13: 1963 | M13: =2019-L13 -> 56 | N13: Islam | O13: Sasak | P13: TAMAT SD/SEDERAJAT | R13: Buruh Harian Lepas
D14: 7 | E14: Muhammad Gusni | F14: Cucu | G14: 520101 0103970001 | H14: L | I14: Belum kawin | J14: Menang Timur | K14: 35228 | L14: 1996 | M14: =2019-L14 -> 23 | N14: Islam | O14: Sasak | P14: SLTA/SEDERAJAT | R14: Buruh Harian Lepas
B15: 3 | C15: 5201012405120017 | D15: 8 | E15: Nasarudin | F15: KK | G15: 520101 0207830001 | H15: L | I15: Kawin | J15: Menang Timur | K15: 43648 | L15: 1983 | M15: =2019-L15 -> 36 | N15: Islam | O15: Sasak | P15: SD/MI | R15: Wiraswasta
D16: 9 | E16: Suarni | F16: Istri | G16: 520101 6704910001 | H16: P | I16: Kawin | J16: Menang Timur | K16: 43582 | L16: 1991 | M16: =2019-L16 -> 28 | N16: Islam | O16: Sasak | P16: SD/MI | R16: Ibu Rumah Tangga
D17: 10 | E17: Hairul Azmi | F17: Anak | G17: 520101 2703070003 | H17: L | I17: Belum kawin | J17: Gerung | K17: 43545 | L17: 2007 | M17: =2019-L17 -> 12 | N17: Islam | O17: Sasak | P17: SD/MI | R17: Pelajar
B18: 4 | C18: 520101 0503086626 | D18: 11 | E18: Murad | F18: KK | G18: 520101 0905700001 | H18: L | I18: Kawin | J18: Menang Timur | K18: 25697 | L18: 1970 | M18: =2019-L18 -> 49 | N18: Islam | O18: Sasak | P18: TAMAT SD/SEDERAJAT | R18: Buruh Harian Lepas
D19: 12 | E19: Rumini | F19: Istri | G19: 520101 4302700001 | H19: P | I19: Kawin | J19: Menang Timur | K19: 25602 | L19: 1970 | M19: =2019-L19 -> 49 | N19: Islam | O19: Sasak | P19: TAMAT SD/SEDERAJAT | R19: Buruh Harian Lepas
D20: 13 | E20: Ruminah | F20: Anak | G20: 520101 6606011001 | H20: P | I20: Belum kawin | J20: Menang Timur | K20: 37068 | L20: 2001 | M20: =2019-L20 -> 18 | N20: Islam | O20: Sasak | P20: SLTP/SEDERAJAT | R20: Pelajar
D21: 14 | E21: M Hardi | F21: Anak | G21: 520101 0701090003 | H21: L | I21: Belum kawin | J21: Gerung | K21: 39820 | L21: 2009 | M21: =2019-L21 -> 10 | N21: Islam | O21: Sasak | P21: TIDAK/BELUM SEKOLAH | R21: Belum Bekerja
B22: 5 | D22: 15 | E22: Hajjah Nurul Hidayah | F22: KK | G22: 520101 4805600001 | H22: P | I22: Janda | K22: 22044 | L22: 1960 | M22: =2019-L22 -> 59 | N22: Islam | O22: Sasak | P22: - | R22: Petani
D23: 16 | E23: Musahar | F23: Anak | G23: 0 | H23: L | I23: Belum kawin | K23: 28469 | L23: 1977 | M23: =2019-L23 -> 42 | N23: Islam | O23: Sasak | P23: SD/MI | R23: -
B24: 6 | C24: 5201010503089385 | D24: 17 | E24: Haji M Kamil | F24: KK | G24: 5201011902850001 | H24: L | I24: Kawin | J24: Lombok barat | K24: 16560 | L24: 1974 | M24: =2019-L24 -> 45 | N24: Islam | O24: Sasak | P24: SD/MI | R24: Sopir
D25: 18 | E25: Nurjanah | F25: Istri | G25: 5201017105880001 | H25: P | I25: Kawin | J25: Bawak Gunung | K25: 20366 | L25: 1985 | M25: =2019-L25 -> 34 | N25: Islam | O25: Sasak | P25: SLTP/MTSN | R25: Ibu Rumah Tangga
D26: 19 | E26: Putri Nabila | F26: Anak | G26: 5201014907080002 | H26: P | I26: Belum kawin | J26: Aik Ampat | K26: 36614 | L26: 2008 | M26: =2019-L26 -> 11 | N26: Islam | O26: Sasak | P26: SD/MI | R26: Pelajar
B27: 7 | C27: 520101 0503086709 | D27: 20 | E27: Haji Mahmud | F27: KK | G27: 520101 1010790004 | H27: L | I27: Kawin | J27: Menang Timur | K27: 29138 | L27: 1979 | M27: =2019-L27 -> 40 | N27: Islam | O27: Sasak | P27: TAMAT SD/SEDERAJAT | R27: PNS/TNI/ POLRI
D28: 21 | E28: Markisah | F28: Istri | G28: 520101 4810850002 | H28: P | I28: Kawin | J28: Dasan Belo | K28: 31328 | L28: 1985 | M28: =2019-L28 -> 34 | N28: Islam | O28: Sasak | P28: SLTA/SEDERAJAT | R28: Mengurus Rumah Tangga
D29: 22 | E29: M Nanang Sastro Wiguna | F29: Anak | G29: 520101 1012040001 | H29: L | I29: Belum kawin | J29: Menang Timur | K29: 38331 | L29: 2004 | M29: =2019-L29 -> 15 | N29: Islam | O29: Sasak | P29: TAMAT SD/SEDERAJAT | R29: Pelajar
B30: 8 | D30: 23 | E30: Haji Rusni | F30: KK | G30: 0 | H30: L | I30: Kawin | K30: 16560 | L30: 1945 | M30: =2019-L30 -> 74 | N30: Islam | P30: - | R30: Pekerja lepas
D31: 24 | E31: Sukini | F31: Istri | G31: 0 | H31: P | I31: Kawin | K31: 20366 | L31: 1955 | M31: =2019-L31 -> 64 | N31: Islam | P31: - | R31: Pekerja lepas
D32: 25 | E32: Mustiani | F32: Anak | G32: 0 | H32: P | I32: Belum kawin | K32: 36614 | L32: 2000 | M32: =2019-L32 -> 19 | N32: Islam | P32: SD/MI | R32: -
B33: 9 | C33: 520101 0503086638 | D33: 26 | E33: Benar | F33: KK | G33: 520101 1112520001 | H33: L | I33: Cerai Mati | J33: Menang Timur | K33: 19339 | L33: 1952 | M33: =2019-L33 -> 67 | N33: Islam | O33: Sasak | P33: BELUM TAMAT SD/SEDERAJAT | R33: Buruh Harian Lepas
D34: 27 | E34: Rohadi | F34: Anak | G34: 520101 1302880007 | H34: L | I34: Belum kawin | J34: Menang Timur | K34: 28534 | L34: 1978 | M34: =2019-L34 -> 41 | N34: Islam | O34: Sasak | P34: BELUM TAMAT SD/SEDERAJAT | R34: Buruh Harian Lepas
B35: 10 | C35: 520101 0503086601 | D35: 28 | E35: Samsiah | F35: KK | G35: 520101 1312640002 | H35: L | I35: Kawin | J35: Menang Timur | K35: 23724 | L35: 1964 | M35: =2019-L35 -> 55 | N35: Islam | O35: Sasak | P35: TAMAT SD/SEDERAJAT | R35: Buruh Harian Lepas
D36: 29 | E36: Ayuni | F36: Istri | G36: 520101 6503660001 | H36: P | I36: Kawin | J36: Menang Timur | K36: 24191 | L36: 1966 | M36: =2019-L36 -> 53 | N36: Islam | O36: Sasak | P36: TAMAT SD/SEDERAJAT | R36: Buruh Harian Lepas
D37: 30 | E37: Saruni | F37: Anak | G37: 520101 6901010003 | H37: P | I37: Belum kawin | J37: Gerung | K37: 36920 | L37: 2001 | M37: =2019-L37 -> 18 | N37: Islam | O37: Sasak | P37: SLTP/SEDERAJAT | R37: Pelajar
B38: 11 | C38: 520101 0503086739 | D38: 31 | E38: Cilok | F38: KK | G38: 520101 6010690001 | H38: P | I38: Cerai Mati | J38: Menang Timur | K38: 14538 | L38: 1939 | M38: =2019-L38 -> 80 | N38: Islam | O38: Sasak | P38: TIDAK/BELUM SEKOLAH | R38: Buruh Harian Lepas
B39: 12 | C39: 5201013108160002 | D39: 32 | E39: Sahrip | F39: KK | G39: 5201010112490002 | H39: L | I39: Kawin | J39: Menang Timur | K39: 43800 | L39: 1949 | M39: =2019-L39 -> 70 | N39: Islam | P39: SD/MI | R39: Buruh Harian Lepas
D40: 33 | E40: Munisah | F40: Istri | G40: 5201015912570001 | H40: P | I40: Kawin | J40: Menang Timur | K40: 43818 | L40: 1957 | M40: =2019-L40 -> 62 | N40: Islam | P40: SD/MI | R40: Buruh Harian Lepas
D41: 34 | E41: Mustiani | F41: Anak | G41: 5201014202991001 | H41: P | I41: Belum kawin | J41: Menang Timur | K41: 43498 | L41: 2001 | M41: =2019-L41 -> 18 | N41: Islam | P41: SD/MI | R41: Pelajar
...

Sheet Sheet1
A1: 31 | C1: 64
A2: 22 | C2: 67
A3: 24 | C3: 82
A4: =SUM(A1:A3) -> 77 | C4: =SUM(C1:C3) -> 213

Sheet pindah keluar
A1: No | D1: Nama Lengkap/panggilan | E1: Kedudukan dalam Keluarga | F1: NIK | G1: Jenis Kelamin (L/P) | H1: Status Perkawinan | I1: Lahir | L1: Usia | M1: Agama | N1: Etnis | O1: Pendidikan Terakhir | P1: Pekerjaan | Q1: Cacat | S1: ada/tidak
B2: Nomor KK | I2: tempat | J2: Tanggal | K2: Tahun | Q2: Mental | R2: Fisik | S2: KK | T2: KTP/KIA | U2: Buku Nikah
C4: 10 | D4: Husnul Khatimah | E4: Anak | F4: 520101 4107900463 | G4: P | H4: Belum kawin | J4: 33238 | M4: Islam | O4: SLTA/MA | P4: Wiraswasta
C5: 89 | D5: Baiq Dwi Astina fitri | E5: Anak | F5: 520101 4107920334 | G5: P | H5: Belum kawin | J5: 33674 | M5: Islam | O5: SLTA/MA | P5: Wiraswasta
C6: 30 | D6: Irmawati | E6: Anak | F6: 520101 6008900001 | G6: P | H6: Belum kawin | J6: 33105 | M6: Islam | O6: SLTP/MTSN | P6: Pekerja lepas
C7: 73 | D7: Demah | E7: Lain-lain | F7: 0 | G7: P | H7: Janda | J7: 22038 | M7: Islam | O7: - | P7: Pekerja lepas
C8: 74 | D8: Nurgina Hidayati | E8: 520101 4101980007 | F8: P | G8: Belum kawin | H8: Anak | I8: 35796 | M8: Islam | O8: SLTP/MTSN | Q8: -
C9: 41 | D9: Inaq Ayah | E9: 0 | F9: P | G9: Belum kawin | H9: Lain-lain | I9: 20271 | M9: Islam | O9: - | Q9: Pekerja lepas

Sheet meninggal
A1: No | D1: Nama Lengkap/panggilan | E1: Kedudukan dalam Keluarga | F1: NIK | G1: Jenis Kelamin (L/P) | H1: Status Perkawinan | I1: Lahir | L1: Usia | M1: Agama | N1: Etnis | O1: Pendidikan Terakhir | P1: Pekerjaan | Q1: Cacat | S1: ada/tidak
B2: Nomor KK | I2: tempat | J2: Tanggal | K2: Tahun | Q2: Mental | R2: Fisik | S2: KK | T2: KTP/KIA | U2: Buku Nikah
C3: 12 | D3: Haji Zainap | E3: Lain-lain | F3: 520101 4107580076 | G3: P | H3: Janda | J3: 17715 | M3: Islam | O3: - | P3: -
C4: 87 | D4: Lalu Herman Sugandi | E4: KK | F4: 520101 3112621007 | G4: L | H4: Kawin | J4: 31/12/1962 | M4: Islam | O4: SLTA/MA | Q4: -
C5: 83 | D5: Lesah | E5: Istri | F5: 0 | G5: P | H5: Kawin | J5: 24107 | M5: Islam | O5: - | Q5: Pekerja lepas
